Workbook
Name Mtoe_to_TWh: 'conversion factor'!$B$10

Sheet 2. share of renewables

Sheet 4. FEC to PEC ratio
B1: Source | C1: Unit | D1: 2005 | I1: 2010 | N1: 2015 | S1: 2020
A2: Total FEC to PEC ratio | C2: % | D2: =D4/D5 -> 0.69521018 | E2: =E4/E5 -> 0.69214644 | F2: =F4/F5 -> 0.69020326 | G2: =G4/G5 -> 0.69635795 | H2: =H4/H5 -> 0.69899125 | I2: =I4/I5 -> 0.70289206 | J2: =J4/J5 -> 0.6972459 | K2: =K4/K5 -> 0.70374932 | ... T2: =T4/T5 -> 0.73862902
A3: Input-output ratio for power and heat | C3: % | D3: =D7/D6 -> 0.47143999 | E3: =E7/E6 -> 0.47030423 | F3: =F7/F6 -> 0.47198021 | G3: =G7/G6 -> 0.47833015 | H3: =H7/H6 -> 0.48463535 | I3: =I7/I6 -> 0.49364167 | J3: =J7/J6 -> 0.48974154 | K3: =K7/K6 -> 0.493304 | ... T3: =T7/T6 -> 0.54513901
A4: Total FEC | B4: Energy balance | C4: Mtoe | D4: 1041.2574 | E4: 1045.8461 | F4: 1028.5167 | G4: 1036.7125 | H4: 980.82991 | I4: 1024.5031 | J4: 984.60139 | K4: 982.56257 | L4: 980.34902 | M4: 938.78575 | N4: 957.87004 | O4: 976.88393 | P4: 989.00026 | Q4: 991.56332 | R4: 985.96802 | S4: 906.25318 | T4: 968.42634
A5: Total PEC | B5: Energy balance | C5: Mtoe | D5: 1497.7591 | E5: 1511.0185 | F5: 1490.165 | G5: 1488.7637 | H5: 1403.2077 | I5: 1457.554 | J5: 1412.1293 | K5: 1396.1826 | L5: 1384.1501 | M5: 1330.4564 | N5: 1352.705 | O5: 1364.0691 | P5: 1383.7981 | Q5: 1377.3392 | R5: 1354.076 | S5: 1235.7807 | T5: 1311.1133
A6: Total transformation input - elec and heat - energy use | B6: Energy balance | C6: ktoe | D6: 663293.07 | E6: 672015.91 | F6: 667542.61 | G6: 660778.2 | H6: 623432.51 | I6: 648117.12 | J6: 635568.08 | K6: 632820.26 | L6: 618297.46 | M6: 603986.19 | N6: 608191.33 | O6: 603565.06 | P6: 606794.68 | Q6: 594360.31 | R6: 576070.97 | S6: 535150.1 | T6: 566253.2
A7: Total transformation output - elec and heat - energy use | B7: Energy balance | C7: ktoe | D7: 312702.88 | E7: 316051.92 | F7: 315066.9 | G7: 316070.14 | H7: 302137.43 | I7: 319937.61 | J7: 311264.09 | K7: 312172.76 | L7: 310405.84 | M7: 300894.91 | N7: 305695.64 | O7: 309850.1 | P7: 312839.74 | Q7: 309894.17 | R7: 305995.34 | S7: 293745.51 | T7: 308686.71
A8: Gross electricity production | B8: Energy balance | C8: ktoe | D8: 250757.53 | E8: 255170.57 | F8: 256472.88 | G8: 257443.64 | H8: 244409.39 | I8: 256204.67 | J8: 252541.88 | K8: 252307.68 | L8: 250764.58 | M8: 245615.35 | N8: 249402.6 | O8: 251248.16 | P8: 254043.3 | Q8: 252625.12 | R8: 249558.9 | S8: 239455.84 | T8: 249915.15
A9: Gross heat production | B9: Energy balance | C9: ktoe | D9: 59679.316 | E9: 58988.21 | F9: 56678.904 | G9: 56703.185 | H9: 55920.872 | I9: 61638.428 | J9: 56963.916 | K9: 58058.013 | L9: 57703.081 | M9: 53326.667 | N9: 53957.768 | O9: 56160.636 | P9: 56068.399 | Q9: 54791.658 | R9: 53882.349 | S9: 51684.573 | T9: 56002.997

Sheet Colour palette
S1: 2020 | T1: 2021 | U1: 2022 | V1: 2023 | W1: 2024 | X1: 2025 | Y1: 2026 | Z1: 2027 | AA1: 2028 | AB1: 2029 | AC1: 2030 | AD1: 2031 | AE1: 2032 | AF1: 2033 | AG1: 2034 | AH1: 2035 | AI1: 2036 | AJ1: 2037 | AK1: 2038 | AL1: 2039 | AM1: 2040 | AN1: 2041 | AO1: 2042 | AP1: 2043 | AQ1: 2044 | AR1: 2045 | AS1: 2046 | AT1: 2047 | AU1: 2048 | AV1: 2049 | AW1: 2050
Q2: Demand-side Focus Pathway | R2: 1 | S2: 1 | T2: 0.98 | U2: 0.96 | V2: 0.94 | W2: 0.92 | X2: 0.9 | Y2: 0.88 | Z2: 0.86 | AA2: 0.85 | AB2: 0.83 | AC2: 0.81 | AD2: 0.79 | AE2: 0.77 | AF2: 0.75 | AG2: 0.73 | AH2: 0.71 | AI2: 0.69 | AJ2: 0.67 | AK2: 0.65 | AL2: 0.63 | AM2: 0.61 | AN2: 0.6 | AO2: 0.58 | AP2: 0.57 | AQ2: 0.56 | AR2: 0.54 | AS2: 0.53 | AT2: 0.52 | AU2: 0.51 | AV2: 0.5 | AW2: 0.49
Q3: High Renewable Energy Pathway | R3: 1 | S3: 1 | T3: 0.99 | U3: 0.99 | V3: 0.98 | W3: 0.97 | X3: 0.96 | Y3: 0.94 | Z3: 0.92 | AA3: 0.89 | AB3: 0.87 | AC3: 0.85 | AD3: 0.83 | AE3: 0.8 | AF3: 0.78 | AG3: 0.75 | AH3: 0.73 | AI3: 0.71 | AJ3: 0.69 | AK3: 0.67 | AL3: 0.64 | AM3: 0.62 | AN3: 0.61 | AO3: 0.6 | AP3: 0.59 | AQ3: 0.58 | AR3: 0.56 | AS3: 0.56 | AT3: 0.55 | AU3: 0.55 | AV3: 0.55 | AW3: 0.54
B4: Font and colours: | E4: Half page width: | Q4: Mixed Options Pathway | R4: 1 | S4: 1.01 | T4: 0.99 | U4: 0.98 | V4: 0.96 | W4: 0.95 | X4: 0.93 | Y4: 0.92 | Z4: 0.9 | AA4: 0.89 | AB4: 0.88 | AC4: 0.86 | AD4: 0.85 | AE4: 0.83 | AF4: 0.82 | AG4: 0.8 | AH4: 0.79 | AI4: 0.78 | AJ4: 0.77 | AK4: 0.77 | AL4: 0.76 | AM4: 0.76 | AN4: 0.76 | AO4: 0.76 | AP4: 0.76 | AQ4: 0.76 | AR4: 0.76 | AS4: 0.76 | AT4: 0.76 | AU4: 0.77 | AV4: 0.77 | AW4: 0.77
Q5: #REF! | R5: 1 | S5: 1 | T5: 0.99 | U5: 0.97 | V5: 0.95 | W5: 0.93 | X5: 0.91 | Y5: 0.9 | Z5: 0.88 | AA5: 0.86 | AB5: 0.84 | AC5: 0.83 | AD5: 0.81 | AE5: 0.79 | AF5: 0.77 | AG5: 0.76 | AH5: 0.74 | AI5: 0.73 | AJ5: 0.72 | AK5: 0.72 | AL5: 0.71 | AM5: 0.7 | AN5: 0.7 | AO5: 0.7 | AP5: 0.7 | AQ5: 0.7 | AR5: 0.7 | AS5: 0.7 | AT5: 0.71 | AU5: 0.71 | AV5: 0.71 | AW5: 0.71
A6: Font: | B6: Segoe UI, size 8 | Q6: #REF! | R6: 1 | S6: 1 | T6: 0.99 | U6: 0.97 | V6: 0.96 | W6: 0.95 | X6: 0.94 | Y6: 0.93 | Z6: 0.91 | AA6: 0.9 | AB6: 0.88 | AC6: 0.87 | AD6: 0.85 | AE6: 0.83 | AF6: 0.81 | AG6: 0.79 | AH6: 0.77 | AI6: 0.76 | AJ6: 0.74 | AK6: 0.72 | AL6: 0.71 | AM6: 0.69 | AN6: 0.69 | AO6: 0.68 | AP6: 0.68 | AQ6: 0.68 | AR6: 0.67 | AS6: 0.67 | AT6: 0.67 | AU6: 0.66 | AV6: 0.66 | AW6: 0.66
B7: Signature colour | Q7: #REF! | R7: 1 | S7: 1 | T7: 0.98 | U7: 0.96 | V7: 0.94 | W7: 0.92 | X7: 0.9 | Y7: 0.88 | Z7: 0.86 | AA7: 0.84 | AB7: 0.83 | AC7: 0.81 | AD7: 0.79 | AE7: 0.77 | AF7: 0.75 | AG7: 0.73 | AH7: 0.71 | AI7: 0.7 | AJ7: 0.7 | AK7: 0.69 | AL7: 0.68 | AM7: 0.68 | AN7: 0.68 | AO7: 0.69 | AP7: 0.69 | AQ7: 0.7 | AR7: 0.7 | AS7: 0.71 | AT7: 0.71 | AU7: 0.71 | AV7: 0.71 | AW7: 0.71
Q8: #REF! | R8: 1 | S8: 1 | T8: 0.99 | U8: 0.99 | V8: 0.98 | W8: 0.97 | X8: 0.96 | Y8: 0.94 | Z8: 0.92 | AA8: 0.89 | AB8: 0.87 | AC8: 0.85 | AD8: 0.83 | AE8: 0.8 | AF8: 0.78 | AG8: 0.76 | AH8: 0.73 | AI8: 0.71 | AJ8: 0.69 | AK8: 0.67 | AL8: 0.65 | AM8: 0.63 | AN8: 0.62 | AO8: 0.6 | AP8: 0.59 | AQ8: 0.58 | AR8: 0.57 | AS8: 0.56 | AT8: 0.56 | AU8: 0.55 | AV8: 0.55 | AW8: 0.54
A9: Gridlines: | B9: Signature colour | Q9: #REF! | R9: 1 | S9: 1 | T9: 0.99 | U9: 0.99 | V9: 0.98 | W9: 0.97 | X9: 0.96 | Y9: 0.94 | Z9: 0.92 | AA9: 0.89 | AB9: 0.87 | AC9: 0.85 | AD9: 0.83 | AE9: 0.8 | AF9: 0.78 | AG9: 0.76 | AH9: 0.73 | AI9: 0.71 | AJ9: 0.69 | AK9: 0.67 | AL9: 0.65 | AM9: 0.63 | AN9: 0.62 | AO9: 0.6 | AP9: 0.59 | AQ9: 0.58 | AR9: 0.57 | AS9: 0.56 | AT9: 0.56 | AU9: 0.55 | AV9: 0.55 | AW9: 0.54
B10: Transparency: 90% | Q10: #REF! | R10: 1 | S10: 1 | T10: 0.99 | U10: 0.99 | V10: 0.98 | W10: 0.97 | X10: 0.96 | Y10: 0.94 | Z10: 0.92 | AA10: 0.89 | AB10: 0.87 | AC10: 0.85 | AD10: 0.82 | AE10: 0.8 | AF10: 0.77 | AG10: 0.75 | AH10: 0.73 | AI10: 0.7 | AJ10: 0.68 | AK10: 0.66 | AL10: 0.64 | AM10: 0.61 | AN10: 0.6 | AO10: 0.59 | AP10: 0.58 | AQ10: 0.57 | AR10: 0.56 | AS10: 0.56 | AT10: 0.56 | AU10: 0.55 | AV10: 0.55 | AW10: 0.55
Q11: #REF! | R11: 1 | S11: 1 | T11: 0.99 | U11: 0.99 | V11: 0.98 | W11: 0.97 | X11: 0.96 | Y11: 0.94 | Z11: 0.92 | AA11: 0.89 | AB11: 0.87 | AC11: 0.85 | AD11: 0.82 | AE11: 0.8 | AF11: 0.77 | AG11: 0.75 | AH11: 0.73 | AI11: 0.7 | AJ11: 0.68 | AK11: 0.66 | AL11: 0.64 | AM11: 0.62 | AN11: 0.6 | AO11: 0.59 | AP11: 0.58 | AQ11: 0.57 | AR11: 0.56 | AS11: 0.56 | AT11: 0.56 | AU11: 0.55 | AV11: 0.55 | AW11: 0.55
A12: Lines: | B12: High width: 2.25 pt | Q12: #REF! | R12: #N/A | S12: #N/A | T12: #N/A | U12: #N/A | V12: #N/A | W12: #N/A | X12: #N/A | Y12: #N/A | Z12: #N/A | AA12: #N/A | AB12: #N/A | AC12: #N/A | AD12: #N/A | AE12: #N/A | AF12: #N/A | AG12: #N/A | AH12: #N/A | AI12: #N/A | AJ12: #N/A | AK12: #N/A | AL12: #N/A | AM12: #N/A | AN12: #N/A | AO12: #N/A | AP12: #N/A | AQ12: #N/A | AR12: #N/A | AS12: #N/A | AT12: #N/A | AU12: #N/A | AV12: #N/A | AW12: #N/A
B13: Low width: 0.25 pt | Q13: #REF! | R13: #N/A | S13: #N/A | T13: #N/A | U13: #N/A | V13: #N/A | W13: #N/A | X13: #N/A | Y13: #N/A | Z13: #N/A | AA13: #N/A | AB13: #N/A | AC13: #N/A | AD13: #N/A | AE13: #N/A | AF13: #N/A | AG13: #N/A | AH13: #N/A | AI13: #N/A | AJ13: #N/A | AK13: #N/A | AL13: #N/A | AM13: #N/A | AN13: #N/A | AO13: #N/A | AP13: #N/A | AQ13: #N/A | AR13: #N/A | AS13: #N/A | AT13: #N/A | AU13: #N/A | AV13: #N/A | AW13: #N/A
Q14: #REF! | R14: 1 | S14: 1 | T14: 0.99 | U14: 0.99 | V14: 0.98 | W14: 0.97 | X14: 0.96 | Y14: 0.94 | Z14: 0.92 | AA14: 0.89 | AB14: 0.87 | AC14: 0.85 | AD14: 0.82 | AE14: 0.8 | AF14: 0.78 | AG14: 0.75 | AH14: 0.73 | AI14: 0.71 | AJ14: 0.68 | AK14: 0.66 | AL14: 0.64 | AM14: 0.62 | AN14: 0.61 | AO14: 0.59 | AP14: 0.58 | AQ14: 0.57 | AR14: 0.56 | AS14: 0.56 | AT14: 0.55 | AU14: 0.55 | AV14: 0.55 | AW14: 0.54
A15: Colours: | B15: Primary colour palette | Q15: #REF! | R15: 1 | S15: 1 | T15: 0.99 | U15: 0.99 | V15: 0.98 | W15: 0.97 | X15: 0.96 | Y15: 0.94 | Z15: 0.92 | AA15: 0.89 | AB15: 0.87 | AC15: 0.85 | AD15: 0.82 | AE15: 0.79 | AF15: 0.77 | AG15: 0.74 | AH15: 0.71 | AI15: 0.69 | AJ15: 0.67 | AK15: 0.65 | AL15: 0.62 | AM15: 0.6 | AN15: 0.59 | AO15: 0.58 | AP15: 0.58 | AQ15: 0.57 | AR15: 0.56 | AS15: 0.56 | AT15: 0.55 | AU15: 0.55 | AV15: 0.55 | AW15: 0.55
Q16: #REF! | R16: 1 | S16: 1.01 | T16: 0.99 | U16: 0.98 | V16: 0.97 | W16: 0.95 | X16: 0.94 | Y16: 0.93 | Z16: 0.91 | AA16: 0.9 | AB16: 0.89 | AC16: 0.87 | AD16: 0.86 | AE16: 0.85 | AF16: 0.83 | AG16: 0.82 | AH16: 0.8 | AI16: 0.79 | AJ16: 0.78 | AK16: 0.77 | AL16: 0.76 | AM16: 0.75 | AN16: 0.75 | AO16: 0.75 | AP16: 0.75 | AQ16: 0.75 | AR16: 0.75 | AS16: 0.76 | AT16: 0.76 | AU16: 0.76 | AV16: 0.76 | AW16: 0.77
Q17: #REF! | R17: #N/A | S17: #N/A | T17: #N/A | U17: #N/A | V17: #N/A | W17: #N/A | X17: #N/A | Y17: #N/A | Z17: #N/A | AA17: #N/A | AB17: #N/A | AC17: #N/A | AD17: #N/A | AE17: #N/A | AF17: #N/A | AG17: #N/A | AH17: #N/A | AI17: #N/A | AJ17: #N/A | AK17: #N/A | AL17: #N/A | AM17: #N/A | AN17: #N/A | AO17: #N/A | AP17: #N/A | AQ17: #N/A | AR17: #N/A | AS17: #N/A | AT17: #N/A | AU17: #N/A | AV17: #N/A | AW17: #N/A
Q18: #REF! | R18: 1 | S18: 1 | T18: 0.99 | U18: 0.99 | V18: 0.98 | W18: 0.97 | X18: 0.96 | Y18: 0.94 | Z18: 0.92 | AA18: 0.89 | AB18: 0.87 | AC18: 0.85 | AD18: 0.82 | AE18: 0.8 | AF18: 0.77 | AG18: 0.75 | AH18: 0.72 | AI18: 0.7 | AJ18: 0.68 | AK18: 0.66 | AL18: 0.64 | AM18: 0.61 | AN18: 0.6 | AO18: 0.59 | AP18: 0.58 | AQ18: 0.57 | AR18: 0.56 | AS18: 0.56 | AT18: 0.55 | AU18: 0.55 | AV18: 0.55 | AW18: 0.54
B19: Primary colour palette | Q19: #REF! | R19: 1 | S19: 1 | T19: 0.99 | U19: 0.99 | V19: 0.98 | W19: 0.97 | X19: 0.96 | Y19: 0.94 | Z19: 0.92 | AA19: 0.89 | AB19: 0.87 | AC19: 0.85 | AD19: 0.82 | AE19: 0.8 | AF19: 0.77 | AG19: 0.75 | AH19: 0.72 | AI19: 0.7 | AJ19: 0.68 | AK19: 0.66 | AL19: 0.64 | AM19: 0.61 | AN19: 0.6 | AO19: 0.59 | AP19: 0.58 | AQ19: 0.57 | AR19: 0.56 | AS19: 0.56 | AT19: 0.56 | AU19: 0.55 | AV19: 0.55 | AW19: 0.54
Q20: #REF! | R20: #N/A | S20: #N/A | T20: #N/A | U20: #N/A | V20: #N/A | W20: #N/A | X20: #N/A | Y20: #N/A | Z20: #N/A | AA20: #N/A | AB20: #N/A | AC20: #N/A | AD20: #N/A | AE20: #N/A | AF20: #N/A | AG20: #N/A | AH20: #N/A | AI20: #N/A | AJ20: #N/A | AK20: #N/A | AL20: #N/A | AM20: #N/A | AN20: #N/A | AO20: #N/A | AP20: #N/A | AQ20: #N/A | AR20: #N/A | AS20: #N/A | AT20: #N/A | AU20: #N/A | AV20: #N/A | AW20: #N/A
B21: Primary colour palette | Q21: #REF! | R21: #N/A | S21: #N/A | T21: #N/A | U21: #N/A | V21: #N/A | W21: #N/A | X21: #N/A | Y21: #N/A | Z21: #N/A | AA21: #N/A | AB21: #N/A | AC21: #N/A | AD21: #N/A | AE21: #N/A | AF21: #N/A | AG21: #N/A | AH21: #N/A | AI21: #N/A | AJ21: #N/A | AK21: #N/A | AL21: #N/A | AM21: #N/A | AN21: #N/A | AO21: #N/A | AP21: #N/A | AQ21: #N/A | AR21: #N/A | AS21: #N/A | AT21: #N/A | AU21: #N/A | AV21: #N/A | AW21: #N/A
Q22: #REF! | R22: 1 | S22: 1 | T22: 0.99 | U22: 0.98 | V22: 0.98 | W22: 0.97 | X22: 0.96 | Y22: 0.94 | Z22: 0.92 | AA22: 0.89 | AB22: 0.87 | AC22: 0.85 | AD22: 0.82 | AE22: 0.8 | AF22: 0.77 | AG22: 0.75 | AH22: 0.73 | AI22: 0.7 | AJ22: 0.68 | AK22: 0.66 | AL22: 0.64 | AM22: 0.62 | AN22: 0.6 | AO22: 0.59 | AP22: 0.58 | AQ22: 0.57 | AR22: 0.56 | AS22: 0.56 | AT22: 0.55 | AU22: 0.55 | AV22: 0.54 | AW22: 0.54
Q23: #REF! | R23: 1 | S23: 1 | T23: 0.99 | U23: 0.99 | V23: 0.98 | W23: 0.97 | X23: 0.96 | Y23: 0.94 | Z23: 0.92 | AA23: 0.89 | AB23: 0.87 | AC23: 0.84 | AD23: 0.82 | AE23: 0.79 | AF23: 0.77 | AG23: 0.74 | AH23: 0.71 | AI23: 0.69 | AJ23: 0.67 | AK23: 0.65 | AL23: 0.63 | AM23: 0.6 | AN23: 0.6 | AO23: 0.59 | AP23: 0.58 | AQ23: 0.57 | AR23: 0.56 | AS23: 0.56 | AT23: 0.56 | AU23: 0.55 | AV23: 0.55 | AW23: 0.55
B24: Primary colour palette | Q24: #REF! | R24: #N/A | S24: #N/A | T24: #N/A | U24: #N/A | V24: #N/A | W24: #N/A | X24: #N/A | Y24: #N/A | Z24: #N/A | AA24: #N/A | AB24: #N/A | AC24: #N/A | AD24: #N/A | AE24: #N/A | AF24: #N/A | AG24: #N/A | AH24: #N/A | AI24: #N/A | AJ24: #N/A | AK24: #N/A | AL24: #N/A | AM24: #N/A | AN24: #N/A | AO24: #N/A | AP24: #N/A | AQ24: #N/A | AR24: #N/A | AS24: #N/A | AT24: #N/A | AU24: #N/A | AV24: #N/A | AW24: #N/A
Q25: #REF! | R25: 1 | S25: 1 | T25: 0.99 | U25: 0.99 | V25: 0.98 | W25: 0.97 | X25: 0.96 | Y25: 0.94 | Z25: 0.92 | AA25: 0.89 | AB25: 0.87 | AC25: 0.85 | AD25: 0.83 | AE25: 0.81 | AF25: 0.8 | AG25: 0.78 | AH25: 0.76 | AI25: 0.74 | AJ25: 0.72 | AK25: 0.7 | AL25: 0.68 | AM25: 0.66 | AN25: 0.65 | AO25: 0.64 | AP25: 0.63 | AQ25: 0.62 | AR25: 0.61 | AS25: 0.61 | AT25: 0.61 | AU25: 0.61 | AV25: 0.61 | AW25: 0.6
E26: Full page width: | Q26: #REF! | R26: 1 | S26: 1 | T26: 0.99 | U26: 0.99 | V26: 0.98 | W26: 0.97 | X26: 0.96 | Y26: 0.94 | Z26: 0.92 | AA26: 0.89 | AB26: 0.87 | AC26: 0.85 | AD26: 0.83 | AE26: 0.81 | AF26: 0.8 | AG26: 0.78 | AH26: 0.76 | AI26: 0.74 | AJ26: 0.72 | AK26: 0.7 | AL26: 0.68 | AM26: 0.66 | AN26: 0.65 | AO26: 0.64 | AP26: 0.63 | AQ26: 0.62 | AR26: 0.61 | AS26: 0.61 | AT26: 0.61 | AU26: 0.61 | AV26: 0.61 | AW26: 0.6
Q27: #REF! | R27: 1 | S27: 1.01 | T27: 0.99 | U27: 0.98 | V27: 0.96 | W27: 0.95 | X27: 0.94 | Y27: 0.92 | Z27: 0.91 | AA27: 0.89 | AB27: 0.88 | AC27: 0.87 | AD27: 0.85 | AE27: 0.84 | AF27: 0.82 | AG27: 0.81 | AH27: 0.79 | AI27: 0.78 | AJ27: 0.78 | AK27: 0.77 | AL27: 0.76 | AM27: 0.75 | AN27: 0.75 | AO27: 0.75 | AP27: 0.75 | AQ27: 0.75 | AR27: 0.75 | AS27: 0.75 | AT27: 0.75 | AU27: 0.76 | AV27: 0.76 | AW27: 0.76
Q28: #REF! | R28: #N/A | S28: #N/A | T28: #N/A | U28: #N/A | V28: #N/A | W28: #N/A | X28: #N/A | Y28: #N/A | Z28: #N/A | AA28: #N/A | AB28: #N/A | AC28: #N/A | AD28: #N/A | AE28: #N/A | AF28: #N/A | AG28: #N/A | AH28: #N/A | AI28: #N/A | AJ28: #N/A | AK28: #N/A | AL28: #N/A | AM28: #N/A | AN28: #N/A | AO28: #N/A | AP28: #N/A | AQ28: #N/A | AR28: #N/A | AS28: #N/A | AT28: #N/A | AU28: #N/A | AV28: #N/A | AW28: #N/A
Q29: #REF! | R29: #N/A | S29: #N/A | T29: #N/A | U29: #N/A | V29: #N/A | W29: #N/A | X29: #N/A | Y29: #N/A | Z29: #N/A | AA29: #N/A | AB29: #N/A | AC29: #N/A | AD29: #N/A | AE29: #N/A | AF29: #N/A | AG29: #N/A | AH29: #N/A | AI29: #N/A | AJ29: #N/A | AK29: #N/A | AL29: #N/A | AM29: #N/A | AN29: #N/A | AO29: #N/A | AP29: #N/A | AQ29: #N/A | AR29: #N/A | AS29: #N/A | AT29: #N/A | AU29: #N/A | AV29: #N/A | AW29: #N/A
Q30: #REF! | R30: 1 | S30: 1 | T30: 0.99 | U30: 0.99 | V30: 0.98 | W30: 0.97 | X30: 0.96 | Y30: 0.94 | Z30: 0.92 | AA30: 0.89 | AB30: 0.87 | AC30: 0.85 | AD30: 0.83 | AE30: 0.81 | AF30: 0.8 | AG30: 0.78 | AH30: 0.76 | AI30: 0.74 | AJ30: 0.72 | AK30: 0.7 | AL30: 0.68 | AM30: 0.65 | AN30: 0.65 | AO30: 0.64 | AP30: 0.63 | AQ30: 0.62 | AR30: 0.61 | AS30: 0.61 | AT30: 0.6 | AU30: 0.6 | AV30: 0.6 | AW30: 0.59
A31: Title and | B31: In Word document | Q31: #REF! | R31: 1 | S31: 1 | T31: 0.99 | U31: 0.99 | V31: 0.98 | W31: 0.97 | X31: 0.96 | Y31: 0.94 | Z31: 0.92 | AA31: 0.89 | AB31: 0.87 | AC31: 0.85 | AD31: 0.83 | AE31: 0.8 | AF31: 0.78 | AG31: 0.76 | AH31: 0.73 | AI31: 0.71 | AJ31: 0.69 | AK31: 0.66 | AL31: 0.64 | AM31: 0.62 | AN31: 0.61 | AO31: 0.6 | AP31: 0.6 | AQ31: 0.59 | AR31: 0.59 | AS31: 0.58 | AT31: 0.58 | AU31: 0.58 | AV31: 0.58 | AW31: 0.58
A32: source: | B32: (CO2 / Energy / Supply / Electricity) | Q32: #REF! | R32: 1 | S32: 1 | T32: 0.99 | U32: 0.99 | V32: 0.98 | W32: 0.97 | X32: 0.96 | Y32: 0.94 | Z32: 0.92 | AA32: 0.89 | AB32: 0.87 | AC32: 0.85 | AD32: 0.82 | AE32: 0.79 | AF32: 0.76 | AG32: 0.73 | AH32: 0.7 | AI32: 0.68 | AJ32: 0.66 | AK32: 0.64 | AL32: 0.62 | AM32: 0.6 | AN32: 0.6 | AO32: 0.6 | AP32: 0.59 | AQ32: 0.59 | AR32: 0.59 | AS32: 0.59 | AT32: 0.59 | AU32: 0.6 | AV32: 0.6 | AW32: 0.6
Q33: #REF! | R33: 1 | S33: 1 | T33: 0.99 | U33: 0.99 | V33: 0.98 | W33: 0.97 | X33: 0.97 | Y33: 0.96 | Z33: 0.95 | AA33: 0.94 | AB33: 0.94 | AC33: 0.93 | AD33: 0.92 | AE33: 0.9 | AF33: 0.89 | AG33: 0.88 | AH33: 0.87 | AI33: 0.85 | AJ33: 0.83 | AK33: 0.81 | AL33: 0.8 | AM33: 0.78 | AN33: 0.77 | AO33: 0.76 | AP33: 0.76 | AQ33: 0.75 | AR33: 0.74 | AS33: 0.74 | AT33: 0.73 | AU33: 0.72 | AV33: 0.72 | AW33: 0.71
Q34: #REF! | R34: 1 | S34: 1 | T34: 0.99 | U34: 0.99 | V34: 0.98 | W34: 0.98 | X34: 0.97 | Y34: 0.96 | Z34: 0.95 | AA34: 0.95 | AB34: 0.94 | AC34: 0.93 | AD34: 0.92 | AE34: 0.91 | AF34: 0.9 | AG34: 0.89 | AH34: 0.87 | AI34: 0.86 | AJ34: 0.84 | AK34: 0.82 | AL34: 0.8 | AM34: 0.78 | AN34: 0.78 | AO34: 0.77 | AP34: 0.76 | AQ34: 0.76 | AR34: 0.75 | AS34: 0.74 | AT34: 0.74 | AU34: 0.73 | AV34: 0.72 | AW34: 0.71
Q35: #REF! | R35: 1 | S35: 1 | T35: 0.99 | U35: 0.99 | V35: 0.98 | W35: 0.98 | X35: 0.97 | Y35: 0.97 | Z35: 0.96 | AA35: 0.95 | AB35: 0.95 | AC35: 0.94 | AD35: 0.93 | AE35: 0.92 | AF35: 0.9 | AG35: 0.89 | AH35: 0.88 | AI35: 0.86 | AJ35: 0.85 | AK35: 0.83 | AL35: 0.81 | AM35: 0.79 | AN35: 0.78 | AO35: 0.78 | AP35: 0.77 | AQ35: 0.76 | AR35: 0.75 | AS35: 0.75 | AT35: 0.74 | AU35: 0.73 | AV35: 0.72 | AW35: 0.71
Q36: #REF! | R36: 1 | S36: 1 | T36: 0.99 | U36: 0.99 | V36: 0.98 | W36: 0.97 | X36: 0.97 | Y36: 0.96 | Z36: 0.95 | AA36: 0.94 | AB36: 0.93 | AC36: 0.92 | AD36: 0.91 | AE36: 0.9 | AF36: 0.89 | AG36: 0.88 | AH36: 0.86 | AI36: 0.85 | AJ36: 0.83 | AK36: 0.81 | AL36: 0.79 | AM36: 0.77 | AN36: 0.77 | AO36: 0.76 | AP36: 0.75 | AQ36: 0.75 | AR36: 0.74 | AS36: 0.73 | AT36: 0.73 | AU36: 0.72 | AV36: 0.71 | AW36: 0.71
Q37: #REF! | R37: 1 | S37: 1 | T37: 0.98 | U37: 0.96 | V37: 0.95 | W37: 0.93 | X37: 0.91 | Y37: 0.9 | Z37: 0.89 | AA37: 0.88 | AB37: 0.87 | AC37: 0.86 | AD37: 0.84 | AE37: 0.83 | AF37: 0.82 | AG37: 0.8 | AH37: 0.79 | AI37: 0.77 | AJ37: 0.75 | AK37: 0.72 | AL37: 0.7 | AM37: 0.68 | AN37: 0.67 | AO37: 0.66 | AP37: 0.65 | AQ37: 0.64 | AR37: 0.63 | AS37: 0.63 | AT37: 0.62 | AU37: 0.61 | AV37: 0.61 | AW37: 0.6
Q38: #REF! | R38: 1 | S38: 1 | T38: 0.99 | U38: 0.98 | V38: 0.96 | W38: 0.95 | X38: 0.94 | Y38: 0.92 | Z38: 0.91 | AA38: 0.89 | AB38: 0.88 | AC38: 0.86 | AD38: 0.85 | AE38: 0.83 | AF38: 0.81 | AG38: 0.8 | AH38: 0.78 | AI38: 0.78 | AJ38: 0.77 | AK38: 0.76 | AL38: 0.76 | AM38: 0.75 | AN38: 0.75 | AO38: 0.75 | AP38: 0.75 | AQ38: 0.75 | AR38: 0.75 | AS38: 0.75 | AT38: 0.75 | AU38: 0.75 | AV38: 0.75 | AW38: 0.76
Q39: #REF! | R39: 1 | S39: 0.99 | T39: 0.97 | U39: 0.95 | V39: 0.93 | W39: 0.91 | X39: 0.89 | Y39: 0.88 | Z39: 0.87 | AA39: 0.85 | AB39: 0.84 | AC39: 0.83 | AD39: 0.81 | AE39: 0.79 | AF39: 0.77 | AG39: 0.76 | AH39: 0.74 | AI39: 0.72 | AJ39: 0.71 | AK39: 0.69 | AL39: 0.68 | AM39: 0.66 | AN39: 0.65 | AO39: 0.64 | AP39: 0.64 | AQ39: 0.63 | AR39: 0.62 | AS39: 0.62 | AT39: 0.61 | AU39: 0.61 | AV39: 0.6 | AW39: 0.6
Q40: #REF! | R40: 1 | S40: 1 | T40: 0.99 | U40: 0.97 | V40: 0.96 | W40: 0.95 | X40: 0.94 | Y40: 0.93 | Z40: 0.91 | AA40: 0.9 | AB40: 0.88 | AC40: 0.87 | AD40: 0.85 | AE40: 0.83 | AF40: 0.81 | AG40: 0.79 | AH40: 0.77 | AI40: 0.76 | AJ40: 0.74 | AK40: 0.73 | AL40: 0.71 | AM40: 0.69 | AN40: 0.69 | AO40: 0.68 | AP40: 0.68 | AQ40: 0.68 | AR40: 0.67 | AS40: 0.67 | AT40: 0.67 | AU40: 0.66 | AV40: 0.66 | AW40: 0.66
...

Sheet O1 & Fig 2. GHG emissions
A1: Graph 1
B2: Source | C2: Unit | D2: 1990 | S2: 2005 | X2: 2010 | AC2: 2015 | AH2: 2020 | AM2: 2025 | AR2: 2030 | AW2: 2035 | BB2: 2040 | BG2: 2045 | BL2: 2050
A3: Total | B3: EEA GHG data viewer | C3: Mt CO2e | D3: =($V$68*D5)+SUM(D6:D13) -> 4777.3938 | S3: =SUM(S6:S13)+S5*$V$68 -> 4393.8544 | T3: =SUM(T6:T13)+T5*$V$68 -> 4392.7755 | U3: =SUM(U6:U13)+U5*$V$68 -> 4417.4073 | V3: =SUM(V6:V13)+V5*$V$68 -> 4279.5858 | W3: =SUM(W6:W13)+W5*$V$68 -> 3940.7242 | X3: =SUM(X6:X13)+X5*$V$68 -> 4025.1679 | Y3: =SUM(Y6:Y13)+Y5*$V$68 -> 3921.3273 | Z3: =SUM(Z6:Z13)+Z5*$V$68 -> 3843.6804 | ... AJ3: =SUM(AJ6:AJ13)+AJ5*$V$68 -> 3333.9118
A4: WAM projections | B4: EEA GHG data viewer | C4: Mt CO2e | AI4: ='MS projections raw data'!N46 -> 3303.8425 | AJ4: ='MS projections raw data'!O46 -> 3207.1956 | AK4: ='MS projections raw data'!P46 -> 3179.0117 | AL4: ='MS projections raw data'!Q46 -> 3075.5284 | AM4: ='MS projections raw data'!R46 -> 2986.8554 | AN4: ='MS projections raw data'!S46 -> 2871.6228 | AO4: ='MS projections raw data'!T46 -> 2752.349 | AP4: ='MS projections raw data'!U46 -> 2646.9268 | ... BL4: ='MS projections raw data'!AQ46 -> 1716.6647
A5: International maritime | B5: EEA GHG data viewer | C5: Mt CO2e | D5: =D86/1000 -> 102.11497 | S5: =S86/1000 -> 153.71822 | T5: =T86/1000 -> 164.51554 | U5: =U86/1000 -> 171.66204 | V5: =V86/1000 -> 169.48976 | W5: =W86/1000 -> 150.69215 | X5: =X86/1000 -> 151.61654 | Y5: =Y86/1000 -> 150.43869 | Z5: =Z86/1000 -> 140.07679 | ... AJ5: =AJ86/1000 -> 137.74268
A6: International aviation | B6: EEA GHG data viewer | C6: Mt CO2e | D6: =D85/1000 -> 54.097721 | S6: =S85/1000 -> 96.093547 | T6: =T85/1000 -> 101.16153 | U6: =U85/1000 -> 105.83007 | V6: =V85/1000 -> 107.39423 | W6: =W85/1000 -> 98.727741 | X6: =X85/1000 -> 100.3677 | Y6: =Y85/1000 -> 102.83706 | Z6: =Z85/1000 -> 101.71127 | ... AJ6: =AJ85/1000 -> 103.28234
A7: Energy supply | B7: EEA GHG data viewer | C7: Mt CO2e | D7: =(D74+D83)/1000 -> 1610.7598 | S7: =(S74+S83)/1000 -> 1489.2309 | T7: =(T74+T83)/1000 -> 1494.1525 | U7: =(U74+U83)/1000 -> 1503.6685 | V7: =(V74+V83)/1000 -> 1433.2436 | W7: =(W74+W83)/1000 -> 1325.2181 | X7: =(X74+X83)/1000 -> 1343.1401 | Y7: =(Y74+Y83)/1000 -> 1333.8555 | Z7: =(Z74+Z83)/1000 -> 1315.8796 | ... AJ7: =(AJ74+AJ83)/1000 -> 924.33416
A8: Industry | B8: EEA GHG data viewer | C8: Mt CO2e | D8: =(D75+D87)/1000 -> 1173.8012 | S8: =(S75+S87)/1000 -> 981.27376 | T8: =(T75+T87)/1000 -> 973.78646 | U8: =(U75+U87)/1000 -> 995.61813 | V8: =(V75+V87)/1000 -> 952.33845 | W8: =(W75+W87)/1000 -> 789.42831 | X8: =(X75+X87)/1000 -> 838.81444 | Y8: =(Y75+Y87)/1000 -> 826.15345 | Z8: =(Z75+Z87)/1000 -> 795.67043 | ... AJ8: =(AJ75+AJ87)/1000 -> 691.32881
A9: Transport | B9: EEA GHG data viewer | C9: Mt CO2e | D9: =(D76)/1000 -> 672.47557 | S9: =(S76)/1000 -> 847.3859 | T9: =(T76)/1000 -> 855.4936 | U9: =(U76)/1000 -> 863.98736 | V9: =(V76)/1000 -> 844.92426 | W9: =(W76)/1000 -> 823.12303 | X9: =(X76)/1000 -> 817.63933 | Y9: =(Y76)/1000 -> 808.24043 | Z9: =(Z76)/1000 -> 778.70675 | ... AJ9: =(AJ76)/1000 -> 803.30064
A10: Buildings and agriculture energy | B10: EEA GHG data viewer | C10: Mt CO2e | D10: =D77/1000 -> 712.67284 | S10: =S77/1000 -> 665.03924 | T10: =T77/1000 -> 663.44783 | U10: =U77/1000 -> 589.49466 | V10: =V77/1000 -> 635.07002 | W10: =W77/1000 -> 621.38705 | X10: =X77/1000 -> 656.09143 | Y10: =Y77/1000 -> 581.49116 | Z10: =Z77/1000 -> 589.57096 | ... AJ10: =AJ77/1000 -> 481.83207
A11: Agriculture (non-energy) | B11: EEA GHG data viewer | C11: Mt CO2e | D11: =D88/1000 -> 484.60681 | S11: =S88/1000 -> 389.22394 | T11: =T88/1000 -> 386.07974 | U11: =U88/1000 -> 389.07721 | V11: =V88/1000 -> 386.57501 | W11: =W88/1000 -> 381.54065 | X11: =X88/1000 -> 376.26183 | Y11: =Y88/1000 -> 375.71069 | Z11: =Z88/1000 -> 375.53513 | ... AJ11: =AJ88/1000 -> 370.64949
A12: LULUCF | B12: EEA GHG data viewer | C12: Mt CO2e | D12: =D89/1000 -> -208.79523 | S12: =S89/1000 -> -342.10948 | T12: =T89/1000 -> -351.29638 | U12: =U89/1000 -> -300.61729 | V12: =V89/1000 -> -344.26277 | W12: =W89/1000 -> -347.02233 | X12: =X89/1000 -> -352.59019 | Y12: =Y89/1000 -> -347.2738 | Z12: =Z89/1000 -> -342.6336 | ... AJ12: =AJ89/1000 -> -243.76729
A13: Waste and other sectors | B13: EEA GHG data viewer | C13: Mt CO2e | D13: =D95/1000-D12-D11-D10-D9-D8-D7 -> 212.68138 | S13: =S95/1000-S12-S11-S10-S9-S8-S7 -> 169.7282 | T13: =T95/1000-T12-T11-T10-T9-T8-T7 -> 165.07888 | U13: =U95/1000-U12-U11-U10-U9-U8-U7 -> 160.92182 | V13: =V95/1000-V12-V11-V10-V9-V8-V7 -> 156.26092 | W13: =W95/1000-W12-W11-W10-W9-W8-W7 -> 152.26219 | X13: =X95/1000-X12-X11-X10-X9-X8-X7 -> 148.79456 | Y13: =Y95/1000-Y12-Y11-Y10-Y9-Y8-Y7 -> 144.41494 | Z13: =Z95/1000-Z12-Z11-Z10-Z9-Z8-Z7 -> 139.94723 | ... AJ13: =AJ95/1000-AJ12-AJ11-AJ10-AJ9-AJ8-AJ7 -> 115.14677
A14: 2020 (-20%) | AH14: =(D94+D85)/1000*0.8 -> 3936.8763
A15: 2030 (-55%) | AR15: =0.45*D3 -> 2149.8272
A16: 2040 advice (-90 to -95%) | BB16: =BB17 -> 238.86969
A17: 2040 dummy | BB17: =0.05*D3 -> 238.86969
A18: 2050 (climate neutrality) | BL18: 0
A19: linear trajectory to targets | AJ19: 3248.2071 | AK19: 3107.2481 | AL19: 2966.2891 | AM19: 2825.3301 | AN19: 2684.3711 | AO19: 2543.4121 | AP19: 2402.4531 | AQ19: 2261.4941 | AR19: 2120.535 | AV19: 1696.428 | AW19: 1590.4013 | AX19: 1484.3745 | AY19: 1378.3478 | AZ19: 1272.321 | BA19: 1166.2943 | BB19: 1060.2675 | BC19: 954.24077 | BD19: 848.21402 | BE19: 742.18726 | BF19: 636.16051 | BG19: 530.13376 | BH19: 424.10701 | BI19: 318.08026 | BJ19: 212.0535 | BK19: 106.02675 | BL19: 4.5474735e-13
A20: linear trajector towards 2040 range | AR20: 2120.535 | AV20: 1460.813 | AW20: 1295.8825 | AX20: 1130.952 | AY20: 966.02152 | AZ20: 801.09102 | BA20: 636.16051 | BB20: 471.23001
A21: linear trajector towards 2040 advice | AR21: 2120.535 | AV21: 1366.567 | AW21: 1178.075 | AX21: 989.58302 | AY21: 801.09102 | AZ21: 612.59901 | BA21: 424.10701 | BB21: 235.615
A23: Average 2005-2022 | S23: =(AJ3-S3)/17 -> -62.349568
A24: Average 2018-2022 | S24: =AVERAGE(AJ3-AI3,AI3-AH3,AH3-AG3,AG3-AF3) -> -94.323105
A25: Average 2023-2030 | S25: =AK19-AJ19 -> -140.95901
A26: Average 2031-2050 | S26: =BF19-BE19 -> -106.02675
A27: Average 2031-2040 (95%) | S27: =(BB17-AS19)/9 -> 26.541077
A28: Average 2031-2040 (90%) | S28: =(2*BB17-AS19)/9 -> 53.082154
A30: WAM 2030 compared to 1990 | S30: =AR4/D3-1 -> -0.49149456
S35: =X8-U8 -> -156.80369
V36: INDICATOR O1
A37: Graph 1
S38: 2005 | T38: 2022 | U38: 2005-2022 | V38: 2005-2022 %
A39: Energy supply | S39: =S7 -> 1489.2309 | T39: =AJ7 -> 924.33416 | U39: =T39-S39 -> -564.89671 | V39: =T39/S39-1 -> -0.37932111
A40: Industry | S40: =S8 -> 981.27376 | T40: =AJ8 -> 691.32881 | U40: =T40-S40 -> -289.94494 | V40: =T40/S40-1 -> -0.29547814
A41: Transport (incl. int. bunkers) | S41: =S9+S6+S5*$V$68 -> 1041.4679 | T41: =AJ9+AJ6+AJ5*V68 -> 994.38777 | U41: =T41-S41 -> -47.080151 | V41: =T41/S41-1 -> -0.04520557
A42: Buildings and agriculture energy | S42: =S10 -> 665.03924 | T42: =AJ10 -> 481.83207 | U42: =T42-S42 -> -183.20717 | V42: =T42/S42-1 -> -0.27548325
A43: Agriculture (non-energy) | S43: =S11 -> 389.22394 | T43: =AJ11 -> 370.64949 | U43: =T43-S43 -> -18.574447 | V43: =T43/S43-1 -> -0.047721748
A44: Waste and other sectors | S44: =S13 -> 169.7282 | T44: =AJ13 -> 115.14677 | U44: =T44-S44 -> -54.581429 | V44: =T44/S44-1 -> -0.32158138
A45: LULUCF | S45: =S12 -> -342.10948 | T45: =AJ12 -> -243.76729 | U45: =T45-S45 -> 98.342187 | V45: =T45/S45-1 -> -0.28745824
S51: =S41+#REF! -> #REF! | T51: =T41+#REF! -> #REF!
...

Sheet O2. Primary & final energy use
A1: Graph
B2: Source | C2: Unit | D2: Conversion | E2: 2005 | J2: 2010 | O2: 2015 | T2: 2020 | Y2: 2025 | AD2: 2030 | AI2: 2035 | AN2: 2040 | AS2: 2045 | AX2: 2050
A3: PEC | B3: Eurostat | C3: Mtoe | D3: ='conversion factor'!$E$5 -> 0.01163 | E3: 1497.7591 | F3: 1511.0185 | G3: 1490.165 | H3: 1488.7637 | I3: 1403.2077 | J3: 1457.554 | K3: 1412.1293 | L3: 1396.1826 | M3: 1384.1501 | N3: 1330.4564 | O3: 1352.705 | P3: 1364.0691 | Q3: 1383.7981 | R3: 1377.3392 | S3: 1354.076 | T3: 1235.7807 | U3: 1311.1133
A4: FEC | B4: Eurostat | C4: Mtoe | D4: ='conversion factor'!$E$5 -> 0.01163 | E4: 1041.2574 | F4: 1045.8461 | G4: 1028.5167 | H4: 1036.7125 | I4: 980.82991 | J4: 1024.5031 | K4: 984.60139 | L4: 982.56257 | M4: 980.34902 | N4: 938.78575 | O4: 957.87004 | P4: 976.88393 | Q4: 989.00026 | R4: 991.56332 | S4: 985.96802 | T4: 906.25318 | U4: 968.42634
A6: PEC | B6: Eurostat | C6: TWh | D6: ='conversion factor'!$E$6 -> 11.63 | E6: =E3*$D6 -> 17418.938 | F6: =F3*$D6 -> 17573.145 | G6: =G3*$D6 -> 17330.619 | H6: =H3*$D6 -> 17314.322 | I6: =I3*$D6 -> 16319.306 | J6: =J3*$D6 -> 16951.353 | K6: =K3*$D6 -> 16423.064 | L6: =L3*$D6 -> 16237.604 | ... U6: =U3*$D6 -> 15248.248
A7: FEC | B7: Eurostat | C7: TWh | D7: ='conversion factor'!$E$6 -> 11.63 | E7: =E4*$D7 -> 12109.823 | F7: =F4*$D7 -> 12163.19 | G7: =G4*$D7 -> 11961.65 | H7: =H4*$D7 -> 12056.966 | I7: =I4*$D7 -> 11407.052 | J7: =J4*$D7 -> 11914.971 | K7: =K4*$D7 -> 11450.914 | L7: =L4*$D7 -> 11427.203 | ... U7: =U4*$D7 -> 11262.798
A8: Solid fossil fuels | C8: TWh | D8: ='conversion factor'!$E$5 -> 0.01163 | E8: =(E60+E62)*$D8 -> 338.53715 | F8: =(F60+F62)*$D8 -> 354.5083 | G8: =(G60+G62)*$D8 -> 346.73655 | H8: =(H60+H62)*$D8 -> 339.56691 | I8: =(I60+I62)*$D8 -> 303.42755 | J8: =(J60+J62)*$D8 -> 323.55036 | K8: =(K60+K62)*$D8 -> 319.69757 | L8: =(L60+L62)*$D8 -> 307.91276 | ... U8: =(U60+U62)*$D8 -> 225.52955 | AX8: =C148 -> 6.8399002
A9: Oil products | C9: TWh | D9: ='conversion factor'!$E$5 -> 0.01163 | E9: =(46+E65+E78)*$D9 -> 5078.9422 | F9: =(46+F65+F78)*$D9 -> 5080.4669 | G9: =(46+G65+G78)*$D9 -> 4942.0336 | H9: =(46+H65+H78)*$D9 -> 4945.2475 | I9: =(46+I65+I78)*$D9 -> 4686.3011 | J9: =(46+J65+J78)*$D9 -> 4636.9409 | K9: =(46+K65+K78)*$D9 -> 4516.7297 | L9: =(46+L65+L78)*$D9 -> 4359.8925 | ... U9: =(46+U65+U78)*$D9 -> 4058.8654 | AX9: =E148 -> 162.63784
A10: Fossil gases | C10: TWh | D10: ='conversion factor'!$E$5 -> 0.01163 | E10: =(E61+E64)*$D10 -> 2665.7097 | F10: =(F61+F64)*$D10 -> 2609.376 | G10: =(G61+G64)*$D10 -> 2489.0672 | H10: =(H61+H64)*$D10 -> 2528.8634 | I10: =(I61+I64)*$D10 -> 2366.0323 | J10: =(J61+J64)*$D10 -> 2591.6298 | K10: =(K61+K64)*$D10 -> 2385.6286 | L10: =(L61+L64)*$D10 -> 2444.1026 | ... U10: =(U61+U64)*$D10 -> 2517.5242 | AX10: =G148 -> 88.767533
A11: Electricity | C11: TWh | D11: ='conversion factor'!$E$5 -> 0.01163 | E11: =E73*$D11 -> 2435.6737 | F11: =F73*$D11 -> 2487.9653 | G11: =G73*$D11 -> 2507.6016 | H11: =H73*$D11 -> 2521.0477 | I11: =I73*$D11 -> 2392.8326 | J11: =J73*$D11 -> 2510.6553 | K11: =K73*$D11 -> 2475.454 | L11: =L73*$D11 -> 2484.0507 | ... U11: =U73*$D11 -> 2487.2038 | AX11: =M148 -> 3439.0984
A12: Biomass | C12: TWh | D12: ='conversion factor'!$E$5 -> 0.01163 | E12: =E67*$D12 -> 692.08622 | F12: =F67*$D12 -> 744.19388 | G12: =G67*$D12 -> 815.54689 | H12: =H67*$D12 -> 870.34011 | I12: =I67*$D12 -> 898.78376 | J12: =J67*$D12 -> 975.02217 | K12: =K67*$D12 -> 937.10442 | L12: =L67*$D12 -> 1011.0632 | ... U12: =U67*$D12 -> 1249.1495 | AX12: =K148 -> 947.10183
A13: Other renewables | C13: TWh | D13: ='conversion factor'!$E$5 -> 0.01163 | E13: =E68*$D13 -> 13.659679 | F13: =F68*$D13 -> 14.800245 | G13: =G68*$D13 -> 16.198183 | H13: =H68*$D13 -> 18.330043 | I13: =I68*$D13 -> 20.595288 | J13: =J68*$D13 -> 22.25147 | K13: =K68*$D13 -> 24.464984 | L13: =L68*$D13 -> 25.730491 | ... U13: =U68*$D13 -> 35.294631 | AX13: =L148 -> 644.4236
A14: Others | C14: TWh | D14: ='conversion factor'!$E$5 -> 0.01163 | E14: =(E74+E72)*$D14 -> 612.31508 | F14: =(F74+F72)*$D14 -> 602.48652 | G14: =(G74+G72)*$D14 -> 576.15863 | H14: =(H74+H72)*$D14 -> 586.07905 | I14: =(I74+I72)*$D14 -> 578.9828 | J14: =(J74+J72)*$D14 -> 632.29161 | K14: =(K74+K72)*$D14 -> 585.54846 | L14: =(L74+L72)*$D14 -> 599.34931 | ... U14: =(U74+U72)*$D14 -> 607.85182 | AX14: =J148 -> 539.42217
A15: H2 and derivates | C15: TWh | AX15: =H148+I148+F148 -> 1329.8162
A16: FEC benchmark | B16: EED for 2030, 2020 CTP for 2050 (figure 37) | C16: TWh | AD16: =763*'conversion factor'!$E$6 -> 8873.69 | AX16: =N148 -> 7158.1074
A17: PEC benchmark | B17: EED for 2030, 1.5LIFE for 2050 (figure 17) | C17: TWh | AD17: =992.5*'conversion factor'!$E$6 -> 11542.775
A18: linear trajectory - FEC | C18: TWh | U18: =U7 -> 11262.798 | V18: =U18-($U18-$AD16)/9 -> 10997.342 | W18: =V18-($U18-$AD16)/9 -> 10731.885 | X18: =W18-($U18-$AD16)/9 -> 10466.429 | Y18: =X18-($U18-$AD16)/9 -> 10200.972 | Z18: =Y18-($U18-$AD16)/9 -> 9935.5159 | AA18: =Z18-($U18-$AD16)/9 -> 9670.0594 | AB18: =AA18-($U18-$AD16)/9 -> 9404.603 | AC18: =AB18-($U18-$AD16)/9 -> 9139.1465 | AD18: =AC18-($U18-$AD16)/9 -> 8873.69 | AE18: =AD18-($AD18-$AX20)/20 -> 8735.767 | AF18: =AE18-($AD18-$AX20)/20 -> 8597.844 | AG18: =AF18-($AD18-$AX20)/20 -> 8459.921 | AH18: =AG18-($AD18-$AX20)/20 -> 8321.998 | AI18: =AH18-($AD18-$AX20)/20 -> 8184.075 | AJ18: =AI18-($AD18-$AX20)/20 -> 8046.1521 | AK18: =AJ18-($AD18-$AX20)/20 -> 7908.2291 | AL18: =AK18-($AD18-$AX20)/20 -> 7770.3061 | ... AX18: =AW18-($AD18-$AX20)/20 -> 6115.2302
A19: linear trajectory - PEC | C19: TWh | U19: =U6 -> 15248.248 | V19: =U19-($U19-$AD17)/9 -> 14836.529 | W19: =V19-($U19-$AD17)/9 -> 14424.809 | X19: =W19-($U19-$AD17)/9 -> 14013.09 | Y19: =X19-($U19-$AD17)/9 -> 13601.371 | Z19: =Y19-($U19-$AD17)/9 -> 13189.652 | AA19: =Z19-($U19-$AD17)/9 -> 12777.933 | AB19: =AA19-($U19-$AD17)/9 -> 12366.213 | AC19: =AB19-($U19-$AD17)/9 -> 11954.494 | AD19: =AC19-($U19-$AD17)/9 -> 11542.775 | AE19: =AD19-($AD19-$AX21)/20 -> 11411.94 | AF19: =AE19-($AD19-$AX21)/20 -> 11281.105 | AG19: =AF19-($AD19-$AX21)/20 -> 11150.271 | AH19: =AG19-($AD19-$AX21)/20 -> 11019.436 | AI19: =AH19-($AD19-$AX21)/20 -> 10888.601 | AJ19: =AI19-($AD19-$AX21)/20 -> 10757.766 | AK19: =AJ19-($AD19-$AX21)/20 -> 10626.932 | AL19: =AK19-($AD19-$AX21)/20 -> 10496.097 | ... AX19: =AW19-($AD19-$AX21)/20 -> 8926.0799
A20: FEC - 2040 advice scenarios | C20: TWh | AD20: =O160 -> 9428.6201 | AN20: =O163 -> 6817.3606 | AX20: =O166 -> 6115.2302
A21: PEC - 2040 advice scenarios | C21: TWh | AD21: =P117 -> 12768.989 | AN21: =P118 -> 9580.9355 | AX21: =P119 -> 8926.0799
E24: Absolute | F24: Relative | G24: per year
A25: 2005-2021 PEC | E25: =U6-E6 -> -2170.6905 | F25: =U6/E6-1 -> -0.12461669 | G25: =E25/16 -> -135.66816
A26: 2005-2021 FEC | E26: =U7-E7 -> -847.0249 | F26: =U7/E7-1 -> -0.069945274 | G26: =E26/16 -> -52.939056
A27: 2022-2030 FEC | G27: =AD18-AC18 -> -265.45648
A28: 2031-2050 FEC | G28: =AE18-AD18 -> -137.92299
A29: 2031-2040 ESABCC | G29: =(AN20-AD18)/10 -> -205.63294
A56: Historical raw data
A57: Final energy consumption (excl. aviation)
E58: 2005 | F58: 2006 | G58: 2007 | H58: 2008 | I58: 2009 | J58: 2010 | K58: 2011 | L58: 2012 | M58: 2013 | N58: 2014 | O58: 2015 | P58: 2016 | Q58: 2017 | R58: 2018 | S58: 2019 | T58: 2020 | U58: 2021
A59: Total | E59: 986665.26 | F59: 989951.38 | G59: 971318.81 | H59: 980665.27 | I59: 935196.9 | J59: 973238.43 | K59: 933799.89 | L59: 933168.99 | M59: 931391.98 | N59: 890023.88 | O59: 908984.15 | P59: 927265.93 | Q59: 940167.95 | R59: 942179.34 | S59: 937506.45 | T59: 885085.84 | U59: 939886.9
A60: Solid fossil fuels | E60: 28537.155 | F60: 29834.966 | G60: 29168.041 | H60: 28552.088 | I60: 25517.358 | J60: 27217.029 | K60: 26913.817 | L60: 25964.361 | M60: 24807.941 | N60: 23239.168 | O60: 23503.331 | P60: 23744.106 | Q60: 23921.985 | R60: 22633.104 | S60: 19812.592 | T60: 19146.079 | U60: 19036.609
A61: Manufactured gases | E61: 6443.264 | F61: 6525.623 | G61: 6225.358 | H61: 5878.742 | I61: 4174.456 | J61: 5124.58 | K61: 5118.692 | L61: 5227.033 | M61: 4940.899 | N61: 5004.599 | O61: 4943.941 | P61: 4761.716 | Q61: 4666.093 | R61: 4899.327 | S61: 4483.863 | T61: 4114.878 | U61: 4289.723
A62: Peat and peat products | E62: 571.8 | F62: 647.261 | G62: 645.936 | H62: 645.411 | I62: 572.715 | J62: 603.294 | K62: 575.226 | L62: 511.371 | M62: 490.807 | N62: 483.665 | O62: 459.346 | P62: 446.179 | Q62: 432.658 | R62: 462.112 | S62: 435.331 | T62: 379.126 | U62: 355.442
A63: Oil shale and oil sands | E63: 67.215 | F63: 52.051 | G63: 74.463 | H63: 70.11 | I63: 32.443 | J63: 44.063 | K63: 52.219 | L63: 41.521 | M63: 36.274 | N63: 33.911 | O63: 14.961 | P63: 9.738 | Q63: 19.981 | R63: 22.423 | S63: 19.881 | T63: 1.38 | U63: 0
A64: Natural gas | E64: 222766.51 | F64: 217840.33 | G64: 207795.9 | H64: 211564.37 | I64: 199267.7 | J64: 217715.47 | K64: 200008.44 | L64: 204927.96 | M64: 209709.5 | N64: 186291.95 | O64: 192386.95 | P64: 200188.46 | Q64: 201756.46 | R64: 201938.16 | S64: 199198.2 | T64: 194121.14 | U64: 212178.39
A65: Oil and petroleum products (excluding biofuel portion) | E65: 405516.22 | F65: 404058.37 | G65: 390736.26 | H65: 390377.87 | I65: 371049.72 | J65: 366539.11 | K65: 355252.57 | L65: 342223.85 | M65: 338181.83 | N65: 333318.14 | O65: 338568.41 | P65: 342815.52 | Q65: 345490.99 | R65: 344043.78 | S65: 345624.85 | T65: 309799.81 | U65: 327457.53
A66: Renewables and biofuels | E66: 60683.224 | F66: 65261.748 | G66: 71517.203 | H66: 76411.879 | I66: 79052.369 | J66: 85750.098 | K66: 82680.086 | L66: 89148.211 | M66: 89751.771 | N66: 86339.013 | O66: 89632.296 | P66: 90892.452 | Q66: 97135.122 | R66: 102058.61 | S66: 104096.99 | T66: 103655.54 | U66: 110442.31
A67: Biofuels | E67: =E66-E68 -> 59508.703 | F67: =F66-F68 -> 63989.156 | G67: =G66-G68 -> 70124.41 | H67: =H66-H68 -> 74835.779 | I67: =I66-I68 -> 77281.493 | J67: =J66-J68 -> 83836.816 | K67: =K66-K68 -> 80576.476 | L67: =L66-L68 -> 86935.787 | ... U67: =U66-U68 -> 107407.52
A68: Other renewables | E68: =E69+E70 -> 1174.521 | F68: =F69+F70 -> 1272.592 | G68: =G69+G70 -> 1392.793 | H68: =H69+H70 -> 1576.1 | I68: =I69+I70 -> 1770.876 | J68: =J69+J70 -> 1913.282 | K68: =K69+K70 -> 2103.61 | L68: =L69+L70 -> 2212.424 | ... U68: =U69+U70 -> 3034.792
A69: Solar thermal | E69: 734.146 | F69: 834.368 | G69: 953.2 | H69: 1113.588 | I69: 1293.992 | J69: 1493.333 | K69: 1661.721 | L69: 1761.108 | M69: 1843.834 | N69: 1962.197 | O69: 2071.454 | P69: 2123.213 | Q69: 2186.864 | R69: 2331.401 | S69: 2357.548 | T69: 2451.644 | U69: 2459.135
...

Sheet O3. gross inland consumption
A1: gross inland consumption (excl. bunkers, incl. non-energy use)
B2: Source | C2: Unit | D2: Conversion Factor | E2: 2005 | J2: 2010 | O2: 2015 | T2: 2020 | Y2: 2025 | AD2: 2030 | AI2: 2035 | AN2: 2040 | AS2: 2045 | AX2: 2050
A3: Total | B3: Eurostat energy balance | C3: TWh | D3: ='conversion factor'!$E$5 -> 0.01163 | E3: =E78*$D3 -> 18652.096 | F3: =F78*$D3 -> 18808.789 | G3: =G78*$D3 -> 18569.902 | H3: =H78*$D3 -> 18524.242 | I3: =I78*$D3 -> 17430.293 | J3: =J78*$D3 -> 18130.769 | K3: =K78*$D3 -> 17597.327 | L3: =L78*$D3 -> 17372.233 | ... U3: =U78*$D3 -> 16533.976
A4: Solid fosil fuels | B4: Eurostat energy balance | C4: TWh | D4: ='conversion factor'!$E$5 -> 0.01163 | E4: =(E79+E81)*$D4 -> 3222.06 | F4: =(F79+F81)*$D4 -> 3316.0546 | G4: =(G79+G81)*$D4 -> 3330.4901 | H4: =(H79+H81)*$D4 -> 3081.4578 | I4: =(I79+I81)*$D4 -> 2732.402 | J4: =(J79+J81)*$D4 -> 2889.2147 | K4: =(K79+K81)*$D4 -> 2950.0304 | L4: =(L79+L81)*$D4 -> 2928.1207 | ... U4: =(U79+U81)*$D4 -> 1908.7876
A5: Oil products | B5: Eurostat energy balance | C5: TWh | D5: ='conversion factor'!$E$5 -> 0.01163 | E5: =(E82+E84)*$D5 -> 7001.1601 | F5: =(F82+F84)*$D5 -> 6980.1738 | G5: =(G82+G84)*$D5 -> 6791.7356 | H5: =(H82+H84)*$D5 -> 6750.0319 | I5: =(I82+I84)*$D5 -> 6346.7436 | J5: =(J82+J84)*$D5 -> 6314.7194 | K5: =(K82+K84)*$D5 -> 6139.4172 | L5: =(L82+L84)*$D5 -> 5871.4039 | ... U5: =(U82+U84)*$D5 -> 5386.3396
A6: Fossil gas | B6: Eurostat energy balance | C6: TWh | D6: ='conversion factor'!$E$5 -> 0.01163 | E6: =E83*$D6 -> 4183.4401 | F6: =F83*$D6 -> 4177.1829 | G6: =G83*$D6 -> 4105.8249 | H6: =H83*$D6 -> 4178.4547 | I6: =I83*$D6 -> 3927.3549 | J6: =J83*$D6 -> 4219.8553 | K6: =K83*$D6 -> 3878.8057 | L6: =L83*$D6 -> 3807.8706 | ... U6: =U83*$D6 -> 3954.5257
A7: Non-bio renewables | B7: Eurostat energy balance | C7: TWh | D7: ='conversion factor'!$E$5 -> 0.01163 | E7: =E86*$D7 -> 454.62848 | F7: =F86*$D7 -> 475.07979 | G7: =G86*$D7 -> 501.45186 | H7: =H86*$D7 -> 542.6425 | I7: =I86*$D7 -> 569.2332 | J7: =J86*$D7 -> 647.05724 | K7: =K86*$D7 -> 654.62482 | L7: =L86*$D7 -> 739.88782 | ... U7: =U86*$D7 -> 1201.3425
A8: Bioenergy | B8: Eurostat energy balance | C8: TWh | D8: ='conversion factor'!$E$5 -> 0.01163 | E8: =E94*$D8 -> 940.04334 | F8: =F94*$D8 -> 1012.7141 | G8: =G94*$D8 -> 1103.2825 | H8: =H94*$D8 -> 1186.1146 | I8: =I94*$D8 -> 1242.1122 | J8: =J94*$D8 -> 1368.2556 | K8: =K94*$D8 -> 1328.5412 | L8: =L94*$D8 -> 1452.5651 | ... U8: =U94*$D8 -> 1723.2148
A9: Nuclear | B9: Eurostat energy balance | C9: TWh | D9: ='conversion factor'!$E$5 -> 0.01163 | E9: =E109*$D9 -> 2753.6846 | F9: =F109*$D9 -> 2748.7438 | G9: =G109*$D9 -> 2622.0462 | H9: =H109*$D9 -> 2659.4462 | I9: =I109*$D9 -> 2471.8813 | J9: =J109*$D9 -> 2554.189 | K9: =K109*$D9 -> 2504.473 | L9: =L109*$D9 -> 2423.371 | ... U9: =U109*$D9 -> 2170.885
A10: Other | B10: Eurostat energy balance | C10: TWh | D10: ='conversion factor'!$E$5 -> 0.01163 | E10: =(E106+E110+E111)*$D10 -> 97.079611 | F10: =(F106+F110+F111)*$D10 -> 98.839986 | G10: =(G106+G110+G111)*$D10 -> 115.07052 | H10: =(H106+H110+H111)*$D10 -> 126.09404 | I10: =(I106+I110+I111)*$D10 -> 140.56561 | J10: =(J106+J110+J111)*$D10 -> 137.47802 | K10: =(K106+K110+K111)*$D10 -> 141.43437 | L10: =(L106+L110+L111)*$D10 -> 149.01402 | ... U10: =(U106+U110+U111)*$D10 -> 188.88109
A11: benchmark total | AD11: =P63*'conversion factor'!E6 -> 13310.693 | AX11: =P66*'conversion factor'!E6 -> 14071.435
A12: benchmark fossil gas | AD12: =AD45*AD11 -> 7639.8237 | AX12: =AX45*AX11 -> 2456.6045
A13: benchmark oil products | AD13: =AD43*AD11 -> 5080.7325 | AX13: =AX43*AX11 -> 1374.3705
A14: benchmark solid fossil fuels | AD14: =AD42*AD11 -> 707.7721 | AX14: =AX42*AX11 -> 88.088893
A15: linear trajectory towards benchmark | U15: 1421.6661 | V15: 1390.8714 | W15: 1360.0766 | X15: 1329.2819 | Y15: 1298.4872 | Z15: 1267.6925 | AA15: 1236.8978 | AB15: 1206.103 | AC15: 1175.3083 | AD15: 1144.5136 | AE15: 1147.7842 | AF15: 1151.0548 | AG15: 1154.3254 | AH15: 1157.596 | AI15: 1160.8666 | AJ15: 1164.1372 | AK15: 1167.4078 | AL15: 1170.6784 | AM15: 1173.949 | AN15: 1177.2196 | AO15: 1180.4902 | AP15: 1183.7608 | AQ15: 1187.0314 | AR15: 1190.302 | AS15: 1193.5726 | AT15: 1196.8432 | AU15: 1200.1138 | AV15: 1203.3844 | AW15: 1206.655 | AX15: 1209.9256
A16: linear trajectory towards benchmark | U16: 967.29604 | V16: 932.80832 | W16: 898.32061 | X16: 863.83289 | Y16: 829.34517 | Z16: 794.85746 | AA16: 760.36974 | AB16: 725.88202 | AC16: 691.39431 | AD16: 656.90659 | AE16: 634.62276 | AF16: 612.33893 | AG16: 590.0551 | AH16: 567.77127 | AI16: 545.48744 | AJ16: 523.2036 | AK16: 500.91977 | AL16: 478.63594 | AM16: 456.35211 | AN16: 434.06828 | AO16: 411.78445 | AP16: 389.50062 | AQ16: 367.21679 | AR16: 344.93296 | AS16: 322.64912 | AT16: 300.36529 | AU16: 278.08146 | AV16: 255.79763 | AW16: 233.5138 | AX16: 211.22997
A17: linear trajectory towards benchmark | U17: 627.26803 | V17: 606.11207 | W17: 584.9561 | X17: 563.80014 | Y17: 542.64418 | Z17: 521.48821 | AA17: 500.33225 | AB17: 479.17629 | AC17: 458.02032 | AD17: 436.86436 | AE17: 420.92987 | AF17: 404.99538 | AG17: 389.0609 | AH17: 373.12641 | AI17: 357.19192 | AJ17: 341.25743 | AK17: 325.32294 | AL17: 309.38845 | AM17: 293.45397 | AN17: 277.51948 | AO17: 261.58499 | AP17: 245.6505 | AQ17: 229.71601 | AR17: 213.78152 | AS17: 197.84704 | AT17: 181.91255 | AU17: 165.97806 | AV17: 150.04357 | AW17: 134.10908 | AX17: 118.1746
A18: linear trajectory towards benchmark | U18: 164.12619 | V18: 152.65189 | W18: 141.17758 | X18: 129.70328 | Y18: 118.22897 | Z18: 106.75467 | AA18: 95.280361 | AB18: 83.806056 | AC18: 72.331751 | AD18: 60.857446 | AE18: 58.193288 | AF18: 55.52913 | AG18: 52.864972 | AH18: 50.200813 | AI18: 47.536655 | AJ18: 44.872497 | AK18: 42.208339 | AL18: 39.54418 | AM18: 36.880022 | AN18: 34.215864 | AO18: 31.551706 | AP18: 28.887547 | AQ18: 26.223389 | AR18: 23.559231 | AS18: 20.895073 | AT18: 18.230914 | AU18: 15.566756 | AV18: 12.902598 | AW18: 10.23844 | AX18: 7.5742814
A20: Average 2005-2021 | E20: =(U3-E3)/16 -> -132.38249
A21: Average 2022-2030 | E21: =(AD11-U3)/9 -> -358.14258
A22: Average 2031-2050 | E22: =(AE15-AD15) -> 3.2706
G34: INDICATOR O3
A35: gross inland consumption (excl. bunkers, incl. non-energy use)
B36: Source | C36: Unit | E36: 2005 | J36: 2010 | O36: 2015 | T36: 2020 | Y36: 2025 | AD36: 2030 | AI36: 2035 | AN36: 2040 | AS36: 2045 | AX36: 2050
A37: solid fossil fuels | B37: Eurostat energy balance | C37: ktoe | E37: =E4/E3 -> 0.1727452 | F37: =F4/F3 -> 0.17630346 | G37: =G4/G3 -> 0.17934883 | H37: =H4/H3 -> 0.16634731 | I37: =I4/I3 -> 0.15676168 | J37: =J4/J3 -> 0.15935423 | K37: =K4/K3 -> 0.16764083 | L37: =L4/L3 -> 0.16855177 | ... U37: =U4/U3 -> 0.11544637
A38: % of oil (non cummulative) | E38: =E5/E3 -> 0.37535513 | F38: =F5/F3 -> 0.37111235 | G38: =G5/G3 -> 0.36573891 | H38: =H5/H3 -> 0.36438911 | I38: =I5/I3 -> 0.36412146 | J38: =J5/J3 -> 0.34828745 | K38: =K5/K3 -> 0.34888352 | L38: =L5/L3 -> 0.33797635 | ... U38: =U5/U3 -> 0.325774
A39: oil products | B39: Eurostat energy balance | C39: ktoe | E39: =E38+E37 -> 0.54810033 | F39: =F5/F3+F37 -> 0.54741581 | G39: =G5/G3+G37 -> 0.54508774 | H39: =H5/H3+H37 -> 0.53073642 | I39: =I5/I3+I37 -> 0.52088314 | J39: =J5/J3+J37 -> 0.50764167 | K39: =K5/K3+K37 -> 0.51652435 | L39: =L5/L3+L37 -> 0.50652812 | M39: =M5/M3+M37 -> 0.50068209 | ... U39: =U5/U3+U37 -> 0.44122037
A40: % of natural gas (non cummulative) | E40: =E6/E3 -> 0.22428793 | F40: =F6/F3 -> 0.22208675 | G40: =G6/G3 -> 0.22110106 | H40: =H6/H3 -> 0.22556684 | I40: =I6/I3 -> 0.22531778 | J40: =J6/J3 -> 0.23274552 | K40: =K6/K3 -> 0.22042017 | L40: =L6/L3 -> 0.21919293 | ... U40: =U6/U3 -> 0.23917572
A41: natural gas | B41: Eurostat energy balance | C41: ktoe | E41: =E40+E39 -> 0.77238826 | F41: =F6/F3+F39 -> 0.76950256 | G41: =G6/G3+G39 -> 0.76618879 | H41: =H6/H3+H39 -> 0.75630326 | I41: =I6/I3+I39 -> 0.74620092 | J41: =J6/J3+J39 -> 0.74038719 | K41: =K6/K3+K39 -> 0.73694451 | L41: =L6/L3+L39 -> 0.72572105 | M41: =M6/M3+M39 -> 0.71798669 | ... U41: =U6/U3+U39 -> 0.68039609
A42: benchmark solid fossils | B42: Eurostat energy balance | C42: ktoe | AD42: =G63 -> 0.053173196 | AX42: =G66 -> 0.0062601216
A43: benchmark oil | B43: Eurostat energy balance | C43: ktoe | AD43: =AD42+AD44 -> 0.38170307 | AX43: =AX42+AX44 -> 0.09767096
A44: benchmark oil (non cummulative) | AD44: =E63+H63 -> 0.32852988 | AX44: =E66+H66 -> 0.091410838
A45: benchmark natural gas | B45: Eurostat energy balance | C45: ktoe | AD45: =AD43+AD46 -> 0.57396137 | AX45: =AX43+AX46 -> 0.17458096
A46: benchmark natural gas (non cummulative) | AD46: =F63+I63 -> 0.19225829 | AX46: =F66+I66 -> 0.076909996
A47: linear trajectory to benchmark | U47: 0.11544637 | V47: 0.10852713 | W47: 0.10160789 | X47: 0.094688647 | Y47: 0.087769405 | Z47: 0.080850163 | AA47: 0.073930921 | AB47: 0.06701168 | AC47: 0.060092438 | AD47: 0.053173196 | AE47: 0.050827542 | AF47: 0.048481889 | AG47: 0.046136235 | AH47: 0.043790581 | AI47: 0.041444928 | AJ47: 0.039099274 | AK47: 0.03675362 | AL47: 0.034407966 | AM47: 0.032062313 | AN47: 0.029716659 | AO47: 0.027371005 | AP47: 0.025025351 | AQ47: 0.022679698 | AR47: 0.020334044 | AS47: 0.01798839 | AT47: 0.015642737 | AU47: 0.013297083 | AV47: 0.010951429 | AW47: 0.0086057753 | AX47: 0.0062601216
A48: linear trajectory 2 | U48: 0.44122037 | V48: 0.43460734 | W48: 0.42799431 | X48: 0.42138127 | Y48: 0.41476824 | Z48: 0.40815521 | AA48: 0.40154217 | AB48: 0.39492914 | AC48: 0.38831611 | AD48: 0.38170307 | AE48: 0.36750147 | AF48: 0.35329986 | AG48: 0.33909826 | AH48: 0.32489665 | AI48: 0.31069505 | AJ48: 0.29649344 | AK48: 0.28229183 | AL48: 0.26809023 | AM48: 0.25388862 | AN48: 0.23968702 | AO48: 0.22548541 | AP48: 0.21128381 | AQ48: 0.1970822 | AR48: 0.18288059 | AS48: 0.16867899 | AT48: 0.15447738 | AU48: 0.14027578 | AV48: 0.12607417 | AW48: 0.11187257 | AX48: 0.09767096
A49: linear trajectory 3 | U49: 0.68039609 | V49: 0.66857001 | W49: 0.65674393 | X49: 0.64491785 | Y49: 0.63309177 | Z49: 0.62126569 | AA49: 0.60943961 | AB49: 0.59761353 | AC49: 0.58578745 | AD49: 0.57396137 | AE49: 0.55399235 | AF49: 0.53402333 | AG49: 0.51405431 | AH49: 0.49408529 | AI49: 0.47411626 | AJ49: 0.45414724 | AK49: 0.43417822 | AL49: 0.4142092 | AM49: 0.39424018 | AN49: 0.37427116 | AO49: 0.35430214 | AP49: 0.33433312 | AQ49: 0.3143641 | AR49: 0.29439508 | AS49: 0.27442606 | AT49: 0.25445704 | AU49: 0.23448802 | AV49: 0.214519 | AW49: 0.19454998 | AX49: 0.17458096
E51: 2005-2021 | F51: 2022-2030 | G51: 2031-2050
A52: Total | E52: =(U41-E41)/16 -> -0.0057495104 | F52: =X49-W49 -> -0.011826081 | G52: =AE49-AD49 -> -0.019969021
E55: 2005 | F55: 2021 | G55: 2050
...

Sheet MS projections raw data
A1: CountryCode | B1: Year | C1: SubmissionYear | D1: Category | E1: Scenario | F1: Gas | G1: Reported Value | H1: RY calibration | I1: Gapfilled | M1: Scenario | N1: WAM
A2: EU27 | B2: 2021 | C2: 2023 | D2: 1. Energy | E2: WAM | F2: ESR | I2: 1179032.8 | M2: Gas | N2: Total
A3: EU27 | B3: 2021 | C3: 2023 | D3: 1. Energy | E3: WAM | F3: ETS | I3: 1060346.6
A4: EU27 | B4: 2021 | C4: 2023 | D4: 1. Energy | E4: WAM | F4: Total | I4: 2577170.7 | M4: Sum of Gapfilled | N4: Column Labels
A5: EU27 | B5: 2021 | C5: 2023 | D5: 1. Energy | E5: WEM | F5: ESR | I5: 1512531.4 | M5: G+M5:AM14Row Labels | N5: 2021 | O5: 2022 | P5: 2023 | Q5: 2024 | R5: 2025 | S5: 2026 | T5: 2027 | U5: 2028 | V5: 2029 | W5: 2030 | X5: 2031 | Y5: 2032 | Z5: 2033 | AA5: 2034 | AB5: 2035 | AC5: 2036 | AD5: 2037 | AE5: 2038 | AF5: 2039 | AG5: 2040 | AH5: 2041 | AI5: 2042 | AJ5: 2043 | AK5: 2044 | AL5: 2045 | AM5: 2046 | AN5: 2047 | AO5: 2048 | AP5: 2049 | AQ5: 2050 | AR5: Grand Total
A6: EU27 | B6: 2021 | C6: 2023 | D6: 1. Energy | E6: WEM | F6: ETS | I6: 1066654.8 | M6: 1. Energy | N6: 2577170.7 | O6: 2558392.1 | P6: 2528139.7 | Q6: 2429962.2 | R6: 2347068.3 | S6: 2241519.6 | T6: 2136144 | U6: 2044705.7 | V6: 1944873.1 | W6: 1859635.4 | X6: 1798228.7 | Y6: 1738923.8 | Z6: 1681447.5 | AA6: 1625545.2 | AB6: 1568025.2 | AC6: 1523123.3 | AD6: 1481579.9 | AE6: 1443002.4 | AF6: 1405637.2 | AG6: 1369555.1 | AH6: 1344742.6 | AI6: 1324183.1 | AJ6: 1304800.8 | AK6: 1285722.8 | AL6: 1268505.9 | AM6: 1257198.5 | AN6: 1247320.8 | AO6: 1237575.1 | AP6: 1228707.2 | AQ6: 1219398.5 | AR6: 51020835
A7: EU27 | B7: 2021 | C7: 2023 | D7: 1. Energy | E7: WEM | F7: Total | I7: 2588698 | M7: 2. Industrial processes | N7: 311847.06 | O7: 310151.05 | P7: 310109.73 | Q7: 307927.24 | R7: 305035.57 | S7: 296981.71 | T7: 288607.66 | U7: 279658.27 | V7: 270294.03 | W7: 260627.09 | X7: 254148.84 | Y7: 248050.6 | Z7: 242100.12 | AA7: 236323.67 | AB7: 230658.58 | AC7: 226607.96 | AD7: 222881.05 | AE7: 219332.79 | AF7: 215835.43 | AG7: 212221.17 | AH7: 212954.46 | AI7: 212883.37 | AJ7: 212839.6 | AK7: 212765.84 | AL7: 212868.18 | AM7: 212774.49 | AN7: 212678.38 | AO7: 212581.79 | AP7: 212494.5 | AQ7: 212173.23 | AR7: 7376413.5
A8: EU27 | B8: 2021 | C8: 2023 | D8: 1. Energy | E8: WOM | F8: ESR | I8: 10121.2 | M8: 3. Agriculture | N8: 383919.26 | O8: 381680.5 | P8: 377029.05 | Q8: 374394.57 | R8: 371471.61 | S8: 368922.18 | T8: 366318.33 | U8: 363845.88 | V8: 361317.57 | W8: 358687.98 | X8: 357383.26 | Y8: 356324.6 | Z8: 355246.04 | AA8: 354173.93 | AB8: 353086.52 | AC8: 352562.06 | AD8: 352061.73 | AE8: 351526.94 | AF8: 350972.23 | AG8: 350480.08 | AH8: 349544.09 | AI8: 348736.82 | AJ8: 347952.19 | AK8: 347154.45 | AL8: 346379.27 | AM8: 345729.42 | AN8: 345088.23 | AO8: 344487.89 | AP8: 343879.12 | AQ8: 343224.92 | AR8: 10703581
A9: EU27 | B9: 2021 | C9: 2023 | D9: 1. Energy | E9: WOM | F9: ETS | I9: 8220.4161 | M9: 4. Land Use, Land-Use Change and Forestry (LULUCF, reported emissions and removals) (9) | N9: -248120.88 | O9: -248352.44 | P9: -248859.62 | Q9: -252808.11 | R9: -255099.62 | S9: -252720.54 | T9: -254213.44 | U9: -255138.2 | V9: -257437.97 | W9: -260294.28 | X9: -259423.26 | Y9: -260056.07 | Z9: -259325.36 | AA9: -257190.33 | AB9: -257250.27 | AC9: -254459.47 | AD9: -251280.33 | AE9: -247076.37 | AF9: -247190.36 | AG9: -246260.15 | AH9: -245465.07 | AI9: -246288.43 | AJ9: -246139.41 | AK9: -246180.04 | AL9: -246120.11 | AM9: -245125.7 | AN9: -245008.99 | AO9: -244398.34 | AP9: -243920.62 | AQ9: -244475.99 | AR9: -7525679.8
A10: EU27 | B10: 2021 | C10: 2023 | D10: 1. Energy | E10: WOM | F10: Total | I10: 130129.54 | M10: 5. Waste | N10: 120080.74 | O10: 116605.58 | P10: 112995.02 | Q10: 109103.61 | R10: 105666.04 | S10: 102831 | T10: 100009.41 | U10: 97217.207 | V10: 94459.041 | W10: 91715.071 | X10: 88972.327 | Y10: 86275.693 | Z10: 83680.112 | AA10: 81123.32 | AB10: 78600.034 | AC10: 76519.778 | AD10: 74472.739 | AE10: 72460.475 | AF10: 70484.06 | AG10: 68527.308 | AH10: 67312.83 | AI10: 66133.495 | AJ10: 64963.71 | AK10: 63817.199 | AL10: 62687.913 | AM10: 61717.465 | AN10: 60782.596 | AO10: 59869.606 | AP10: 58964.411 | AQ10: 58076.529 | AR10: 2456124.3
A11: EU27 | B11: 2021 | C11: 2023 | D11: 1.A.1. Energy industries | E11: WAM | F11: ESR | I11: 69944.867 | M11: IB.Aviation | N11: 74387.355 | O11: 87849.528 | P11: 98540.026 | Q11: 105907.95 | R11: 111692.22 | S11: 113083.83 | T11: 114483.87 | U11: 115649.64 | V11: 116801.68 | W11: 117989.72 | X11: 118583.53 | Y11: 119129.38 | Z11: 119664.9 | AA11: 120190.52 | AB11: 120707.64 | AC11: 121308.88 | AD11: 121797.9 | AE11: 122278.57 | AF11: 122750.46 | AG11: 122739.27 | AH11: 123344.72 | AI11: 123944.47 | AJ11: 124535.18 | AK11: 125117.04 | AL11: 125689.9 | AM11: 126266.82 | AN11: 126779.8 | AO11: 127282.11 | AP11: 127773.73 | AQ11: 127857.48 | AR11: 3524128.1
A12: EU27 | B12: 2021 | C12: 2023 | D12: 1.A.1. Energy industries | E12: WAM | F12: ETS | I12: 737232.26 | M12: IB.Navigation | N12: 131197.73 | O12: 133589.48 | P12: 135481.53 | Q12: 137301.07 | R12: 139092.37 | S12: 138737.47 | T12: 138380.8 | U12: 138022.25 | V12: 137661.74 | W12: 137310.56 | X12: 137673.12 | Y12: 138035.3 | Z12: 138397.84 | AA12: 138761.35 | AB12: 139125.83 | AC12: 139573.33 | AD12: 140002.38 | AE12: 140431.82 | AF12: 140861.77 | AG12: 141292.02 | AH12: 141583.73 | AI12: 141876.12 | AJ12: 142168.75 | AK12: 142462.01 | AL12: 142755.51 | AM12: 143423.86 | AN12: 144092.56 | AO12: 144761.4 | AP12: 145430.48 | AQ12: 146099.61 | AR12: 4195583.8
A13: EU27 | B13: 2021 | C13: 2023 | D13: 1.A.1. Energy industries | E13: WAM | F13: Total | I13: 807005.29 | M13: Indirect CO2 (if available) (10) | N13: 948.07378 | O13: 902.8689 | P13: 899.12898 | Q13: 897.46927 | R13: 890.2806 | S13: 886.96056 | T13: 885.9178 | U13: 882.05175 | V13: 879.41414 | W13: 876.23125 | X13: 869.28232 | Y13: 866.03338 | Z13: 862.38445 | AA13: 858.83552 | AB13: 855.68657 | AC13: 852.60348 | AD13: 849.72038 | AE13: 846.53729 | AF13: 843.55419 | AG13: 840.2711 | AH13: 841.26933 | AI13: 842.36757 | AJ13: 843.4658 | AK13: 844.36404 | AL13: 845.46227 | AM13: 849.06221 | AN13: 853.16214 | AO13: 857.06208 | AP13: 861.06202 | AQ13: 865.16195 | AR13: 25995.745
A14: EU27 | B14: 2021 | C14: 2023 | D14: 1.A.1. Energy industries | E14: WEM | F14: ESR | I14: 69880.225 | M14: Total excluding LULUCF | N14: 3393883.3 | O14: 3367684.1 | P14: 3329321.6 | Q14: 3222423.8 | R14: 3130262.8 | S14: 3011259.6 | T14: 2892078.6 | U14: 2786415.4 | V14: 2671922.9 | W14: 2571635.4 | X14: 2499692.9 | Y14: 2430522.4 | Z14: 2363412.9 | AA14: 2298097.2 | AB14: 2231294.1 | AC14: 2179730.1 | AD14: 2131905.9 | AE14: 2087226.5 | AF14: 2043826.7 | AG14: 2001675.9 | AH14: 1974981 | AI14: 1952361.1 | AJ14: 1930978.3 | AK14: 1909879.5 | AL14: 1890858.1 | AM14: 1877835 | AN14: 1866283.7 | AO14: 1854926.7 | AP14: 1844456.3 | AQ14: 1833283.4 | AR14: 71580115
A15: EU27 | B15: 2021 | C15: 2023 | D15: 1.A.1. Energy industries | E15: WEM | F15: ETS | I15: 742257.61 | M15: Total including LULUCF | N15: 3145822.4 | O15: 3119346.1 | P15: 3080471.7 | Q15: 2969620.5 | R15: 2875163.2 | S15: 2758539 | T15: 2637865.1 | U15: 2531277.2 | V15: 2414484.8 | W15: 2311341 | X15: 2240266.3 | Y15: 2170466.8 | Z15: 2104087.6 | AA15: 2040907 | AB15: 1974044.3 | AC15: 1925270.7 | AD15: 1880625.5 | AE15: 1840150.4 | AF15: 1796636.4 | AG15: 1755415.7 | AH15: 1686226.1 | AI15: 1671079.6 | AJ15: 1657334.9 | AK15: 1642741.2 | AL15: 1644737.7 | AM15: 1621724.1 | AN15: 1614452.4 | AO15: 1607317.3 | AP15: 1600535.5 | AQ15: 1588807.2 | AR15: 63906758
A16: EU27 | B16: 2021 | C16: 2023 | D16: 1.A.1. Energy industries | E16: WEM | F16: Total | I16: 811966.02 | M16: Grand Total | N16: 9891135.7 | O16: 9827848.8 | P16: 9724127.9 | Q16: 9404730.3 | R16: 9131242.7 | S16: 8780040.8 | T16: 8420560.3 | U16: 8102535.5 | V16: 7755256.4 | W16: 7449524.2 | X16: 7236395 | Y16: 7028538.6 | Z16: 6829573.9 | AA16: 6638790.8 | AB16: 6439147.6 | AC16: 6291089.2 | AD16: 6154896.4 | AE16: 6030180.1 | AF16: 5900657.4 | AG16: 5776486.7 | AH16: 5656065.7 | AI16: 5595752.1 | AJ16: 5540277.6 | AK16: 5484324.4 | AL16: 5449207.8 | AM16: 5402393 | AN16: 5373322.6 | AO16: 5345260.6 | AP16: 5319181.7 | AQ16: 5285310 | AR16: 2.0726385e+08
A17: EU27 | B17: 2021 | C17: 2023 | D17: 1.A.1. Energy industries | E17: WOM | F17: ESR | I17: 138.27333
A18: EU27 | B18: 2021 | C18: 2023 | D18: 1.A.1. Energy industries | E18: WOM | F18: ETS | I18: 6865.1161
A19: EU27 | B19: 2021 | C19: 2023 | D19: 1.A.1. Energy industries | E19: WOM | F19: Total | I19: 47976.889
A20: EU27 | B20: 2021 | C20: 2023 | D20: 1.A.2. Manufacturing industries and construction | E20: WAM | F20: ESR | I20: 118391.28
A21: EU27 | B21: 2021 | C21: 2023 | D21: 1.A.2. Manufacturing industries and construction | E21: WAM | F21: ETS | I21: 305698.24 | N21: 2021 | O21: 2022 | P21: 2023 | Q21: 2024 | R21: 2025 | S21: 2026 | T21: 2027 | U21: 2028 | V21: 2029 | W21: 2030 | X21: 2031 | Y21: 2032 | Z21: 2033 | AA21: 2034 | AB21: 2035 | AC21: 2036 | AD21: 2037 | AE21: 2038 | AF21: 2039 | AG21: 2040 | AH21: 2041 | AI21: 2042 | AJ21: 2043 | AK21: 2044 | AL21: 2045 | AM21: 2046 | AN21: 2047 | AO21: 2048 | AP21: 2049 | AQ21: 2050
A22: EU27 | B22: 2021 | C22: 2023 | D22: 1.A.2. Manufacturing industries and construction | E22: WAM | F22: Total | I22: 423690.01 | M22: 1. Energy | N22: 2577170.7 | O22: 2558392.1 | P22: 2528139.7 | Q22: 2429962.2 | R22: 2347068.3 | S22: 2241519.6 | T22: 2136144 | U22: 2044705.7 | V22: 1944873.1 | W22: 1859635.4 | X22: 1798228.7 | Y22: 1738923.8 | Z22: 1681447.5 | AA22: 1625545.2 | AB22: 1568025.2 | AC22: 1523123.3 | AD22: 1481579.9 | AE22: 1443002.4 | AF22: 1405637.2 | AG22: 1369555.1 | AH22: 1344742.6 | AI22: 1324183.1 | AJ22: 1304800.8 | AK22: 1285722.8 | AL22: 1268505.9 | AM22: 1257198.5 | AN22: 1247320.8 | AO22: 1237575.1 | AP22: 1228707.2 | AQ22: 1219398.5
A23: EU27 | B23: 2021 | C23: 2023 | D23: 1.A.2. Manufacturing industries and construction | E23: WEM | F23: ESR | I23: 118552.94 | M23: 2. Industrial processes | N23: 311847.06 | O23: 310151.05 | P23: 310109.73 | Q23: 307927.24 | R23: 305035.57 | S23: 296981.71 | T23: 288607.66 | U23: 279658.27 | V23: 270294.03 | W23: 260627.09 | X23: 254148.84 | Y23: 248050.6 | Z23: 242100.12 | AA23: 236323.67 | AB23: 230658.58 | AC23: 226607.96 | AD23: 222881.05 | AE23: 219332.79 | AF23: 215835.43 | AG23: 212221.17 | AH23: 212954.46 | AI23: 212883.37 | AJ23: 212839.6 | AK23: 212765.84 | AL23: 212868.18 | AM23: 212774.49 | AN23: 212678.38 | AO23: 212581.79 | AP23: 212494.5 | AQ23: 212173.23
A24: EU27 | B24: 2021 | C24: 2023 | D24: 1.A.2. Manufacturing industries and construction | E24: WEM | F24: ETS | I24: 306940.57 | M24: 3. Agriculture | N24: 383919.26 | O24: 381680.5 | P24: 377029.05 | Q24: 374394.57 | R24: 371471.61 | S24: 368922.18 | T24: 366318.33 | U24: 363845.88 | V24: 361317.57 | W24: 358687.98 | X24: 357383.26 | Y24: 356324.6 | Z24: 355246.04 | AA24: 354173.93 | AB24: 353086.52 | AC24: 352562.06 | AD24: 352061.73 | AE24: 351526.94 | AF24: 350972.23 | AG24: 350480.08 | AH24: 349544.09 | AI24: 348736.82 | AJ24: 347952.19 | AK24: 347154.45 | AL24: 346379.27 | AM24: 345729.42 | AN24: 345088.23 | AO24: 344487.89 | AP24: 343879.12 | AQ24: 343224.92
