Workbook
Name Mtoe_to_TWh: 'conversion factor'!$B$10

Sheet conversion factor
A1: https://www.iea.org/data-and-statistics/data-tools/unit-converter
B3: Kwh | C3: Mwh | D3: Gwh | E3: Twh
A4: 1 toe | B4: =C4*1000 -> 11630 | C4: 11.63 | D4: =C4*0.001 -> 0.01163 | E4: =D4*0.001 -> 1.163e-05
A5: 1 ktoe | B5: =B4*1000 -> 11630000 | C5: =C4*1000 -> 11630 | D5: =D4*1000 -> 11.63 | E5: =E4*1000 -> 0.01163
A6: 1 Mtoe | B6: =B4*1000000 -> 11630000000 | C6: =C4*1000000 -> 11630000 | D6: =D4*1000000 -> 11630 | E6: =E4*1000000 -> 11.63
A10: Mtoe to TWh | B10: 11.63

Sheet Colour palette
S1: 2020 | T1: 2021 | U1: 2022 | V1: 2023 | W1: 2024 | X1: 2025 | Y1: 2026 | Z1: 2027 | AA1: 2028 | AB1: 2029 | AC1: 2030 | AD1: 2031 | AE1: 2032 | AF1: 2033 | AG1: 2034 | AH1: 2035 | AI1: 2036 | AJ1: 2037 | AK1: 2038 | AL1: 2039 | AM1: 2040 | AN1: 2041 | AO1: 2042 | AP1: 2043 | AQ1: 2044 | AR1: 2045 | AS1: 2046 | AT1: 2047 | AU1: 2048 | AV1: 2049 | AW1: 2050
Q2: Demand-side Focus Pathway | R2: 1 | S2: 1 | T2: 0.98 | U2: 0.96 | V2: 0.94 | W2: 0.92 | X2: 0.9 | Y2: 0.88 | Z2: 0.86 | AA2: 0.85 | AB2: 0.83 | AC2: 0.81 | AD2: 0.79 | AE2: 0.77 | AF2: 0.75 | AG2: 0.73 | AH2: 0.71 | AI2: 0.69 | AJ2: 0.67 | AK2: 0.65 | AL2: 0.63 | AM2: 0.61 | AN2: 0.6 | AO2: 0.58 | AP2: 0.57 | AQ2: 0.56 | AR2: 0.54 | AS2: 0.53 | AT2: 0.52 | AU2: 0.51 | AV2: 0.5 | AW2: 0.49
Q3: High Renewable Energy Pathway | R3: 1 | S3: 1 | T3: 0.99 | U3: 0.99 | V3: 0.98 | W3: 0.97 | X3: 0.96 | Y3: 0.94 | Z3: 0.92 | AA3: 0.89 | AB3: 0.87 | AC3: 0.85 | AD3: 0.83 | AE3: 0.8 | AF3: 0.78 | AG3: 0.75 | AH3: 0.73 | AI3: 0.71 | AJ3: 0.69 | AK3: 0.67 | AL3: 0.64 | AM3: 0.62 | AN3: 0.61 | AO3: 0.6 | AP3: 0.59 | AQ3: 0.58 | AR3: 0.56 | AS3: 0.56 | AT3: 0.55 | AU3: 0.55 | AV3: 0.55 | AW3: 0.54
B4: Font and colours: | E4: Half page width: | Q4: Mixed Options Pathway | R4: 1 | S4: 1.01 | T4: 0.99 | U4: 0.98 | V4: 0.96 | W4: 0.95 | X4: 0.93 | Y4: 0.92 | Z4: 0.9 | AA4: 0.89 | AB4: 0.88 | AC4: 0.86 | AD4: 0.85 | AE4: 0.83 | AF4: 0.82 | AG4: 0.8 | AH4: 0.79 | AI4: 0.78 | AJ4: 0.77 | AK4: 0.77 | AL4: 0.76 | AM4: 0.76 | AN4: 0.76 | AO4: 0.76 | AP4: 0.76 | AQ4: 0.76 | AR4: 0.76 | AS4: 0.76 | AT4: 0.76 | AU4: 0.77 | AV4: 0.77 | AW4: 0.77
Q5: #REF! | R5: 1 | S5: 1 | T5: 0.99 | U5: 0.97 | V5: 0.95 | W5: 0.93 | X5: 0.91 | Y5: 0.9 | Z5: 0.88 | AA5: 0.86 | AB5: 0.84 | AC5: 0.83 | AD5: 0.81 | AE5: 0.79 | AF5: 0.77 | AG5: 0.76 | AH5: 0.74 | AI5: 0.73 | AJ5: 0.72 | AK5: 0.72 | AL5: 0.71 | AM5: 0.7 | AN5: 0.7 | AO5: 0.7 | AP5: 0.7 | AQ5: 0.7 | AR5: 0.7 | AS5: 0.7 | AT5: 0.71 | AU5: 0.71 | AV5: 0.71 | AW5: 0.71
A6: Font: | B6: Segoe UI, size 8 | Q6: #REF! | R6: 1 | S6: 1 | T6: 0.99 | U6: 0.97 | V6: 0.96 | W6: 0.95 | X6: 0.94 | Y6: 0.93 | Z6: 0.91 | AA6: 0.9 | AB6: 0.88 | AC6: 0.87 | AD6: 0.85 | AE6: 0.83 | AF6: 0.81 | AG6: 0.79 | AH6: 0.77 | AI6: 0.76 | AJ6: 0.74 | AK6: 0.72 | AL6: 0.71 | AM6: 0.69 | AN6: 0.69 | AO6: 0.68 | AP6: 0.68 | AQ6: 0.68 | AR6: 0.67 | AS6: 0.67 | AT6: 0.67 | AU6: 0.66 | AV6: 0.66 | AW6: 0.66
B7: Signature colour | Q7: #REF! | R7: 1 | S7: 1 | T7: 0.98 | U7: 0.96 | V7: 0.94 | W7: 0.92 | X7: 0.9 | Y7: 0.88 | Z7: 0.86 | AA7: 0.84 | AB7: 0.83 | AC7: 0.81 | AD7: 0.79 | AE7: 0.77 | AF7: 0.75 | AG7: 0.73 | AH7: 0.71 | AI7: 0.7 | AJ7: 0.7 | AK7: 0.69 | AL7: 0.68 | AM7: 0.68 | AN7: 0.68 | AO7: 0.69 | AP7: 0.69 | AQ7: 0.7 | AR7: 0.7 | AS7: 0.71 | AT7: 0.71 | AU7: 0.71 | AV7: 0.71 | AW7: 0.71
Q8: #REF! | R8: 1 | S8: 1 | T8: 0.99 | U8: 0.99 | V8: 0.98 | W8: 0.97 | X8: 0.96 | Y8: 0.94 | Z8: 0.92 | AA8: 0.89 | AB8: 0.87 | AC8: 0.85 | AD8: 0.83 | AE8: 0.8 | AF8: 0.78 | AG8: 0.76 | AH8: 0.73 | AI8: 0.71 | AJ8: 0.69 | AK8: 0.67 | AL8: 0.65 | AM8: 0.63 | AN8: 0.62 | AO8: 0.6 | AP8: 0.59 | AQ8: 0.58 | AR8: 0.57 | AS8: 0.56 | AT8: 0.56 | AU8: 0.55 | AV8: 0.55 | AW8: 0.54
A9: Gridlines: | B9: Signature colour | Q9: #REF! | R9: 1 | S9: 1 | T9: 0.99 | U9: 0.99 | V9: 0.98 | W9: 0.97 | X9: 0.96 | Y9: 0.94 | Z9: 0.92 | AA9: 0.89 | AB9: 0.87 | AC9: 0.85 | AD9: 0.83 | AE9: 0.8 | AF9: 0.78 | AG9: 0.76 | AH9: 0.73 | AI9: 0.71 | AJ9: 0.69 | AK9: 0.67 | AL9: 0.65 | AM9: 0.63 | AN9: 0.62 | AO9: 0.6 | AP9: 0.59 | AQ9: 0.58 | AR9: 0.57 | AS9: 0.56 | AT9: 0.56 | AU9: 0.55 | AV9: 0.55 | AW9: 0.54
B10: Transparency: 90% | Q10: #REF! | R10: 1 | S10: 1 | T10: 0.99 | U10: 0.99 | V10: 0.98 | W10: 0.97 | X10: 0.96 | Y10: 0.94 | Z10: 0.92 | AA10: 0.89 | AB10: 0.87 | AC10: 0.85 | AD10: 0.82 | AE10: 0.8 | AF10: 0.77 | AG10: 0.75 | AH10: 0.73 | AI10: 0.7 | AJ10: 0.68 | AK10: 0.66 | AL10: 0.64 | AM10: 0.61 | AN10: 0.6 | AO10: 0.59 | AP10: 0.58 | AQ10: 0.57 | AR10: 0.56 | AS10: 0.56 | AT10: 0.56 | AU10: 0.55 | AV10: 0.55 | AW10: 0.55
Q11: #REF! | R11: 1 | S11: 1 | T11: 0.99 | U11: 0.99 | V11: 0.98 | W11: 0.97 | X11: 0.96 | Y11: 0.94 | Z11: 0.92 | AA11: 0.89 | AB11: 0.87 | AC11: 0.85 | AD11: 0.82 | AE11: 0.8 | AF11: 0.77 | AG11: 0.75 | AH11: 0.73 | AI11: 0.7 | AJ11: 0.68 | AK11: 0.66 | AL11: 0.64 | AM11: 0.62 | AN11: 0.6 | AO11: 0.59 | AP11: 0.58 | AQ11: 0.57 | AR11: 0.56 | AS11: 0.56 | AT11: 0.56 | AU11: 0.55 | AV11: 0.55 | AW11: 0.55
A12: Lines: | B12: High width: 2.25 pt | Q12: #REF! | R12: #N/A | S12: #N/A | T12: #N/A | U12: #N/A | V12: #N/A | W12: #N/A | X12: #N/A | Y12: #N/A | Z12: #N/A | AA12: #N/A | AB12: #N/A | AC12: #N/A | AD12: #N/A | AE12: #N/A | AF12: #N/A | AG12: #N/A | AH12: #N/A | AI12: #N/A | AJ12: #N/A | AK12: #N/A | AL12: #N/A | AM12: #N/A | AN12: #N/A | AO12: #N/A | AP12: #N/A | AQ12: #N/A | AR12: #N/A | AS12: #N/A | AT12: #N/A | AU12: #N/A | AV12: #N/A | AW12: #N/A
B13: Low width: 0.25 pt | Q13: #REF! | R13: #N/A | S13: #N/A | T13: #N/A | U13: #N/A | V13: #N/A | W13: #N/A | X13: #N/A | Y13: #N/A | Z13: #N/A | AA13: #N/A | AB13: #N/A | AC13: #N/A | AD13: #N/A | AE13: #N/A | AF13: #N/A | AG13: #N/A | AH13: #N/A | AI13: #N/A | AJ13: #N/A | AK13: #N/A | AL13: #N/A | AM13: #N/A | AN13: #N/A | AO13: #N/A | AP13: #N/A | AQ13: #N/A | AR13: #N/A | AS13: #N/A | AT13: #N/A | AU13: #N/A | AV13: #N/A | AW13: #N/A
Q14: #REF! | R14: 1 | S14: 1 | T14: 0.99 | U14: 0.99 | V14: 0.98 | W14: 0.97 | X14: 0.96 | Y14: 0.94 | Z14: 0.92 | AA14: 0.89 | AB14: 0.87 | AC14: 0.85 | AD14: 0.82 | AE14: 0.8 | AF14: 0.78 | AG14: 0.75 | AH14: 0.73 | AI14: 0.71 | AJ14: 0.68 | AK14: 0.66 | AL14: 0.64 | AM14: 0.62 | AN14: 0.61 | AO14: 0.59 | AP14: 0.58 | AQ14: 0.57 | AR14: 0.56 | AS14: 0.56 | AT14: 0.55 | AU14: 0.55 | AV14: 0.55 | AW14: 0.54
A15: Colours: | B15: Primary colour palette | Q15: #REF! | R15: 1 | S15: 1 | T15: 0.99 | U15: 0.99 | V15: 0.98 | W15: 0.97 | X15: 0.96 | Y15: 0.94 | Z15: 0.92 | AA15: 0.89 | AB15: 0.87 | AC15: 0.85 | AD15: 0.82 | AE15: 0.79 | AF15: 0.77 | AG15: 0.74 | AH15: 0.71 | AI15: 0.69 | AJ15: 0.67 | AK15: 0.65 | AL15: 0.62 | AM15: 0.6 | AN15: 0.59 | AO15: 0.58 | AP15: 0.58 | AQ15: 0.57 | AR15: 0.56 | AS15: 0.56 | AT15: 0.55 | AU15: 0.55 | AV15: 0.55 | AW15: 0.55
Q16: #REF! | R16: 1 | S16: 1.01 | T16: 0.99 | U16: 0.98 | V16: 0.97 | W16: 0.95 | X16: 0.94 | Y16: 0.93 | Z16: 0.91 | AA16: 0.9 | AB16: 0.89 | AC16: 0.87 | AD16: 0.86 | AE16: 0.85 | AF16: 0.83 | AG16: 0.82 | AH16: 0.8 | AI16: 0.79 | AJ16: 0.78 | AK16: 0.77 | AL16: 0.76 | AM16: 0.75 | AN16: 0.75 | AO16: 0.75 | AP16: 0.75 | AQ16: 0.75 | AR16: 0.75 | AS16: 0.76 | AT16: 0.76 | AU16: 0.76 | AV16: 0.76 | AW16: 0.77
Q17: #REF! | R17: #N/A | S17: #N/A | T17: #N/A | U17: #N/A | V17: #N/A | W17: #N/A | X17: #N/A | Y17: #N/A | Z17: #N/A | AA17: #N/A | AB17: #N/A | AC17: #N/A | AD17: #N/A | AE17: #N/A | AF17: #N/A | AG17: #N/A | AH17: #N/A | AI17: #N/A | AJ17: #N/A | AK17: #N/A | AL17: #N/A | AM17: #N/A | AN17: #N/A | AO17: #N/A | AP17: #N/A | AQ17: #N/A | AR17: #N/A | AS17: #N/A | AT17: #N/A | AU17: #N/A | AV17: #N/A | AW17: #N/A
Q18: #REF! | R18: 1 | S18: 1 | T18: 0.99 | U18: 0.99 | V18: 0.98 | W18: 0.97 | X18: 0.96 | Y18: 0.94 | Z18: 0.92 | AA18: 0.89 | AB18: 0.87 | AC18: 0.85 | AD18: 0.82 | AE18: 0.8 | AF18: 0.77 | AG18: 0.75 | AH18: 0.72 | AI18: 0.7 | AJ18: 0.68 | AK18: 0.66 | AL18: 0.64 | AM18: 0.61 | AN18: 0.6 | AO18: 0.59 | AP18: 0.58 | AQ18: 0.57 | AR18: 0.56 | AS18: 0.56 | AT18: 0.55 | AU18: 0.55 | AV18: 0.55 | AW18: 0.54
B19: Primary colour palette | Q19: #REF! | R19: 1 | S19: 1 | T19: 0.99 | U19: 0.99 | V19: 0.98 | W19: 0.97 | X19: 0.96 | Y19: 0.94 | Z19: 0.92 | AA19: 0.89 | AB19: 0.87 | AC19: 0.85 | AD19: 0.82 | AE19: 0.8 | AF19: 0.77 | AG19: 0.75 | AH19: 0.72 | AI19: 0.7 | AJ19: 0.68 | AK19: 0.66 | AL19: 0.64 | AM19: 0.61 | AN19: 0.6 | AO19: 0.59 | AP19: 0.58 | AQ19: 0.57 | AR19: 0.56 | AS19: 0.56 | AT19: 0.56 | AU19: 0.55 | AV19: 0.55 | AW19: 0.54
Q20: #REF! | R20: #N/A | S20: #N/A | T20: #N/A | U20: #N/A | V20: #N/A | W20: #N/A | X20: #N/A | Y20: #N/A | Z20: #N/A | AA20: #N/A | AB20: #N/A | AC20: #N/A | AD20: #N/A | AE20: #N/A | AF20: #N/A | AG20: #N/A | AH20: #N/A | AI20: #N/A | AJ20: #N/A | AK20: #N/A | AL20: #N/A | AM20: #N/A | AN20: #N/A | AO20: #N/A | AP20: #N/A | AQ20: #N/A | AR20: #N/A | AS20: #N/A | AT20: #N/A | AU20: #N/A | AV20: #N/A | AW20: #N/A
B21: Primary colour palette | Q21: #REF! | R21: #N/A | S21: #N/A | T21: #N/A | U21: #N/A | V21: #N/A | W21: #N/A | X21: #N/A | Y21: #N/A | Z21: #N/A | AA21: #N/A | AB21: #N/A | AC21: #N/A | AD21: #N/A | AE21: #N/A | AF21: #N/A | AG21: #N/A | AH21: #N/A | AI21: #N/A | AJ21: #N/A | AK21: #N/A | AL21: #N/A | AM21: #N/A | AN21: #N/A | AO21: #N/A | AP21: #N/A | AQ21: #N/A | AR21: #N/A | AS21: #N/A | AT21: #N/A | AU21: #N/A | AV21: #N/A | AW21: #N/A
Q22: #REF! | R22: 1 | S22: 1 | T22: 0.99 | U22: 0.98 | V22: 0.98 | W22: 0.97 | X22: 0.96 | Y22: 0.94 | Z22: 0.92 | AA22: 0.89 | AB22: 0.87 | AC22: 0.85 | AD22: 0.82 | AE22: 0.8 | AF22: 0.77 | AG22: 0.75 | AH22: 0.73 | AI22: 0.7 | AJ22: 0.68 | AK22: 0.66 | AL22: 0.64 | AM22: 0.62 | AN22: 0.6 | AO22: 0.59 | AP22: 0.58 | AQ22: 0.57 | AR22: 0.56 | AS22: 0.56 | AT22: 0.55 | AU22: 0.55 | AV22: 0.54 | AW22: 0.54
Q23: #REF! | R23: 1 | S23: 1 | T23: 0.99 | U23: 0.99 | V23: 0.98 | W23: 0.97 | X23: 0.96 | Y23: 0.94 | Z23: 0.92 | AA23: 0.89 | AB23: 0.87 | AC23: 0.84 | AD23: 0.82 | AE23: 0.79 | AF23: 0.77 | AG23: 0.74 | AH23: 0.71 | AI23: 0.69 | AJ23: 0.67 | AK23: 0.65 | AL23: 0.63 | AM23: 0.6 | AN23: 0.6 | AO23: 0.59 | AP23: 0.58 | AQ23: 0.57 | AR23: 0.56 | AS23: 0.56 | AT23: 0.56 | AU23: 0.55 | AV23: 0.55 | AW23: 0.55
B24: Primary colour palette | Q24: #REF! | R24: #N/A | S24: #N/A | T24: #N/A | U24: #N/A | V24: #N/A | W24: #N/A | X24: #N/A | Y24: #N/A | Z24: #N/A | AA24: #N/A | AB24: #N/A | AC24: #N/A | AD24: #N/A | AE24: #N/A | AF24: #N/A | AG24: #N/A | AH24: #N/A | AI24: #N/A | AJ24: #N/A | AK24: #N/A | AL24: #N/A | AM24: #N/A | AN24: #N/A | AO24: #N/A | AP24: #N/A | AQ24: #N/A | AR24: #N/A | AS24: #N/A | AT24: #N/A | AU24: #N/A | AV24: #N/A | AW24: #N/A
Q25: #REF! | R25: 1 | S25: 1 | T25: 0.99 | U25: 0.99 | V25: 0.98 | W25: 0.97 | X25: 0.96 | Y25: 0.94 | Z25: 0.92 | AA25: 0.89 | AB25: 0.87 | AC25: 0.85 | AD25: 0.83 | AE25: 0.81 | AF25: 0.8 | AG25: 0.78 | AH25: 0.76 | AI25: 0.74 | AJ25: 0.72 | AK25: 0.7 | AL25: 0.68 | AM25: 0.66 | AN25: 0.65 | AO25: 0.64 | AP25: 0.63 | AQ25: 0.62 | AR25: 0.61 | AS25: 0.61 | AT25: 0.61 | AU25: 0.61 | AV25: 0.61 | AW25: 0.6
E26: Full page width: | Q26: #REF! | R26: 1 | S26: 1 | T26: 0.99 | U26: 0.99 | V26: 0.98 | W26: 0.97 | X26: 0.96 | Y26: 0.94 | Z26: 0.92 | AA26: 0.89 | AB26: 0.87 | AC26: 0.85 | AD26: 0.83 | AE26: 0.81 | AF26: 0.8 | AG26: 0.78 | AH26: 0.76 | AI26: 0.74 | AJ26: 0.72 | AK26: 0.7 | AL26: 0.68 | AM26: 0.66 | AN26: 0.65 | AO26: 0.64 | AP26: 0.63 | AQ26: 0.62 | AR26: 0.61 | AS26: 0.61 | AT26: 0.61 | AU26: 0.61 | AV26: 0.61 | AW26: 0.6
Q27: #REF! | R27: 1 | S27: 1.01 | T27: 0.99 | U27: 0.98 | V27: 0.96 | W27: 0.95 | X27: 0.94 | Y27: 0.92 | Z27: 0.91 | AA27: 0.89 | AB27: 0.88 | AC27: 0.87 | AD27: 0.85 | AE27: 0.84 | AF27: 0.82 | AG27: 0.81 | AH27: 0.79 | AI27: 0.78 | AJ27: 0.78 | AK27: 0.77 | AL27: 0.76 | AM27: 0.75 | AN27: 0.75 | AO27: 0.75 | AP27: 0.75 | AQ27: 0.75 | AR27: 0.75 | AS27: 0.75 | AT27: 0.75 | AU27: 0.76 | AV27: 0.76 | AW27: 0.76
Q28: #REF! | R28: #N/A | S28: #N/A | T28: #N/A | U28: #N/A | V28: #N/A | W28: #N/A | X28: #N/A | Y28: #N/A | Z28: #N/A | AA28: #N/A | AB28: #N/A | AC28: #N/A | AD28: #N/A | AE28: #N/A | AF28: #N/A | AG28: #N/A | AH28: #N/A | AI28: #N/A | AJ28: #N/A | AK28: #N/A | AL28: #N/A | AM28: #N/A | AN28: #N/A | AO28: #N/A | AP28: #N/A | AQ28: #N/A | AR28: #N/A | AS28: #N/A | AT28: #N/A | AU28: #N/A | AV28: #N/A | AW28: #N/A
Q29: #REF! | R29: #N/A | S29: #N/A | T29: #N/A | U29: #N/A | V29: #N/A | W29: #N/A | X29: #N/A | Y29: #N/A | Z29: #N/A | AA29: #N/A | AB29: #N/A | AC29: #N/A | AD29: #N/A | AE29: #N/A | AF29: #N/A | AG29: #N/A | AH29: #N/A | AI29: #N/A | AJ29: #N/A | AK29: #N/A | AL29: #N/A | AM29: #N/A | AN29: #N/A | AO29: #N/A | AP29: #N/A | AQ29: #N/A | AR29: #N/A | AS29: #N/A | AT29: #N/A | AU29: #N/A | AV29: #N/A | AW29: #N/A
Q30: #REF! | R30: 1 | S30: 1 | T30: 0.99 | U30: 0.99 | V30: 0.98 | W30: 0.97 | X30: 0.96 | Y30: 0.94 | Z30: 0.92 | AA30: 0.89 | AB30: 0.87 | AC30: 0.85 | AD30: 0.83 | AE30: 0.81 | AF30: 0.8 | AG30: 0.78 | AH30: 0.76 | AI30: 0.74 | AJ30: 0.72 | AK30: 0.7 | AL30: 0.68 | AM30: 0.65 | AN30: 0.65 | AO30: 0.64 | AP30: 0.63 | AQ30: 0.62 | AR30: 0.61 | AS30: 0.61 | AT30: 0.6 | AU30: 0.6 | AV30: 0.6 | AW30: 0.59
A31: Title and | B31: In Word document | Q31: #REF! | R31: 1 | S31: 1 | T31: 0.99 | U31: 0.99 | V31: 0.98 | W31: 0.97 | X31: 0.96 | Y31: 0.94 | Z31: 0.92 | AA31: 0.89 | AB31: 0.87 | AC31: 0.85 | AD31: 0.83 | AE31: 0.8 | AF31: 0.78 | AG31: 0.76 | AH31: 0.73 | AI31: 0.71 | AJ31: 0.69 | AK31: 0.66 | AL31: 0.64 | AM31: 0.62 | AN31: 0.61 | AO31: 0.6 | AP31: 0.6 | AQ31: 0.59 | AR31: 0.59 | AS31: 0.58 | AT31: 0.58 | AU31: 0.58 | AV31: 0.58 | AW31: 0.58
A32: source: | B32: (only unit on chart) | Q32: #REF! | R32: 1 | S32: 1 | T32: 0.99 | U32: 0.99 | V32: 0.98 | W32: 0.97 | X32: 0.96 | Y32: 0.94 | Z32: 0.92 | AA32: 0.89 | AB32: 0.87 | AC32: 0.85 | AD32: 0.82 | AE32: 0.79 | AF32: 0.76 | AG32: 0.73 | AH32: 0.7 | AI32: 0.68 | AJ32: 0.66 | AK32: 0.64 | AL32: 0.62 | AM32: 0.6 | AN32: 0.6 | AO32: 0.6 | AP32: 0.59 | AQ32: 0.59 | AR32: 0.59 | AS32: 0.59 | AT32: 0.59 | AU32: 0.6 | AV32: 0.6 | AW32: 0.6
Q33: #REF! | R33: 1 | S33: 1 | T33: 0.99 | U33: 0.99 | V33: 0.98 | W33: 0.97 | X33: 0.97 | Y33: 0.96 | Z33: 0.95 | AA33: 0.94 | AB33: 0.94 | AC33: 0.93 | AD33: 0.92 | AE33: 0.9 | AF33: 0.89 | AG33: 0.88 | AH33: 0.87 | AI33: 0.85 | AJ33: 0.83 | AK33: 0.81 | AL33: 0.8 | AM33: 0.78 | AN33: 0.77 | AO33: 0.76 | AP33: 0.76 | AQ33: 0.75 | AR33: 0.74 | AS33: 0.74 | AT33: 0.73 | AU33: 0.72 | AV33: 0.72 | AW33: 0.71
Q34: #REF! | R34: 1 | S34: 1 | T34: 0.99 | U34: 0.99 | V34: 0.98 | W34: 0.98 | X34: 0.97 | Y34: 0.96 | Z34: 0.95 | AA34: 0.95 | AB34: 0.94 | AC34: 0.93 | AD34: 0.92 | AE34: 0.91 | AF34: 0.9 | AG34: 0.89 | AH34: 0.87 | AI34: 0.86 | AJ34: 0.84 | AK34: 0.82 | AL34: 0.8 | AM34: 0.78 | AN34: 0.78 | AO34: 0.77 | AP34: 0.76 | AQ34: 0.76 | AR34: 0.75 | AS34: 0.74 | AT34: 0.74 | AU34: 0.73 | AV34: 0.72 | AW34: 0.71
Q35: #REF! | R35: 1 | S35: 1 | T35: 0.99 | U35: 0.99 | V35: 0.98 | W35: 0.98 | X35: 0.97 | Y35: 0.97 | Z35: 0.96 | AA35: 0.95 | AB35: 0.95 | AC35: 0.94 | AD35: 0.93 | AE35: 0.92 | AF35: 0.9 | AG35: 0.89 | AH35: 0.88 | AI35: 0.86 | AJ35: 0.85 | AK35: 0.83 | AL35: 0.81 | AM35: 0.79 | AN35: 0.78 | AO35: 0.78 | AP35: 0.77 | AQ35: 0.76 | AR35: 0.75 | AS35: 0.75 | AT35: 0.74 | AU35: 0.73 | AV35: 0.72 | AW35: 0.71
Q36: #REF! | R36: 1 | S36: 1 | T36: 0.99 | U36: 0.99 | V36: 0.98 | W36: 0.97 | X36: 0.97 | Y36: 0.96 | Z36: 0.95 | AA36: 0.94 | AB36: 0.93 | AC36: 0.92 | AD36: 0.91 | AE36: 0.9 | AF36: 0.89 | AG36: 0.88 | AH36: 0.86 | AI36: 0.85 | AJ36: 0.83 | AK36: 0.81 | AL36: 0.79 | AM36: 0.77 | AN36: 0.77 | AO36: 0.76 | AP36: 0.75 | AQ36: 0.75 | AR36: 0.74 | AS36: 0.73 | AT36: 0.73 | AU36: 0.72 | AV36: 0.71 | AW36: 0.71
Q37: #REF! | R37: 1 | S37: 1 | T37: 0.98 | U37: 0.96 | V37: 0.95 | W37: 0.93 | X37: 0.91 | Y37: 0.9 | Z37: 0.89 | AA37: 0.88 | AB37: 0.87 | AC37: 0.86 | AD37: 0.84 | AE37: 0.83 | AF37: 0.82 | AG37: 0.8 | AH37: 0.79 | AI37: 0.77 | AJ37: 0.75 | AK37: 0.72 | AL37: 0.7 | AM37: 0.68 | AN37: 0.67 | AO37: 0.66 | AP37: 0.65 | AQ37: 0.64 | AR37: 0.63 | AS37: 0.63 | AT37: 0.62 | AU37: 0.61 | AV37: 0.61 | AW37: 0.6
Q38: #REF! | R38: 1 | S38: 1 | T38: 0.99 | U38: 0.98 | V38: 0.96 | W38: 0.95 | X38: 0.94 | Y38: 0.92 | Z38: 0.91 | AA38: 0.89 | AB38: 0.88 | AC38: 0.86 | AD38: 0.85 | AE38: 0.83 | AF38: 0.81 | AG38: 0.8 | AH38: 0.78 | AI38: 0.78 | AJ38: 0.77 | AK38: 0.76 | AL38: 0.76 | AM38: 0.75 | AN38: 0.75 | AO38: 0.75 | AP38: 0.75 | AQ38: 0.75 | AR38: 0.75 | AS38: 0.75 | AT38: 0.75 | AU38: 0.75 | AV38: 0.75 | AW38: 0.76
Q39: #REF! | R39: 1 | S39: 0.99 | T39: 0.97 | U39: 0.95 | V39: 0.93 | W39: 0.91 | X39: 0.89 | Y39: 0.88 | Z39: 0.87 | AA39: 0.85 | AB39: 0.84 | AC39: 0.83 | AD39: 0.81 | AE39: 0.79 | AF39: 0.77 | AG39: 0.76 | AH39: 0.74 | AI39: 0.72 | AJ39: 0.71 | AK39: 0.69 | AL39: 0.68 | AM39: 0.66 | AN39: 0.65 | AO39: 0.64 | AP39: 0.64 | AQ39: 0.63 | AR39: 0.62 | AS39: 0.62 | AT39: 0.61 | AU39: 0.61 | AV39: 0.6 | AW39: 0.6
Q40: #REF! | R40: 1 | S40: 1 | T40: 0.99 | U40: 0.97 | V40: 0.96 | W40: 0.95 | X40: 0.94 | Y40: 0.93 | Z40: 0.91 | AA40: 0.9 | AB40: 0.88 | AC40: 0.87 | AD40: 0.85 | AE40: 0.83 | AF40: 0.81 | AG40: 0.79 | AH40: 0.77 | AI40: 0.76 | AJ40: 0.74 | AK40: 0.73 | AL40: 0.71 | AM40: 0.69 | AN40: 0.69 | AO40: 0.68 | AP40: 0.68 | AQ40: 0.68 | AR40: 0.67 | AS40: 0.67 | AT40: 0.67 | AU40: 0.66 | AV40: 0.66 | AW40: 0.66
...

Sheet I1. GHG emissions
A1: Graph feed
B2: Source | C2: Unit | D2: 2005 | I2: 2010 | N2: 2015 | S2: 2020 | X2: 2025 | AC2: 2030 | AH2: 2035 | AM2: 2040 | AR2: 2045 | AW2: 2050
A3: Total | B3: EEA GHG data viewer | C3: Mt CO2e | D3: =(D46+D54)/1000 -> 981.27376 | E3: =(E46+E54)/1000 -> 973.78646 | F3: =(F46+F54)/1000 -> 995.61813 | G3: =(G46+G54)/1000 -> 952.33845 | H3: =(H46+H54)/1000 -> 789.42831 | I3: =(I46+I54)/1000 -> 838.81444 | J3: =(J46+J54)/1000 -> 826.15345 | K3: =(K46+K54)/1000 -> 795.67043 | ... U3: =(U46+U54)/1000 -> 691.32881
A4: Total (CO2 only) | B4: EEA GHG data viewer | C4: Mt CO2e | D4: =(D104+D105)/1000 -> 846.23154 | E4: =(E104+E105)/1000 -> 841.93794 | F4: =(F104+F105)/1000 -> 858.35254 | G4: =(G104+G105)/1000 -> 819.45573 | H4: =(H104+H105)/1000 -> 664.81233 | I4: =(I104+I105)/1000 -> 719.5554 | J4: =(J104+J105)/1000 -> 707.40423 | K4: =(K104+K105)/1000 -> 676.08116 | ... U4: =(U104+U105)/1000 -> 605.55116
A5: Iron and steel | B5: EEA GHG data viewer | C5: Mt CO2e | D5: =(D47+D72)/1000 -> 193.15413 | E5: =(E47+E72)/1000 -> 198.50066 | F5: =(F47+F72)/1000 -> 201.86984 | G5: =(G47+G72)/1000 -> 186.83828 | H5: =(H47+H72)/1000 -> 129.57684 | I5: =(I47+I72)/1000 -> 162.13319 | J5: =(J47+J72)/1000 -> 158.78095 | K5: =(K47+K72)/1000 -> 149.00264 | ... T5: =(T47+T72)/1000 -> 147.01485
A6: Chemicals | B6: EEA GHG data viewer | C6: Mt CO2e | D6: =(D49+D60)/1000 -> 194.703 | E6: =(E49+E60)/1000 -> 181.20545 | F6: =(F49+F60)/1000 -> 182.77373 | G6: =(G49+G60)/1000 -> 171.13872 | H6: =(H49+H60)/1000 -> 144.65984 | I6: =(I49+I60)/1000 -> 144.54893 | J6: =(J49+J60)/1000 -> 140.6777 | K6: =(K49+K60)/1000 -> 134.88674 | ... T6: =(T49+T60)/1000 -> 123.86514
A7: Cement | B7: EEA EU ETS data viewer | C7: Mt CO2e | D7: =(D99)/1000 -> 143.41195 | E7: =(E99)/1000 -> 147.15261 | F7: =(F99)/1000 -> 163.11498 | G7: =(G99)/1000 -> 150.48991 | H7: =(H99)/1000 -> 121.31189 | I7: =(I99)/1000 -> 119.34112 | J7: =(J99)/1000 -> 116.97662 | K7: =(K99)/1000 -> 109.89505 | ... T7: =(T99)/1000 -> 110.22327
A8: Other sub-sectors | B8: EEA GHG data viewer | C8: Mt CO2e | D8: =D3-D5-D6-D7 -> 450.00469 | E8: =E3-E5-E6-E7 -> 446.92775 | F8: =F3-F5-F6-F7 -> 447.85958 | G8: =G3-G5-G6-G7 -> 443.87155 | H8: =H3-H5-H6-H7 -> 393.87974 | I8: =I3-I5-I6-I7 -> 412.7912 | J8: =J3-J5-J6-J7 -> 409.71817 | K8: =K3-K5-K6-K7 -> 401.886 | ... T8: =T3-T5-T6-T7 -> 376.37083
A9: linear trajector to benchmarks | B9: linear trajectory | C9: Mt CO2e | U9: 691.32881 | V9: 666.9647 | W9: 642.60059 | X9: 618.23647 | Y9: 593.87236 | Z9: 569.50824 | AA9: 545.14413 | AB9: 520.78002 | AC9: 496.4159 | AD9: 475.47011 | AE9: 454.52431 | AF9: 433.57852 | AG9: 412.63272 | AH9: 391.68693 | AI9: 370.74113 | AJ9: 349.79534 | AK9: 328.84954 | AL9: 307.90375 | AM9: 286.95795 | AN9: 266.01216 | AO9: 245.06636 | AP9: 224.12057 | AQ9: 203.17477 | AR9: 182.22898 | AS9: 161.28318 | AT9: 140.33739 | AU9: 119.39159 | AV9: 98.445795 | AW9: 77.5
A10: linear trajector to benchmarks 2 | B10: linear trajectory | C10: Mt CO2e | U10: 605.55116 | V10: 589.0982 | W10: 572.64524 | X10: 556.19229 | Y10: 539.73933 | Z10: 523.28637 | AA10: 506.83341 | AB10: 490.38045 | AC10: 473.92749 | AD10: 453.60612 | AE10: 433.28474 | AF10: 412.96337 | AG10: 392.64199 | AH10: 372.32062 | AI10: 351.99924 | AJ10: 331.67787 | AK10: 311.35649 | AL10: 291.03512 | AM10: 270.71375 | AN10: 250.39237 | AO10: 230.071 | AP10: 209.74962 | AQ10: 189.42825 | AR10: 169.10687 | AS10: 148.7855 | AT10: 128.46412 | AU10: 108.14275 | AV10: 87.821375 | AW10: 67.5
A11: 2030 benchmark | B11: FF55 MIX | C11: Mt CO2e | AC11: =SUM(AC109:AC113) -> 496.4159
A12: 2030 benchmark (CO2 only) | B12: FF55 MIX | AC12: =AC109+AC110 -> 473.92749
A13: 2050 benchmark | B13: CTP | C13: Mt CO2e | AW13: =E121 -> 77.5
A14: 2050 benchmark (CO2 only) | B14: CTP | C14: Mt CO2e | AW14: =E119+E118 -> 67.5
A15: 2040 advice scenarios (CO2 only) | C15: Mt CO2e | AM15: 129 | AW15: =AW138 -> 21.7077
A16: 2040 advice min | C16: Mt CO2e | AM16: 89 | AW16: =AW137 -> 5.2357
A17: Gross value added (2005=100) | C17: % of 2005 | D17: 100 | E17: 101.541 | F17: 103.794 | G17: 106.502 | H17: 107.121 | I17: 106.463 | J17: 107.861 | K17: 109.731 | L17: 110.792 | M17: 110.972 | N17: 114.084 | O17: 114.141 | P17: 114.224 | Q17: 115.075 | R17: 117.21 | S17: 118.66 | T17: 121.182 | U17: 133.059
A19: Average 2005-2022 | B19: calculated | C19: Mt CO2e | D19: =(U3-D3)/17 -> -17.055585
A20: Average 2017-2021 | B20: calculated | C20: Mt CO2e | D20: =(T3-P3)/4 -> -8.3905015 | G20: Indicator I1
A21: Average 2018-2022 | B21: calculated | C21: Mt CO2e | D21: =AVERAGE(U3-Q3)/4 -> -23.486949
A22: Average 2022-2030 | B22: calculated | C22: Mt CO2e | D22: =(AC9-T3)/9 -> -29.006466
A23: Average 2023-2030 | B23: calculated | C23: Mt CO2e | D23: =(AC9-U3)/8 -> -24.364114
A24: Average 2031-2050 | B24: calculated | C24: Mt CO2e | D24: =AE9-AD9 -> -20.945795
A26: Average 2005-2022 (CO2 only) | B26: calculated | C26: Mt CO2e | D26: =(U4-D4)/17 -> -14.15767
D27: 2005-2021
A28: Iron and steel | D28: =T5/D5-1 -> -0.23887283
A29: chemicals | D29: =T6/D6-1 -> -0.36382521
A30: cement | D30: =T7/D7-1 -> -0.23142196
A31: other subsectors | D31: =T8/D8-1 -> -0.16362909
D40: 473.92749
A43: Historical data
A44: All GHGs
A45: Sector | B45: Source | C45: Unit | D45: 2005 | E45: 2006 | F45: 2007 | G45: 2008 | H45: 2009 | I45: 2010 | J45: 2011 | K45: 2012 | L45: 2013 | M45: 2014 | N45: 2015 | O45: 2016 | P45: 2017 | Q45: 2018 | R45: 2019 | S45: 2020 | T45: 2021 | U45: 2022 (proxy)
A46: 1.A.2 - Manufacturing Industries and Construction | B46: EEA GHG data viewer | C46: kt CO2e | D46: 556523.8 | E46: 546025.34 | F46: 558821.74 | G46: 539298.56 | H46: 447681.17 | I46: 480724.97 | J46: 468688.84 | K46: 450892.56 | L46: 432830.47 | M46: 419987.2 | N46: 428994.7 | O46: 434138.47 | P46: 441345.55 | Q46: 442369.92 | R46: 428579.9 | S46: 412771.88 | T46: 439540.13 | U46: 398202.32
A47: 1.A.2.a - Iron and Steel | B47: EEA GHG data viewer | C47: kt CO2e | D47: 105195.78 | E47: 105786.76 | F47: 113121.87 | G47: 105942.33 | H47: 74338.594 | I47: 93329.779 | J47: 92651.345 | K47: 86978.152 | L47: 81983.505 | M47: 80583.691 | N47: 85620.562 | O47: 82270.658 | P47: 82921.438 | Q47: 82741.115 | R47: 78548.167 | S47: 69669.793 | T47: 79592.435
A48: 1.A.2.b - Non-Ferrous Metals | B48: EEA GHG data viewer | C48: kt CO2e | D48: 11481.897 | E48: 11507.632 | F48: 11589.219 | G48: 11099.26 | H48: 10078.701 | I48: 11058.486 | J48: 10185.994 | K48: 9248.4225 | L48: 8994.9345 | M48: 8471.8817 | N48: 8610.4113 | O48: 8720.0899 | P48: 8900.5287 | Q48: 8614.4304 | R48: 8881.1903 | S48: 8387.0876 | T48: 9496.5356
A49: 1.A.2.c - Chemicals | B49: EEA GHG data viewer | C49: kt CO2e | D49: 84642.992 | E49: 83294.121 | F49: 83946.663 | G49: 83378.025 | H49: 72400.56 | I49: 76266.277 | J49: 74843.112 | K49: 73217.125 | L49: 69690.367 | M49: 64414.16 | N49: 63994.164 | O49: 65140.923 | P49: 67504.683 | Q49: 69772.981 | R49: 65596.111 | S49: 66957.922 | T49: 71819.845
A50: 1.A.2.d - Pulp, Paper and Print | B50: EEA GHG data viewer | C50: kt CO2e | D50: 30831.444 | E50: 30433.125 | F50: 29562.723 | G50: 28226.145 | H50: 26485.725 | I50: 27205.072 | J50: 26138.148 | K50: 25422.207 | L50: 24910.829 | M50: 23365.407 | N50: 23589.919 | O50: 23974.439 | P50: 24024.492 | Q50: 23951.275 | R50: 24727.018 | S50: 22486.315 | T50: 23774.576
A51: 1.A.2.e - Food Processing, Beverages and Tobacco | B51: EEA GHG data viewer | C51: kt CO2e | D51: 45384.168 | E51: 41185.079 | F51: 40457.017 | G51: 38587.184 | H51: 35153.199 | I51: 36444.619 | J51: 34739.926 | K51: 34662.808 | L51: 34953.81 | M51: 34746.389 | N51: 35459.476 | O51: 36002.584 | P51: 36579.36 | Q51: 36786.972 | R51: 36263.172 | S51: 34896.666 | T51: 36843.585
A52: 1.A.2.f - Non-metallic minerals | B52: EEA GHG data viewer | C52: kt CO2e | D52: 125162.75 | E52: 123512.02 | F52: 126165.9 | G52: 121291 | H52: 98848.969 | I52: 99975.673 | J52: 98054.619 | K52: 93107.541 | L52: 83163.865 | M52: 84427.301 | N52: 84249.262 | O52: 86503.771 | P52: 86737.503 | Q52: 88766.998 | R52: 85877.742 | S52: 81701.413 | T52: 84372.779 | AH52: 0
...

Sheet Figure 21. emissions profile
A1: Sector 1 | B1: Source | C1: 2019 (kt CO2e) | D1: 2019 (Mt CO2e) | E1: 2021 (kt CO2e) | F1: 2021 (Mt CO2e) | G1: Sector 2 | H1: Sector 3 | J1: Row Labels | K1: Sum of 2019 (Mt CO2e) | L1: Sum of 2021 (Mt CO2e) | O1: Row Labels | P1: Sum of 2021 (Mt CO2e)
A2: 1.A.2 - Manufacturing Industries and Construction | B2: EEA GHG data viewer | C2: 428579.9 | D2: =C2/1000 -> 428.5799 | E2: 439540.13 | F2: =E2/1000 -> 439.54013 | G2: aggregate | H2: aggregate | J2: cement and lime | K2: 145.17591 | L2: 118.74314 | O2: Iron and steel | P2: 147.01485
A3: 1.A.2.a - Iron and Steel | B3: EEA GHG data viewer | C3: 78548.167 | D3: =C3/1000 -> 78.548167 | E3: 79592.435 | F3: =E3/1000 -> 79.592435 | G3: Iron and steel | H3: iron and steel | J3: Chemicals | K3: 121.31098 | L3: 123.86514 | O3: Chemicals | P3: 123.86514
A4: 1.A.2.b - Non-Ferrous Metals | B4: EEA GHG data viewer | C4: 8881.1903 | D4: =C4/1000 -> 8.8811903 | E4: 9496.5356 | F4: =E4/1000 -> 9.4965356 | G4: other | H4: other ferrous and non-ferrous | J4: Iron and steel | K4: 145.36342 | L4: 147.01485 | O4: Cement | P4: =F57 -> 93.596201
A5: 1.A.2.c - Chemicals | B5: EEA GHG data viewer | C5: 65596.111 | D5: =C5/1000 -> 65.596111 | E5: 71819.845 | F5: =E5/1000 -> 71.819845 | G5: Chemicals | H5: chemicals | J5: other | K5: 348.27782 | L5: 367.85096 | O5: other | P5: =GETPIVOTDATA("Sum of 2021 (Mt CO2e)",$J$1)-P4-P3-P2 -> 392.9979
A6: 1.A.2.d - Pulp, Paper and Print | B6: EEA GHG data viewer | C6: 24727.018 | D6: =C6/1000 -> 24.727018 | E6: 23774.576 | F6: =E6/1000 -> 23.774576 | G6: other | H6: pulp and paper | J6: Grand Total | K6: 760.12813 | L6: 757.47409
A7: 1.A.2.e - Food Processing, Beverages and Tobacco | B7: EEA GHG data viewer | C7: 36263.172 | D7: =C7/1000 -> 36.263172 | E7: 36843.585 | F7: =E7/1000 -> 36.843585 | G7: other | H7: food, beverages and tobacco
A8: 1.A.2.f - Non-metallic minerals | B8: EEA GHG data viewer | C8: 85877.742 | D8: =C8/1000 -> 85.877742 | E8: 84372.779 | F8: =E8/1000 -> 84.372779 | G8: aggregate | H8: aggregate
A9: - of which cement and lime | C9: =C57+C58-C14-C15 -> 53916.4 | D9: =C9/1000 -> 53.9164 | E9: =E57+E58-E14-E15 -> 28595.393 | F9: =E9/1000 -> 28.595393 | G9: cement and lime | H9: cement and lime
A10: - of which other non-metalic minerals | C10: =C8-C9 -> 31961.341 | D10: =C10/1000 -> 31.961341 | E10: =E8-E9 -> 55777.385 | F10: =E10/1000 -> 55.777385 | G10: other | H10: other non-metalic minerals
A11: 1.A.2.g - Other Manufacturing Industries and Constructions | B11: EEA GHG data viewer | C11: 128686.5 | D11: =C11/1000 -> 128.6865 | E11: 133640.38 | F11: =E11/1000 -> 133.64038 | G11: other | H11: other
A12: 2 - Industrial Processes and Product Use | B12: EEA GHG data viewer | C12: 331548.23 | D12: =C12/1000 -> 331.54823 | E12: 317933.96 | F12: =E12/1000 -> 317.93396 | G12: aggregate | H12: aggregate
A13: 2.A - Mineral Industry | B13: EEA GHG data viewer | C13: 105196.89 | D13: =C13/1000 -> 105.19689 | E13: 104085.64 | F13: =E13/1000 -> 104.08564 | G13: aggregate | H13: aggregate
A14: 2.A.1 - Cement Production | B14: EEA GHG data viewer | C14: 73556.1 | D14: =C14/1000 -> 73.5561 | E14: 72419.613 | F14: =E14/1000 -> 72.419613 | G14: cement and lime | H14: cement
A15: 2.A.2 - Lime Production | B15: EEA GHG data viewer | C15: 17703.413 | D15: =C15/1000 -> 17.703413 | E15: 17728.138 | F15: =E15/1000 -> 17.728138 | G15: cement and lime | H15: other non-metalic minerals
A16: 2.A.3 - Glass production | B16: EEA GHG data viewer | C16: 3969.1735 | D16: =C16/1000 -> 3.9691735 | E16: 4064.7184 | F16: =E16/1000 -> 4.0647184 | G16: other | H16: other non-metalic minerals
A17: 2.A.4 - Other Process Uses of Carbonates | B17: EEA GHG data viewer | C17: 9968.2025 | D17: =C17/1000 -> 9.9682025 | E17: 9873.1652 | F17: =E17/1000 -> 9.8731652 | G17: other | H17: other non-metalic minerals
A18: 2.B - Chemical Industry | B18: EEA GHG data viewer | C18: 55714.869 | D18: =C18/1000 -> 55.714869 | E18: 52045.293 | F18: =E18/1000 -> 52.045293 | G18: aggregate | H18: aggregate
A19: 2.B.1 - Ammonia Production | B19: EEA GHG data viewer | C19: 19943.801 | D19: =C19/1000 -> 19.943801 | E19: 19301.46 | F19: =E19/1000 -> 19.30146 | G19: Chemicals | H19: chemicals | K19: industrial GHG emissions in 2021 per sub-sector (in Mt CO2e. and % of total)
A20: 2.B.2 - Nitric Acid Production | B20: EEA GHG data viewer | C20: 2745.454 | D20: =C20/1000 -> 2.745454 | E20: 2397.6389 | F20: =E20/1000 -> 2.3976389 | G20: Chemicals | H20: chemicals
A21: 2.B.3 - Adipic Acid Production | B21: EEA GHG data viewer | C21: 283.23687 | D21: =C21/1000 -> 0.28323687 | E21: 143.74206 | F21: =E21/1000 -> 0.14374206 | G21: Chemicals | H21: chemicals
A22: 2.B.4 - Caprolactam, Glyoxal and Glyoxylic Acid Production | B22: EEA GHG data viewer | C22: 1508.0092 | D22: =C22/1000 -> 1.5080092 | E22: 1035.4031 | F22: =E22/1000 -> 1.0354031 | G22: Chemicals | H22: chemicals
A23: 2.B.5 - Carbide Production | B23: EEA GHG data viewer | C23: 270.93929 | D23: =C23/1000 -> 0.27093929 | E23: 262.11689 | F23: =E23/1000 -> 0.26211689 | G23: Chemicals | H23: chemicals
A24: 2.B.6 - Titanium Dioxide Production | B24: EEA GHG data viewer | C24: 120.09837 | D24: =C24/1000 -> 0.12009837 | E24: 123.50909 | F24: =E24/1000 -> 0.12350909 | G24: Chemicals | H24: chemicals
A25: 2.B.7 - Soda Ash Production | B25: EEA GHG data viewer | C25: 1948.8551 | D25: =C25/1000 -> 1.9488551 | E25: 1832.151 | F25: =E25/1000 -> 1.832151 | G25: Chemicals | H25: chemicals
A26: 2.B.8 - Petrochemical and Carbon Black Production | B26: EEA GHG data viewer | C26: 12895.284 | D26: =C26/1000 -> 12.895284 | E26: 13207.577 | F26: =E26/1000 -> 13.207577 | G26: Chemicals | H26: chemicals
A27: 2.B.9 - Fluorochemical Production | B27: EEA GHG data viewer | C27: 2662.625 | D27: =C27/1000 -> 2.662625 | E27: 1051.1049 | F27: =E27/1000 -> 1.0511049 | G27: Chemicals | H27: chemicals
A28: 2.B.10 - Other chemical industry | B28: EEA GHG data viewer | C28: 13336.567 | D28: =C28/1000 -> 13.336567 | E28: 12690.59 | F28: =E28/1000 -> 12.69059 | G28: Chemicals | H28: chemicals
A29: 2.C - Metal Industry | B29: EEA GHG data viewer | C29: 74906.841 | D29: =C29/1000 -> 74.906841 | E29: 74664.268 | F29: =E29/1000 -> 74.664268 | G29: aggregate | H29: aggregate
A30: 2.C.1 - Iron and Steel Production | B30: EEA GHG data viewer | C30: 66815.25 | D30: =C30/1000 -> 66.81525 | E30: 67422.42 | F30: =E30/1000 -> 67.42242 | G30: Iron and steel | H30: Iron and steel
A31: 2.C.2 - Ferroalloys Production | B31: EEA GHG data viewer | C31: 2609.3178 | D31: =C31/1000 -> 2.6093178 | E31: 2189.1354 | F31: =E31/1000 -> 2.1891354 | G31: other | H31: other ferrous and non-ferrous
... A42: 2.E.1 - Integrated Circuit or Semiconductor | B42: EEA GHG data viewer | C42: 769.11721 | D42: =C42/1000 -> 0.76911721 | E42: 742.20341 | F42: =E42/1000 -> 0.74220341 | G42: other | H42: other
A43: 2.E.2 - TFT Flat Panel Display | B43: EEA GHG data viewer | D43: =C43/1000 -> 0 | F43: =E43/1000 -> 0 | G43: other | H43: other
A44: 2.E.3 - Photovoltaics | B44: EEA GHG data viewer | D44: =C44/1000 -> 0 | F44: =E44/1000 -> 0 | G44: other | H44: other
A45: 2.E.4 - Heat Transfer Fluid | B45: EEA GHG data viewer | C45: 23.292115 | D45: =C45/1000 -> 0.023292115 | E45: 25.47048 | F45: =E45/1000 -> 0.02547048 | G45: other | H45: other
A46: 2.E.5 - Other electronics industry | B46: EEA GHG data viewer | C46: 0.98787 | D46: =C46/1000 -> 0.00098787 | F46: =E46/1000 -> 0 | G46: other | H46: other
A47: 2.F - Product Uses as Substitutes for ODS | B47: EEA GHG data viewer | C47: 78104.078 | D47: =C47/1000 -> 78.104078 | E47: 70842.225 | F47: =E47/1000 -> 70.842225 | G47: aggregate | H47: aggregate
A48: 2.F.1 - Refrigeration and Air conditioning | B48: EEA GHG data viewer | C48: 71756.135 | D48: =C48/1000 -> 71.756135 | E48: 65043.871 | F48: =E48/1000 -> 65.043871 | G48: other | H48: F-gases
A49: 2.F.2 - Foam Blowing Agents | B49: EEA GHG data viewer | C49: 1828.9243 | D49: =C49/1000 -> 1.8289243 | E49: 1634.5317 | F49: =E49/1000 -> 1.6345317 | G49: other | H49: F-gases
A50: 2.F.3 - Fire Protection | B50: EEA GHG data viewer | C50: 2403.7241 | D50: =C50/1000 -> 2.4037241 | E50: 2383.2847 | F50: =E50/1000 -> 2.3832847 | G50: other | H50: F-gases
...

Sheet I2. Production and consumption
A1: Steel
B2: Source | C2: Unit | D2: 2005 | I2: 2010 | N2: 2015 | S2: 2020
A3: Production | B3: Eurofer Steel in Figures 2022 (crude steel output) | C3: Mt | G3: 185.03224 | H3: 129.26978 | I3: 163.07653 | J3: 168.09782 | K3: 159.00343 | L3: 154.31767 | M3: 157.06496 | N3: 155.12873 | O3: 154.29781 | P3: 160.86903 | Q3: 160.06576 | R3: 150.24445 | S3: 132.21726 | T3: 152.78208
A4: Production | B4: Eurofer Steel in Figures 2022 (finished steel output) | C4: Mt | K4: 145.358 | L4: 142.25 | M4: 144.052 | N4: 142.874 | O4: 143.653 | P4: 147.772 | Q4: 148.478 | R4: 139.199 | S4: 123.664 | T4: 140.65
A5: Use | B5: Eurofer Steel in Figures 2022 | C5: Mt | G5: 173.811 | H5: 113.52 | I5: 139.077 | J5: 147.828 | K5: 132.18 | L5: 132.072 | M5: 135.732 | N5: 142.068 | O5: 146.796 | P5: 148.92 | Q5: 152.712 | R5: 144.768 | S5: 129.288 | T5: 148.956
A6: Difference | B6: calculated | C6: Mt | K6: =K4-K5 -> 13.178 | L6: =L4-L5 -> 10.178 | M6: =M4-M5 -> 8.32 | N6: =N4-N5 -> 0.806 | O6: =O4-O5 -> -3.143 | P6: =P4-P5 -> -1.148 | Q6: =Q4-Q5 -> -4.234 | R6: =R4-R5 -> -5.569 | ... T6: =T4-T5 -> -8.306
A7: Import | B7: Eurostat EU trade since 2002 by CPA 2.1 (DS-059268) | C7: Mt | G7: 48.829396 | H7: 26.530051 | I7: 33.209668 | J7: 39.478382 | K7: 30.440176 | L7: 33.975869 | M7: 36.280126 | N7: 43.016655 | O7: 44.162149 | P7: 44.908824 | Q7: 49.450438 | R7: 44.267942 | S7: 36.525231 | T7: 47.176036
A8: Export | B8: Eurostat EU trade since 2002 by CPA 2.1 (DS-059268) | C8: Mt | G8: 29.806234 | H8: 26.672804 | I8: 30.294907 | J8: 31.05282 | K8: 33.553666 | L8: 30.462541 | M8: 30.850526 | N8: 28.806755 | O8: 27.946372 | P8: 28.482287 | Q8: 26.152524 | R8: 25.760837 | S8: 21.340454 | T8: 21.409915
A9: Trade balance | B9: calculated | C9: Mt | G9: =G8-G7 -> -19.023162 | H9: =H8-H7 -> 0.1427534 | I9: =I8-I7 -> -2.9147615 | J9: =J8-J7 -> -8.4255613 | K9: =K8-K7 -> 3.1134906 | L9: =L8-L7 -> -3.5133284 | M9: =M8-M7 -> -5.4296002 | N9: =N8-N7 -> -14.209899 | ... T9: =T8-T7 -> -25.766121
A11: Average 2017-2021 | D11: =AVERAGE(T5-S5,S5-R5,R5-Q5,Q5-P5) -> 0.009 | M11: =M4/M3 -> 0.9171492 | N11: =N4/N3 -> 0.92100282 | O11: =O4/O3 -> 0.93101126 | P11: =P4/P3 -> 0.91858576 | Q11: =Q4/Q3 -> 0.92760628 | R11: =R4/R3 -> 0.9264835 | S11: =S4/S3 -> 0.93530907 | T11: =T4/T3 -> 0.92059224
A13: Cement
B14: Source | C14: Unit | I14: 2010 | N14: 2015 | S14: 2020
A15: Production | B15: Provided by Cembureau | C15: Mt | D15: 239.527 | E15: 256.169 | F15: 261.812 | G15: 244.355 | H15: 197.892 | I15: 185.623 | J15: 187.216 | K15: 164.687 | L15: 156.994 | M15: 157.525 | N15: 158.108 | O15: 159.874 | P15: 165.694 | Q15: 179.792 | R15: 173.053 | S15: 172.231 | T15: 182.549
A16: Use | B16: Provided by Cembureau | C16: Mt | D16: 232.29 | E16: 250.175 | F16: 254.029 | G16: 235.559 | H16: 189.106 | I16: 176.409 | J16: 178.253 | K16: 151.764 | L16: 142.188 | M16: 140.49 | N16: 141.356 | O16: 142.746 | P16: 147.836 | Q16: 155.342 | R16: 157.444 | S16: 159.215 | T16: 170.472
A17: Difference | B17: calculated | C17: Mt | D17: =D15-D16 -> 7.237 | E17: =E15-E16 -> 5.994 | F17: =F15-F16 -> 7.783 | G17: =G15-G16 -> 8.796 | H17: =H15-H16 -> 8.786 | I17: =I15-I16 -> 9.214 | J17: =J15-J16 -> 8.963 | K17: =K15-K16 -> 12.923 | ... T17: =T15-T16 -> 12.077
A18: Import | B18: Eurostat EU trade since 2002 by CPA 2.1 (DS-059268) | C18: Mt | D18: 15.252737 | E18: 16.010581 | F18: 18.332848 | G18: 10.896095 | H18: 7.6650245 | I18: 5.6254366 | J18: 4.3293103 | K18: 2.944935 | L18: 2.6824019 | M18: 2.5325485 | N18: 2.6133071 | O18: 2.42527 | P18: 3.1882888 | Q18: 3.4076022 | R18: 5.2322343 | S18: 6.3119639 | T18: 9.7064403
A19: Export | B19: Eurostat EU trade since 2002 by CPA 2.1 (DS-059268) | C19: Mt | D19: 12.936851 | E19: 11.454387 | F19: 10.93445 | G19: 13.100721 | H19: 13.892032 | I19: 16.361451 | J19: 13.170613 | K19: 19.953939 | L19: 25.077026 | M19: 27.918478 | N19: 26.820222 | O19: 24.625602 | P19: 22.341496 | Q19: 18.580939 | R19: 14.942994 | S19: 13.219775 | T19: 13.198037
A20: Trade balance | B20: calculated | C20: Mt | D20: =D19-D18 -> -2.3158858 | E20: =E19-E18 -> -4.5561949 | F20: =F19-F18 -> -7.3983985 | G20: =G19-G18 -> 2.2046262 | H20: =H19-H18 -> 6.2270072 | I20: =I19-I18 -> 10.736014 | J20: =J19-J18 -> 8.8413023 | K20: =K19-K18 -> 17.009004 | ... T20: =T19-T18 -> 3.4915972
A22: Average 2017-2021 | D22: =AVERAGE(T16-S16,S16-R16,R16-Q16,Q16-P16) -> 5.659
A24: Chemicals
B25: Source | C25: Unit | I25: 2010 | N25: 2015 | S25: 2020
A26: Production | B26: calculated | C26: Mt | E26: =SUM(E27:E33) -> 33.518075 | F26: =SUM(F27:F33) -> 36.246996 | G26: =SUM(G27:G33) -> 31.117619 | H26: =SUM(H27:H33) -> 28.083484 | I26: =SUM(I27:I33) -> 30.660657 | J26: =SUM(J27:J33) -> 32.080734 | K26: =SUM(K27:K33) -> 31.200394 | L26: =SUM(L27:L33) -> 29.589364 | ... U26: =SUM(U27:U33) -> 26.839574
A27: - of which ethylene | B27: Eurostat sold production, exports and imports (code DS-056120) | C27: Mt | E27: 12.099995 | F27: 14.178715 | G27: 11.868967 | H27: 9.9257453 | I27: 12.156694 | J27: 12.107575 | K27: 11.713151 | L27: 10.34106 | M27: 11.024052 | N27: 10.657337 | O27: 10.860381 | P27: 11.744647 | Q27: 10.690058 | R27: 9.817689 | S27: 9.7353332 | T27: 10 | U27: 9.6064602
A28: - of which propylene | B28: Eurostat sold production, exports and imports (code DS-056120) | C28: Mt | E28: 10.355846 | F28: 11.390539 | G28: 10.41218 | H28: 9.2213145 | I28: 9.6312747 | J28: 9.8828846 | K28: 9.5138379 | L28: 8.9870171 | M28: 9.4741108 | N28: 9.559588 | O28: 9.7137054 | P28: 10.287057 | Q28: 10.044501 | R28: 9.7924461 | S28: 10 | T28: 9.7426019 | U28: 8.9217571
A29: - of which benzene | B29: Eurostat sold production, exports and imports (code DS-056120) | C29: Mt | E29: 5.647354 | F29: 5.68717 | G29: 4.8 | H29: 4.8132951 | I29: 4.9728469 | J29: 6.1928237 | K29: 6.1298411 | L29: 6.3477446 | M29: 6.2895174 | N29: 5.9145912 | O29: 5.979281 | P29: 6.1085583 | Q29: 5.6 | R29: 5.4064826 | S29: 5.2544714 | T29: 6.2944227 | U29: 5.639483
A30: - of which toluene | B30: Eurostat sold production, exports and imports (code DS-056120) | C30: Mt | E30: 1.6957346 | F30: 1.6899812 | G30: 1.5274441 | H30: 1.440881 | I30: 1.317171 | J30: 1.2933429 | K30: 1.2343715 | L30: 1.2791024 | M30: 1.3188164 | N30: 1.3852643 | O30: 1.3139596 | P30: 1.4238731 | Q30: 1.3258779 | R30: 1.2794011 | S30: 1.249507 | T30: 1 | U30: 1.1751407
A31: - of which o-Xylene | B31: Eurostat sold production, exports and imports (code DS-056120) | C31: Mt | E31: 0.56918118 | F31: 0.47680124 | G31: 0.66969656 | H31: 0.70989645 | I31: 0.40345642 | J31: 0.41198505 | K31: 0.3621391 | L31: 0.4446734 | M31: 0.49692034 | N31: 0.49141533 | O31: 0.37896919 | P31: 0.400811 | Q31: 0.22893626 | R31: 0.22955776 | S31: 0.17870472 | T31: 0.18 | U31: 0.14703406
A32: - of which p-Xylene | B32: Eurostat sold production, exports and imports (code DS-056120) | C32: Mt | E32: 2.0085954 | F32: 1.7952467 | G32: 0.91445819 | H32: 1.1052903 | I32: 1.1851053 | J32: 1.3033674 | K32: 1.3780775 | L32: 1.3397637 | M32: 1.102881 | N32: 1.2076284 | O32: 0.97550402 | P32: 1.0452295 | Q32: 0.80931744 | R32: 0.89550441 | S32: 0.73878121 | T32: 0.6 | U32: 0.549699
A33: - of which m-Xylene and mixed xylene isomers | B33: Eurostat sold production, exports and imports (code DS-056120) | C33: Mt | E33: 1.1413691 | F33: 1.0285428 | G33: 0.92487251 | H33: 0.86706092 | I33: 0.99410827 | J33: 0.88875499 | K33: 0.86897587 | L33: 0.85000336 | M33: 0.87164626 | N33: 0.91346055 | O33: 0.91736333 | P33: 0.94612219 | Q33: 0.94155131 | R33: 0.93202882 | S33: 0.85057722 | T33: 0.9 | U33: 0.8
A34: Use | B34: calculated | C34: Mt | E34: =E26-E35 -> 35.991754 | F34: =F26-F35 -> 39.390657 | G34: =G26-G35 -> 33.351163 | H34: =H26-H35 -> 29.562272 | I34: =I26-I35 -> 32.741205 | J34: =J26-J35 -> 33.954248 | K34: =K26-K35 -> 32.582584 | L34: =L26-L35 -> 30.984954 | ... U34: =U26-U35 -> 29.107128
A35: Trade balance | B35: calculated | C35: Mt | E35: =E44-E36 -> -2.4736789 | F35: =F44-F36 -> -3.1436611 | G35: =G44-G36 -> -2.2335448 | H35: =H44-H36 -> -1.478788 | I35: =I44-I36 -> -2.0805481 | J35: =J44-J36 -> -1.8735148 | K35: =K44-K36 -> -1.3821896 | L35: =L44-L36 -> -1.3955899 | ... U35: =U44-U36 -> -2.2675537
A36: Import | B36: calculated | C36: Mt | E36: =SUM(E37:E43) -> 3.6972343 | F36: =SUM(F37:F43) -> 4.4879989 | G36: =SUM(G37:G43) -> 3.4573382 | H36: =SUM(H37:H43) -> 2.8117923 | I36: =SUM(I37:I43) -> 2.9841959 | J36: =SUM(J37:J43) -> 3.1926908 | K36: =SUM(K37:K43) -> 2.7053228 | L36: =SUM(L37:L43) -> 2.7682372 | ... U36: =SUM(U37:U43) -> 3.3315652
A37: - of which ethylene | B37: Eurostat sold production, exports and imports (code DS-056120) | C37: Mt | E37: 1.5486027 | F37: 1.9101667 | G37: 1.4475951 | H37: 1.2290101 | I37: 1.1949306 | J37: 1.1784766 | K37: 1.0051484 | L37: 1.1650942 | M37: 0.8140495 | N37: 1.1288497 | O37: 1.2494755 | P37: 1.3261649 | Q37: 1.376512 | R37: 1.4185796 | S37: 1.2961027 | T37: 0.87732496 | U37: 1.2426082
A38: - of which propylene | B38: Eurostat sold production, exports and imports (code DS-056120) | C38: Mt | E38: 1.0040396 | F38: 1.1494441 | G38: 0.6338235 | H38: 0.558885 | I38: 0.723305 | J38: 0.7494352 | K38: 0.6165615 | L38: 0.5628204 | M38: 0.4350917 | N38: 0.5194684 | O38: 0.6289835 | P38: 0.7030132 | Q38: 0.62616 | R38: 0.8455699 | S38: 0.69313842 | T38: 0.74792151 | U38: 0.50772954
A39: - of which benzene | B39: Eurostat sold production, exports and imports (code DS-056120) | C39: Mt | E39: 0.7478965 | F39: 0.8506079 | G39: 0.9144626 | H39: 0.6868722 | I39: 0.7713624 | J39: 0.9034372 | K39: 0.7524077 | L39: 0.8708824 | M39: 0.9488023 | N39: 0.940197 | O39: 1.0769815 | P39: 1.0521058 | Q39: 1.0495044 | R39: 1.0302582 | S39: 1.0372322 | T39: 1.1247476 | U39: 0.72380394
A40: - of which toluene | B40: Eurostat sold production, exports and imports (code DS-056120) | C40: Mt | E40: 0.0529164 | F40: 0.1483364 | G40: 0.1406226 | H40: 0.070911 | I40: 0.0477936 | J40: 0.0499153 | K40: 0.0491632 | L40: 0.024203 | M40: 0.0381771 | N40: 0.023865 | O40: 0.0365229 | P40: 0.027925 | Q40: 0.0283288 | R40: 0.050491828 | S40: 0.026964021 | T40: 0.014039966 | U40: 0.023749282
A41: - of which o-Xylene | B41: Eurostat sold production, exports and imports (code DS-056120) | C41: Mt | E41: 0.0861513 | F41: 0.1058511 | G41: 0.0912346 | H41: 0.0672676 | I41: 0.089781 | J41: 0.0850444 | K41: 0.0702122 | L41: 0.0584313 | M41: 0.064507 | N41: 0.0855043 | O41: 0.1166635 | P41: 0.0851389 | Q41: 0.1100099 | R41: 0.11357239 | S41: 0.14139793 | T41: 0.15497753 | U41: 0.17563638
A42: - of which p-Xylene | B42: Eurostat sold production, exports and imports (code DS-056120) | C42: Mt | E42: 0.170929 | F42: 0.2273287 | G42: 0.1781055 | H42: 0.1077158 | I42: 0.0896718 | J42: 0.1358516 | K42: 0.1781173 | L42: 0.0840575 | M42: 0.0658065 | N42: 0.1199557 | O42: 0.1347842 | P42: 0.1287653 | Q42: 0.3021161 | R42: 0.46647632 | S42: 0.52157054 | T42: 0.71478314 | U42: 0.63661447
A43: - of which m-Xylene and mixed xylene isomers | B43: Eurostat sold production, exports and imports (code DS-056120) | C43: Mt | E43: 0.0866988 | F43: 0.096264 | G43: 0.0514943 | H43: 0.0911306 | I43: 0.0673515 | J43: 0.0905305 | K43: 0.0337125 | L43: 0.0027484 | M43: 0.0515534 | N43: 0.0328568 | O43: 0.0345136 | P43: 0.0472585 | Q43: 0.0818401 | R43: 0.03767513 | S43: 0.027219623 | T43: 0.015898002 | U43: 0.021423338
A44: Export | B44: calculated | C44: Mt | E44: =SUM(E45:E51) -> 1.2235554 | F44: =SUM(F45:F51) -> 1.3443378 | G44: =SUM(G45:G51) -> 1.2237934 | H44: =SUM(H45:H51) -> 1.3330043 | I44: =SUM(I45:I51) -> 0.9036478 | J44: =SUM(J45:J51) -> 1.319176 | K44: =SUM(K45:K51) -> 1.3231332 | L44: =SUM(L45:L51) -> 1.3726473 | ... U44: =SUM(U45:U51) -> 1.0640115
...

Sheet I3. CMUR
A1: CMUR
B2: Source | C2: Unit | D2: 2010 | I2: 2015 | N2: 2020 | S2: 2025 | X2: 2030
A3: Historic | B3: Eurostat SDG_12_41 | C3: % | D3: 0.108 | E3: 0.103 | F3: 0.111 | G3: 0.113 | H3: 0.112 | I3: 0.113 | J3: 0.115 | K3: 0.115 | L3: 0.117 | M3: 0.12 | N3: 0.117 | O3: 0.117
A4: 2030 benchmark | B4: 8th EAP, Circular Economy Action Plan | C4: % | X4: =2*N3 -> 0.234
A5: linear trajectory | C5: % | O5: 0.117 | P5: 0.13 | Q5: 0.143 | R5: 0.156 | S5: 0.169 | T5: 0.182 | U5: 0.195 | V5: 0.208 | W5: 0.221 | X5: 0.234
A7: Average 2017-2021 | D7: =AVERAGE(O3-N3,N3-M3,M3-L3,L3-K3) -> 0.0005
A8: Average 2021-2030 | D8: =P5-O5 -> 0.013
A11: Indicator I3

Sheet I4. GHG intensity products
A1: Steel
B2: Source | C2: Unit | D2: 2005 | I2: 2010 | N2: 2015 | S2: 2020
A3: Production (Mt) | B3: Eurofer data | C3: Mt | G3: ='I2. Production and consumption'!G3 -> 185.03224 | H3: ='I2. Production and consumption'!H3 -> 129.26978 | I3: ='I2. Production and consumption'!I3 -> 163.07653 | J3: ='I2. Production and consumption'!J3 -> 168.09782 | K3: ='I2. Production and consumption'!K3 -> 159.00343 | L3: ='I2. Production and consumption'!L3 -> 154.31767 | M3: ='I2. Production and consumption'!M3 -> 157.06496 | N3: ='I2. Production and consumption'!N3 -> 155.12873 | ... T3: ='I2. Production and consumption'!T3 -> 152.78208 | U3: 136.2
A4: Total emissions (Mt CO2e) | B4: EEA GHG data viewer | C4: Mt CO2e | D4: ='I1. GHG emissions'!D5 -> 193.15413 | E4: ='I1. GHG emissions'!E5 -> 198.50066 | F4: ='I1. GHG emissions'!F5 -> 201.86984 | G4: ='I1. GHG emissions'!G5 -> 186.83828 | H4: ='I1. GHG emissions'!H5 -> 129.57684 | I4: ='I1. GHG emissions'!I5 -> 162.13319 | J4: ='I1. GHG emissions'!J5 -> 158.78095 | K4: ='I1. GHG emissions'!K5 -> 149.00264 | ... T4: ='I1. GHG emissions'!T5 -> 147.01485
A5: Emission intensity (t CO2e/t) | C5: t CO2/t | G5: =G4/G3 -> 1.0097606 | H5: =H4/H3 -> 1.0023753 | I5: =I4/I3 -> 0.99421541 | J5: =J4/J3 -> 0.94457473 | K5: =K4/K3 -> 0.93710327 | L5: =L4/L3 -> 0.94990037 | M5: =M4/M3 -> 0.93782665 | N5: =N4/N3 -> 0.98709755 | ... T5: =T4/T3 -> 0.96225193
A7: Average 2017-2021 | D7: =AVERAGE(T5-S5,S5-R5,R5-Q5,Q5-P5)*1000 -> -0.83306621
A10: Cement
B11: Source | C11: Unit | D11: 2005 | I11: 2010 | N11: 2015 | S11: 2020
A12: Production (Mt) | B12: Cembureau data | C12: Mt | D12: ='I2. Production and consumption'!D15 -> 239.527 | E12: ='I2. Production and consumption'!E15 -> 256.169 | F12: ='I2. Production and consumption'!F15 -> 261.812 | G12: ='I2. Production and consumption'!G15 -> 244.355 | H12: ='I2. Production and consumption'!H15 -> 197.892 | I12: ='I2. Production and consumption'!I15 -> 185.623 | J12: ='I2. Production and consumption'!J15 -> 187.216 | K12: ='I2. Production and consumption'!K15 -> 164.687 | ... T12: ='I2. Production and consumption'!T15 -> 182.549
A13: Total emissions (Mt CO2e) | B13: ETS data | C13: Mt CO2e | D13: ='I1. GHG emissions'!D99/1000 -> 143.41195 | E13: ='I1. GHG emissions'!E99/1000 -> 147.15261 | F13: ='I1. GHG emissions'!F99/1000 -> 163.11498 | G13: ='I1. GHG emissions'!G99/1000 -> 150.48991 | H13: ='I1. GHG emissions'!H99/1000 -> 121.31189 | I13: ='I1. GHG emissions'!I99/1000 -> 119.34112 | J13: ='I1. GHG emissions'!J99/1000 -> 116.97662 | K13: ='I1. GHG emissions'!K99/1000 -> 109.89505 | ... T13: ='I1. GHG emissions'!T99/1000 -> 110.22327 | U13: =T13/D13-1 -> -0.23142196
A14: Emission intensity (t CO2e/t) | C14: t CO2/t | D14: =D13/D12 -> 0.59872977 | E14: =E13/E12 -> 0.57443565 | F14: =F13/F12 -> 0.62302332 | G14: =G13/G12 -> 0.61586588 | H14: =H13/H12 -> 0.61302067 | I14: =I13/I12 -> 0.64292204 | J14: =J13/J12 -> 0.62482173 | K14: =K13/K12 -> 0.66729648 | ... T14: =T13/T12 -> 0.60380102 | U14: =T14/D14-1 -> 0.0084700155
A16: Average 2017-2021 | D16: =AVERAGE(T14-S14,S14-R14,R14-Q14,Q14-P14)*1000 -> -17.835528
A18: Base organic chemicals
B19: Source | C19: Unit | D19: 2005 | I19: 2010 | N19: 2015 | S19: 2020
A20: total production | L20: =L21+L22+L23 -> 41.563355 | M20: =M21+M22+M23 -> 45.623831 | N20: =N21+N22+N23 -> 42.671854 | O20: =O21+O22+O23 -> 44.459177 | P20: =P21+P22+P23 -> 43.648533 | Q20: =Q21+Q22+Q23 -> 42.821067 | R20: =R21+R22+R23 -> 41.648877 | S20: =S21+S22+S23 -> 40.441816 | ... U20: =U21+U22+U23 -> 37.504566
A21: Production - ethylene (Mt) | B21: Eurostat DS-056121 | C21: Mt | L21: 16.096333 | M21: 19.039978 | N21: 17.404166 | O21: 18.037565 | P21: 18 | Q21: 17.439047 | R21: 16.628416 | S21: 16.477749 | T21: 15.649568 | U21: 13.558041
A22: Production - propylene (Mt) | B22: Eurostat DS-056121 | C22: Mt | L22: 12.935621 | M22: 13.387043 | N22: 12.872033 | O22: 12.929714 | P22: 13.128196 | Q22: 12.756553 | R22: 12.435086 | S22: 11.590565 | T22: 12.109004 | U22: 11.168238
A23: Production - aromatics (Mt) | B23: Eurostat DS-056121 | C23: Mt | L23: 12.531402 | M23: 13.196809 | N23: 12.395656 | O23: 13.491898 | P23: 12.520337 | Q23: 12.625467 | R23: 12.585375 | S23: 12.373501 | T23: 11.42717 | U23: 12.778287
A24: Total emissions (Mt CO2e) | B24: EEA EU ETS data viewer (activity code 42) | C24: Mt CO2e | L24: 33.431033 | M24: 33.366782 | N24: 33.600201 | O24: 33.407365 | P24: 34.007494 | Q24: 33.84863 | R24: 31.999661 | S24: 31.866199 | T24: 33.952083 | U24: 28.767537
A25: Emission intensity (t CO2e/t) | C25: t CO2/t | L25: =L24/SUM(L21:L23) -> 0.80433914 | M25: =M24/SUM(M21:M23) -> 0.73134547 | N25: =N24/SUM(N21:N23) -> 0.78740897 | O25: =O24/SUM(O21:O23) -> 0.75141663 | P25: =P24/SUM(P21:P23) -> 0.77912111 | Q25: =Q24/SUM(Q21:Q23) -> 0.79046675 | R25: =R24/SUM(R21:R23) -> 0.76831991 | S25: =S24/SUM(S21:S23) -> 0.78795174 | ... U25: =U24/SUM(U21:U23) -> 0.76704092
A36: Graph feed
D37: 2005 | I37: 2010 | N37: 2015 | S37: 2020
A38: Steel | C38: t CO2/t | G38: =G5 -> 1.0097606 | H38: =H5 -> 1.0023753 | I38: =I5 -> 0.99421541 | J38: =J5 -> 0.94457473 | K38: =K5 -> 0.93710327 | L38: =L5 -> 0.94990037 | M38: =M5 -> 0.93782665 | N38: =N5 -> 0.98709755 | ... T38: =T5 -> 0.96225193
A39: Cement | C39: t CO2/t | D39: =D14 -> 0.59872977 | E39: =E14 -> 0.57443565 | F39: =F14 -> 0.62302332 | G39: =G14 -> 0.61586588 | H39: =H14 -> 0.61302067 | I39: =I14 -> 0.64292204 | J39: =J14 -> 0.62482173 | K39: =K14 -> 0.66729648 | ... T39: =T14 -> 0.60380102
A40: Base organic chemicals | C40: t CO2/t | L40: =L25 -> 0.80433914 | M40: =M25 -> 0.73134547 | N40: =N25 -> 0.78740897 | O40: =O25 -> 0.75141663 | P40: =P25 -> 0.77912111 | Q40: =Q25 -> 0.79046675 | R40: =R25 -> 0.76831991 | S40: =S25 -> 0.78795174 | ... U40: =U25 -> 0.76704092
E42: Indicator I4

Sheet I5. Energy use
A1: Total energy use
B2: Source | C2: Unit | D2: 2005 | I2: 2010 | N2: 2015 | S2: 2020 | X2: 2025 | AC2: 2030 | AH2: 2035 | AM2: 2040 | AR2: 2045 | AW2: 2050
A4: non-energy use | B4: Eurostat energy balances | C4: Mtoe | D4: 99.990623 | E4: 99.997192 | F4: 100.08822 | G4: 97.473406 | H4: 88.569504 | I4: 93.214571 | J4: 91.250167 | K4: 87.860121 | L4: 85.120679 | M4: 87.033583 | N4: 84.302239 | O4: 84.018661 | P4: 90.634032 | Q4: 87.111026 | R4: 86.765967 | S4: 86.237262 | T4: 90.078307
A5: Total | B5: Eurostat energy balances | C5: Mtoe | D5: 275.12525 | E5: 269.57638 | F5: 274.27585 | G5: 265.10807 | H5: 229.18046 | I5: 243.87311 | J5: 244.29556 | K5: 239.7027 | L5: 236.74852 | M5: 233.29777 | N5: 233.50766 | O5: 237.7992 | P5: 240.06351 | Q5: 242.46632 | R5: 239.2396 | S5: 230.92331 | T5: 240.34385
A6: Fossil fuels | B6: Eurostat energy balances | C6: Mtoe | D6: 153.97343 | E6: 147.17088 | F6: 148.63917 | G6: 142.21975 | H6: 119.20615 | I6: 126.45741 | J6: 125.23791 | K6: 122.01803 | L6: 119.61184 | M6: 116.21046 | N6: 115.37357 | O6: 116.90441 | P6: 117.57363 | Q6: 118.72717 | R6: 115.6967 | S6: 112.32517 | T6: 117.67025
A7: electricity | B7: Eurostat energy balances | C7: Mtoe | D7: 87.25259 | E7: 87.202153 | F7: 88.358376 | G7: 86.265145 | H7: 74.300824 | I7: 79.58803 | J7: 80.52822 | K7: 79.129937 | L7: 77.933983 | M7: 78.251377 | N7: 78.580682 | O7: 79.617355 | P7: 81.036995 | Q7: 81.292179 | R7: 80.233557 | S7: 76.037877 | T7: 79.831363
A8: renewables (mainly biomass) | B8: Eurostat energy balances | C8: Mtoe | D8: 17.624981 | E8: 18.387066 | F8: 19.316373 | G8: 18.262628 | H8: 18.020873 | I8: 19.552827 | J8: 19.657035 | K8: 19.04706 | L8: 19.584087 | M8: 19.985262 | N8: 20.803288 | O8: 21.709893 | P8: 22.055517 | Q8: 22.601831 | R8: 23.10638 | S8: 23.181768 | T8: 23.310921
A9: Others (heat and waste) | B9: Eurostat energy balances | C9: Mtoe | D9: 16.207034 | E9: 16.764237 | F9: 17.887465 | G9: 18.290436 | H9: 17.62016 | I9: 18.230786 | J9: 18.820172 | K9: 19.466152 | L9: 19.582331 | M9: 18.816755 | N9: 18.735153 | O9: 19.557802 | P9: 19.377378 | Q9: 19.822711 | R9: 20.183071 | S9: 19.377115 | T9: 19.531317
A10: 2040 min (delete label) | B10: ESABCC database | AC10: 323.02966 | AM10: 239.02752 | AW10: 231.86931
A11: 2040 advice range | B11: ESABCC database | AC11: 1.9513718 | AM11: 12.685111 | AW11: 17.442923
A12: 2030 benchmark (max) | B12: FF55 MIX | C12: Mtoe | AC12: 211.313
A13: 2030 benchmark (min) | B13: Repower EU (SWD) | AC13: 196
A14: 2050 benchmark | B14: CTP MIX | C14: Mtoe | AW14: 218.73423
A15: linear trajectory | C15: Mtoe | T15: 240.34385 | U15: 237.1182 | V15: 233.89255 | W15: 230.6669 | X15: 227.44125 | Y15: 224.2156 | Z15: 220.98995 | AA15: 217.7643 | AB15: 214.53865 | AC15: 211.313 | AD15: 209.85415 | AE15: 208.3953 | AF15: 206.93645 | AG15: 205.4776 | AH15: 204.01874 | AI15: 202.55989 | AJ15: 201.10104 | AK15: 199.64219 | AL15: 198.18334 | AM15: 196.72449 | AN15: 195.26564 | AO15: 193.80679 | AP15: 192.34794 | AQ15: 190.88908 | AR15: 189.43023 | AS15: 187.97138 | AT15: 186.51253 | AU15: 185.05368 | AV15: 183.59483 | AW15: 182.13598
A16: linear trajectory 2 | C16: Mtoe | AC16: 211.313 | AD16: 208.80336 | AE16: 206.29373 | AF16: 203.78409 | AG16: 201.27446 | AH16: 198.76482 | AI16: 196.25519 | AJ16: 193.74555 | AK16: 191.23591 | AL16: 188.72628 | AM16: 186.21664 | AN16: 183.70701 | AO16: 181.19737 | AP16: 178.68774 | AQ16: 176.1781 | AR16: 173.66847 | AS16: 171.15883 | AT16: 168.64919 | AU16: 166.13956 | AV16: 163.62992 | AW16: 161.12029
A18: Average 2017-2021 | D18: 0.07008525
A19: Average 2021-2030 | D19: -3.2256499
A20: Average 2030-2050 min | D20: -1.4588511
A21: Average 2030-2050 max | D21: -2.5096356
A23: non-energy use | B23: Eurostat energy balances | C23: TWh | D23: =D4*'conversion factor'!$E$6 -> 1162.8909 | E23: =E4*'conversion factor'!$E$6 -> 1162.9673 | F23: =F4*'conversion factor'!$E$6 -> 1164.026 | G23: =G4*'conversion factor'!$E$6 -> 1133.6157 | H23: =H4*'conversion factor'!$E$6 -> 1030.0633 | I23: =I4*'conversion factor'!$E$6 -> 1084.0855 | J23: =J4*'conversion factor'!$E$6 -> 1061.2394 | K23: =K4*'conversion factor'!$E$6 -> 1021.8132 | ... T23: =T4*'conversion factor'!$E$6 -> 1047.6107
A24: Total | B24: Eurostat energy balances | C24: TWh | D24: =D5*'conversion factor'!$E$6 -> 3199.7067 | E24: =E5*'conversion factor'!$E$6 -> 3135.1733 | F24: =F5*'conversion factor'!$E$6 -> 3189.8281 | G24: =G5*'conversion factor'!$E$6 -> 3083.2069 | H24: =H5*'conversion factor'!$E$6 -> 2665.3687 | I24: =I5*'conversion factor'!$E$6 -> 2836.2443 | J24: =J5*'conversion factor'!$E$6 -> 2841.1573 | K24: =K5*'conversion factor'!$E$6 -> 2787.7423 | ... T24: =T5*'conversion factor'!$E$6 -> 2795.199
A25: Fossil fuels | B25: Eurostat energy balances | C25: TWh | D25: =D6*'conversion factor'!$E$6 -> 1790.711 | E25: =E6*'conversion factor'!$E$6 -> 1711.5974 | F25: =F6*'conversion factor'!$E$6 -> 1728.6735 | G25: =G6*'conversion factor'!$E$6 -> 1654.0158 | H25: =H6*'conversion factor'!$E$6 -> 1386.3676 | I25: =I6*'conversion factor'!$E$6 -> 1470.6997 | J25: =J6*'conversion factor'!$E$6 -> 1456.5169 | K25: =K6*'conversion factor'!$E$6 -> 1419.0696 | ... T25: =T6*'conversion factor'!$E$6 -> 1368.505
A26: electricity | B26: Eurostat energy balances | C26: TWh | D26: =D7*'conversion factor'!$E$6 -> 1014.7476 | E26: =E7*'conversion factor'!$E$6 -> 1014.161 | F26: =F7*'conversion factor'!$E$6 -> 1027.6079 | G26: =G7*'conversion factor'!$E$6 -> 1003.2636 | H26: =H7*'conversion factor'!$E$6 -> 864.11858 | I26: =I7*'conversion factor'!$E$6 -> 925.60879 | J26: =J7*'conversion factor'!$E$6 -> 936.5432 | K26: =K7*'conversion factor'!$E$6 -> 920.28117 | ... T26: =T7*'conversion factor'!$E$6 -> 928.43875
A27: renewables (mainly biomass) | B27: Eurostat energy balances | C27: TWh | D27: =D8*'conversion factor'!$E$6 -> 204.97853 | E27: =E8*'conversion factor'!$E$6 -> 213.84158 | F27: =F8*'conversion factor'!$E$6 -> 224.64942 | G27: =G8*'conversion factor'!$E$6 -> 212.39436 | H27: =H8*'conversion factor'!$E$6 -> 209.58275 | I27: =I8*'conversion factor'!$E$6 -> 227.39938 | J27: =J8*'conversion factor'!$E$6 -> 228.61132 | K27: =K8*'conversion factor'!$E$6 -> 221.51731 | ... T27: =T8*'conversion factor'!$E$6 -> 271.10601
A28: Others (heat and waste) | B28: Eurostat energy balances | C28: TWh | D28: =D9*'conversion factor'!$E$6 -> 188.48781 | E28: =E9*'conversion factor'!$E$6 -> 194.96808 | F28: =F9*'conversion factor'!$E$6 -> 208.03122 | G28: =G9*'conversion factor'!$E$6 -> 212.71777 | H28: =H9*'conversion factor'!$E$6 -> 204.92246 | I28: =I9*'conversion factor'!$E$6 -> 212.02404 | J28: =J9*'conversion factor'!$E$6 -> 218.8786 | K28: =K9*'conversion factor'!$E$6 -> 226.39135 | ... T28: =T9*'conversion factor'!$E$6 -> 227.14922
A29: 2040 min (delete label) | B29: ESABCC database | C29: TWh | AC29: =AC10*'conversion factor'!$E$6 -> 3756.835 | AM29: =AM10*'conversion factor'!$E$6 -> 2779.8901 | AW29: =AW10*'conversion factor'!$E$6 -> 2696.6401
A30: 2040 advice range | B30: ESABCC database | C30: TWh | AC30: =AC11*'conversion factor'!$E$6 -> 22.694454 | AM30: =AM11*'conversion factor'!$E$6 -> 147.52784 | AW30: =AW11*'conversion factor'!$E$6 -> 202.8612
A31: 2030 benchmark (max) | B31: FF55 MIX | C31: TWh | AC31: =AC12*'conversion factor'!$E$6 -> 2457.5702
A32: 2030 benchmark (min) | B32: Repower EU (SWD) | C32: TWh | AC32: =AC13*'conversion factor'!$E$6 -> 2279.48
A33: 2050 benchmark | B33: CTP MIX | C33: TWh | AW33: =AW14*'conversion factor'!$E$6 -> 2543.8791
A34: linear trajectory | C34: TWh | T34: =T15*'conversion factor'!$E$6 -> 2795.199 | U34: =U15*'conversion factor'!$E$6 -> 2757.6847 | V34: =V15*'conversion factor'!$E$6 -> 2720.1703 | W34: =W15*'conversion factor'!$E$6 -> 2682.656 | X34: =X15*'conversion factor'!$E$6 -> 2645.1417 | Y34: =Y15*'conversion factor'!$E$6 -> 2607.6274 | Z34: =Z15*'conversion factor'!$E$6 -> 2570.1131 | AA34: =AA15*'conversion factor'!$E$6 -> 2532.5988 | ... AW34: =AW15*'conversion factor'!$E$6 -> 2118.2414
