Workbook

Sheet T1. GHG emissions
A1: Total transport incl. international aviation, excl. international maritime
B2: Source | C2: Unit | D2: 1990 | E2: 2005 | J2: 2010 | O2: 2015 | T2: 2020 | Y2: 2025 | AD2: 2030 | AI2: 2035 | AN2: 2040 | AS2: 2045 | AX2: 2050
A3: Total | B3: EEA GHG data viewer | C3: Mt CO2e | D3: =672.476+54.098 -> 726.574 | E3: =E4+E5+E6+E8+E10+E9 -> 943.47944 | F3: =F4+F5+F6+F8+F10+F9 -> 956.65513 | G3: =G4+G5+G6+G8+G10+G9 -> 969.81743 | H3: =H4+H5+H6+H8+H10+H9 -> 952.31849 | I3: =I4+I5+I6+I8+I10+I9 -> 921.85077 | J3: =J4+J5+J6+J8+J10+J9 -> 918.00703 | K3: =K4+K5+K6+K8+K10+K9 -> 911.07749 | L3: =L4+L5+L6+L8+L10+L9 -> 880.41802 | ... U3: =U4+U5+U6+U8+U10+U9 -> 851.85503 | V3: =(V39+V51)/1000 -> 906.58298
A4: Road - cars and motorcycles | B4: EEA GHG data viewer | C4: Mt CO2e | D4: =(D42+D45)/1000 -> 397.47614 | E4: =(E42+E45)/1000 -> 491.58834 | F4: =(F42+F45)/1000 -> 493.17414 | G4: =(G42+G45)/1000 -> 499.67277 | H4: =(H42+H45)/1000 -> 492.32041 | I4: =(I42+I45)/1000 -> 487.92105 | J4: =(J42+J45)/1000 -> 481.69079 | K4: =(K42+K45)/1000 -> 475.21366 | ... U4: =(U42+U45)/1000 -> 450.25308
A5: Road - HDV and buses | B5: EEA GHG data viewer | C5: Mt CO2e | D5: =(D44/1000) -> 163.10739 | E5: =(E44/1000) -> 212.73026 | F5: =(F44/1000) -> 217.24945 | G5: =(G44/1000) -> 217.80183 | H5: =(H44/1000) -> 211.14004 | I5: =(I44/1000) -> 199.94252 | J5: =(J44/1000) -> 201.98021 | K5: =(K44/1000) -> 201.56149 | ... U5: =(U44/1000) -> 209.37061
A6: Road - Light Duty Trucks | B6: EEA GHG data viewer | C6: Mt CO2e | D6: =D43/1000 -> 59.057762 | E6: =E43/1000 -> 92.042303 | F6: =F43/1000 -> 93.929947 | G6: =G43/1000 -> 96.305671 | H6: =H43/1000 -> 91.879212 | I6: =I43/1000 -> 88.318866 | J6: =J43/1000 -> 87.236198 | K6: =K43/1000 -> 86.850327 | ... U6: =U43/1000 -> 88.121016
A7: Railways, IWW and others | B7: EEA GHG data viewer | C7: Mt CO2e | D7: =D8+D9 -> 41.006573 | E7: =E8+E9 -> 34.29061 | F7: =F8+F9 -> 34.447957 | G7: =G8+G9 -> 33.103105 | H7: =H8+H9 -> 32.856116 | I7: =I8+I9 -> 31.099204 | J7: =J8+J9 -> 30.924361 | K7: =K8+K9 -> 28.990938 | ... U7: =U8+U9 -> 24.53952
A8: - of which Railways, IWW | B8: EEA GHG data viewer | C8: Mt CO2e | D8: =(D47+D48)/1000 -> 34.554406 | E8: =(E47+E48)/1000 -> 25.950326 | F8: =(F47+F48)/1000 -> 26.156568 | G8: =(G47+G48)/1000 -> 25.441668 | H8: =(H47+H48)/1000 -> 24.622828 | I8: =(I47+I48)/1000 -> 23.942443 | J8: =(J47+J48)/1000 -> 24.040785 | K8: =(K47+K48)/1000 -> 22.311976 | ... U8: =(U47+U48)/1000 -> 19.726616
A9: - of which Other | B9: EEA GHG data viewer | C9: Mt CO2e | D9: =(D46+D49)/1000 -> 6.4521664 | E9: =(E46+E49)/1000 -> 8.3402837 | F9: =(F46+F49)/1000 -> 8.291389 | G9: =(G46+G49)/1000 -> 7.6614377 | H9: =(H46+H49)/1000 -> 8.2332884 | I9: =(I46+I49)/1000 -> 7.1567615 | J9: =(J46+J49)/1000 -> 6.8835763 | K9: =(K46+K49)/1000 -> 6.6789616 | ... U9: =(U46+U49)/1000 -> 4.8129047
A10: Aviation | B10: EEA GHG data viewer | C10: Mt CO2e | D10: =D11+D12 -> 65.925432 | E10: =E11+E12 -> 112.82794 | F10: =F11+F12 -> 117.85364 | G10: =G11+G12 -> 122.93405 | H10: =H11+H12 -> 124.12271 | I10: =I11+I12 -> 114.56914 | J10: =J11+J12 -> 116.17547 | K10: =K11+K12 -> 118.46107 | ... U10: =U11+U12 -> 79.570797
A11: - of which domestic | B11: EEA GHG data viewer | C11: Mt CO2e | D11: =D40/1000 -> 11.82771 | E11: =E40/1000 -> 16.734388 | F11: =F40/1000 -> 16.69211 | G11: =G40/1000 -> 17.103987 | H11: =H40/1000 -> 16.728479 | I11: =I40/1000 -> 15.841396 | J11: =J40/1000 -> 15.807764 | K11: =K40/1000 -> 15.624008 | ... U11: =U40/1000 -> 9.816464
A12: - of which international | B12: EEA GHG data viewer | C12: Mt CO2e | D12: =D51/1000 -> 54.097721 | E12: =E51/1000 -> 96.093547 | F12: =F51/1000 -> 101.16153 | G12: =G51/1000 -> 105.83007 | H12: =H51/1000 -> 107.39423 | I12: =I51/1000 -> 98.727741 | J12: =J51/1000 -> 100.3677 | K12: =K51/1000 -> 102.83706 | ... U12: =U51/1000 -> 69.754333
A13: linear trajector to benchmarks | B13: linear trajectory | C13: Mt CO2e | V13: 906.58298 | W13: 880.42261 | X13: 854.26223 | Y13: 828.10186 | Z13: 801.94149 | AA13: 775.78112 | AB13: 749.62074 | AC13: 723.46037 | AD13: 697.3 | AE13: 666.06787 | AF13: 634.83574 | AG13: 603.60361 | AH13: 572.37148 | AI13: 541.13935 | AJ13: 509.90722 | AK13: 478.67509 | AL13: 447.44296 | AM13: 416.21083 | AN13: 384.9787 | AO13: 353.74657 | AP13: 322.51444 | AQ13: 291.28231 | AR13: 260.05018 | AS13: 228.81805 | AT13: 197.58592 | AU13: 166.35379 | AV13: 135.12166 | AW13: 103.88953 | AX13: 72.6574
A14: 2030 benchmark | B14: CTP MIX | C14: Mt CO2e | AD14: =AD61 -> 697.23833
A15: 2050 benchmark | B15: -0.9 | C15: Mt CO2e | AX15: =10%*D3 -> 72.6574
A16: 2040 advice | B16: ESABCC db | C16: Mt CO2e | AD16: =AD77 -> 643.11258 | AN16: =AN77 -> 171.09886 | AX16: =AX77 -> 54.754782
A17: 2040 advice min | AD17: =AD78 -> 643.3353 | AN17: =AN78 -> 172.03549 | AX17: =AX78 -> 54.947529
A19: Average 2005-2022 | E19: =(V3-E3)/17 -> -2.1703802
A20: Average 2017-2021 | E20: =(U3-Q3)/4 -> -24.321975
A21: Average 2018-2022 | B21: calculated | C21: Mt CO2e | E21: =AVERAGE(V3-U3,U3-T3,T3-S3,S3-R3) -> -12.564587
A22: Average 2022-2030 | E22: =(AD13-U3)/9 -> -17.172781
A23: Average 2023-2030 | B23: calculated | C23: Mt CO2e | E23: =W13-V13 -> -26.160372 | F23: =E23/E21 -> 2.0820717
A24: Average 2031-2050 | B24: calculated | C24: Mt CO2e | E24: =(AX15-AD14)/20 -> -31.229047 | F24: =E24/E21 -> 2.4854813
E26: min | F26: max
A27: Average 2031-2040 | E27: =(AN16-AD13)/10 -> -52.620114 | F27: =(AN17-AD13)/10 -> -52.526451
I33: Indicator T1
A37: Historic data
B38: Source | C38: Unit | D38: 1990 | E38: 2005 | J38: 2010 | O38: 2015 | T38: 2020 | V38: 2022 (proxy)
A39: 1.A.3 - Transport | B39: EEA GHG data viewer | C39: kt CO2e | D39: 672475.57 | E39: 847385.9 | F39: 855493.6 | G39: 863987.36 | H39: 844924.26 | I39: 823123.03 | J39: 817639.33 | K39: 808240.43 | L39: 778706.75 | M39: 772714.01 | N39: 778078.28 | O39: 793239.54 | P39: 810749.17 | Q39: 824980.67 | R39: 826483.02 | S39: 832732.96 | T39: 720181.52 | U39: 782100.69 | V39: 803300.64
A40: 1.A.3.a - Domestic Aviation | B40: EEA GHG data viewer | C40: kt CO2e | D40: 11827.71 | E40: 16734.388 | F40: 16692.11 | G40: 17103.987 | H40: 16728.479 | I40: 15841.396 | J40: 15807.764 | K40: 15624.008 | L40: 14479.646 | M40: 13279.927 | N40: 13073.225 | O40: 13151.245 | P40: 13623.167 | Q40: 14002.873 | R40: 14621.706 | S40: 14926.382 | T40: 7922.1448 | U40: 9816.464
A41: 1.A.3.b - Road Transportation | B41: EEA GHG data viewer | C41: kt CO2e | D41: 620042.1 | E41: 796541.58 | F41: 804510.86 | G41: 813944.1 | H41: 795526.18 | I41: 776380.84 | J41: 771043.95 | K41: 763762.11 | L41: 736943.33 | M41: 733289.93 | N41: 741094.33 | O41: 755426.66 | P41: 771808.53 | Q41: 784253.2 | R41: 784407.49 | S41: 789995.45 | T41: 687577.47 | U41: 747866.01
A42: 1.A.3.b.i - Cars | B42: EEA GHG data viewer | C42: kt CO2e | D42: 388860.35 | E42: 480541.42 | F42: 482224.75 | G42: 488774.54 | H42: 480951.23 | I42: 476868.11 | J42: 470814.64 | K42: 464550.59 | L42: 446069.66 | M42: 448657.45 | N42: 458349.51 | O42: 466627.86 | P42: 477579.93 | Q42: 483452.27 | R42: 480336.43 | S42: 483220.25 | T42: 406560.92 | U42: 440486.99
A43: 1.A.3.b.ii - Light duty trucks | B43: EEA GHG data viewer | C43: kt CO2e | D43: 59057.762 | E43: 92042.303 | F43: 93929.947 | G43: 96305.671 | H43: 91879.212 | I43: 88318.866 | J43: 87236.198 | K43: 86850.327 | L43: 83852.261 | M43: 80353.773 | N43: 80458.778 | O43: 82200.361 | P43: 83344.277 | Q43: 84587.236 | R43: 85923.181 | S43: 86143.866 | T43: 77538.642 | U43: 88121.016
A44: 1.A.3.b.iii - Heavy duty trucks and buses | B44: EEA GHG data viewer | C44: kt CO2e | D44: 163107.39 | E44: 212730.26 | F44: 217249.45 | G44: 217801.83 | H44: 211140.04 | I44: 199942.52 | J44: 201980.21 | K44: 201561.49 | L44: 196460.03 | M44: 194031.32 | N44: 191775.93 | O44: 196116.17 | P44: 200624.42 | Q44: 206072.86 | R44: 208220.82 | S44: 210357.03 | T44: 194382.62 | U44: 209370.61
A45: 1.A.3.b.iv - Motorcycles | B45: EEA GHG data viewer | C45: kt CO2e | D45: 8615.7858 | E45: 11046.916 | F45: 10949.383 | G45: 10898.227 | H45: 11369.178 | I45: 11052.937 | J45: 10876.154 | K45: 10663.065 | L45: 10434.277 | M45: 10133.125 | N45: 10417.871 | O45: 10389.465 | P45: 10156.171 | Q45: 10030.518 | R45: 9818.0652 | S45: 10171.737 | T45: 8991.7981 | U45: 9766.083
A46: 1.A.3.b.v - Other Road Transportation | B46: EEA GHG data viewer | C46: kt CO2e | D46: 400.81756 | E46: 180.68381 | F46: 157.3326 | G46: 163.83157 | H46: 186.51477 | I46: 198.40964 | J46: 136.74853 | K46: 136.63439 | L46: 127.10938 | M46: 114.26928 | N46: 92.237862 | O46: 92.800769 | P46: 103.72532 | Q46: 110.31669 | R46: 108.99286 | S46: 102.56368 | T46: 103.48195 | U46: 121.30411
A47: 1.A.3.c - Railways | B47: EEA GHG data viewer | C47: kt CO2e | D47: 12831.588 | E47: 6282.6952 | F47: 6156.4174 | G47: 6401.8181 | H47: 6161.8267 | I47: 5442.4844 | J47: 5426.9685 | K47: 5457.2134 | L47: 5276.0097 | M47: 4953.9103 | N47: 4537.9443 | O47: 4540.9188 | P47: 4409.6432 | Q47: 4337.338 | R47: 4142.6051 | S47: 4107.9693 | T47: 3660.556 | U47: 3751.1541
A48: 1.A.3.d - Domestic Navigation | B48: EEA GHG data viewer | C48: kt CO2e | D48: 21722.819 | E48: 19667.631 | F48: 20000.151 | G48: 19039.85 | H48: 18461.001 | I48: 18499.958 | J48: 18613.817 | K48: 16854.763 | L48: 16063.167 | M48: 14694.89 | N48: 13946.772 | O48: 14695.953 | P48: 15513.018 | Q48: 16469.915 | R48: 17265.787 | S48: 17941.249 | T48: 16386.005 | U48: 15975.462
A49: 1.A.3.e - Other Transportation | B49: EEA GHG data viewer | C49: kt CO2e | D49: 6051.3488 | E49: 8159.5999 | F49: 8134.0564 | G49: 7497.6062 | H49: 8046.7736 | I49: 6958.3519 | J49: 6746.8277 | K49: 6542.3272 | L49: 5944.5944 | M49: 6495.3484 | N49: 5426.0081 | O49: 5424.7606 | P49: 5394.8126 | Q49: 5917.3408 | R49: 6045.4289 | S49: 5761.9124 | T49: 4635.3447 | U49: 4691.6006
A50: 1.D.1 - International Bunkers | B50: EEA GHG data viewer | C50: kt CO2e | D50: 156212.7 | E50: 249811.76 | F50: 265677.07 | G50: 277492.1 | H50: 276883.99 | I50: 249419.89 | J50: 251984.24 | K50: 253275.76 | L50: 241788.07 | M50: 234878.36 | N50: 233174.52 | O50: 237691.85 | P50: 247952.67 | Q50: 258835.31 | R50: 268194.07 | S50: 269573.88 | T50: 177140.82 | U50: 198840.42 | V50: 241025.02
...

Sheet T2a. total demand passenger
A1: graph feed (excl. IWW and maritime)
B2: Source | C2: Unit | I2: 2010 | S2: 2020 | AC2: 2030 | AM2: 2040 | AW2: 2050
A3: Total | B3: Eurostat Statistical Pocketbook 2022 | C3: Gpkm | D3: =D4+D5+D6+D7 -> 5225.9 | E3: =E4+E5+E6+E7 -> 5287.1 | F3: =F4+F5+F6+F7 -> 5360.8 | G3: =G4+G5+G6+G7 -> 5389.9 | H3: =H4+H5+H6+H7 -> 5410.6 | I3: =I4+I5+I6+I7 -> 5388.2 | J3: =J4+J5+J6+J7 -> 5400.6 | K3: =K4+K5+K6+K7 -> 5346.8 | ... S3: =S4+S5+S6+S7 -> 4435.8
A4: cars and 2-wheels | B4: Eurostat Statistical Pocketbook 2022 | C4: Gpkm | D4: =D23+D24 -> 3953.8 | E4: =E23+E24 -> 3988.9 | F4: =F23+F24 -> 4030.9 | G4: =G23+G24 -> 4046.1 | H4: =H23+H24 -> 4121.2 | I4: =I23+I24 -> 4089.7 | J4: =J23+J24 -> 4061.3 | K4: =K23+K24 -> 4013.6 | ... S4: =S23+S24 -> 3683.1
A5: buses and coaches | B5: Eurostat Statistical Pocketbook 2022 | C5: Gpkm | D5: =D25 -> 497.8 | E5: =E25 -> 497.8 | F5: =F25 -> 507.9 | G5: =G25 -> 514.1 | H5: =H25 -> 489.7 | I5: =I25 -> 482.2 | J5: =J25 -> 485.6 | K5: =K25 -> 481.6 | ... S5: =S25 -> 293.6
A6: rail | B6: Eurostat Statistical Pocketbook 2022 | C6: Gpkm | D6: =D26+D28 -> 413 | E6: =E26+E28 -> 424 | F6: =F26+F28 -> 429.8 | G6: =G26+G28 -> 445.9 | H6: =H26+H28 -> 437.9 | I6: =I26+I28 -> 439 | J6: =J26+J28 -> 445.2 | K6: =K26+K28 -> 449.5 | ... S6: =S26+S28 -> 281.2
A7: aviation | B7: Eurostat Statistical Pocketbook 2022 | C7: Gpkm | D7: =D29 -> 361.3 | E7: =E29 -> 376.4 | F7: =F29 -> 392.2 | G7: =G29 -> 383.8 | H7: =H29 -> 361.8 | I7: =I29 -> 377.3 | J7: =J29 -> 408.5 | K7: =K29 -> 402.1 | ... S7: =S29 -> 177.9
A8: 2030 benchmark | B8: CTP-MIX | C8: Gpkm | AC8: =AC42-AC48 -> 6448
A9: 2050 benchmark (min) | B9: 1.5TECH | C9: Gpkm | AW9: =AW69 -> 6656.2999
A10: 2050 benchmark (max) | B10: 1.5LIFE | C10: Gpkm | AW10: =AW61 -> 6783.9753
A11: linear trajectory to benchmark | C11: Gpkm | R11: 5992.2 | S11: 6033.6364 | T11: 6075.0727 | U11: 6116.5091 | V11: 6157.9455 | W11: 6199.3818 | X11: 6240.8182 | Y11: 6282.2545 | Z11: 6323.6909 | AA11: 6365.1273 | AB11: 6406.5636 | AC11: 6448 | AD11: 6458.415 | AE11: 6468.83 | AF11: 6479.245 | AG11: 6489.66 | AH11: 6500.075 | AI11: 6510.49 | AJ11: 6520.905 | AK11: 6531.32 | AL11: 6541.735 | AM11: 6552.15 | AN11: 6562.565 | AO11: 6572.98 | AP11: 6583.3949 | AQ11: 6593.8099 | AR11: 6604.2249 | AS11: 6614.6399 | AT11: 6625.0549 | AU11: 6635.4699 | AV11: 6645.8849 | AW11: 6656.2999
A12: linear trajectory to benchmark 2 | C12: Gpkm | AC12: 6448 | AD12: 6464.7988 | AE12: 6481.5975 | AF12: 6498.3963 | AG12: 6515.1951 | AH12: 6531.9938 | AI12: 6548.7926 | AJ12: 6565.5913 | AK12: 6582.3901 | AL12: 6599.1889 | AM12: 6615.9876 | AN12: 6632.7864 | AO12: 6649.5852 | AP12: 6666.3839 | AQ12: 6683.1827 | AR12: 6699.9815 | AS12: 6716.7802 | AT12: 6733.579 | AU12: 6750.3777 | AV12: 6767.1765 | AW12: 6783.9753
A14: Change 2015-2019 | D14: =AVERAGE(R3-Q3,Q3-P3,P3-O3,O3-N3) -> 91.7
A15: Change 2019-2030 | D15: =(AC8-R3)/11 -> 41.436364 | E15: =D14/D15 -> 2.213032
A16: Change 2031-2050 1 | D16: =(AW9-AC8)/20 -> 10.414996 | E16: =D14/D16 -> 8.8046122
A17: Change 2031-2050 2 | D17: =(AW10-AC8)/20 -> 16.798763 | E17: =D14/D17 -> 5.4587351
A20: Raw historic data
A21: Passenger travel | X21: Indicator T2a
B22: Source | C22: Unit | D22: 2005 | E22: 2006 | F22: 2007 | G22: 2008 | H22: 2009 | I22: 2010 | J22: 2011 | K22: 2012 | L22: 2013 | M22: 2014 | N22: 2015 | O22: 2016 | P22: 2017 | Q22: 2018 | R22: 2019 | S22: 2020
A23: Passenger Cars | B23: Eurostat Statistical Pocketbook 2022 | C23: Gpkm | D23: 3839.2 | E23: 3875.3 | F23: 3921.3 | G23: 3931.6 | H23: 4009.2 | I23: 3975.9 | J23: 3943.6 | K23: 3898.5 | L23: 3957.2 | M23: 4012.5 | N23: 4101 | O23: 4185 | P23: 4228.5 | Q23: 4257 | R23: 4299.9 | S23: 3583
A24: Powered 2-wheelers | B24: Eurostat Statistical Pocketbook 2022 | C24: Gpkm | D24: 114.6 | E24: 113.6 | F24: 109.6 | G24: 114.5 | H24: 112 | I24: 113.8 | J24: 117.7 | K24: 115.1 | L24: 114.7 | M24: 117.4 | N24: 117.4 | O24: 118.7 | P24: 112.2 | Q24: 106.8 | R24: 111.3 | S24: 100.1
A25: Buses & Coaches | B25: Eurostat Statistical Pocketbook 2022 | C25: Gpkm | D25: 497.8 | E25: 497.8 | F25: 507.9 | G25: 514.1 | H25: 489.7 | I25: 482.2 | J25: 485.6 | K25: 481.6 | L25: 480.5 | M25: 476.2 | N25: 493.4 | O25: 498.3 | P25: 479 | Q25: 484.1 | R25: 487.5 | S25: 293.6
A26: Railways | B26: Eurostat Statistical Pocketbook 2022 | C26: Gpkm | D26: 339.8 | E26: 349.4 | F26: 353.4 | G26: 366.6 | H26: 359.3 | I26: 358.3 | J26: 364.1 | K26: 367.3 | L26: 371.8 | M26: 376.3 | N26: 381.6 | O26: 386.5 | P26: 400.8 | Q26: 407.3 | R26: 420.9 | S26: 227.3
A27: - of which highspeed rail | B27: Eurostat Statistical Pocketbook 2022 | C27: Gpkm | D27: 79.663 | E27: 83.411 | F27: 87.303 | G27: 96.61 | H27: 103.086 | I27: 104.85538 | J27: 103.69534 | K27: 105.43988 | L27: 107.30405 | M27: 106.3797 | N27: 109.9236 | O27: 114.3155 | P27: 124.23454 | Q27: 126.07479 | R27: 132.00774 | S27: 69.372916
A28: Tram & Metro | B28: Eurostat Statistical Pocketbook 2022 | C28: Gpkm | D28: 73.2 | E28: 74.6 | F28: 76.4 | G28: 79.3 | H28: 78.6 | I28: 80.7 | J28: 81.1 | K28: 82.2 | L28: 82 | M28: 82.2 | N28: 80.2 | O28: 82.6 | P28: 84.3 | Q28: 86.9 | R28: 87.1 | S28: 53.9
A29: Air | B29: Eurostat Statistical Pocketbook 2022 | C29: Gpkm | D29: 361.3 | E29: 376.4 | F29: 392.2 | G29: 383.8 | H29: 361.8 | I29: 377.3 | J29: 408.5 | K29: 402.1 | L29: 406 | M29: 425.6 | N29: 451.8 | O29: 492.6 | P29: 538.4 | Q29: 571.8 | R29: 585.5 | S29: 177.9
A30: Sea | B30: Eurostat Statistical Pocketbook 2022 | C30: Gpkm | D30: 21.3 | E30: 21.4 | F30: 21.3 | G30: 21.9 | H30: 22.4 | I30: 22.5 | J30: 20 | K30: 18.5 | L30: 19.3 | M30: 19.4 | N30: 19.4 | O30: 18.4 | P30: 19.7 | Q30: 20.8 | R30: 21.1 | S30: 10.3
A31: IWW | B31: Eurostat Statistical Pocketbook 2022 | C31: Gpkm
A32: Total | B32: Eurostat Statistical Pocketbook 2022 | C32: Gpkm | D32: 5247.2 | E32: 5308.4 | F32: 5381.9 | G32: 5411.8 | H32: 5433.1 | I32: 5410.6 | J32: 5420.7 | K32: 5365.3 | L32: 5431.6 | M32: 5509.7 | N32: 5644.8 | O32: 5782 | P32: 5862.9 | Q32: 5934.7 | R32: 6013.3 | S32: 4446
A33: Total excluding air, sea | B33: Eurostat Statistical Pocketbook 2022 | C33: Gpkm | D33: =D32-D30-D29 -> 4864.6 | E33: =E32-E30-E29 -> 4910.6 | F33: =F32-F30-F29 -> 4968.4 | G33: =G32-G30-G29 -> 5006.1 | H33: =H32-H30-H29 -> 5048.9 | I33: =I32-I30-I29 -> 5010.8 | J33: =J32-J30-J29 -> 4992.2 | K33: =K32-K30-K29 -> 4944.7 | ... S33: =S32-S30-S29 -> 4257.8
A40: 2030 decarbonisation scenarios
B41: Source | C41: Unit | D41: 2005 | I41: 2010 | S41: 2020 | AC41: 2030 | AM41: 2040 | AW41: 2050
A42: Passenger transport activity (Gpkm) | B42: FF55 - MIX scenario | C42: Gpkm | D42: 5277 | I42: 5453 | N42: 5618 | S42: 4498 | X42: 6088 | AC42: 6487
A43: Buses and coaches | B43: FF55 - MIX scenario | C43: Gpkm | D43: 498 | I43: 484 | N43: 487 | S43: 313 | X43: 473 | AC43: 542
A44: Passenger cars | B44: FF55 - MIX scenario | C44: Gpkm | D44: 3841 | I44: 3981 | N44: 4057 | S44: 3548 | X44: 4354 | AC44: 4533
A45: Powered two-wheelers | B45: FF55 - MIX scenario | C45: Gpkm | D45: 115 | I45: 115 | N45: 120 | S45: 100 | X45: 123 | AC45: 129
A46: Rail | B46: FF55 - MIX scenario | C46: Gpkm | D46: 417 | I46: 444 | N46: 471 | S46: 275 | X46: 532 | AC46: 633
A47: Intra-EU aviation | B47: FF55 - MIX scenario | C47: Gpkm | D47: 373 | I47: 398 | N47: 450 | S47: 244 | X47: 571 | AC47: 612
A48: Inland waterways and domestic maritime | B48: FF55 - MIX scenario | C48: Gpkm | D48: 32 | I48: 31 | N48: 34 | S48: 19 | X48: 36 | AC48: 39
A50: 2050 decarbonization scenarios
...

Sheet T2b. total demand freight
A1: graph feed (excl. IWW and maritime)
B2: Source | C2: Unit | I2: 2010 | S2: 2020 | AC2: 2030 | AM2: 2040 | AW2: 2050
A3: Total | B3: Eurostat Statistical Pocketbook 2022 | C3: Gtkm | D3: =D4+D5+D6 -> 2121.362 | E3: =E4+E5+E6 -> 2193.4576 | F3: =F4+F5+F6 -> 2273.77 | G3: =G4+G5+G6 -> 2245.0506 | H3: =H4+H5+H6 -> 1992.2916 | I3: =I4+I5+I6 -> 2088.6125 | J3: =J4+J5+J6 -> 2084.5782 | K3: =K4+K5+K6 -> 2016.7014 | ... S3: =S4+S5+S6 -> 2254.034
A4: Road | B4: Eurostat Statistical Pocketbook 2022 | C4: Gtkm | D4: =D44 -> 1588.1541 | E4: =E44 -> 1638.7946 | F4: =F44 -> 1697.644 | G4: =G44 -> 1676.4616 | H4: =H44 -> 1515.3166 | I4: =I44 -> 1558.2925 | J4: =J44 -> 1541.6312 | K4: =K44 -> 1481.6904 | ... S4: =S44 -> 1744.986
A5: Rail | B5: Eurostat Statistical Pocketbook 2022 | C5: Gtkm | D5: =D46 -> 394.597 | E5: =E46 -> 416.246 | F5: =F46 -> 430.724 | G5: =G46 -> 421.686 | H5: =H46 -> 344.369 | I5: =I46 -> 374.955 | J5: =J46 -> 401.122 | K5: =K46 -> 385.189 | ... S5: =S46 -> 377.307
A6: IWW | B6: Eurostat Statistical Pocketbook 2022 | C6: Gtkm | D6: =D47 -> 138.61097 | E6: =E47 -> 138.41697 | F6: =F47 -> 145.402 | G6: =G47 -> 146.903 | H6: =H47 -> 132.606 | I6: =I47 -> 155.365 | J6: =J47 -> 141.825 | K6: =K47 -> 149.822 | ... S6: =S47 -> 131.741
A7: 2030 benchmark | B7: CTP-MIX | C7: Gtkm | AC7: =AC55 -> 2815.5077
A8: 2050 benchmark (min) | B8: 1.5TECH | C8: Gtkm | AW8: =AW71 -> 3183.8632
A9: 2050 benchmark (max) | B9: 1.5LIFE | C9: Gtkm | AW9: =AW78 -> 3198.5454
A10: linear trajectory to benchmark | C10: Gtkm | R10: 2312.405 | S10: 2358.1416 | T10: 2403.8782 | U10: 2449.6148 | V10: 2495.3514 | W10: 2541.088 | X10: 2586.8246 | Y10: 2632.5612 | Z10: 2678.2978 | AA10: 2724.0344 | AB10: 2769.7711 | AC10: 2815.5077 | AD10: 2833.9254 | AE10: 2852.3432 | AF10: 2870.761 | AG10: 2889.1788 | AH10: 2907.5966 | AI10: 2926.0143 | AJ10: 2944.4321 | AK10: 2962.8499 | AL10: 2981.2677 | AM10: 2999.6855 | AN10: 3018.1032 | AO10: 3036.521 | AP10: 3054.9388 | AQ10: 3073.3566 | AR10: 3091.7743 | AS10: 3110.1921 | AT10: 3128.6099 | AU10: 3147.0277 | AV10: 3165.4455 | AW10: 3183.8632
A11: linear trajectory to benchmark 2 | C11: Gtkm | AC11: 2815.5077 | AD11: 2834.6595 | AE11: 2853.8114 | AF11: 2872.9633 | AG11: 2892.1152 | AH11: 2911.2671 | AI11: 2930.419 | AJ11: 2949.5709 | AK11: 2968.7228 | AL11: 2987.8746 | AM11: 3007.0265 | AN11: 3026.1784 | AO11: 3045.3303 | AP11: 3064.4822 | AQ11: 3083.6341 | AR11: 3102.786 | AS11: 3121.9379 | AT11: 3141.0898 | AU11: 3160.2416 | AV11: 3179.3935 | AW11: 3198.5454
A13: Change 2015-2019 | D13: =AVERAGE(R3-Q3,Q3-P3,P3-O3,O3-N3) -> 51.137329
A14: Change 2019-2030 | D14: =(AC7-R3)/11 -> 45.736605 | E14: =D13/D14 -> 1.1180832
A15: Change 2031-2050 1 | D15: =(AW8-AC7)/20 -> 18.417779 | E15: =D13/D15 -> 2.7765198
A16: Change 2031-2050 2 | D16: =(AW9-AC7)/20 -> 19.151888 | E16: =D13/D16 -> 2.6700934
A18: Indicator T2b
A41: Raw historic data
A42: Passenger travel
B43: Source | C43: Unit | D43: 2005 | E43: 2006 | F43: 2007 | G43: 2008 | H43: 2009 | I43: 2010 | J43: 2011 | K43: 2012 | L43: 2013 | M43: 2014 | N43: 2015 | O43: 2016 | P43: 2017 | Q43: 2018 | R43: 2019 | S43: 2020
A44: Road | B44: Eurostat Statistical Pocketbook 2022 | C44: Gtkm | D44: 1588.1541 | E44: 1638.7946 | F44: 1697.644 | G44: 1676.4616 | H44: 1515.3166 | I44: 1558.2925 | J44: 1541.6312 | K44: 1481.6904 | L44: 1516.364 | M44: 1527.4346 | N44: 1561.9877 | O44: 1619.7477 | P44: 1707.3139 | Q44: 1707.496 | R44: 1764.787 | S44: 1744.986
A45: Sea | B45: Eurostat Statistical Pocketbook 2022 | C45: Gtkm | D45: 844.47159 | E45: 842.96923 | F45: 842.92936 | G45: 841.12354 | H45: 769.75739 | I45: 834.10071 | J45: 850.14406 | K45: 838.42273 | L45: 850.98289 | M45: 875.11991 | N45: 870.77097 | O45: 909.32038 | P45: 916.98869 | Q45: 976.97412 | R45: 979.07616 | S45: 924.28547
A46: Rail | B46: Eurostat Statistical Pocketbook 2022 | C46: Gtkm | D46: 394.597 | E46: 416.246 | F46: 430.724 | G46: 421.686 | H46: 344.369 | I46: 374.955 | J46: 401.122 | K46: 385.189 | L46: 384.319 | M46: 388.932 | N46: 398.517 | O46: 407.458 | P46: 411.278 | Q46: 418.314 | R46: 407.921 | S46: 377.307
A47: Inland Waterway | B47: Eurostat Statistical Pocketbook 2022 | C47: Gtkm | D47: 138.61097 | E47: 138.41697 | F47: 145.402 | G47: 146.903 | H47: 132.606 | I47: 155.365 | J47: 141.825 | K47: 149.822 | L47: 152.584 | M47: 150.707 | N47: 147.351 | O47: 146.609 | P47: 147.22333 | Q47: 131.30278 | R47: 139.697 | S47: 131.741
A48: Oil Pipeline | B48: Eurostat Statistical Pocketbook 2022 | C48: Gtkm | D48: 126.8085 | E48: 125.78925 | F48: 118.22249 | G48: 114.76497 | H48: 111.63421 | I48: 110.96845 | J48: 108.27032 | K48: 104.98251 | L48: 102.08348 | M48: 101.08569 | N48: 104.14977 | O48: 104.69674 | P48: 104.0207 | Q48: 104.11186 | R48: 101.00952 | S48: 91.725138
A49: Air | B49: Eurostat Statistical Pocketbook 2022 | C49: Gtkm | D49: 1.8295109 | E49: 1.8862399 | F49: 1.9500601 | G49: 1.9093615 | H49: 1.8066758 | I49: 1.8374579 | J49: 1.8527511 | K49: 1.8226663 | L49: 1.8346995 | M49: 2.1144168 | N49: 2.1423488 | O49: 2.1499893 | P49: 2.1719835 | Q49: 2.2161326 | R49: 2.3225078 | S49: 2.0623148
A50: Total | B50: Eurostat Statistical Pocketbook 2022 | C50: Gtkm | D50: 3094.4716 | E50: 3164.1023 | F50: 3236.8719 | G50: 3202.8485 | H50: 2875.4899 | I50: 3035.5191 | J50: 3044.8453 | K50: 2961.9293 | L50: 3008.1681 | M50: 3045.3936 | N50: 3084.9188 | O50: 3189.9818 | P50: 3288.9966 | Q50: 3340.4149 | R50: 3394.8132 | S50: 3272.1069
A52: 2030 decarbonisation scenarios
B53: Source | C53: Unit | D53: 2005 | I53: 2010 | S53: 2020 | AC53: 2030 | AM53: 2040 | AW53: 2050
A54: Total | B54: CTP MIX | C54: Gtkm | D54: 2362 | I54: 2320 | N54: 2314 | S54: 2377 | X54: 2750 | AC54: 2999
A55: Total excl. domestic maritime | B55: own calculation | C55: Gtkm | D55: =D56+D57+D59 -> 2210.611 | I55: =I56+I57+I59 -> 2175.365 | N55: =N56+N57+N59 -> 2171.351 | S55: =S56+S57+S59 -> 2242.2213 | X55: =X56+X57+X59 -> 2588.1672 | AC55: =AC56+AC57+AC59 -> 2815.5077
A56: Heavy goods and light commercial vehicles | B56: CTP MIX | C56: Gtkm | D56: 1677 | I56: 1645 | N56: 1628 | S56: 1721 | X56: 1945 | AC56: 2027
A57: Rail | B57: CTP MIX | C57: Gtkm | D57: 395 | I57: 375 | N57: 396 | S57: 382 | X57: 476 | AC57: 600
A58: Inland waterways and domestic maritime | B58: CTP MIX | C58: Gtkm | D58: 291 | I58: 301 | N58: 290 | S58: 274 | X58: 329 | AC58: 371
A59: IWW only | B59: own calculation | C59: Gtkm | D59: =D58/$D$58*$D$47 -> 138.61097 | I59: =I58/I58*I6 -> 155.365 | N59: =N58/$N$58*$N$6 -> 147.351 | S59: =S58/$N$58*$N$6 -> 139.22129 | X59: =X58/$N$58*$N$6 -> 167.16717 | AC59: =AC58/$N$58*$N$6 -> 188.50766
A61: 2050 decarbonization scenarios
A62: Baseline
B63: Source | C63: Unit | D63: rate 2015-2030 | E63: rate 2030-2050 | N63: 2015 | S63: 2020 | X63: 2025 | AC63: 2030 | AH63: 2035 | AM63: 2040 | AR63: 2045 | AW63: 2050
A64: Total | N64: =N65+N66+N67 -> 2107.8557 | O64: =O65+O66+O67 -> 2143.7534 | P64: =P65+P66+P67 -> 2180.2942 | Q64: =Q65+Q66+Q67 -> 2217.4903 | R64: =R65+R66+R67 -> 2255.3543 | S64: =S65+S66+S67 -> 2293.8987 | T64: =T65+T66+T67 -> 2333.1367 | U64: =U65+U66+U67 -> 2373.0814 | ... AW64: =AW65+AW66+AW67 -> 3255.6775
A65: Road | B65: ACP4A In-depth analysis fig 46 | C65: Gtkm | D65: 0.015 | E65: 0.008 | N65: =N44 -> 1561.9877 | O65: =N65*(1+$D65) -> 1585.4175 | P65: =O65*(1+$D65) -> 1609.1988 | Q65: =P65*(1+$D65) -> 1633.3367 | R65: =Q65*(1+$D65) -> 1657.8368 | S65: =R65*(1+$D65) -> 1682.7043 | T65: =S65*(1+$D65) -> 1707.9449 | U65: =T65*(1+$D65) -> 1733.5641 | V65: =U65*(1+$D65) -> 1759.5675 | ... AC65: =AB65*(1+$D65) -> 1952.8471 | AD65: =AC65*(1+$E65) -> 1968.4699 | AE65: =AD65*(1+$E65) -> 1984.2176 | AF65: =AE65*(1+$E65) -> 2000.0914 | AG65: =AF65*(1+$E65) -> 2016.0921 | AH65: =AG65*(1+$E65) -> 2032.2208 | AI65: =AH65*(1+$E65) -> 2048.4786 | AJ65: =AI65*(1+$E65) -> 2064.8664 | AK65: =AJ65*(1+$E65) -> 2081.3854 | ... AW65: =AV65*(1+$E65) -> 2290.2288
A66: Rail | B66: ACP4A In-depth analysis fig 46 | C66: Gtkm | D66: 0.025 | E66: 0.013 | N66: =N46 -> 398.517 | O66: =N66*(1+$D66) -> 408.47993 | P66: =O66*(1+$D66) -> 418.69192 | Q66: =P66*(1+$D66) -> 429.15922 | R66: =Q66*(1+$D66) -> 439.8882 | S66: =R66*(1+$D66) -> 450.88541 | T66: =S66*(1+$D66) -> 462.15754 | U66: =T66*(1+$D66) -> 473.71148 | V66: =U66*(1+$D66) -> 485.55427 | ... AC66: =AB66*(1+$D66) -> 577.17144 | AD66: =AC66*(1+$E66) -> 584.67467 | AE66: =AD66*(1+$E66) -> 592.27544 | AF66: =AE66*(1+$E66) -> 599.97502 | AG66: =AF66*(1+$E66) -> 607.7747 | AH66: =AG66*(1+$E66) -> 615.67577 | AI66: =AH66*(1+$E66) -> 623.67955 | AJ66: =AI66*(1+$E66) -> 631.78739 | AK66: =AJ66*(1+$E66) -> 640.00062 | ... AW66: =AV66*(1+$E66) -> 747.29786
...

Sheet T3a & T3c modal split
A1: Figure 1
B2: Source | C2: Unit | D2: 2005 | I2: 2010 | N2: 2015 | S2: 2020 | X2: 2025 | AC2: 2030 | AH2: 2035 | AM2: 2040 | AR2: 2045 | AW2: 2050
A3: Passenger (cars and two-wheelers) | B3: Eurostat Statistical Pocketbook 2022 | C3: % | D3: ='T3b. modal split passenger'!D3 -> 0.81276981 | E3: ='T3b. modal split passenger'!E3 -> 0.81228745 | F3: ='T3b. modal split passenger'!F3 -> 0.81127481 | G3: ='T3b. modal split passenger'!G3 -> 0.80823395 | H3: ='T3b. modal split passenger'!H3 -> 0.81627317 | I3: ='T3b. modal split passenger'!I3 -> 0.81616077 | J3: ='T3b. modal split passenger'!J3 -> 0.8135454 | K3: ='T3b. modal split passenger'!K3 -> 0.81169737 | ... S3: ='T3b. modal split passenger'!S3 -> 0.86500388
A4: Freight (vans and lorries) | B4: ='3. modal split freight'!B3 -> Eurostat Statistical Pocketbook 2022 | C4: ='3. modal split freight'!C3 -> % | D4: ='3. modal split freight'!D3 -> 0.74864829 | E4: ='3. modal split freight'!E3 -> 0.74712847 | F4: ='3. modal split freight'!F3 -> 0.74662081 | G4: ='3. modal split freight'!G3 -> 0.74673667 | H4: ='3. modal split freight'!H3 -> 0.76058976 | I4: ='3. modal split freight'!I3 -> 0.74608981 | ... S4: ='3. modal split freight'!S3 -> 0.77416135
A5: Benchmark passenger | B5: CTP-MIX | C5: % | AC5: =('T2a. total demand passenger'!AC44+'T2a. total demand passenger'!AC45)/SUM('T2a. total demand passenger'!AC43:AC46) -> 0.79869796 | AW5: ='T3b. modal split passenger'!AW6 -> 0.76704735
A6: Benchmark Freight | B6: CTP-MIX | C6: % | AC6: ='3. modal split freight'!AC6 -> 0.71994121 | AW6: ='3. modal split freight'!AW6 -> 0.67162862
A7: linear trajectory passenger | S7: 0.86500388 | T7: 0.85838697 | U7: 0.85177006 | V7: 0.84515316 | W7: 0.83853625 | X7: 0.83191935 | Y7: 0.82530244 | Z7: 0.81868554 | AA7: 0.81206863 | AB7: 0.80545172 | AC7: 0.79883482 | AD7: 0.79724545 | AE7: 0.79565607 | AF7: 0.7940667 | AG7: 0.79247733 | AH7: 0.79088795 | AI7: 0.78929858 | AJ7: 0.78770921 | AK7: 0.78611983 | AL7: 0.78453046 | AM7: 0.78294109 | AN7: 0.78135171 | AO7: 0.77976234 | AP7: 0.77817297 | AQ7: 0.77658359 | AR7: 0.77499422 | AS7: 0.77340485 | AT7: 0.77181547 | AU7: 0.7702261 | AV7: 0.76863673 | AW7: 0.76704735
A8: linear trajectory freight | S8: 0.77416135 | T8: 0.76873933 | U8: 0.76331732 | V8: 0.75789531 | W8: 0.75247329 | X8: 0.74705128 | Y8: 0.74162927 | Z8: 0.73620725 | AA8: 0.73078524 | AB8: 0.72536323 | AC8: 0.71994121 | AD8: 0.71752558 | AE8: 0.71510995 | AF8: 0.71269433 | AG8: 0.7102787 | AH8: 0.70786307 | AI8: 0.70544744 | AJ8: 0.70303181 | AK8: 0.70061618 | AL8: 0.69820055 | AM8: 0.69578492 | AN8: 0.69336929 | AO8: 0.69095366 | AP8: 0.68853803 | AQ8: 0.6861224 | AR8: 0.68370677 | AS8: 0.68129114 | AT8: 0.67887551 | AU8: 0.67645988 | AV8: 0.67404425 | AW8: 0.67162862
D9: Indicator T3a
A24: Figure 2
B25: Source | C25: Unit | D25: 2005 | I25: 2010 | N25: 2015 | S25: 2020 | X25: 2025 | AC25: 2030 | AH25: 2035 | AM25: 2040 | AR25: 2045 | AW25: 2050 | AY25: Average 2015-2019 | AZ25: Average until 2030 | BA25: Average 2031-2050
A26: HSR (passenger) | B26: Eurostat Statistical Pocketbook 2022 | C26: % | D26: ='T3b. modal split passenger'!D72 -> 79.663 | E26: ='T3b. modal split passenger'!E72 -> 83.411 | F26: ='T3b. modal split passenger'!F72 -> 87.303 | G26: ='T3b. modal split passenger'!G72 -> 96.61 | H26: ='T3b. modal split passenger'!H72 -> 103.086 | I26: ='T3b. modal split passenger'!I72 -> 104.85538 | J26: ='T3b. modal split passenger'!J72 -> 103.69534 | K26: ='T3b. modal split passenger'!K72 -> 105.43988 | ... S26: ='T3b. modal split passenger'!S72 -> 69.372916 | AY26: =AVERAGE(R26-Q26,Q26-P26,P26-O26,O26-N26) -> 5.521035 | AZ26: =X32-W32 -> 7.9854055 | BA26: =AQ32-AP32 -> 5.49618
A27: Rail (freight) | B27: ='3. modal split freight'!B26 -> 0 | C27: ='3. modal split freight'!C26 -> 0 | D27: ='3. modal split freight'!D31 -> 394.597 | E27: ='3. modal split freight'!E31 -> 416.246 | F27: ='3. modal split freight'!F31 -> 430.724 | G27: ='3. modal split freight'!G31 -> 421.686 | H27: ='3. modal split freight'!H31 -> 344.369 | I27: ='3. modal split freight'!I31 -> 374.955 | J27: ='3. modal split freight'!J31 -> 401.122 | K27: ='3. modal split freight'!K31 -> 385.189 | ... S27: ='3. modal split freight'!S31 -> 377.307 | AY27: =AVERAGE(R27-Q27,Q27-P27,P27-O27,O27-N27) -> 2.351 | AZ27: =X33-W33 -> 17.2595 | BA27: =AQ33-AP33 -> 9.962925
A28: IWW (freight) | B28: CTP-MIX | C28: % | D28: ='3. modal split freight'!D42 -> 138.61097 | E28: ='3. modal split freight'!E42 -> 138.41697 | F28: ='3. modal split freight'!F42 -> 145.402 | G28: ='3. modal split freight'!G42 -> 146.903 | H28: ='3. modal split freight'!H42 -> 132.606 | I28: ='3. modal split freight'!I42 -> 155.365 | J28: ='3. modal split freight'!J42 -> 141.825 | K28: ='3. modal split freight'!K42 -> 149.822 | ... S28: ='3. modal split freight'!S42 -> 131.741 | AY28: =AVERAGE(R28-Q28,Q28-P28,P28-O28,O28-N28) -> -1.9135 | AZ28: =X34-W34 -> 4.0447045 | BA28: =AQ34-AP34 -> 1.8418875
A29: HSR (passenger) benchmark | B29: CTP-MIX | C29: % | AC29: =2*N26 -> 219.8472 | AW29: =3*N26 -> 329.7708
A30: Rail (freight) benchmark | AC30: =1.5*N27 -> 597.7755 | AW30: =2*N27 -> 797.034
A31: IWW (freight) benchmark | AC31: =1.25*N28 -> 184.18875 | AW31: =1.5*N28 -> 221.0265
A32: linear trajectory to benchmark | R32: 132.00774 | S32: 139.99315 | T32: 147.97855 | U32: 155.96396 | V32: 163.94936 | W32: 171.93477 | X32: 179.92017 | Y32: 187.90558 | Z32: 195.89098 | AA32: 203.87639 | AB32: 211.86179 | AC32: 219.8472 | AD32: 225.34338 | AE32: 230.83956 | AF32: 236.33574 | AG32: 241.83192 | AH32: 247.3281 | AI32: 252.82428 | AJ32: 258.32046 | AK32: 263.81664 | AL32: 269.31282 | AM32: 274.809 | AN32: 280.30518 | AO32: 285.80136 | AP32: 291.29754 | AQ32: 296.79372 | AR32: 302.2899 | AS32: 307.78608 | AT32: 313.28226 | AU32: 318.77844 | AV32: 324.27462 | AW32: 329.7708
A33: linear trajectory to benchmark | R33: 407.921 | S33: 425.1805 | T33: 442.44 | U33: 459.6995 | V33: 476.959 | W33: 494.2185 | X33: 511.478 | Y33: 528.7375 | Z33: 545.997 | AA33: 563.2565 | AB33: 580.516 | AC33: 597.7755 | AD33: 607.73843 | AE33: 617.70135 | AF33: 627.66428 | AG33: 637.6272 | AH33: 647.59013 | AI33: 657.55305 | AJ33: 667.51598 | AK33: 677.4789 | AL33: 687.44183 | AM33: 697.40475 | AN33: 707.36768 | AO33: 717.3306 | AP33: 727.29353 | AQ33: 737.25645 | AR33: 747.21938 | AS33: 757.1823 | AT33: 767.14523 | AU33: 777.10815 | AV33: 787.07108 | AW33: 797.034
A34: linear trajectory to benchmark | R34: 139.697 | S34: 143.7417 | T34: 147.78641 | U34: 151.83111 | V34: 155.87582 | W34: 159.92052 | X34: 163.96523 | Y34: 168.00993 | Z34: 172.05464 | AA34: 176.09934 | AB34: 180.14405 | AC34: 184.18875 | AD34: 186.03064 | AE34: 187.87253 | AF34: 189.71441 | AG34: 191.5563 | AH34: 193.39819 | AI34: 195.24008 | AJ34: 197.08196 | AK34: 198.92385 | AL34: 200.76574 | AM34: 202.60763 | AN34: 204.44951 | AO34: 206.2914 | AP34: 208.13329 | AQ34: 209.97518 | AR34: 211.81706 | AS34: 213.65895 | AT34: 215.50084 | AU34: 217.34273 | AV34: 219.18461 | AW34: 221.0265
D35: Average 2015-2019 | E35: 2020-2030 | F35: 2031-2050
A36: HSR | D36: =(R26-N26)/4 -> 5.521035 | E36: =(AC29-R26)/11 -> 7.9854055 | F36: =AD32-AC32 -> 5.49618
A37: Rail freight | D37: =(R27-N27)/4 -> 2.351 | E37: =(AC30-R27)/11 -> 17.2595 | F37: =AD33-AC33 -> 9.962925
A38: IWW freight | D38: =(R28-N28)/4 -> -1.9135 | E38: =(AC31-R28)/11 -> 4.0447045 | F38: =AD34-AC34 -> 1.8418875
A42: Indicator T3c

Sheet T3b. modal split passenger
A1: Modal shares land transport
B2: Source | C2: Unit | I2: 2010 | S2: 2020 | AC2: 2030 | AM2: 2040 | AW2: 2050
A3: Cars&2W | B3: Eurostat Statistical Pocketbook 2022 | C3: % | D3: ='T2a. total demand passenger'!D4/('T2a. total demand passenger'!D$3-'T2a. total demand passenger'!D$7) -> 0.81276981 | E3: ='T2a. total demand passenger'!E4/('T2a. total demand passenger'!E$3-'T2a. total demand passenger'!E$7) -> 0.81228745 | F3: ='T2a. total demand passenger'!F4/('T2a. total demand passenger'!F$3-'T2a. total demand passenger'!F$7) -> 0.81127481 | G3: ='T2a. total demand passenger'!G4/('T2a. total demand passenger'!G$3-'T2a. total demand passenger'!G$7) -> 0.80823395 | H3: ='T2a. total demand passenger'!H4/('T2a. total demand passenger'!H$3-'T2a. total demand passenger'!H$7) -> 0.81627317 | I3: ='T2a. total demand passenger'!I4/('T2a. total demand passenger'!I$3-'T2a. total demand passenger'!I$7) -> 0.81616077 | J3: ='T2a. total demand passenger'!J4/('T2a. total demand passenger'!J$3-'T2a. total demand passenger'!J$7) -> 0.8135454 | K3: ='T2a. total demand passenger'!K4/('T2a. total demand passenger'!K$3-'T2a. total demand passenger'!K$7) -> 0.81169737 | ... S3: ='T2a. total demand passenger'!S4/('T2a. total demand passenger'!S$3-'T2a. total demand passenger'!S$7) -> 0.86500388
A4: Buses&coaches | B4: Eurostat Statistical Pocketbook 2022 | C4: % | D4: ='T2a. total demand passenger'!D5/('T2a. total demand passenger'!D$3-'T2a. total demand passenger'!D$7) -> 0.10233113 | E4: ='T2a. total demand passenger'!E5/('T2a. total demand passenger'!E$3-'T2a. total demand passenger'!E$7) -> 0.10137048 | F4: ='T2a. total demand passenger'!F5/('T2a. total demand passenger'!F$3-'T2a. total demand passenger'!F$7) -> 0.10222195 | G4: ='T2a. total demand passenger'!G5/('T2a. total demand passenger'!G$3-'T2a. total demand passenger'!G$7) -> 0.10269471 | H4: ='T2a. total demand passenger'!H5/('T2a. total demand passenger'!H$3-'T2a. total demand passenger'!H$7) -> 0.096993345 | I4: ='T2a. total demand passenger'!I5/('T2a. total demand passenger'!I$3-'T2a. total demand passenger'!I$7) -> 0.096230218 | J4: ='T2a. total demand passenger'!J5/('T2a. total demand passenger'!J$3-'T2a. total demand passenger'!J$7) -> 0.097273692 | K4: ='T2a. total demand passenger'!K5/('T2a. total demand passenger'!K$3-'T2a. total demand passenger'!K$7) -> 0.097397213 | ... S4: ='T2a. total demand passenger'!S5/('T2a. total demand passenger'!S$3-'T2a. total demand passenger'!S$7) -> 0.068954179
A5: Rail | B5: Eurostat Statistical Pocketbook 2022 | C5: % | D5: ='T2a. total demand passenger'!D6/('T2a. total demand passenger'!D$3-'T2a. total demand passenger'!D$7) -> 0.084899067 | E5: ='T2a. total demand passenger'!E6/('T2a. total demand passenger'!E$3-'T2a. total demand passenger'!E$7) -> 0.086342069 | F5: ='T2a. total demand passenger'!F6/('T2a. total demand passenger'!F$3-'T2a. total demand passenger'!F$7) -> 0.08650324 | G5: ='T2a. total demand passenger'!G6/('T2a. total demand passenger'!G$3-'T2a. total demand passenger'!G$7) -> 0.089071333 | H5: ='T2a. total demand passenger'!H6/('T2a. total demand passenger'!H$3-'T2a. total demand passenger'!H$7) -> 0.086733481 | I5: ='T2a. total demand passenger'!I6/('T2a. total demand passenger'!I$3-'T2a. total demand passenger'!I$7) -> 0.087609012 | J5: ='T2a. total demand passenger'!J6/('T2a. total demand passenger'!J$3-'T2a. total demand passenger'!J$7) -> 0.089180906 | K5: ='T2a. total demand passenger'!K6/('T2a. total demand passenger'!K$3-'T2a. total demand passenger'!K$7) -> 0.090905414 | ... S5: ='T2a. total demand passenger'!S6/('T2a. total demand passenger'!S$3-'T2a. total demand passenger'!S$7) -> 0.066041946
A6: Benchmark - cars&2W | B6: CTP-MIX | C6: % | AC6: =('T2a. total demand passenger'!AC44+'T2a. total demand passenger'!AC45)/('T2a. total demand passenger'!AC42-'T2a. total demand passenger'!AC47-'T2a. total demand passenger'!AC48) -> 0.79883482 | AW6: ='T2a. total demand passenger'!AW70/('T2a. total demand passenger'!AW69-'T2a. total demand passenger'!AW72-'T2a. total demand passenger'!AW73)-AW7 -> 0.76704735
A7: Benchmark - buses&coaches | B7: CTP-MIX | C7: % | AC7: ='T2a. total demand passenger'!AC43/('T2a. total demand passenger'!AC42-'T2a. total demand passenger'!AC47-'T2a. total demand passenger'!AC48) -> 0.09287183 | AW7: 0.09
A8: Benchmark - rail | B8: CTP-MIX | C8: % | AC8: ='T2a. total demand passenger'!AC46/('T2a. total demand passenger'!AC42-'T2a. total demand passenger'!AC47-'T2a. total demand passenger'!AC48) -> 0.1084647 | AW8: ='T2a. total demand passenger'!AW71/('T2a. total demand passenger'!AW69-'T2a. total demand passenger'!AW72-'T2a. total demand passenger'!AW73) -> 0.14759137
A9: linear trajectories | C9: % | S9: 0.86500388 | T9: 0.85838697 | U9: 0.85177006 | V9: 0.84515316 | W9: 0.83853625 | X9: 0.83191935 | Y9: 0.82530244 | Z9: 0.81868554 | AA9: 0.81206863 | AB9: 0.80545172 | AC9: 0.79883482 | AD9: 0.79724545 | AE9: 0.79565607 | AF9: 0.7940667 | AG9: 0.79247733 | AH9: 0.79088795 | AI9: 0.78929858 | AJ9: 0.78770921 | AK9: 0.78611983 | AL9: 0.78453046 | AM9: 0.78294109 | AN9: 0.78135171 | AO9: 0.77976234 | AP9: 0.77817297 | AQ9: 0.77658359 | AR9: 0.77499422 | AS9: 0.77340485 | AT9: 0.77181547 | AU9: 0.7702261 | AV9: 0.76863673 | AW9: 0.76704735
A10: linear trajectories | C10: % | S10: 0.068954179 | T10: 0.071345944 | U10: 0.073737709 | V10: 0.076129475 | W10: 0.07852124 | X10: 0.080913005 | Y10: 0.08330477 | Z10: 0.085696535 | AA10: 0.0880883 | AB10: 0.090480065 | AC10: 0.09287183 | AD10: 0.092728239 | AE10: 0.092584647 | AF10: 0.092441056 | AG10: 0.092297464 | AH10: 0.092153873 | AI10: 0.092010281 | AJ10: 0.09186669 | AK10: 0.091723098 | AL10: 0.091579507 | AM10: 0.091435915 | AN10: 0.091292324 | AO10: 0.091148732 | AP10: 0.091005141 | AQ10: 0.090861549 | AR10: 0.090717958 | AS10: 0.090574366 | AT10: 0.090430775 | AU10: 0.090287183 | AV10: 0.090143592 | AW10: 0.09
A11: linear trajectories | C11: % | S11: 0.066041946 | T11: 0.070284221 | U11: 0.074526497 | V11: 0.078768772 | W11: 0.083011048 | X11: 0.087253324 | Y11: 0.091495599 | Z11: 0.095737875 | AA11: 0.099980151 | AB11: 0.10422243 | AC11: 0.1084647 | AD11: 0.11042104 | AE11: 0.11237737 | AF11: 0.1143337 | AG11: 0.11629004 | AH11: 0.11824637 | AI11: 0.1202027 | AJ11: 0.12215904 | AK11: 0.12411537 | AL11: 0.1260717 | AM11: 0.12802804 | AN11: 0.12998437 | AO11: 0.1319407 | AP11: 0.13389704 | AQ11: 0.13585337 | AR11: 0.1378097 | AS11: 0.13976604 | AT11: 0.14172237 | AU11: 0.1436787 | AV11: 0.14563504 | AW11: 0.14759137
A13: % of cars and 2W
A15: Change 2015-2019 | D15: =AVERAGE(R3-Q3,Q3-P3,P3-O3,O3-N3) -> 0.00012656395
A16: Change 2019-2030 | D16: =(AC6-R3)/11 -> -0.0015492527
A17: Change 2031-2050 | D17: =(AW6-AC6)/20 -> -0.0015893732
A18: % of buses and coaches
A20: Change 2015-2019 | D20: =AVERAGE(R4-Q4,Q4-P4,P4-O4,O4-N4) -> -0.0013007225
A21: Change 2019-2030
A22: Change 2031-2050
A23: % of rail
A25: Change 2015-2019 | D25: =AVERAGE(R5-Q5,Q5-P5,P5-O5,O5-N5) -> 0.0011741586
A26: Change 2019-2030 | D26: =(AC8-R5)/11 -> 0.0013188368 | E26: =D26/D25 -> 1.1232186
A27: Change 2031-2050 | D27: =(AW8-AC8)/20 -> 0.0019563334 | E27: =D27/D25 -> 1.6661577
A30: Aviation
A31: Total
B32: Source | C32: Unit | I32: 2010 | S32: 2020 | AC32: 2030 | AM32: 2040 | AW32: 2050
A33: Historic | B33: Eurostat Statistical Pocketbook 2022 | C33: Gpkm | D33: ='T2a. total demand passenger'!D29 -> 361.3 | E33: ='T2a. total demand passenger'!E29 -> 376.4 | F33: ='T2a. total demand passenger'!F29 -> 392.2 | G33: ='T2a. total demand passenger'!G29 -> 383.8 | H33: ='T2a. total demand passenger'!H29 -> 361.8 | I33: ='T2a. total demand passenger'!I29 -> 377.3 | J33: ='T2a. total demand passenger'!J29 -> 408.5 | K33: ='T2a. total demand passenger'!K29 -> 402.1 | ... S33: ='T2a. total demand passenger'!S29 -> 177.9
A34: benchmark 2030 | B34: CTP-MIX | C34: Gpkm | X34: ='T2a. total demand passenger'!X47 -> 571 | AC34: ='T2a. total demand passenger'!AC47 -> 612
A35: benchmark 2050 (min) | B35: 1.5TECH | C35: Gpkm | AW35: ='T2a. total demand passenger'!AW64 -> 846.69428
A36: benchmark 2050 (max) | B36: 1.5LIFE | C36: Gpkm | AW36: ='T2a. total demand passenger'!AW72 -> 715.76217
A37: linear trajectory | S37: 177.9 | T37: 256.52 | U37: 335.14 | V37: 413.76 | W37: 492.38 | X37: 571 | Y37: 579.2 | Z37: 587.4 | AA37: 595.6 | AB37: 603.8 | AC37: 612 | AD37: 623.73471 | AE37: 635.46943 | AF37: 647.20414 | AG37: 658.93886 | AH37: 670.67357 | AI37: 682.40828 | AJ37: 694.143 | AK37: 705.87771 | AL37: 717.61243 | AM37: 729.34714 | AN37: 741.08185 | AO37: 752.81657 | AP37: 764.55128 | AQ37: 776.286 | AR37: 788.02071 | AS37: 799.75542 | AT37: 811.49014 | AU37: 823.22485 | AV37: 834.95957 | AW37: 846.69428
A38: linear trajectory 2 | AC38: 612 | AD38: 617.18811 | AE38: 622.37622 | AF38: 627.56433 | AG38: 632.75243 | AH38: 637.94054 | AI38: 643.12865 | AJ38: 648.31676 | AK38: 653.50487 | AL38: 658.69298 | AM38: 663.88109 | AN38: 669.0692 | AO38: 674.2573 | AP38: 679.44541 | AQ38: 684.63352 | AR38: 689.82163 | AS38: 695.00974 | AT38: 700.19785 | AU38: 705.38596 | AV38: 710.57407 | AW38: 715.76217
F39: annual change (% vs 2015 level)
A40: Change 2015-2019 | D40: =AVERAGE(R33-Q33,Q33-P33,P33-O33,O33-N33) -> 33.425 | F40: =D40/$M$33 -> 0.078536184
A41: Change 2019-2030 | D41: =(AC34-R33)/11 -> 2.4090909 | E41: =D40/D41 -> 13.874528 | F41: =D41/$M$33 -> 0.005660458
A42: Change 2031-2050 1 | D42: =(AW35-AC34)/20 -> 11.734714 | E42: =D40/D42 -> 2.8483864 | F42: =D42/$M$33 -> 0.027572166
A43: Change 2031-2050 2 | D43: =(AW36-AC34)/20 -> 5.1881087 | E43: =D40/D43 -> 6.4426175 | F43: =D43/$M$33 -> 0.012190105
A45: Indicator T3b
A60: Short haul aviation and high-speed rail
A61: Short haul flights
...

Sheet T4. GHG intensity
A1: Passenger cars
B2: Source | C2: Unit | D2: 2005 | I2: 2010 | N2: 2015 | S2: 2020 | X2: 2025 | AC2: 2030 | AG2: 2035
A3: Historic - NEDC | B3: EEA | C3: gCO2/km | D3: 162.4 | E3: 161.3 | F3: 158.7 | G3: 153.5 | H3: 145.7 | I3: 140.3 | J3: 135.7 | K3: 132.2 | L3: 126.7 | M3: 123.4 | N3: 119.5 | O3: 118.1 | P3: 118.5 | Q3: 120.8 | R3: 122.3 | S3: 107.5
A4: Historic - WLTP | B4: EEA | C4: gCO2/km | S4: 130.3 | T4: 114.1 | U4: 108.2
A5: Previous objectives (NEDC) | B5: Regulation (EU) 2019/631 | C5: gCO2/km | N5: 130 | S5: 95 | X5: 80.8 | AC5: 59.4
A6: New objectives (WLTP) | B6: Regulation (EU) 2023/851 | C6: gCO2/km | X6: 93.3 | AC6: 49 | AG6: 0
A8: Average 2018-2022 | D8: =AVERAGE(U4-T4,T4-S4,S3-R3,R3-Q3) -> -8.85
A9: Required 2023-2030 | D9: =(AC6-U4)/8 -> -7.4 | E9: =D9/D8 -> 0.83615819
A10: Required 2031-2035 | D10: =AC6/-5 -> -9.8 | E10: =D10/D8 -> 1.1073446
A12: Indicator T4 (left)
A31: Note: This figure and the figure below to be combined into one figure, with a left pane and right pane. The legend on the bottom should be common to both panes.
A33: Vans
B34: Source | C34: Unit | D34: 2005 | I34: 2010 | N34: 2015 | S34: 2020 | X34: 2025 | AC34: 2030 | AG34: 2035
A35: Historic - NEDC | B35: EEA | C35: gCO2/km | K35: 180.2 | L35: 173.3 | M35: 169.1 | N35: 168.3 | O35: 163.7 | P35: 156.1 | Q35: 157.9 | R35: 158 | S35: 155
A36: Historic - WLTP | B36: EEA | C36: gCO2/km | R36: 188 | S36: 200 | T36: 194 | U36: 185.3
A37: Previous objectives | B37: Regulation (EU) 2019/631 | C37: gCO2/km | P37: 175 | S37: 147 | X37: 125 | AC37: 103
A38: New objectives | B38: Regulation (EU) 2023/851 | C38: gCO2/km | AC38: =0.5*S35 -> 77.5 | AG38: 0
A40: Average 2018-2022 | D40: =AVERAGE(U36-T36,T36-S36,S36-R36,R35-Q35) -> -0.65
A41: Required 2023-2030 | D41: =(AC37-U36)/8 -> -10.2875
A42: Required 2031-2035 | D42: =AC38/-5 -> -15.5
A44: Inditor T4 (right)
A66: HDV
B67: Source | C67: Unit | D67: 2005 | I67: 2010 | N67: 2015 | S67: 2020 | X67: 2025 | AC67: 2030 | AG67: 2035 | AL67: 2040
A68: Historic | B68: EEA | C68: gCO2/tkm | R68: 52.75
A69: Previous objectives | B69: Regulation (EU) 2019/1242 | C69: gCO2/tkm | X69: =0.85*R68 -> 44.8375 | AC69: =0.7*R68 -> 36.925
A70: New objectives | B70: COM(2023) 88 final | C70: gCO2/tkm | X70: =0.85*R68 -> 44.8375 | AC70: =0.55*R68 -> 29.0125 | AG70: =0.35*R68 -> 18.4625 | AL70: =0.1*R68 -> 5.275
A72: Required 2019-2030 | D72: =(AC70-R68)/11 -> -2.1579545
A73: Required 2031-2040 | D73: =(AL70-AC70)/10 -> -2.37375

Sheet T5a&b. ZEV shares
A2: Indicator T5a | K2: Indicator T5b
A22: Passenger cars
A23: Graph feed
B24: Source | C24: Unit | D24: 2005 | I24: 2010 | N24: 2015 | S24: 2020 | X24: 2025 | AC24: 2030 | AG24: 2035
A25: ZEV share | B25: EU alternative fuel observatory, EEA for 2022 | C25: % of sales | I25: =I45 -> 0.0001 | J25: =J45 -> 0.0007 | K25: =K45 -> 0.0013 | L25: =L45 -> 0.0022 | M25: =M45 -> 0.0033 | N25: =N45 -> 0.0046 | O25: =O45 -> 0.0047 | P25: =P45 -> 0.0068 | ... U25: =U45 -> 0.1341
A26: LEV share | B26: EU alternative fuel observatory, EEA for 2022 | C26: % of sales | I26: =I48+I25 -> 0.0457 | J26: =J48+J25 -> 0.0254 | K26: =K48+K25 -> 0.0385 | L26: =L48+L25 -> 0.0347 | M26: =M48+M25 -> 0.0358 | N26: =N48+N25 -> 0.0377 | O26: =O48+O25 -> 0.0329 | P26: =P48+P25 -> 0.037 | ... U26: =U48+U25 -> 0.2596
A27: benchmark | B27: Regulation (EU) 2023/851 | C27: % of sales | AG27: 1
A28: linear trajectory | U28: 0.1341 | V28: 0.20625833 | W28: 0.27841667 | X28: 0.350575 | Y28: 0.42273333 | Z28: 0.49489167 | AA28: 0.56705 | AB28: 0.63920833 | AC28: 0.71136667 | AD28: 0.783525 | AE28: 0.85568333 | AF28: 0.92784167 | AG28: 1
B29: pp. | C29: % increase
A30: Average 2018-2022 | B30: =AVERAGE(U25-T25,T25-S25,S25-R25,R25-Q25) -> 0.030875
A31: Required 2023-2035 | B31: =V28-U28 -> 0.072158333 | C31: =B31/B30 -> 2.337112
A33: Historic data
A34: Category | B34: Source | C34: Unit | I34: 2010 | J34: 2011 | K34: 2012 | L34: 2013 | M34: 2014 | N34: 2015 | O34: 2016 | P34: 2017 | Q34: 2018 | R34: 2019 | S34: 2020 | T34: 2021 | U34: 2022
A35: ZEV | B35: EU alternative fuel observatory | C35: # of sales | I35: =I36+I37 -> 752 | J35: =J36+J37 -> 8014 | K35: =K36+K37 -> 12716 | L35: =L36+L37 -> 21639 | M35: =M36+M37 -> 32793 | N35: =N36+N37 -> 51036 | O35: =O36+O37 -> 56509 | P35: =P36+P37 -> 85962 | ... U35: =U36+U37 -> 1118332
A36: BEV | B36: EU alternative fuel observatory | C36: # of sales | I36: 752 | J36: 8014 | K36: 12716 | L36: 21622 | M36: 32762 | N36: 50901 | O36: 56368 | P36: 85808 | Q36: 135613 | R36: 247545 | S36: 535894 | T36: 873612 | U36: 1117053
A37: H2 | B37: EU alternative fuel observatory | C37: # of sales | I37: 0 | J37: 0 | K37: 0 | L37: 17 | M37: 31 | N37: 135 | O37: 141 | P37: 154 | Q37: 187 | R37: 479 | S37: 744 | T37: 917 | U37: 1279
A38: LEV | B38: EU alternative fuel observatory | C38: # of sales | I38: =I39+I40+I41 -> 519470 | J38: =J39+J40+J41 -> 278940 | K38: =K39+K40+K41 -> 372890 | L38: =L39+L40+L41 -> 313919 | M38: =M39+M40+M41 -> 327578 | N38: =N39+N40+N41 -> 367260 | O38: =O39+O40+O41 -> 336818 | P38: =P39+P40+P41 -> 381772 | ... U38: =U39+U40+U41 -> 1155237
A39: PHEV | B39: EU alternative fuel observatory | C39: # of sales | I39: 2 | J39: 329 | K39: 8025 | L39: 22575 | M39: 21245 | N39: 65825 | O39: 61699 | P39: 82191 | Q39: 104720 | R39: 139984 | S39: 510149 | T39: 865752 | U39: 881573
A40: LPG | B40: EU alternative fuel observatory | C40: # of sales | I40: 440622 | J40: 225669 | K40: 297935 | L40: 196630 | M40: 207561 | N40: 219673 | O40: 216007 | P40: 250264 | Q40: 162584 | R40: 172179 | S40: 147093 | T40: 183460 | U40: 255209
A41: CNG | B41: EU alternative fuel observatory | C41: # of sales | I41: 78846 | J41: 52942 | K41: 66930 | L41: 94714 | M41: 98772 | N41: 81762 | O41: 59112 | P41: 49317 | Q41: 66237 | R41: 68436 | S41: 54724 | T41: 40244 | U41: 18455
A42: Conventional ICE | B42: Calculated | C42: # of sales | I42: =I43-I38-I35 -> 6999778 | J42: =J43-J38-J35 -> 11161617 | K42: =K43-K38-K35 -> 9395932.5 | L42: =L43-L38-L35 -> 9500351.1 | M42: =M43-M38-M35 -> 9576901.7 | N42: =N43-N38-N35 -> 10676487 | O42: =O43-O38-O35 -> 11629864 | P42: =P43-P38-P35 -> 12173737 | ... U42: =U43-U38-U35 -> 6065968.7
A43: Total | B43: Calculated | C43: # of sales | I43: =I35/I45 -> 7520000 | J43: =J35/J45 -> 11448571 | K43: =K35/K45 -> 9781538.5 | L43: =L35/L45 -> 9835909.1 | M43: =M35/M45 -> 9937272.7 | N43: =N35/N45 -> 11094783 | O43: =O35/O45 -> 12023191 | P43: =P35/P45 -> 12641471 | ... U43: =U35/U45 -> 8339537.7
A45: ZEV | B45: EU alternative fuel observatory | C45: % of sales | I45: =I46+I47 -> 0.0001 | J45: =J46+J47 -> 0.0007 | K45: =K46+K47 -> 0.0013 | L45: =L46+L47 -> 0.0022 | M45: =M46+M47 -> 0.0033 | N45: =N46+N47 -> 0.0046 | O45: =O46+O47 -> 0.0047 | P45: =P46+P47 -> 0.0068 | ... U45: =U46+U47 -> 0.1341
A46: BEV | B46: EU alternative fuel observatory, EEA for 2022 | C46: % of sales | I46: 0.0001 | J46: 0.0007 | K46: 0.0013 | L46: 0.0022 | M46: 0.0033 | N46: 0.0046 | O46: 0.0047 | P46: 0.0068 | Q46: 0.0106 | R46: 0.019 | S46: 0.0538 | T46: 0.0886 | U46: 0.134
A47: H2 | B47: EU alternative fuel observatory | C47: % of sales | I47: 0 | J47: 0 | K47: 0 | L47: 0 | M47: 0 | N47: 0 | O47: 0 | P47: 0 | Q47: 0 | R47: 0 | S47: 0.0001 | T47: 0.0001 | U47: 0.0001
A48: LEV | B48: EU alternative fuel observatory | C48: % of sales | I48: =I49+I50+I51 -> 0.0456 | J48: =J49+J50+J51 -> 0.0247 | K48: =K49+K50+K51 -> 0.0372 | L48: =L49+L50+L51 -> 0.0325 | M48: =M49+M50+M51 -> 0.0325 | N48: =N49+N50+N51 -> 0.0331 | O48: =O49+O50+O51 -> 0.0282 | P48: =P49+P50+P51 -> 0.0302 | ... U48: =U49+U50+U51 -> 0.1255
A49: PHEV | B49: EU alternative fuel observatory | C49: % of sales | I49: 0 | J49: 0 | K49: 0.0008 | L49: 0.0023 | M49: 0.0021 | N49: 0.0059 | O49: 0.0052 | P49: 0.0065 | Q49: 0.0082 | R49: 0.0107 | S49: 0.0513 | T49: 0.0878 | U49: =23%-U46 -> 0.096
A50: LPG | B50: EU alternative fuel observatory | C50: % of sales | I50: 0.0387 | J50: 0.02 | K50: 0.0297 | L50: 0.0204 | M50: 0.0206 | N50: 0.0198 | O50: 0.0181 | P50: 0.0198 | Q50: 0.0127 | R50: 0.0132 | S50: 0.0148 | T50: 0.0186 | U50: 0.0275
A51: CNG | B51: EU alternative fuel observatory | C51: % of sales | I51: 0.0069 | J51: 0.0047 | K51: 0.0067 | L51: 0.0098 | M51: 0.0098 | N51: 0.0074 | O51: 0.0049 | P51: 0.0039 | Q51: 0.0052 | R51: 0.0052 | S51: 0.0055 | T51: 0.0041 | U51: 0.002
A53: Vans
A54: Graph feed
B55: Source | C55: Unit | D55: 2005 | I55: 2010 | N55: 2015 | S55: 2020 | X55: 2025 | AC55: 2030 | AG55: 2035
A56: ZEV share | B56: EU alternative fuel observatory | C56: % | I56: =I77 -> 0.0006 | J56: =J77 -> 0.0014 | K56: =K77 -> 0.0055 | L56: =L77 -> 0.0048 | M56: =M77 -> 0.0038 | N56: =N77 -> 0.0045 | O56: =O77 -> 0.0061 | P56: =P77 -> 0.0086 | ... U56: =U77 -> 0.061
A57: LEV share | B57: EU alternative fuel observatory | C57: % | I57: =I80+I56 -> 0.0181 | J57: =J80+J56 -> 0.0077 | K57: =K80+K56 -> 0.0129 | L57: =L80+L56 -> 0.0148 | M57: =M80+M56 -> 0.0105 | N57: =N80+N56 -> 0.0134 | O57: =O80+O56 -> 0.0169 | P57: =P80+P56 -> 0.0175 | ... U57: =U80+U56 -> 0.0698
A58: benchmark | B58: Regulation (EU) 2023/851 | C58: % | AG58: 1
A59: linear trajectory | U59: 0.061 | V59: 0.13925 | W59: 0.2175 | X59: 0.29575 | Y59: 0.374 | Z59: 0.45225 | AA59: 0.5305 | AB59: 0.60875 | AC59: 0.687 | AD59: 0.76525 | AE59: 0.8435 | AF59: 0.92175 | AG59: 1
A61: Average 2018-2022 | B61: =AVERAGE(U56-T56,T56-S56,S56-R56,R56-Q56) -> 0.01245
A62: Required 2023-2035 | B62: =V59-U59 -> 0.07825
A64: Historic data
A65: Category | B65: Source | C65: Unit | I65: 2010 | J65: 2011 | K65: 2012 | L65: 2013 | M65: 2014 | N65: 2015 | O65: 2016 | P65: 2017 | Q65: 2018 | R65: 2019 | S65: 2020 | T65: 2021 | U65: 2022
...

Sheet T6a. % of fossil fuels
A1: % of fossil fuels
B2: Source | C2: Unit | D2: 2005 | I2: 2010 | N2: 2015 | S2: 2020 | X2: 2025 | AC2: 2030 | AH2: 2035 | AM2: 2040 | AR2: 2045 | AW2: 2050
A3: Historic | B3: Energy balances | C3: % | D3: =D16 -> 0.97693313 | E3: =E16 -> 0.97247514 | F3: =F16 -> 0.96783368 | G3: =G16 -> 0.96313576 | H3: =H16 -> 0.95721742 | I3: =I16 -> 0.95306271 | J3: =J16 -> 0.95080239 | K3: =K16 -> 0.94663168 | ... T3: =T16 -> 0.93435578
A4: 2030 benchmark | B4: CTP MIX | C4: % | AC4: =AC70 -> 0.89104865
A5: 2050 benchmark | B5: CTP MIX | C5: % | AW5: =AW70 -> 0.14063216
A7: Average 2017-2021 | D7: =AVERAGE(T3-S3,S3-R3,R3-Q3,Q3-P3) -> -0.003517583
A8: Required 2022-2030 | D8: =(AC4-T3)/8 -> -0.0054133911 | E8: =D8/D7 -> 1.5389519
A9: Required 2031-2035 | D9: =#REF!-#REF! -> #REF! | E9: =D9/D7 -> #REF!
A13: Historic data
A14: Total overviez | AJ14: Indicator T6a
B15: Source | C15: Unit | D15: 2005 | I15: 2010 | N15: 2015 | S15: 2020 | X15: 2025 | AC15: 2030 | AH15: 2035
A16: % fossil | D16: =(D23+D24+D25+D26+D27+D34+D35+D36+D37+D38+D45+D46+D47+D48+D49)/(D22+D33+D44) -> 0.97693313 | E16: =(E23+E24+E25+E26+E27+E34+E35+E36+E37+E38+E45+E46+E47+E48+E49)/(E22+E33+E44) -> 0.97247514 | F16: =(F23+F24+F25+F26+F27+F34+F35+F36+F37+F38+F45+F46+F47+F48+F49)/(F22+F33+F44) -> 0.96783368 | G16: =(G23+G24+G25+G26+G27+G34+G35+G36+G37+G38+G45+G46+G47+G48+G49)/(G22+G33+G44) -> 0.96313576 | H16: =(H23+H24+H25+H26+H27+H34+H35+H36+H37+H38+H45+H46+H47+H48+H49)/(H22+H33+H44) -> 0.95721742 | I16: =(I23+I24+I25+I26+I27+I34+I35+I36+I37+I38+I45+I46+I47+I48+I49)/(I22+I33+I44) -> 0.95306271 | J16: =(J23+J24+J25+J26+J27+J34+J35+J36+J37+J38+J45+J46+J47+J48+J49)/(J22+J33+J44) -> 0.95080239 | K16: =(K23+K24+K25+K26+K27+K34+K35+K36+K37+K38+K45+K46+K47+K48+K49)/(K22+K33+K44) -> 0.94663168 | ... T16: =(T23+T24+T25+T26+T27+T34+T35+T36+T37+T38+T45+T46+T47+T48+T49)/(T22+T33+T44) -> 0.93435578
A17: % bio | D17: =(D29+D40+D51)/(D22+D33+D44) -> 0.0087247071 | E17: =(E29+E40+E51)/(E22+E33+E44) -> 0.014031062 | F17: =(F29+F40+F51)/(F22+F33+F44) -> 0.019195223 | G17: =(G29+G40+G51)/(G22+G33+G44) -> 0.023910983 | H17: =(H29+H40+H51)/(H22+H33+H44) -> 0.029501086 | I17: =(I29+I40+I51)/(I22+I33+I44) -> 0.033471506 | J17: =(J29+J40+J51)/(J22+J33+J44) -> 0.035386033 | K17: =(K29+K40+K51)/(K22+K33+K44) -> 0.039166826 | ... T17: =(T29+T40+T51)/(T22+T33+T44) -> 0.050175588
A18: % electricity | D18: =(D28+D39+D50)/(D22+D33+D44) -> 0.014342159 | E18: =(E28+E39+E50)/(E22+E33+E44) -> 0.013493794 | F18: =(F28+F39+F50)/(F22+F33+F44) -> 0.0129711 | G18: =(G28+G39+G50)/(G22+G33+G44) -> 0.012953256 | H18: =(H28+H39+H50)/(H22+H33+H44) -> 0.013281489 | I18: =(I28+I39+I50)/(I22+I33+I44) -> 0.013465789 | J18: =(J28+J39+J50)/(J22+J33+J44) -> 0.013811573 | K18: =(K28+K39+K50)/(K22+K33+K44) -> 0.014201492 | ... T18: =(T28+T39+T50)/(T22+T33+T44) -> 0.015472573
A20: Transport excl. Bunkers
B21: Source | C21: Unit | D21: 2005 | I21: 2010 | N21: 2015 | S21: 2020 | X21: 2025 | AC21: 2030 | AH21: 2035
A22: Total | B22: Eurostat energy balance | C22: ktoe | D22: 281578.77 | E22: 287221.11 | F22: 291835.11 | G22: 287886.2 | H22: 280641.74 | I22: 279992.44 | J22: 278951.01 | K22: 269187.62 | L22: 265449.96 | M22: 268808.99 | N22: 272463.42 | O22: 278736.34 | P22: 284509.21 | Q22: 285944.66 | R22: 288722.81 | S22: 251439.59 | T22: 274834.95
A23: Solid fossil fuels | B23: Eurostat energy balance | C23: ktoe | D23: 5.489 | E23: 1.116 | F23: 0.993 | G23: 1.021 | H23: 0.483 | I23: 0.476 | J23: 0.469 | K23: 0.477 | L23: 0.488 | M23: 1.154 | N23: 1.192 | O23: 1.159 | P23: 1.357 | Q23: 1 | R23: 0.581 | S23: 0.351 | T23: 0.412
A24: Manufactured gases | B24: Eurostat energy balance | C24: ktoe | D24: 0 | E24: 0 | F24: 0 | G24: 0 | H24: 0 | I24: 0 | J24: 0 | K24: 0 | L24: 0 | M24: 0 | N24: 0 | O24: 0 | P24: 0 | Q24: 0 | R24: 0 | S24: 0 | T24: 0
A25: Peat and peat products | B25: Eurostat energy balance | C25: ktoe | D25: 0 | E25: 0 | F25: 0 | G25: 0 | H25: 0 | I25: 0 | J25: 0 | K25: 0 | L25: 0 | M25: 0 | N25: 0 | O25: 0 | P25: 0 | Q25: 0 | R25: 0 | S25: 0 | T25: 0
A26: Natural gas | B26: Eurostat energy balance | C26: ktoe | D26: 2787.873 | E26: 2679.47 | F26: 2770.754 | G26: 2895.259 | H26: 2537.443 | I26: 2660.352 | J26: 3032.095 | K26: 2833.788 | L26: 3119.998 | M26: 2993.783 | N26: 3031.348 | O26: 3198.345 | P26: 3304.196 | Q26: 3488.227 | R26: 3705.199 | S26: 3066.1 | T26: 3718.087
A27: Oil and petroleum products (excluding biofuel portion) | B27: Eurostat energy balance | C27: ktoe | D27: 270483.07 | E27: 274348.9 | F27: 276889.84 | G27: 271182.01 | H27: 262752.14 | I27: 260489.88 | J27: 258278.3 | K27: 247925.9 | L27: 245368.58 | M27: 248039.32 | N27: 251580.02 | O27: 257911.86 | P27: 262345.95 | Q27: 262127.38 | R27: 264124.08 | S27: 227702.74 | T27: 249154.43
A28: Electricity | B28: Eurostat energy balance | C28: ktoe | D28: 5162.098 | E28: 4996.349 | F28: 4908.985 | G28: 4851.788 | H28: 4765.8 | I28: 4831.706 | J28: 4952.236 | K28: 4903.61 | L28: 4913.854 | M28: 4778.688 | N28: 4844.611 | O28: 4939.947 | P28: 5024.902 | Q28: 5063.274 | R28: 5068.646 | S28: 4672.996 | T28: 5215.677
A29: Bioenergy | B29: Eurostat energy balance | C29: ktoe | D29: 3140.238 | E29: 5195.283 | F29: 7264.539 | G29: 8956.128 | H29: 10585.882 | I29: 12010.026 | J29: 12687.909 | K29: 13523.85 | L29: 12047.031 | M29: 12996.05 | N29: 13006.251 | O29: 12685.025 | P29: 13832.806 | Q29: 15264.786 | R29: 15824.299 | S29: 15997.395 | T29: 16746.338
A31: International maritime
B32: Source | C32: Unit | D32: 2005 | I32: 2010 | N32: 2015 | S32: 2020
A33: Total | B33: Eurostat energy balance | C33: ktoe | D33: 47197.778 | E33: 50311.868 | F33: 52464.315 | G33: 51884.183 | H33: 46334.866 | I33: 46700.957 | J33: 46535.697 | K33: 43487.329 | L33: 41030.763 | M33: 39836.329 | N33: 40311.578 | O33: 41540.203 | P33: 42178.037 | Q33: 43415.986 | R33: 43105.004 | S33: 39000.265 | T33: 40760.758
A34: Solid fossil fuels | B34: Eurostat energy balance | C34: ktoe | D34: 0 | E34: 0 | F34: 0 | G34: 0 | H34: 0 | I34: 0 | J34: 0 | K34: 0 | L34: 0 | M34: 0 | N34: 0 | O34: 0 | P34: 0 | Q34: 0 | R34: 0 | S34: 0 | T34: 0
A35: Manufactured gases | B35: Eurostat energy balance | C35: ktoe | D35: 0 | E35: 0 | F35: 0 | G35: 0 | H35: 0 | I35: 0 | J35: 0 | K35: 0 | L35: 0 | M35: 0 | N35: 0 | O35: 0 | P35: 0 | Q35: 0 | R35: 0 | S35: 0 | T35: 0
A36: Peat and peat products | B36: Eurostat energy balance | C36: ktoe | D36: 0 | E36: 0 | F36: 0 | G36: 0 | H36: 0 | I36: 0 | J36: 0 | K36: 0 | L36: 0 | M36: 0 | N36: 0 | O36: 0 | P36: 0 | Q36: 0 | R36: 0 | S36: 0 | T36: 0
