Workbook
Name CH4fact: 'Named Refs&Conversions'!$C$3
Name EJ2TWh: 'Named Refs&Conversions'!$C$17
Name FF55WindOff: #REF!
Name FF55WindOn: #REF!
Name ktoe2TWh: 'Named Refs&Conversions'!$C$13
Name Mtoe2TWh: 'Named Refs&Conversions'!$C$14
Name N2Ofact: 'Named Refs&Conversions'!$C$4
Name REPowerPVTot: #REF!

Sheet Colour Palette
A3: Font and colours:
A5: Segoe UI, size 8
A6: Signature colour
A8: Signature colour
A9: Transparency: 90%
A11: High width: 2.25 pt
A12: Low width: 0.25 pt
A14: Primary colour palette
A18: Primary colour palette
A20: Primary colour palette
A23: Primary colour palette

Sheet Named Refs&Conversions
B2: CO2e emissions factors | E2: Named Reference Name | H2: Rationale
B3: CH4 | C3: 28 | E3: CH4fact | H3: Table 8.A.1 of IPCC AR5 - the official common metric as per Glasgow CMA decision and EU regulations
B4: N2O | C4: 265 | E4: N2Ofact | H4: Table 8.A.1 of IPCC AR5 - the official common metric as per Glasgow CMA decision and EU regulations
B5: CH4 (AR4) | C5: 25
B9: Unit conversions | E9: Usually from: https://www.convert-measurement-units.com/
B10: oil equivalent to Watt hours
B11: 1 toe = | C11: 11.63 | D11: MWh
B12: 1 ktoe = | C12: =C11*1000 -> 11630 | D12: MWh
B13: 1 ktoe = | C13: =C12/1000000 -> 0.01163 | D13: TWh
B14: 1Mtoe = | C14: =ktoe2TWh*1000 -> 11.63 | D14: TWh
B16: joules to Watt hours
B17: 1 EJ = | C17: 277.78 | D17: TWh

Sheet B1. GHG emissions
A1: Total buildings
B2: Source | C2: Unit | D2: 2005 | I2: 2010 | N2: 2015 | S2: 2020 | X2: 2025 | AC2: 2030 | AH2: 2035 | AM2: 2040 | AR2: 2045 | AW2: 2050 | AZ2: 2021 vs 2005
A3: Total | B3: Calculated | C3: Mt CO2e | D3: =D4+D5+D6 -> 665.03924 | E3: =E4+E5+E6 -> 663.44783 | F3: =F4+F5+F6 -> 589.49466 | G3: =G4+G5+G6 -> 635.07002 | H3: =H4+H5+H6 -> 621.38705 | I3: =I4+I5+I6 -> 656.09143 | J3: =J4+J5+J6 -> 581.49116 | K3: =K4+K5+K6 -> 589.57096 | ... T3: =T4+T5+T6 -> 532.53389 | U3: 481.83207 | AZ3: =T3-D3 -> -132.50535 | BA3: =AZ3/D3 -> -0.19924441
A4: =A62 -> Residential | B4: Inventory CRFs (see below) | C4: Mt CO2e | D4: =D62 -> 426.80485 | E4: =E62 -> 420.47885 | F4: =F62 -> 368.56147 | G4: =G62 -> 399.00521 | H4: =H62 -> 389.51004 | I4: =I62 -> 412.95249 | J4: =J62 -> 362.00698 | K4: =K62 -> 372.54849 | ... T4: =T62 -> 324.73676 | AZ4: =T4-D4 -> -102.06809 | BA4: =AZ4/D4 -> -0.23914463
A5: Tertiary | B5: Inventory CRFs (see below) | C5: Mt CO2e | D5: =D63+D64 -> 238.23439 | E5: =E63+E64 -> 242.96899 | F5: =F63+F64 -> 220.93319 | G5: =G63+G64 -> 236.06481 | H5: =H63+H64 -> 231.87702 | I5: =I63+I64 -> 243.13893 | J5: =J63+J64 -> 219.48418 | K5: =K63+K64 -> 217.02247 | ... T5: =T63+T64 -> 207.79713 | AZ5: =T5-D5 -> -30.437267 | BA5: =AZ5/D5 -> -0.12776185
AZ6: =T6-D6 -> 0 | BA6: =AZ6/D6 -> #DIV/0!
A7: 2040 advice minimum (1) | AM7: =AM79 -> 82.919064 | AW7: =AW79 -> 1.749033
A8: 2040 advice scenarios | AM8: =AM80-AM7 -> 43.931394 | AW8: =AW80-AW7 -> 12.752292
A9: 2030 benchmark | AC9: =AC83+AC84 -> 250.34768
A10: 2050 benchmark | AW10: =AW87+AW88 -> 26.413929
A11: linear trajectory to benchmark | U11: 481.83207 | V11: 452.89652 | W11: 423.96097 | X11: 395.02543 | Y11: 366.08988 | Z11: 337.15433 | AA11: 308.21878 | AB11: 279.28323 | AC11: 250.34768 | AD11: =($AW11-$AC11)/20+AC11 -> 239.151 | AE11: =($AW11-$AC11)/20+AD11 -> 227.95431 | AF11: =($AW11-$AC11)/20+AE11 -> 216.75762 | AG11: =($AW11-$AC11)/20+AF11 -> 205.56093 | AH11: =($AW11-$AC11)/20+AG11 -> 194.36425 | AI11: =($AW11-$AC11)/20+AH11 -> 183.16756 | AJ11: =($AW11-$AC11)/20+AI11 -> 171.97087 | AK11: =($AW11-$AC11)/20+AJ11 -> 160.77418 | ... AV11: =($AW11-$AC11)/20+AU11 -> 37.610617 | AW11: =AW10 -> 26.413929
T16: 846.71317 | U16: 837.42654 | V16: 828.13992 | W16: 818.85329 | X16: 809.56667 | Y16: 787.11333 | Z16: 764.66 | AA16: 742.20667 | AB16: 719.75333 | AC16: 697.3 | AD16: 666.06787 | AE16: 634.83574 | AF16: 603.60361 | AG16: 572.37148 | AH16: 541.13935 | AI16: 509.90722 | AJ16: 478.67509 | AK16: 447.44296 | AL16: 416.21083 | AM16: 384.9787 | AN16: 353.74657 | AO16: 322.51444 | AP16: 291.28231 | AQ16: 260.05018 | AR16: 228.81805 | AS16: 197.58592 | AT16: 166.35379 | AU16: 135.12166 | AV16: 103.88953 | AW16: 72.6574
X17: =X18+X19 -> 809.56667 | AC17: =AC18+AC19 -> 697.3
X18: 691.6 | AC18: 583.5
X19: 117.96667 | AC19: 113.8
AW20: =10%*#REF! -> #REF!
AC21: 680 | AM21: 200 | AW21: 30
A22: Data for summary sheet at end of chapter | AC22: 600 | AM22: 100 | AW22: 20
A24: Y-on-y reduction | E24: =E3-D3 -> -1.5914083 | F24: =F3-E3 -> -73.953171 | G24: =G3-F3 -> 45.57536 | H24: =H3-G3 -> -13.682969 | I24: =I3-H3 -> 34.704374 | J24: =J3-I3 -> -74.600268 | K24: =K3-J3 -> 8.0798033 | L24: =L3-K3 -> 4.3275854 | ... T24: =T3-S3 -> 12.820213
A25: 2005-2022 | B25: calculated | C25: Mt CO2e | D25: =(U3-D3)/17 -> -10.776892
A26: 2017-2021 | D26: =(T3-P3)/4 -> -3.2986056
A27: 2018-2022 | B27: calculated | C27: Mt CO2e | D27: =(U3-Q3)/4 -> -12.775056
A28: 2022-2030 | D28: =(AC9-T3)/9 -> -31.354022
A29: 2023-2030 | B29: calculated | C29: Mt CO2e | D29: =V11-U11 -> -28.935548 | E29: =D29/D27 -> 2.2650036
A30: 2031-2050 | B30: calculated | C30: Mt CO2e | D30: =AD11-AC11 -> -11.196688
D35: Indicator B1
AH47: 0
A58: Historical inventory data
A60: EU27
D61: 2005 | E61: 2006 | F61: 2007 | G61: 2008 | H61: 2009 | I61: 2010 | J61: 2011 | K61: 2012 | L61: 2013 | M61: 2014 | N61: 2015 | O61: 2016 | P61: 2017 | Q61: 2018 | R61: 2019 | S61: 2020 | T61: 2021
A62: Residential | B62: CRF Table 1.A(a)s4 | D62: =('[1]Table1.A(a)s4'!$G$23+'[1]Table1.A(a)s4'!$H$23*CH4fact+'[1]Table1.A(a)s4'!$I$23*N2Ofact)/1000 -> 426.80485 | E62: =('[2]Table1.A(a)s4'!$G$23+'[2]Table1.A(a)s4'!$H$23*CH4fact+'[2]Table1.A(a)s4'!$I$23*N2Ofact)/1000 -> 420.47885 | F62: =('[3]Table1.A(a)s4'!$G$23+'[3]Table1.A(a)s4'!$H$23*CH4fact+'[3]Table1.A(a)s4'!$I$23*N2Ofact)/1000 -> 368.56147 | G62: =('[4]Table1.A(a)s4'!$G$23+'[4]Table1.A(a)s4'!$H$23*CH4fact+'[4]Table1.A(a)s4'!$I$23*N2Ofact)/1000 -> 399.00521 | H62: =('[5]Table1.A(a)s4'!$G$23+'[5]Table1.A(a)s4'!$H$23*CH4fact+'[5]Table1.A(a)s4'!$I$23*N2Ofact)/1000 -> 389.51004 | I62: =('[6]Table1.A(a)s4'!$G$23+'[6]Table1.A(a)s4'!$H$23*CH4fact+'[6]Table1.A(a)s4'!$I$23*N2Ofact)/1000 -> 412.95249 | J62: =('[7]Table1.A(a)s4'!$G$23+'[7]Table1.A(a)s4'!$H$23*CH4fact+'[7]Table1.A(a)s4'!$I$23*N2Ofact)/1000 -> 362.00698 | K62: =('[8]Table1.A(a)s4'!$G$23+'[8]Table1.A(a)s4'!$H$23*CH4fact+'[8]Table1.A(a)s4'!$I$23*N2Ofact)/1000 -> 372.54849 | L62: =('[9]Table1.A(a)s4'!$G$23+'[9]Table1.A(a)s4'!$H$23*CH4fact+'[9]Table1.A(a)s4'!$I$23*N2Ofact)/1000 -> 375.12388 | M62: =('[10]Table1.A(a)s4'!$G$23+'[10]Table1.A(a)s4'!$H$23*CH4fact+'[10]Table1.A(a)s4'!$I$23*N2Ofact)/1000 -> 316.9146 | N62: =('[11]Table1.A(a)s4'!$G$23+'[11]Table1.A(a)s4'!$H$23*CH4fact+'[11]Table1.A(a)s4'!$I$23*N2Ofact)/1000 -> 335.16026 | O62: =('[12]Table1.A(a)s4'!$G$23+'[12]Table1.A(a)s4'!$H$23*CH4fact+'[12]Table1.A(a)s4'!$I$23*N2Ofact)/1000 -> 341.31848 | P62: =('[13]Table1.A(a)s4'!$G$23+'[13]Table1.A(a)s4'!$H$23*CH4fact+'[13]Table1.A(a)s4'!$I$23*N2Ofact)/1000 -> 338.54089 | Q62: =('[14]Table1.A(a)s4'!$G$23+'[14]Table1.A(a)s4'!$H$23*CH4fact+'[14]Table1.A(a)s4'!$I$23*N2Ofact)/1000 -> 328.39196 | R62: =('[15]Table1.A(a)s4'!$G$23+'[15]Table1.A(a)s4'!$H$23*CH4fact+'[15]Table1.A(a)s4'!$I$23*N2Ofact)/1000 -> 321.17518 | S62: =('[16]Table1.A(a)s4'!$G$23+'[16]Table1.A(a)s4'!$H$23*CH4fact+'[16]Table1.A(a)s4'!$I$23*N2Ofact)/1000 -> 319.38421 | T62: =('[17]Table1.A(a)s4'!$G$23+'[17]Table1.A(a)s4'!$H$23*CH4fact+'[17]Table1.A(a)s4'!$I$23*N2Ofact)/1000 -> 324.73676
A63: Tertiary | B63: CRF Table 1.A(a)s4 | D63: =('[1]Table1.A(a)s4'!$G$16+'[1]Table1.A(a)s4'!$H$16*CH4fact+'[1]Table1.A(a)s4'!$I$16*N2Ofact)/1000 -> 154.3626 | E63: =('[2]Table1.A(a)s4'!$G$16+'[2]Table1.A(a)s4'!$H$16*CH4fact+'[2]Table1.A(a)s4'!$I$16*N2Ofact)/1000 -> 162.01645 | F63: =('[3]Table1.A(a)s4'!$G$16+'[3]Table1.A(a)s4'!$H$16*CH4fact+'[3]Table1.A(a)s4'!$I$16*N2Ofact)/1000 -> 142.78457 | G63: =('[4]Table1.A(a)s4'!$G$16+'[4]Table1.A(a)s4'!$H$16*CH4fact+'[4]Table1.A(a)s4'!$I$16*N2Ofact)/1000 -> 157.0021 | H63: =('[5]Table1.A(a)s4'!$G$16+'[5]Table1.A(a)s4'!$H$16*CH4fact+'[5]Table1.A(a)s4'!$I$16*N2Ofact)/1000 -> 154.30609 | I63: =('[6]Table1.A(a)s4'!$G$16+'[6]Table1.A(a)s4'!$H$16*CH4fact+'[6]Table1.A(a)s4'!$I$16*N2Ofact)/1000 -> 163.29738 | J63: =('[7]Table1.A(a)s4'!$G$16+'[7]Table1.A(a)s4'!$H$16*CH4fact+'[7]Table1.A(a)s4'!$I$16*N2Ofact)/1000 -> 140.57009 | K63: =('[8]Table1.A(a)s4'!$G$16+'[8]Table1.A(a)s4'!$H$16*CH4fact+'[8]Table1.A(a)s4'!$I$16*N2Ofact)/1000 -> 140.71549 | L63: =('[9]Table1.A(a)s4'!$G$16+'[9]Table1.A(a)s4'!$H$16*CH4fact+'[9]Table1.A(a)s4'!$I$16*N2Ofact)/1000 -> 142.47917 | M63: =('[10]Table1.A(a)s4'!$G$16+'[10]Table1.A(a)s4'!$H$16*CH4fact+'[10]Table1.A(a)s4'!$I$16*N2Ofact)/1000 -> 124.87065 | N63: =('[11]Table1.A(a)s4'!$G$16+'[11]Table1.A(a)s4'!$H$16*CH4fact+'[11]Table1.A(a)s4'!$I$16*N2Ofact)/1000 -> 130.48531 | O63: =('[12]Table1.A(a)s4'!$G$16+'[12]Table1.A(a)s4'!$H$16*CH4fact+'[12]Table1.A(a)s4'!$I$16*N2Ofact)/1000 -> 130.89357 | P63: =('[13]Table1.A(a)s4'!$G$16+'[13]Table1.A(a)s4'!$H$16*CH4fact+'[13]Table1.A(a)s4'!$I$16*N2Ofact)/1000 -> 131.28436 | Q63: =('[14]Table1.A(a)s4'!$G$16+'[14]Table1.A(a)s4'!$H$16*CH4fact+'[14]Table1.A(a)s4'!$I$16*N2Ofact)/1000 -> 127.58944 | R63: =('[15]Table1.A(a)s4'!$G$16+'[15]Table1.A(a)s4'!$H$16*CH4fact+'[15]Table1.A(a)s4'!$I$16*N2Ofact)/1000 -> 125.15035 | S63: =('[16]Table1.A(a)s4'!$G$16+'[16]Table1.A(a)s4'!$H$16*CH4fact+'[16]Table1.A(a)s4'!$I$16*N2Ofact)/1000 -> 122.10588 | T63: =('[17]Table1.A(a)s4'!$G$16+'[17]Table1.A(a)s4'!$H$16*CH4fact+'[17]Table1.A(a)s4'!$I$16*N2Ofact)/1000 -> 129.9028
A64: Agriculture and fisheries - energy | B64: CRF Table 1.A(a)s4 | D64: =('[1]Table1.A(a)s4'!$G$30+'[1]Table1.A(a)s4'!$H$30*CH4fact+'[1]Table1.A(a)s4'!$I$30*N2Ofact)/1000 -> 83.871788 | E64: =('[2]Table1.A(a)s4'!$G$30+'[2]Table1.A(a)s4'!$H$30*CH4fact+'[2]Table1.A(a)s4'!$I$30*N2Ofact)/1000 -> 80.952536 | F64: =('[3]Table1.A(a)s4'!$G$30+'[3]Table1.A(a)s4'!$H$30*CH4fact+'[3]Table1.A(a)s4'!$I$30*N2Ofact)/1000 -> 78.148628 | G64: =('[4]Table1.A(a)s4'!$G$30+'[4]Table1.A(a)s4'!$H$30*CH4fact+'[4]Table1.A(a)s4'!$I$30*N2Ofact)/1000 -> 79.062712 | H64: =('[5]Table1.A(a)s4'!$G$30+'[5]Table1.A(a)s4'!$H$30*CH4fact+'[5]Table1.A(a)s4'!$I$30*N2Ofact)/1000 -> 77.570931 | I64: =('[6]Table1.A(a)s4'!$G$30+'[6]Table1.A(a)s4'!$H$30*CH4fact+'[6]Table1.A(a)s4'!$I$30*N2Ofact)/1000 -> 79.841555 | J64: =('[7]Table1.A(a)s4'!$G$30+'[7]Table1.A(a)s4'!$H$30*CH4fact+'[7]Table1.A(a)s4'!$I$30*N2Ofact)/1000 -> 78.914085 | K64: =('[8]Table1.A(a)s4'!$G$30+'[8]Table1.A(a)s4'!$H$30*CH4fact+'[8]Table1.A(a)s4'!$I$30*N2Ofact)/1000 -> 76.306984 | L64: =('[9]Table1.A(a)s4'!$G$30+'[9]Table1.A(a)s4'!$H$30*CH4fact+'[9]Table1.A(a)s4'!$I$30*N2Ofact)/1000 -> 76.295502 | M64: =('[10]Table1.A(a)s4'!$G$30+'[10]Table1.A(a)s4'!$H$30*CH4fact+'[10]Table1.A(a)s4'!$I$30*N2Ofact)/1000 -> 75.989406 | N64: =('[11]Table1.A(a)s4'!$G$30+'[11]Table1.A(a)s4'!$H$30*CH4fact+'[11]Table1.A(a)s4'!$I$30*N2Ofact)/1000 -> 75.355257 | O64: =('[12]Table1.A(a)s4'!$G$30+'[12]Table1.A(a)s4'!$H$30*CH4fact+'[12]Table1.A(a)s4'!$I$30*N2Ofact)/1000 -> 75.52257 | P64: =('[13]Table1.A(a)s4'!$G$30+'[13]Table1.A(a)s4'!$H$30*CH4fact+'[13]Table1.A(a)s4'!$I$30*N2Ofact)/1000 -> 75.903066 | Q64: =('[14]Table1.A(a)s4'!$G$30+'[14]Table1.A(a)s4'!$H$30*CH4fact+'[14]Table1.A(a)s4'!$I$30*N2Ofact)/1000 -> 76.950898 | R64: =('[15]Table1.A(a)s4'!$G$30+'[15]Table1.A(a)s4'!$H$30*CH4fact+'[15]Table1.A(a)s4'!$I$30*N2Ofact)/1000 -> 76.497543 | S64: =('[16]Table1.A(a)s4'!$G$30+'[16]Table1.A(a)s4'!$H$30*CH4fact+'[16]Table1.A(a)s4'!$I$30*N2Ofact)/1000 -> 78.223577 | T64: =('[17]Table1.A(a)s4'!$G$30+'[17]Table1.A(a)s4'!$H$30*CH4fact+'[17]Table1.A(a)s4'!$I$30*N2Ofact)/1000 -> 77.894328
A66: Residential | B66: absolute change vs 2005 | D66: =D62-$D62 -> 0 | E66: =E62-$D62 -> -6.3260013 | F66: =F62-$D62 -> -58.24338 | G66: =G62-$D62 -> -27.799636 | H66: =H62-$D62 -> -37.294813 | I66: =I62-$D62 -> -13.852356 | J66: =J62-$D62 -> -64.797867 | K66: =K62-$D62 -> -54.256359 | ... T66: =T62-$D62 -> -102.06809
A67: Tertiary | B67: absolute change vs 2005 | D67: =D63-$D63 -> 0 | E67: =E63-$D63 -> 7.653845 | F67: =F63-$D63 -> -11.578039 | G67: =G63-$D63 -> 2.6394925 | H67: =H63-$D63 -> -0.056518233 | I67: =I63-$D63 -> 8.9347752 | J67: =J63-$D63 -> -13.792512 | K67: =K63-$D63 -> -13.647115 | ... T67: =T63-$D63 -> -24.459806
A69: Residential | B69: % change vs 2005 | E69: =E66/$D62 -> -0.014821765 | F69: =F66/$D62 -> -0.13646373 | G69: =G66/$D62 -> -0.065134302 | H69: =H66/$D62 -> -0.087381418 | I69: =I66/$D62 -> -0.032455948 | J69: =J66/$D62 -> -0.15182083 | K69: =K66/$D62 -> -0.12712217 | L69: =L66/$D62 -> -0.12108806 | ... T69: =T66/$D62 -> -0.23914463
A70: Tertiary | B70: % change vs 2005 | E70: =E67/$D63 -> 0.049583544 | F70: =F67/$D63 -> -0.075005464 | G70: =G67/$D63 -> 0.0170993 | H70: =H67/$D63 -> -0.00036613941 | I70: =I67/$D63 -> 0.057881734 | J70: =J67/$D63 -> -0.089351379 | K70: =K67/$D63 -> -0.088409463 | L70: =L67/$D63 -> -0.076983895 | ... T70: =T67/$D63 -> -0.15845681
A72: UK (in case needed for downscaling EU28)
N73: 2015
A74: Residential | B74: CRF Table 1.A(a)s4 | N74: =('[18]Table1.A(a)s4'!$G$32+'[18]Table1.A(a)s4'!$H$32*CH4fact+'[18]Table1.A(a)s4'!$I$32*N2Ofact)/1000 -> 65.504297
...

Sheet B2. buildings - energy
B1: 2017-2021 | C1: 2022-2030 FF55 | D1: 2022-2030 RePowerEU | E1: 2031-2050 from FF55 | F1: 2031-2050 from RePowerEU
A2: Residential | B2: =(T15-P15)/4 -> 29.256831 | C2: =(AC17-T15)/9 -> -97.915687 | D2: =(AC19-T15)/9 -> -113.42235 | E2: =(AW21-AC17)/20 -> -5.5050809 | F2: =(AW21-AC19)/20 -> 1.4729191
A3: Tertiary | B3: =(T15-P15)/5 -> 23.405465 | C3: =(AC97-T14)/9 -> -35.822546 | D3: =(AC95-T14)/9 -> -47.452546 | E3: =((#REF!-#REF!)-AC97)/20 -> #REF! | F3: =((#REF!-#REF!)-AC95)/20 -> #REF!
A8: Eurostat Energy use data
A9: TIME
A10: NRG_BAL (Labels) | D10: 2005 | I10: 2010 | N10: 2015 | S10: 2020 | X10: 2025 | AC10: 2030 | AH10: 2035 | AM10: 2040 | AR10: 2045 | AW10: 2050
A11: Final consumption - other sectors - commercial and public services - energy use | B11: Eurostat energy balances | C11: TJ | D11: 5358277.2 | E11: 5568843.7 | F11: 5287873.2 | G11: 5617880 | H11: 5624745.5 | I11: 5860782.6 | J11: 5371888.1 | K11: 5490871.9 | L11: 5556912.2 | M11: 5167985 | N11: 5380841.6 | O11: 5450012.1 | P11: 5605356.9 | Q11: 5512433.2 | R11: 5382855.9 | S11: 5074802.4 | T11: 5416746.2
A12: Final consumption - other sectors - households - energy use | B12: Eurostat energy balances | C12: TJ | D12: 11150493 | E12: 11111543 | F12: 10435068 | G12: 11064263 | H12: 10985679 | I12: 11678550 | J12: 10546611 | K12: 11012084 | L12: 11141042 | M12: 9824051.5 | N12: 10259139 | O12: 10503571 | P12: 10538534 | Q12: 10456263 | R12: 10390886 | S12: 10388388 | T12: 10959829
A13: Final consumption - other sectors - agriculture and forestry - energy use | B13: Eurostat energy balances | C13: TJ | D13: 1129993.5 | E13: 1061267.7 | F13: 1040200.1 | G13: 1034996.5 | H13: 1009232.2 | I13: 1067822.5 | J13: 1044721.4 | K13: 1033812.9 | L13: 1049292.6 | M13: 1026576.2 | N13: 1027088.1 | O13: 1045031.4 | P13: 1057853.9 | Q13: 1156192.8 | R13: 1173620.9 | S13: 1189811.1 | T13: 1186691.5
A14: Tertiary | B14: Eurostat (above): includes agriculture | C14: TWh | D14: =((D11+D13)*EJ2TWh/1000000) -> 1802.3119 | E14: =((E11+E13)*EJ2TWh/1000000) -> 1841.7123 | F14: =((F11+F13)*EJ2TWh/1000000) -> 1757.8122 | G14: =((G11+G13)*EJ2TWh/1000000) -> 1848.036 | H14: =((H11+H13)*EJ2TWh/1000000) -> 1842.7863 | I14: =((I11+I13)*EJ2TWh/1000000) -> 1924.6279 | J14: =((J11+J13)*EJ2TWh/1000000) -> 1782.4058 | K14: =((K11+K13)*EJ2TWh/1000000) -> 1812.427 | ... T14: =((T11+T13)*EJ2TWh/1000000) -> 1834.3029
A15: Residential | C15: TWh | D15: =D12*EJ2TWh/1000000 -> 3097.3839 | E15: =E12*EJ2TWh/1000000 -> 3086.5644 | F15: =F12*EJ2TWh/1000000 -> 2898.6531 | G15: =G12*EJ2TWh/1000000 -> 3073.4311 | H15: =H12*EJ2TWh/1000000 -> 3051.6018 | I15: =I12*EJ2TWh/1000000 -> 3244.0676 | J15: =J12*EJ2TWh/1000000 -> 2929.6375 | K15: =K12*EJ2TWh/1000000 -> 3058.9367 | ... T15: =T12*EJ2TWh/1000000 -> 3044.4212
A16: Total (residential + tertiary) | C16: TWh | D16: =D15+D14 -> 4899.6958 | E16: =E15+E14 -> 4928.2767 | F16: =F15+F14 -> 4656.4653 | G16: =G15+G14 -> 4921.4671 | H16: =H15+H14 -> 4894.3881 | I16: =I15+I14 -> 5168.6956 | J16: =J15+J14 -> 4712.0432 | K16: =K15+K14 -> 4871.3637 | ... T16: =T15+T14 -> 4878.7241
A17: 2030 benchmark - residential | B17: FF55 value from REPowerEU SWD Table 10 (residential) | C17: TWh | AC17: =AC96 -> 2163.18
A18: 2030 benchmark - tertiary | B18: FF55 MIX (commercial inc ag) added to residential for stacking. | C18: TWh | AC18: =AC97+AC17 -> 3675.08
A19: REPowerEU - residential | B19: Residential - Table 10, REPower SWD | C19: TWh | AC19: =AC94 -> 2023.62
A20: REPowerEU - tertiary | B20: Residential - Table 10, REPower SWD added to residential | C20: TWh | AC20: =AC19+AC95 -> 3430.85
A21: 2050 benchmark - residential | B21: CTP IA figure 39 | C21: TWh | AW21: 2053.0784
A22: 2050 benchmark - tertiary | B22: EC CPFA Fig 19 (1.5 LIFE) added to residential | AW22: =1463.36483685046+AW21 -> 3516.4432
A23: delete this label - 2040 advice minimum | B23: ESABCC database | AM23: =AM83 -> 3027.7326 | AW23: =AW83 -> 2559.9018
A24: 2040 advice scenarios (residential + tertiary) | B24: ESABCC database | AM24: =AM84-AM23 -> 140.81992 | AW24: =AW84-AW23 -> 294.44978
D25: =D13/SUM(D11:D13) -> 0.064063081 | E25: =E13/SUM(E11:E13) -> 0.059817854 | F25: =F13/SUM(F11:F13) -> 0.062052817 | G25: =G13/SUM(G11:G13) -> 0.058417809 | H25: =H13/SUM(H11:H13) -> 0.05727877 | I25: =I13/SUM(I11:I13) -> 0.057387737 | J25: =J13/SUM(J11:J13) -> 0.061587445 | K25: =K13/SUM(K11:K13) -> 0.058951164 | ... T25: =T13/SUM(T11:T13) -> 0.067566672
D28: Indicator B2
A56: % changes (Eurostat) | D56: =D10 -> 2005 | I56: =I10 -> 2010 | N56: =N10 -> 2015 | S56: =S10 -> 2020 | X56: =X10 -> 2025 | AC56: =AC10 -> 2030 | AH56: =AH10 -> 2035 | AM56: =AM10 -> 2040 | AR56: =AR10 -> 2045 | AW56: =AW10 -> 2050
A57: Final Energy Consumption - commercial and institutional | D57: =D11/$D11-1 -> 0 | E57: =E11/$D11-1 -> 0.039297417 | F57: =F11/$D11-1 -> -0.01313931 | G57: =G11/$D11-1 -> 0.048448916 | H57: =H11/$D11-1 -> 0.049730206 | I57: =I11/$D11-1 -> 0.093781149 | J57: =J11/$D11-1 -> 0.002540148 | K57: =K11/$D11-1 -> 0.02474577 | ... T57: =T11/$D11-1 -> 0.010911899
A59: Five-year average | H59: =AVERAGE(D14:H14) -> 1818.5317 | I59: =AVERAGE(E14:I14) -> 1842.995 | J59: =AVERAGE(F14:J14) -> 1831.1336 | K59: =AVERAGE(G14:K14) -> 1842.0566 | L59: =AVERAGE(H14:L14) -> 1839.4637 | M59: =AVERAGE(I14:M14) -> 1815.0515 | N59: =AVERAGE(J14:N14) -> 1786.1248 | O59: =AVERAGE(K14:O14) -> 1790.4823 | ... T59: =AVERAGE(P14:T14) -> 1819.8126
A60: Five-year average 2005 | H60: =H59/$D14-1 -> 0.0089994924 | I60: =I59/$D14-1 -> 0.022572735 | J60: =J59/$D14-1 -> 0.015991569 | K60: =K59/$D14-1 -> 0.022052093 | L60: =L59/$D14-1 -> 0.020613446 | M60: =M59/$D14-1 -> 0.0070684974 | N60: =N59/$D14-1 -> -0.0089812457 | O60: =O59/$D14-1 -> -0.006563527 | ... T60: =T59/$D14-1 -> 0.0097101632
A62: Final Energy Consumption - residential | D62: =D15/$D15-1 -> 0 | E62: =E15/$D15-1 -> -0.0034931233 | F62: =F15/$D15-1 -> -0.064160861 | G62: =G15/$D15-1 -> -0.0077332392 | H62: =H15/$D15-1 -> -0.014780905 | I62: =I15/$D15-1 -> 0.047357287 | J62: =J15/$D15-1 -> -0.054157457 | K62: =K15/$D15-1 -> -0.0124128 | ... T62: =T15/$D15-1 -> -0.017099182
A64: Five-year average | H64: =AVERAGE(D15:H15) -> 3041.5269 | I64: =AVERAGE(E15:I15) -> 3070.8636 | J64: =AVERAGE(F15:J15) -> 3039.4782 | K64: =AVERAGE(G15:K15) -> 3071.5349 | L64: =AVERAGE(H15:L15) -> 3075.8004 | M64: =AVERAGE(I15:M15) -> 3011.2651 | N64: =AVERAGE(J15:N15) -> 2932.4083 | O64: =AVERAGE(K15:O15) -> 2930.0171 | ... T64: =AVERAGE(P15:T15) -> 2929.6845
A65: Five-year average 2005 | H65: =H64/$D15-1 -> -0.018033626 | I65: =I64/$D15-1 -> -0.0085621685 | J65: =J64/$D15-1 -> -0.018695035 | K65: =K64/$D15-1 -> -0.0083454231 | L65: =L64/$D15-1 -> -0.006968298 | M65: =M64/$D15-1 -> -0.027803736 | N65: =N64/$D15-1 -> -0.053262903 | O65: =O64/$D15-1 -> -0.054034882 | ... T65: =T64/$D15-1 -> -0.054142262
A67: FF55 MIX reduction vs 2021 (res + comm + ag) | AC67: =AC18/T16-1 -> -0.24671289
A68: FF55 MIX reduction vs 2021 (res only) | AC68: =AC17/T15-1 -> -0.28946099
A69: FF55 MIX reduction vs 2021 (comm + ag only) | AC69: =(AC18-AC17)/T14-1 -> -0.17576318
A71: Data for summary sheet at end of chapter
A72: Residential
A73: annual change in total final energy consumption 2017-21 | B73: N/A - do not pick a number because no clear direction of travel
A74: annual change in total final energy 2021-benchmark (FF55) | B74: =(AC17-T15)/8 -> -110.15515
A75: annual change in total final energy 2021-REPowerEU | B75: =(AC19-T15)/8 -> -127.60015
A77: Commercial
A78: annual change in total final energy consumption 2017-21 | B78: N/A - do not pick a number because no clear direction of travel
A79: annual change in total final energy 2021-benchmark (FF55) | B79: =((AC18-AC17)-T14)/8 -> -40.300365
...

Sheet B3. (Retrofit)
A4: Renovation Rate (2012-2016) | D4: Residential | E4: Non-residential
A5: Total | D5: 0.123 | E5: 0.095
A6: Below threshold | D6: 0.071 | E6: 0.041
A7: Light | D7: 0.039 | E7: 0.03
A8: Medium | D8: 0.011 | E8: 0.021
A9: Deep | D9: 0.002 | E9: 0.003
A10: Weighted renovation rate (2016-2020) | B10: CTP Impact assessment - pg 66-67 | C10: 2016-2020 | D10: 0.01 | E10: 0.006
A11: Weighted renovation rate (2026-2030) | B11: 2030 CTP - Figure 53 and 54 - average across scenarios | C11: 2026-2030 | D11: 0.018 | E11: 0.011
A12: Light | D12: 0.002 | E12: 0.002
A13: Medium | D13: 0.007 | E13: 0.007
A14: Deep | D14: 0.009 | E14: 0.001
C16: Residential | D16: 2016-2020 | E16: 2026-2030 | G16: Commercial | H16: 2016-2020 | I16: 2026-2030
C17: Light | D17: 0 | E17: 0.0016022758 | G17: Light | H17: 0 | I17: 0.0023603942
C18: Medium | D18: 0 | E18: 0.0065007482 | G18: Medium | H18: 0 | I18: 0.0079493823
C19: Deep | D19: 0 | E19: 0.012805705 | G19: Deep | H19: 0 | I19: 0.00079093972
C20: Weighted renovation rate | D20: 0.01 | E20: =SUM(E17:E19) -> 0.020908729 | G20: Weighted renovation rate | H20: 0.006 | I20: =SUM(I17:I19) -> 0.011100716

Sheet B4. surface area
A1: Residential buildings
A2: # of dwellings and buildings (source: EBSO)
B3: Source | D3: Unit | E3: 2005 | F3: 2006 | G3: 2007 | H3: 2008 | I3: 2009 | J3: 2010 | K3: 2011 | L3: 2012 | M3: 2013 | N3: 2014 | O3: 2015 | P3: 2016 | Q3: 2017 | R3: 2018 | S3: 2019
A4: Total # of buildings | D4: #1000 | L4: 116152.9 | M4: 116951.99 | N4: 117706.84 | O4: 118439.07 | P4: 119171.81
A5: Total # of dwellings | D5: #1000 | E5: 198349.5 | F5: 200768.07 | G5: 202554.12 | H5: 204615.95 | I5: 206444.45 | J5: 208798.63 | K5: 208957.11 | L5: 210929.67 | M5: 212071.93 | N5: 213234.66 | O5: 214597.52 | P5: 215330.54
A6: y-on-y dwelling per building | D6: # | L6: =L5/L4 -> 1.8159656 | M6: =M5/M4 -> 1.8133247 | N6: =N5/N4 -> 1.8115741 | O6: =O5/O4 -> 1.8118811 | P6: =P5/P4 -> 1.8068917
A7: Single-familiy dwelling | D7: #1000 | E7: 95217.44 | F7: 96446.109 | G7: 98310.715 | H7: 99434.544 | I7: 100331.11 | J7: 101059.92 | K7: 101250.52 | L7: 101530.74 | M7: 101281.39 | N7: 99265.132 | O7: 99734.427 | P7: 100075.1 | Q7: 101075.44
A8: Detached single famiy | D8: #1000 | J8: 72244.325 | K8: 72090.203 | L8: 71505.158 | M8: 71892.386 | N8: 71646.844 | O8: 71460.974 | P8: 72351.062
A9: Semi-detached single family | D9: #1000 | J9: 47814.886 | K9: 49731.792 | L9: 50623.121 | M9: 51533.48 | N9: 51389.552 | O9: 51718.002 | P9: 51464
A10: Multi-family | D10: #1000 | J10: 86860.229 | K10: 85881.372 | L10: 87113.954 | M10: 87373.637 | N10: 88918.852 | O10: 90345.555 | P10: 90008.167
A12: surfaces (source: EBSO)
B13: Source | D13: Unit | E13: 2005 | F13: 2006 | G13: 2007 | H13: 2008 | I13: 2009 | J13: 2010 | K13: 2011 | L13: 2012 | M13: 2013 | N13: 2014 | O13: 2015 | P13: 2016 | Q13: 2017 | R13: 2018 | S13: 2019
A14: Total surface of dwellings - EBSCO | D14: Mm2 | L14: 20309.179 | M14: 20438.442 | N14: 20565.049 | O14: 20692.264 | P14: 20820.976
A15: Total surface of dwellings - own calculations | D15: Mm2 | E15: =E5*E18/1000 -> 17416.177 | F15: =F5*F18/1000 -> 17739.164 | G15: =G5*G18/1000 -> 17932.846 | H15: =H5*H18/1000 -> 18167.523 | I15: =I5*I18/1000 -> 18360.57 | J15: =J5*J18/1000 -> 18863.348 | K15: =K5*K18/1000 -> 18939.037 | L15: =L5*L18/1000 -> 19171.377 | ... P15: =P5*P18/1000 -> 19702.658
A16: Total surface of single-family dwellings | D16: Mm2 | L16: 13334.327 | M16: 13417.554 | N16: 13497.363 | O16: 13577.414 | P16: 13657.345 | Q16: 9569.9577
A17: Total surface of multi-family dwellings | D17: Mm2 | L17: 6974.852 | M17: 7020.8877 | N17: 7067.6856 | O17: 7114.8506 | P17: 7163.6315 | Q17: 9181.9838
A18: average floor area dwellings | D18: m2 | E18: 87.8055 | F18: 88.3565 | G18: 88.5336 | H18: 88.7884 | I18: 88.9371 | J18: 90.3423 | K18: 90.636 | L18: 90.8899 | M18: 91.3986 | N18: 91.2536 | O18: 91.414 | P18: 91.4996 | Q18: 91.3931
A19: average floor area single-family dwellings | D19: m2 | E19: 129.4 | F19: 131.7 | G19: 132.4 | H19: 133.7 | I19: 134.7 | J19: 135.4 | K19: 136.1 | L19: 136.6 | M19: 137.6 | N19: 138
A20: average floor area multi-family dwellings | D20: m2
A23: Graph feed
E24: 2005 | J24: 2010 | O24: 2015 | T24: 2020
A25: Total number of dwellings | C25: EBSO (old?) | D25: % of 2005 | E25: =E5/$E5 -> 1 | F25: =F5/$E5 -> 1.0121935 | G25: =G5/$E5 -> 1.021198 | H25: =H5/$E5 -> 1.0315929 | I25: =I5/$E5 -> 1.0408115 | J25: =J5/$E5 -> 1.0526804 | K25: =K5/$E5 -> 1.0534794 | L25: =L5/$E5 -> 1.0634242 | ... P25: =P5/$E5 -> 1.0856117
A26: Average floor area per dwelling | C26: Odyssee (see drivers tab) | D26: % of 2005 (from Odyssee: see energy drivers tab) | E26: ='4 energy drivers'!E7/'4 energy drivers'!$E7 -> 1 | F26: ='4 energy drivers'!F7/'4 energy drivers'!$E7 -> 1.0040531 | G26: ='4 energy drivers'!G7/'4 energy drivers'!$E7 -> 1.0071309 | H26: ='4 energy drivers'!H7/'4 energy drivers'!$E7 -> 1.0101948 | I26: ='4 energy drivers'!I7/'4 energy drivers'!$E7 -> 1.0136345 | J26: ='4 energy drivers'!J7/'4 energy drivers'!$E7 -> 1.0306587 | K26: ='4 energy drivers'!K7/'4 energy drivers'!$E7 -> 1.0365917 | L26: ='4 energy drivers'!L7/'4 energy drivers'!$E7 -> 1.0377189 | ... T26: ='4 energy drivers'!T7/'4 energy drivers'!$E7 -> 1.044306
A27: Total surface - residential | C27: EBSO (old?) | D27: % of 2005 | E27: =E15/$E15 -> 1 | F27: =F15/$E15 -> 1.0185452 | G27: =G15/$E15 -> 1.029666 | H27: =H15/$E15 -> 1.0431406 | I27: =I15/$E15 -> 1.054225 | J27: =J15/$E15 -> 1.0830935 | K27: =K15/$E15 -> 1.0874394 | L27: =L15/$E15 -> 1.1007798 | ... P27: =P15/$E15 -> 1.1312849
A28: EU population | C28: Eurostat (see drivers tab) | E28: ='4 energy drivers'!E32/'4 energy drivers'!$E32 -> 1 | F28: ='4 energy drivers'!F32/'4 energy drivers'!$E32 -> 1.0032304 | G28: ='4 energy drivers'!G32/'4 energy drivers'!$E32 -> 1.0065913 | H28: ='4 energy drivers'!H32/'4 energy drivers'!$E32 -> 1.0098144 | I28: ='4 energy drivers'!I32/'4 energy drivers'!$E32 -> 1.0122039 | J28: ='4 energy drivers'!J32/'4 energy drivers'!$E32 -> 1.0136175 | K28: ='4 energy drivers'!K32/'4 energy drivers'!$E32 -> 1.0118224 | L28: ='4 energy drivers'!L32/'4 energy drivers'!$E32 -> 1.0133043 | ... T28: ='4 energy drivers'!T32/'4 energy drivers'!$E32 -> 1.0281077
A29: Total surface - tertiary | C29: Odyssee (see drivers tab) | D29: % of 2005 (from Odyssee: see energy drivers tab) | E29: ='4 energy drivers'!E18/'4 energy drivers'!$E18 -> 1 | F29: ='4 energy drivers'!F18/'4 energy drivers'!$E18 -> 0.99643473 | G29: ='4 energy drivers'!G18/'4 energy drivers'!$E18 -> 1.0124635 | H29: ='4 energy drivers'!H18/'4 energy drivers'!$E18 -> 1.0385601 | I29: ='4 energy drivers'!I18/'4 energy drivers'!$E18 -> 1.0469482 | J29: ='4 energy drivers'!J18/'4 energy drivers'!$E18 -> 1.055983 | K29: ='4 energy drivers'!K18/'4 energy drivers'!$E18 -> 1.0597429 | L29: ='4 energy drivers'!L18/'4 energy drivers'!$E18 -> 1.0714231 | ... S29: ='4 energy drivers'!S18/'4 energy drivers'!$E18 -> 1.1196775
A30: Average household size | D30: % of 2010 | J30: ='4 energy drivers'!J42/'4 energy drivers'!$J42 -> 1 | K30: ='4 energy drivers'!K42/'4 energy drivers'!$J42 -> 1 | L30: ='4 energy drivers'!L42/'4 energy drivers'!$J42 -> 1 | M30: ='4 energy drivers'!M42/'4 energy drivers'!$J42 -> 1 | N30: ='4 energy drivers'!N42/'4 energy drivers'!$J42 -> 0.95833333 | O30: ='4 energy drivers'!O42/'4 energy drivers'!$J42 -> 0.95833333 | P30: ='4 energy drivers'!P42/'4 energy drivers'!$J42 -> 0.95833333 | Q30: ='4 energy drivers'!Q42/'4 energy drivers'!$J42 -> 0.95833333 | ... T30: ='4 energy drivers'!T42/'4 energy drivers'!$J42 -> 0.95833333
A32: Non-residential buildings
A33: # of dwellings and buildings (source: EBSO)
B34: Source | D34: Unit | E34: 2005 | F34: 2006 | G34: 2007 | H34: 2008 | I34: 2009 | J34: 2010 | K34: 2011 | L34: 2012 | M34: 2013 | N34: 2014 | O34: 2015 | P34: 2016 | Q34: 2017 | R34: 2018 | S34: 2019
A35: Total # of buildings | D35: #1000 | L35: 11432.09 | M35: 11558.358 | N35: 11639.809 | O35: 11775.748 | P35: 11896.637 | Q35: 46300
I38: Indicator B4 | R38: =0.1982/0.0711 -> 2.7876231
R39: =0.2169/0.0782 -> 2.7736573
A55: Data for summary sheet at end of chapter
A56: annual change in total dwelling space (2012-2016) | L56: =L27-K27 -> 0.013340467 | M56: =M27-L27 -> 0.012155443 | N56: =N27-M27 -> 0.0043265548 | O56: =O27-N27 -> 0.0091172463 | P56: =P27-O27 -> 0.0049058347
A57: annual change in total dwelling space (2012-2016) | D57: =AVERAGE(L56:P56) -> 0.0087691092

Sheet B5a&b energy mix new
A1: Residential | B1: Source | C1: Unit
A2: Graph feed
D3: 2005 | I3: 2010 | N3: 2015 | S3: 2020 | X3: 2025 | AC3: 2030 | AH3: 2035 | AM3: 2040 | AR3: 2045 | AW3: 2050
A4: Fossils | B4: calculated | C4: % | D4: =SUM(D39:D41)/D$38 -> 0.5661235 | E4: =SUM(E39:E41)/E$38 -> 0.55726346 | F4: =SUM(F39:F41)/F$38 -> 0.51742437 | G4: =SUM(G39:G41)/G$38 -> 0.52641873 | H4: =SUM(H39:H41)/H$38 -> 0.51881097 | I4: =SUM(I39:I41)/I$38 -> 0.51869881 | J4: =SUM(J39:J41)/J$38 -> 0.50364642 | K4: =SUM(K39:K41)/K$38 -> 0.49741508 | ... T4: =SUM(T39:T41)/T$38 -> 0.455817
A5: Electricity | B5: calculated | C5: % | D5: =D42/D38 -> 0.2160435 | E5: =E42/E38 -> 0.22206552 | F5: =F42/F38 -> 0.23486467 | G5: =G42/G38 -> 0.22649044 | H5: =H42/H38 -> 0.22925665 | I5: =I42/I38 -> 0.22506153 | J5: =J42/J38 -> 0.2402841 | K5: =K42/K38 -> 0.23501991 | ... T5: =T42/T38 -> 0.24546313
A6: Biomass | B6: calculated | C6: % | D6: =D44/D38 -> 0.13012535 | E6: =E44/E38 -> 0.13512946 | F6: =F44/F38 -> 0.153862 | G6: =G44/G38 -> 0.15775224 | H6: =H44/H38 -> 0.16011629 | I6: =I44/I38 -> 0.1595698 | J6: =J44/J38 -> 0.15867276 | K6: =K44/K38 -> 0.1716003 | ... T6: =T44/T38 -> 0.17484867
A7: District heating | D7: =D43/D38 -> 0.083562774 | E7: =E43/E38 -> 0.080309272 | F7: =F43/F38 -> 0.086905004 | G7: =G43/G38 -> 0.08103047 | H7: =H43/H38 -> 0.08140925 | I7: =I43/I38 -> 0.084885953 | J7: =J43/J38 -> 0.084430524 | K7: =K43/K38 -> 0.081819563 | ... T7: =T43/T38 -> 0.086322221
A8: Non-bio renewables | B8: calculated | C8: % | D8: =(D45)/D38 -> 0.0041448854 | E8: =(E45)/E38 -> 0.0052322894 | F8: =(F45)/F38 -> 0.0069439482 | G8: =(G45)/G38 -> 0.0083081117 | H8: =(H45)/H38 -> 0.010406835 | I8: =(I45)/I38 -> 0.011783907 | J8: =(J45)/J38 -> 0.01296619 | K8: =(K45)/K38 -> 0.014145156 | ... T8: =(T45)/T38 -> 0.037548982
A9: Fossils - benchmark | B9: calculated | C9: % | AC9: =SUM(AC50:AC52)/AC49 -> 0.23816373 | AW9: =SUM(AW50:AW52)/AW49 -> 0.011530965
A10: Electricity - benchmark | B10: calculated | C10: % | AC10: =AC58/AC49 -> 0.36687025 | AW10: =AW58/AW49 -> 0.43717563
A11: Biomass - benchmark | B11: calculated | C11: % | AC11: =AC56/AC49 -> 0.17838154 | AW11: =AW56/AW49 -> 0.17709179
A12: District heating - benchmark | AC12: =AC55/AC49 -> 0.097565946 | AW12: =AW55/AW49 -> 0.094382827
A13: Non-bio renewables - benchmark | B13: calculated | C13: % | AC13: =(AC57+AC54+AC53)/AC49 -> 0.11901853 | AW13: =(AW57+AW54+AW53)/AW49 -> 0.27981879
A14: linear trajectories | T14: 0.455817 | U14: 0.4316333 | V14: 0.40744961 | W14: 0.38326591 | X14: 0.35908221 | Y14: 0.33489852 | Z14: 0.31071482 | AA14: 0.28653113 | AB14: 0.26234743 | AC14: 0.23816373 | AD14: 0.2268321 | AE14: 0.21550046 | AF14: 0.20416882 | AG14: 0.19283718 | AH14: 0.18150554 | AI14: 0.1701739 | AJ14: 0.15884227 | AK14: 0.14751063 | AL14: 0.13617899 | AM14: 0.12484735 | AN14: 0.11351571 | AO14: 0.10218407 | AP14: 0.090852434 | AQ14: 0.079520796 | AR14: 0.068189157 | AS14: 0.056857519 | AT14: 0.04552588 | AU14: 0.034194242 | AV14: 0.022862603 | AW14: 0.011530965
A15: linear trajectory | T15: 0.24546313 | U15: 0.25895281 | V15: 0.27244249 | W15: 0.28593217 | X15: 0.29942185 | Y15: 0.31291153 | Z15: 0.32640121 | AA15: 0.33989089 | AB15: 0.35338057 | AC15: 0.36687025 | AD15: 0.37038552 | AE15: 0.37390079 | AF15: 0.37741606 | AG15: 0.38093132 | AH15: 0.38444659 | AI15: 0.38796186 | AJ15: 0.39147713 | AK15: 0.3949924 | AL15: 0.39850767 | AM15: 0.40202294 | AN15: 0.40553821 | AO15: 0.40905348 | AP15: 0.41256875 | AQ15: 0.41608401 | AR15: 0.41959928 | AS15: 0.42311455 | AT15: 0.42662982 | AU15: 0.43014509 | AV15: 0.43366036 | AW15: 0.43717563
A16: linear trajectory | T16: 0.17484867 | U16: 0.17524121 | V16: 0.17563375 | W16: 0.17602629 | X16: 0.17641883 | Y16: 0.17681138 | Z16: 0.17720392 | AA16: 0.17759646 | AB16: 0.177989 | AC16: 0.17838154 | AD16: 0.17831705 | AE16: 0.17825256 | AF16: 0.17818808 | AG16: 0.17812359 | AH16: 0.1780591 | AI16: 0.17799461 | AJ16: 0.17793013 | AK16: 0.17786564 | AL16: 0.17780115 | AM16: 0.17773666 | AN16: 0.17767218 | AO16: 0.17760769 | AP16: 0.1775432 | AQ16: 0.17747871 | AR16: 0.17741423 | AS16: 0.17734974 | AT16: 0.17728525 | AU16: 0.17722076 | AV16: 0.17715628 | AW16: 0.17709179
A17: linear trajectory | T17: 0.086322221 | U17: 0.087571524 | V17: 0.088820827 | W17: 0.090070129 | X17: 0.091319432 | Y17: 0.092568735 | Z17: 0.093818038 | AA17: 0.095067341 | AB17: 0.096316643 | AC17: 0.097565946 | AD17: 0.09740679 | AE17: 0.097247634 | AF17: 0.097088478 | AG17: 0.096929322 | AH17: 0.096770166 | AI17: 0.09661101 | AJ17: 0.096451855 | AK17: 0.096292699 | AL17: 0.096133543 | AM17: 0.095974387 | AN17: 0.095815231 | AO17: 0.095656075 | AP17: 0.095496919 | AQ17: 0.095337763 | AR17: 0.095178607 | AS17: 0.095019451 | AT17: 0.094860295 | AU17: 0.094701139 | AV17: 0.094541983 | AW17: 0.094382827
T18: 0.037548982 | U18: 0.046601154 | V18: 0.055653326 | W18: 0.064705498 | X18: 0.07375767 | Y18: 0.082809842 | Z18: 0.091862015 | AA18: 0.10091419 | AB18: 0.10996636 | AC18: 0.11901853 | AD18: 0.12705854 | AE18: 0.13509856 | AF18: 0.14313857 | AG18: 0.15117858 | AH18: 0.1592186 | AI18: 0.16725861 | AJ18: 0.17529862 | AK18: 0.18333863 | AL18: 0.19137865 | AM18: 0.19941866 | AN18: 0.20745867 | AO18: 0.21549869 | AP18: 0.2235387 | AQ18: 0.23157871 | AR18: 0.23961873 | AS18: 0.24765874 | AT18: 0.25569875 | AU18: 0.26373876 | AV18: 0.27177878 | AW18: 0.27981879
E28: Indicator B5a
D30: 2017-2021 | E30: 2022-2030 | F30: 2031-2050
A31: Fossils | D31: =(T4-P4)/4 -> -0.0057742577 | E31: =(AC9-T4)/9 -> -0.024183696 | F31: =AD14-AC14 -> -0.011331639
A32: Electricity | D32: =(T5-P5)/4 -> 0.00085840462 | E32: =(AC10-T5)/9 -> 0.01348968 | F32: =AE15-AD15 -> 0.003515269
A33: non-bio renewables | D33: =(T8-P8)/4 -> 0.0028784964 | E33: =(AC13-T8)/9 -> 0.0090521721 | F33: =AE18-AD18 -> 0.008040013
A36: Historic
D37: 2005 | I37: 2010 | N37: 2015 | S37: 2020 | X37: 2025 | AC37: 2030 | AH37: 2035 | AM37: 2040 | AR37: 2045 | AW37: 2050
A38: Total | B38: calculated | C38: ktoe | D38: =SUM(D39:D45) -> 266316.41 | E38: =SUM(E39:E45) -> 265392.05 | F38: =SUM(F39:F45) -> 249232.85 | G38: =SUM(G39:G45) -> 264260.89 | H38: =SUM(H39:H45) -> 262381.2 | I38: =SUM(I39:I45) -> 278929.48 | J38: =SUM(J39:J45) -> 251894.43 | K38: =SUM(K39:K45) -> 263012.15 | ... T38: =SUM(T39:T45) -> 261812.69
A39: Other fossils (solids, …) | B39: Eurostat energy balance | C39: ktoe | D39: 9237.906 | E39: 10214.345 | F39: 9163.505 | G39: 9724.203 | H39: 9878.539 | I39: 11416.98 | J39: 9900.838 | K39: 10161.539 | L39: 9821.436 | M39: 8804.607 | N39: 8701.245 | O39: 9006.828 | P39: 8917.467 | Q39: 8344.016 | R39: 6776.026 | S39: 6925.547 | T39: 6630.588
A40: Liquid fossils | B40: Eurostat energy balance | C40: ktoe | D40: 52606.552 | E40: 50544.129 | F40: 39674.239 | G40: 45449.054 | H40: 41516.874 | I40: 41083.057 | J40: 36193.663 | K40: 35601.929 | L40: 35792.314 | M40: 31221.26 | N40: 32054.46 | O40: 30787.212 | P40: 30221.252 | Q40: 28508.875 | R40: 29071.42 | S40: 30460.023 | T40: 24998.342
A41: Natural gas | B41: Eurostat energy balance | C41: ktoe | D41: 88923.519 | E41: 87134.815 | F41: 80121.407 | G41: 83938.626 | H41: 84730.833 | I41: 92180.353 | J41: 80771.228 | K41: 85062.74 | L41: 86508.378 | M41: 70920.886 | N41: 76833.896 | O41: 81737.671 | P41: 81410.204 | Q41: 80473.873 | R41: 79623.462 | S41: 78599.934 | T41: 87709.745
A42: Electricity | B42: Eurostat energy balance | C42: ktoe | D42: 57535.929 | E42: 58934.424 | F42: 58535.992 | G42: 59852.566 | H42: 60152.637 | I42: 62776.295 | J42: 60526.228 | K42: 61813.091 | L42: 61544.727 | M42: 58618.234 | N42: 59488.019 | O42: 60514.434 | P42: 60921.992 | Q42: 60699.591 | R42: 60522.618 | S42: 61271.582 | T42: 64265.362
A43: District heating | B43: Eurostat energy balance | C43: ktoe | D43: 22254.138 | E43: 21313.442 | F43: 21659.582 | G43: 21413.184 | H43: 21360.257 | I43: 23677.195 | J43: 21267.579 | K43: 21519.539 | L43: 22623.038 | M43: 20186.481 | N43: 21084.388 | O43: 22096.583 | P43: 22151.031 | Q43: 21103.143 | R43: 20857.857 | S43: 20414.4 | T43: 22600.253
A44: Renewables - bio | B44: Eurostat energy balance | C44: ktoe | D44: 34654.515 | E44: 35862.283 | F44: 38347.466 | G44: 41687.748 | H44: 42011.506 | I44: 44508.723 | J44: 39968.785 | K44: 45132.963 | L44: 45665.025 | M44: 40391.964 | N44: 41850.106 | O44: 41199.444 | P44: 41537.78 | Q44: 43508.32 | R44: 43573.318 | S44: 42105.459 | T44: 45777.601
A45: Renewables - other | B45: Eurostat energy balance | C45: ktoe | D45: 1103.851 | E45: 1388.608 | F45: 1730.66 | G45: 2195.509 | H45: 2730.558 | I45: 3286.879 | J45: 3266.111 | K45: 3720.348 | L45: 4136.387 | M45: 4493.715 | N45: 5015.878 | O45: 5534.556 | P45: 6553.349 | Q45: 7109.3 | R45: 7764.447 | S45: 8350.866 | T45: 9830.8
A47: CTP MIX scenario
D48: 2005 | I48: 2010 | N48: 2015 | S48: 2020 | X48: 2025 | AC48: 2030 | AH48: 2035 | AM48: 2040 | AR48: 2045 | AW48: 2050
A49: Total | B49: calculated | C49: ktoe | N49: =SUM(N50:N58) -> 243.85928 | AC49: =SUM(AC50:AC58) -> 202.03037 | AW49: =SUM(AW50:AW58) -> 176.53296
A50: Coal | B50: CTP IA part 2 figure 55 | C50: ktoe | N50: 8.451166 | AC50: 0.24901519 | AW50: 0
A51: Oil | B51: CTP IA part 2 figure 55 | C51: ktoe | N51: 31.966492 | AC51: 5.8139191 | AW51: 0.048092689
A52: Natural gas | B52: CTP IA part 2 figure 55 | C52: ktoe | N52: 75.6943 | AC52: 42.053372 | AW52: 1.9875027
A53: e-gas | B53: CTP IA part 2 figure 55 | C53: ktoe | N53: 0 | AC53: 0 | AW53: 13.099554
...

Sheet B6. heat pumps
A1: Objectives
A2: Policy | B2: Source | C2: Indicator | D2: Unit | E2: Target year | F2: Objective
A3: RePowerEU | B3: SWD table 4 | C3: total installed in residential and services | D3: million units | E3: 2030 | F3: 41.5
A4: RePowerEU | B4: Main doc, page 6 | C4: new heat pumps installed | D4: million units | E4: 2026 | F4: 10
A5: RePowerEU | B5: Main doc, page 6 | C5: new sales | E5: 2022-2026 | F5: doubling
A8: Historic
A9: Installed capacity (MW) - Eurostat NRG_INF_HPTC
B10: 2005 | C10: 2006 | D10: 2007 | E10: 2008 | F10: 2009 | G10: 2010 | H10: 2011 | I10: 2012 | J10: 2013 | K10: 2014 | L10: 2015 | M10: 2016 | N10: 2017 | O10: 2018 | P10: 2019 | Q10: 2020 | R10: 2021
A11: Aerothermal | B11: 4591.212 | C11: 8066.171 | D11: 12398.515 | E11: 17212.059 | F11: 21375.631 | G11: 25251.036 | H11: 31355.899 | I11: 35253.971 | J11: 39153.324 | K11: 65252.532 | L11: 72464.264 | M11: 80844.086 | N11: 222658.98 | O11: 230957.92 | P11: 240130.53 | Q11: 253191.47 | R11: 271288.16
A12: Geothermal | B12: 2142.698 | C12: 2748.21 | D12: 3335.942 | E12: 3984.466 | F12: 4703.918 | G12: 5216.176 | H12: 10884.037 | I12: 11511.273 | J12: 12163.824 | K12: 12400.536 | L12: 12739.292 | M12: 13948.033 | N12: 15220.606 | O12: 15890.008 | P12: 16251.334 | Q12: 17062.937 | R12: 17413.348
A13: Hydrothermal | B13: 384.66 | C13: 446.377 | D13: 510.388 | E13: 584.838 | F13: 669.706 | G13: 726.406 | H13: 780.412 | I13: 832.602 | J13: 884.749 | K13: 941.034 | L13: 986.743 | M13: 1028.033 | N13: 1164.782 | O13: 1198.604 | P13: 1228.296 | Q13: 1259.833 | R13: 1355.151
A14: Total | I14: =I11+I12+I13 -> 47597.846 | J14: =J11+J12+J13 -> 52201.897 | K14: =K11+K12+K13 -> 78594.102 | L14: =L11+L12+L13 -> 86190.299 | M14: =M11+M12+M13 -> 95820.152 | N14: =N11+N12+N13 -> 239044.37 | O14: =O11+O12+O13 -> 248046.53 | P14: =P11+P12+P13 -> 257610.16 | ... R14: =R11+R12+R13 -> 290056.66
A16: Number of installations (EHPA annual report) - in 1000 units
B17: 2005 | C17: 2006 | D17: 2007 | E17: 2008 | F17: 2009 | G17: 2010 | H17: 2011 | I17: 2012 | J17: 2013 | K17: 2014 | L17: 2015 | M17: 2016 | N17: 2017 | O17: 2018 | P17: 2019 | Q17: 2020 | R17: 2021 | S17: 2022
A18: Sales | B18: 446.037 | C18: 502.965 | D18: 572.84 | E18: 804.457 | F18: 731.482 | G18: 788.605 | H18: 802.66 | I18: 743.88 | J18: 757.142 | K18: 791.538 | L18: 892.809 | M18: 999.682 | N18: 1120 | O18: 1270 | P18: 1510 | Q18: 1600 | R18: 2160 | S18: 3000
A19: Total stock | B19: 1100 | C19: 1600 | D19: 2170 | E19: 2980 | F19: 3710 | G19: 4500 | H19: 5300 | I19: 6030 | J19: 6780 | K19: 7550 | L19: 8430 | M19: 9410 | N19: 10500 | O19: 11780 | P19: 13210 | Q19: 14770 | R19: 16870 | S19: 19790
A23: Historic vs. required
A24: New units
B25: 2005 | C25: 2006 | D25: 2007 | E25: 2008 | F25: 2009 | G25: 2010 | H25: 2011 | I25: 2012 | J25: 2013 | K25: 2014 | L25: 2015 | M25: 2016 | N25: 2017 | O25: 2018 | P25: 2019 | Q25: 2020 | R25: 2021 | S25: 2022 | T25: 2023 | U25: 2024 | V25: 2025 | W25: 2026 | X25: 2027 | Y25: 2028 | Z25: 2029 | AA25: 2030
B26: 2005 | G26: 2010 | L26: 2015 | Q26: 2020 | V26: 2025 | AA26: 2030
A27: Historic (in MW capacity) | C27: =(C11-B11)/1000 -> 3.474959 | D27: =(D11-C11)/1000 -> 4.332344 | E27: =(E11-D11)/1000 -> 4.813544 | F27: =(F11-E11)/1000 -> 4.163572 | G27: =(G11-F11)/1000 -> 3.875405 | H27: =(H11-G11)/1000 -> 6.104863 | I27: =(I11-H11)/1000 -> 3.898072 | J27: =(J11-I11)/1000 -> 3.899353 | ... R27: =(R11-Q11)/1000 -> 18.096687
A28: Historic | B28: =B18 -> 446.037 | C28: =C18 -> 502.965 | D28: =D18 -> 572.84 | E28: =E18 -> 804.457 | F28: =F18 -> 731.482 | G28: =G18 -> 788.605 | H28: =H18 -> 802.66 | I28: =I18 -> 743.88 | ... R28: =R18 -> 2160 | S28: 3000
A29: Average required | S29: 2000 | T29: 2000 | U29: 2000 | V29: 2000 | W29: 2000 | X29: =Y29 -> 3657.5 | Y29: =Z29 -> 3657.5 | Z29: =AA29 -> 3657.5 | AA29: =(AA36-W36)/4*1000 -> 3657.5
A30: Average 2018-2022 | O30: =AVERAGE(O28:S28) -> 1908 | P30: =O30 -> 1908 | Q30: =P30 -> 1908 | R30: =Q30 -> 1908 | S30: =R30 -> 1908 | T30: =S30 -> 1908 | U30: =T30 -> 1908 | V30: =U30 -> 1908 | W30: =V30 -> 1908 | ... AA30: =Z30 -> 1908
A31: 2018-2022 extrapolated | O31: {=TREND($O$28:$S$28,$O$25:$S$25,O$25)} -> 1086 | P31: {=TREND($O$28:$S$28,$O$25:$S$25,P$25)} -> 1497 | Q31: {=TREND($O$28:$S$28,$O$25:$S$25,Q$25)} -> 1908 | R31: {=TREND($O$28:$S$28,$O$25:$S$25,R$25)} -> 2319 | S31: {=TREND($O$28:$S$28,$O$25:$S$25,S$25)} -> 2730 | T31: {=TREND($O$28:$S$28,$O$25:$S$25,T$25)} -> 3141 | U31: {=TREND($O$28:$S$28,$O$25:$S$25,U$25)} -> 3552 | V31: {=TREND($O$28:$S$28,$O$25:$S$25,V$25)} -> 3963 | ... AA31: {=TREND($O$28:$S$28,$O$25:$S$25,AA$25)} -> 6018
A33: Total stock - in million
B34: 2005 | G34: 2010 | L34: 2015 | Q34: 2020 | V34: 2025 | AA34: 2030
A35: Historic | B35: =B19/1000 -> 1.1 | C35: =C19/1000 -> 1.6 | D35: =D19/1000 -> 2.17 | E35: =E19/1000 -> 2.98 | F35: =F19/1000 -> 3.71 | G35: =G19/1000 -> 4.5 | H35: =H19/1000 -> 5.3 | I35: =I19/1000 -> 6.03 | ... S35: =S19/1000 -> 19.79
A36: RePowerEU objectives | W36: =R35+10 -> 26.87 | AA36: 41.5
T37: =($W36-$S35)/4 -> 1.77 | U37: =($W36-$S35)/4 -> 1.77 | V37: =($W36-$S35)/4 -> 1.77 | X37: =($AA36-$W36)/4 -> 3.6575 | Y37: =($AA36-$W36)/4 -> 3.6575 | Z37: =($AA36-$W36)/4 -> 3.6575
T38: =$S35 -> 19.79 | U38: =T38+T37 -> 21.56 | V38: =U38+U37 -> 23.33 | X38: =$W36 -> 26.87 | Y38: =X38+X37 -> 30.5275 | Z38: =Y38+Y37 -> 34.185
A39: Extrapolation (2018-2022) | O39: {=TREND($O35:$S35,$O25:$S25,O25)} -> 11.348 | P39: {=TREND($O35:$S35,$O25:$S25,P25)} -> 13.316 | Q39: {=TREND($O35:$S35,$O25:$S25,Q25)} -> 15.284 | R39: {=TREND($O35:$S35,$O25:$S25,R25)} -> 17.252 | S39: {=TREND($O35:$S35,$O25:$S25,S25)} -> 19.22 | T39: {=TREND($O35:$S35,$O25:$S25,T25)} -> 21.188 | U39: {=TREND($O35:$S35,$O25:$S25,U25)} -> 23.156 | V39: {=TREND($O35:$S35,$O25:$S25,V25)} -> 25.124 | ... AA39: {=TREND($O35:$S35,$O25:$S25,AA25)} -> 34.964
A41: Historic vs. Required in million units
B42: =B26 -> 2005 | G42: =G26 -> 2010 | L42: =L26 -> 2015 | Q42: =Q26 -> 2020 | V42: =V26 -> 2025 | AA42: =AA26 -> 2030
A43: =A28 -> Historic | B43: =B28/1000 -> 0.446037 | C43: =C28/1000 -> 0.502965 | D43: =D28/1000 -> 0.57284 | E43: =E28/1000 -> 0.804457 | F43: =F28/1000 -> 0.731482 | G43: =G28/1000 -> 0.788605 | H43: =H28/1000 -> 0.80266 | I43: =I28/1000 -> 0.74388 | ... S43: =S28/1000 -> 3
A44: =A29 -> Average required | S44: =S29/1000 -> 2 | T44: =T29/1000 -> 2 | U44: =U29/1000 -> 2 | V44: =V29/1000 -> 2 | W44: =W29/1000 -> 2 | X44: =X29/1000 -> 3.6575 | Y44: =Y29/1000 -> 3.6575 | Z44: =Z29/1000 -> 3.6575 | AA44: =AA29/1000 -> 3.6575
A45: =A30 -> Average 2018-2022 | O45: =O30/1000 -> 1.908 | P45: =P30/1000 -> 1.908 | Q45: =Q30/1000 -> 1.908 | R45: =R30/1000 -> 1.908 | S45: =S30/1000 -> 1.908 | T45: =T30/1000 -> 1.908 | U45: =U30/1000 -> 1.908 | V45: =V30/1000 -> 1.908 | ... AA45: =AA30/1000 -> 1.908
A46: =A31 -> 2018-2022 extrapolated | O46: =O31/1000 -> 1.086 | P46: =P31/1000 -> 1.497 | Q46: =Q31/1000 -> 1.908 | R46: =R31/1000 -> 2.319 | S46: =S31/1000 -> 2.73 | T46: =T31/1000 -> 3.141 | U46: =U31/1000 -> 3.552 | V46: =V31/1000 -> 3.963 | ... AA46: =AA31/1000 -> 6.018
H47: Indicator B6
A67: Data for summary sheet at end of chapter
...

Sheet 4 energy drivers
A1: Selected energy use drivers from Odyssee-MURE database
A2: Database
A4: Item code | B4: ISO code | C4: Unit | D4: Title | E4: 2005 | F4: 2006 | G4: 2007 | H4: 2008 | I4: 2009 | J4: 2010 | K4: 2011 | L4: 2012 | M4: 2013 | N4: 2014 | O4: 2015 | P4: 2016 | Q4: 2017 | R4: 2018 | S4: 2019 | T4: 2020 | U4: 2021 | V4: Source | W4: Note | X4: Title
A5: toccfres | B5: EU | C5: Mtoe | D5: Final energy consumption (residential) | E5: 265.5653 | F5: 264.434 | G5: 248.0293 | H5: 262.606 | I5: 260.4893 | J5: 276.6985 | K5: 249.6825 | L5: 260.5072 | M5: 263.3369 | N5: 231.5988 | O5: 241.6133 | P5: 246.9204 | Q5: 246.7888 | R5: 243.4303 | S5: 241.4174 | T5: 241.3124 | U5: 251.8612 | V5: Enerdata | X5: Final consumption of residential sector
A6: toccfrescc | B6: EU | C6: Mtoe | D6: Climate-corrected final energy consumption (residential) | E6: 259.1989 | F6: 263.5838 | G6: 251.3424 | H6: 263.8712 | I6: 258.4492 | J6: 258.605 | K6: 253.6195 | L6: 253.5566 | M6: 259.4168 | N6: 241.0241 | O6: 247.9985 | P6: 248.1726 | Q6: 247.5761 | R6: 248.1999 | S6: 247.3486 | T6: 253.1593 | V6: NRD,Eurostat,ODYSSEE | X6: Final consumption of residential with climatic corrections
A7: surlog | B7: EU | C7: m2 | D7: Floor area of dwellings (y-on-y) | E7: 86.2299 | F7: 86.5794 | G7: 86.8448 | H7: 87.109 | I7: 87.4056 | J7: 88.8736 | K7: 89.3852 | L7: 89.4824 | M7: 89.6782 | N7: 89.8 | O7: 89.9573 | P7: 90.0468 | Q7: 90.0635 | R7: 90.0315 | S7: 90.0086 | T7: 90.0504 | V7: ODYSSEE | X7: Floor area of dwellings (y-on-y)
D8: Final energy consumption per m2 (residential) | E8: =E5/E7 -> 3.0797357 | F8: =F5/F7 -> 3.0542369 | G8: =G5/G7 -> 2.8560063 | H8: =H5/H7 -> 3.0146828 | I8: =I5/I7 -> 2.9802358 | J8: =J5/J7 -> 3.1133936 | K8: =K5/K7 -> 2.7933316 | L8: =L5/L7 -> 2.9112675 | ... T8: =T5/T7 -> 2.6797482
A9: Source: Odyssee
A11: Date of export: 2023-08-09
A13: Database
A15: Item code | B15: ISO code | C15: Unit | D15: Title | E15: 2005 | F15: 2006 | G15: 2007 | H15: 2008 | I15: 2009 | J15: 2010 | K15: 2011 | L15: 2012 | M15: 2013 | N15: 2014 | O15: 2015 | P15: 2016 | Q15: 2017 | R15: 2018 | S15: 2019 | T15: 2020 | U15: 2021 | V15: Source | W15: Note | X15: Title
A16: toccfter | B16: EU | C16: Mtoe | D16: Final energy consumption (services) | E16: 127.1124 | F16: 131.9009 | G16: 125.0547 | H16: 132.9022 | I16: 132.8969 | J16: 138.9805 | K16: 127.1161 | L16: 130.0307 | M16: 131.4993 | N16: 121.8207 | O16: 126.8507 | P16: 128.2464 | Q16: 128.9799 | R16: 126.1911 | S16: 123.1301 | T16: 115.8597 | U16: n.a. | V16: Enerdata,Eurostat | X16: Final consumption of services
A17: toccftercc | B17: EU | C17: Mtoe | D17: Climate-corrected final energy consumption (services) | E17: 125.3991 | F17: 131.6647 | G17: 125.9433 | H17: 133.2467 | I17: 132.346 | J17: 134.0191 | K17: 128.1193 | L17: 128.2557 | M17: 130.5027 | N17: 124.182 | O17: 128.4402 | P17: 128.5563 | Q17: 129.1742 | R17: 127.3219 | S17: 124.4967 | T17: 118.4395 | U17: n.a. | V17: NRD,Eurostat,ODYSSEE | X17: Total consumption of services (with climatic corrections)
A18: surter | B18: EU | C18: Mm2 | D18: Floor area of services | E18: 5135.1724 | F18: 5116.8641 | G18: 5199.1748 | H18: 5333.1853 | I18: 5376.2595 | J18: 5422.6545 | K18: 5441.9626 | L18: 5501.9421 | M18: 5573.4893 | N18: 5618.2498 | O18: 5657.6099 | P18: 5717.2377 | Q18: 5707.3284 | R18: 5753.2097 | S18: 5749.7369 | T18: 5274.0533 | U18: n.a. | V18: ODYSSEE | X18: Floor area of services
A20: Source: Odyssee
A22: Date of export: 2023-08-09
A24: Dataset: | B24: Population change - Demographic balance and crude rates at national level [DEMO_GIND__custom_7123476]
A25: Last updated: | B25: 13/07/2023 23:00
A27: Time frequency | C27: Annual
A28: Demographic indicator | C28: y-on-y population - total
A30: TIME | E30: 2005 | F30: 2006 | G30: 2007 | H30: 2008 | I30: 2009 | J30: 2010 | K30: 2011 | L30: 2012 | M30: 2013 | N30: 2014 | O30: 2015 | P30: 2016 | Q30: 2017 | R30: 2018 | S30: 2019 | T30: 2020 | U30: 2021 | V30: 2022
A31: GEO (Labels)
A32: European Union - 27 countries (from 2020) | E32: 435116254 | F32: 436521866 | G32: 437984240 | H32: 439386639 | I32: 440426387 | J32: 441041446 | K32: 440260386 | L32: 440905186 | M32: 441958943 | N32: 443274551 | O32: 444234821 | P32: 445167186 | Q32: 445871494 | R32: 446655355 | S32: 447022255 | T32: 447346360 | U32: 446904604 | V32: 447033117
A34: Dataset: | B34: y-on-y household size - EU-SILC survey [ILC_LVPH01__custom_7123881]
A35: Last updated: | B35: 11/07/2023 23:00
A37: Time frequency | C37: Annual
A38: Unit of measure | C38: y-on-y
A40: TIME | E40: 2005 | F40: 2006 | G40: 2007 | H40: 2008 | I40: 2009 | J40: 2010 | K40: 2011 | L40: 2012 | M40: 2013 | N40: 2014 | O40: 2015 | P40: 2016 | Q40: 2017 | R40: 2018 | S40: 2019 | T40: 2020 | U40: 2021 | V40: 2022
A41: GEO (Labels)
A42: European Union - 27 countries (from 2020) | J42: 2.4 | K42: 2.4 | L42: 2.4 | M42: 2.4 | N42: 2.3 | O42: 2.3 | P42: 2.3 | Q42: 2.3 | R42: 2.3 | S42: 2.3 | T42: 2.3 | U42: 2.3 | V42: 2.3
A44: Database
A46: Item code | B46: ISO code | C46: Unit | D46: =X46 -> Title | E46: 2005 | J46: 2010 | O46: 2015 | T46: 2020 | U46: 2021 | V46: Source | W46: Note | X46: Title
A47: toccftercc | B47: EU | C47: Mtoe | D47: =X47 -> Total consumption of services (with climatic corrections) | E47: 125.3991 | F47: 131.6647 | G47: 125.9433 | H47: 133.2467 | I47: 132.346 | J47: 134.0191 | K47: 128.1193 | L47: 128.2557 | M47: 130.5027 | N47: 124.182 | O47: 128.4402 | P47: 128.5563 | Q47: 129.1742 | R47: 127.3219 | S47: 124.4967 | T47: 118.4395 | U47: n.a. | V47: NRD,Eurostat,ODYSSEE | X47: Total consumption of services (with climatic corrections)
A48: surter | B48: EU | C48: Mm2 | D48: =X48 -> Floor area of services | E48: 5135.1724 | F48: 5116.8641 | G48: 5199.1748 | H48: 5333.1853 | I48: 5376.2595 | J48: 5422.6545 | K48: 5441.9626 | L48: 5501.9421 | M48: 5573.4893 | N48: 5618.2498 | O48: 5657.6099 | P48: 5717.2377 | Q48: 5707.3284 | R48: 5753.2097 | S48: 5749.7369 | T48: 5274.0533 | U48: n.a. | V48: ODYSSEE | X48: Floor area of services
C49: toe/m^2 | D49: final energy consumption per square metre - climate corrected (services) | E49: =E47/E48*1000 -> 24.419648 | F49: =F47/F48*1000 -> 25.731522 | G49: =G47/G48*1000 -> 24.22371 | H49: =H47/H48*1000 -> 24.98445 | I49: =I47/I48*1000 -> 24.616743 | J49: =J47/J48*1000 -> 24.714667 | K49: =K47/K48*1000 -> 23.542848 | L49: =L47/L48*1000 -> 23.310987 | ... T49: =T47/T48*1000 -> 22.457016
A50: cutocsurcc | B50: EU | C50: toe/m2 | D50: final energy consumption per square metre - climate corrected (residential) | E50: 17.6111 | F50: 17.6308 | G50: 16.6182 | H50: 17.2254 | I50: 16.6607 | J50: 16.1912 | K50: 15.7581 | L50: 15.6005 | M50: 15.8408 | N50: 14.6191 | O50: 14.9385 | P50: 14.8326 | Q50: 14.7134 | R50: 14.668 | S50: 14.5196 | T50: 14.7585 | U50: n.a. | V50: NRD,Eurostat,ODYSSEE | X50: Unit consumption per m2 with climatic corrections
C51: TWh | D51: =D47 -> Total consumption of services (with climatic corrections) | E51: =E47*Mtoe2TWh -> 1458.3915 | F51: =F47*Mtoe2TWh -> 1531.2605 | G51: =G47*Mtoe2TWh -> 1464.7206 | H51: =H47*Mtoe2TWh -> 1549.6591 | I51: =I47*Mtoe2TWh -> 1539.184 | J51: =J47*Mtoe2TWh -> 1558.6421 | K51: =K47*Mtoe2TWh -> 1490.0275 | L51: =L47*Mtoe2TWh -> 1491.6138 | ... T51: =T47*Mtoe2TWh -> 1377.4514
C52: kWh/m^2 | D52: final energy consumption per square metre - climate corrected (services) | E52: =(E51*1000000000)/(E48*1000000) -> 284.0005 | F52: =(F51*1000000000)/(F48*1000000) -> 299.2576 | G52: =(G51*1000000000)/(G48*1000000) -> 281.72174 | H52: =(H51*1000000000)/(H48*1000000) -> 290.56915 | I52: =(I51*1000000000)/(I48*1000000) -> 286.29272 | J52: =(J51*1000000000)/(J48*1000000) -> 287.43158 | K52: =(K51*1000000000)/(K48*1000000) -> 273.80333 | L52: =(L51*1000000000)/(L48*1000000) -> 271.10678 | ... T52: =(T51*1000000000)/(T48*1000000) -> 261.1751
C53: kWh/m^2 | D53: final energy consumption per square metre - climate corrected (residential) | E53: =E50*1000*Mtoe2TWh/1000 -> 204.81709 | F53: =F50*1000*Mtoe2TWh/1000 -> 205.0462 | G53: =G50*1000*Mtoe2TWh/1000 -> 193.26967 | H53: =H50*1000*Mtoe2TWh/1000 -> 200.3314 | I53: =I50*1000*Mtoe2TWh/1000 -> 193.76394 | J53: =J50*1000*Mtoe2TWh/1000 -> 188.30366 | K53: =K50*1000*Mtoe2TWh/1000 -> 183.2667 | L53: =L50*1000*Mtoe2TWh/1000 -> 181.43381 | ... T53: =T50*1000*Mtoe2TWh/1000 -> 171.64135
D55: y-on-y change services | F55: =F49/E49-1 -> 0.05372208 | G55: =G49/F49-1 -> -0.058597866 | H55: =H49/G49-1 -> 0.031404778 | I55: =I49/H49-1 -> -0.014717412 | J55: =J49/I49-1 -> 0.0039779293 | K55: =K49/J49-1 -> -0.047413896 | L55: =L49/K49-1 -> -0.0098484876 | M55: =M49/L49-1 -> 0.0044577309 | ... T55: =T49/S49-1 -> 0.037151461
...

Sheet 5 heating & cooling
A1: Selected energy use drivers from Odyssee-MURE database - Household sector
A2: Database
A4: Item code | B4: ISO code | C4: Unit | D4: =X4 -> Title | E4: 2005 | F4: 2006 | G4: 2007 | H4: 2008 | I4: 2009 | J4: 2010 | K4: 2011 | L4: 2012 | M4: 2013 | N4: 2014 | O4: 2015 | P4: 2016 | Q4: 2017 | R4: 2018 | S4: 2019 | T4: 2020 | U4: 2021 | V4: Source | W4: Note | X4: Title
A5: dj | B5: EU | C5: degree | D5: =X5 -> Heating degree-days | E5: 3209.72 | F5: 3084.51 | G5: 2985.9 | H5: 3036.39 | I5: 3113.25 | J5: 3497.41 | K5: 2968.15 | L5: 3237.86 | M5: 3160.09 | N5: 2815.53 | O5: 2901.23 | P5: 3033.05 | Q5: 3044.85 | R5: 2940.9 | S5: 2909.29 | T5: 2758.95 | U5: n.a. | V5: Eurostat | X5: Heating degree-days
A6: djcli | B6: EU | C6: degree | D6: =X6 -> Cooling degree-days | E6: 71.74 | F6: 96.17 | G6: 78.06 | H6: 73.5 | I6: 82.81 | J6: 96.73 | K6: 76.89 | L6: 114.81 | M6: 85.09 | N6: 58.96 | O6: 121.61 | P6: 93.49 | Q6: 111.79 | R6: 97.85 | S6: 110.54 | T6: 98.53 | U6: n.a. | V6: Eurostat | X6: Cooling degree-days
A7: toccfreschf | B7: EU | C7: Mtoe | D7: Space heating | E7: 181.9487 | F7: 178.834 | G7: 163.1496 | H7: 174.7494 | I7: 173.65 | J7: 187.1762 | K7: 160.5434 | L7: 170.4486 | M7: 175.3488 | N7: 147.2127 | O7: 156.6705 | P7: 160.615 | Q7: 159.2946 | R7: 155.7637 | S7: 153.8618 | T7: 152.177 | U7: n.a. | V7: ODYSSEE | X7: Final consumption of residential for space heating
A8: toccfreschc | B8: EU | C8: Mtoe | D8: Space heating (climate corrected) | E8: 174.55 | F8: 177.8336 | G8: 167.0463 | H8: 176.2481 | I8: 171.2417 | J8: 166.1051 | K8: 165.2597 | L8: 162.2317 | M8: 170.6033 | N8: 158.8653 | O8: 164.6022 | P8: 162.1529 | Q8: 160.2592 | R8: 161.6711 | S8: 161.2503 | T8: n.a. | U8: n.a. | V8: Eurostat,ODYSSEE | X8: Final consumption of residential for space heating with climatic corrections
A9: elccfrescli | B9: EU | C9: Mtoe | D9: Cooling (electricity) | E9: 0.461 | F9: 0.4967 | G9: 0.53 | H9: 0.5932 | I9: 0.6171 | J9: 0.6821 | K9: 0.7089 | L9: 0.7278 | M9: 0.7238 | N9: 0.697 | O9: 0.7444 | P9: 0.7648 | Q9: 0.8735 | R9: 0.8848 | S9: 0.9582 | T9: 1.0215 | U9: n.a. | V9: ODYSSEE | X9: Final consumption of residential for air cooling
C10: % vs 2005 | D10: =D5 -> Heating degree-days | E10: =E5/$E5 -> 1 | F10: =F5/$E5 -> 0.96099037 | G10: =G5/$E5 -> 0.93026806 | H10: =H5/$E5 -> 0.9459984 | I10: =I5/$E5 -> 0.96994442 | J10: =J5/$E5 -> 1.0896309 | K10: =K5/$E5 -> 0.92473798 | L10: =L5/$E5 -> 1.0087671 | ... T10: =T5/$E5 -> 0.85956096
C11: % vs 2005 | D11: =D6 -> Cooling degree-days | E11: =E6/$E6 -> 1 | F11: =F6/$E6 -> 1.3405353 | G11: =G6/$E6 -> 1.0880959 | H11: =H6/$E6 -> 1.024533 | I11: =I6/$E6 -> 1.1543072 | J11: =J6/$E6 -> 1.3483412 | K11: =K6/$E6 -> 1.071787 | L11: =L6/$E6 -> 1.6003624 | ... T11: =T6/$E6 -> 1.3734318
C12: % vs 2005 | D12: =D7 -> Space heating | E12: =E7/$E7 -> 1 | F12: =F7/$E7 -> 0.98288144 | G12: =G7/$E7 -> 0.89667912 | H12: =H7/$E7 -> 0.96043225 | I12: =I7/$E7 -> 0.95438989 | J12: =J7/$E7 -> 1.0287306 | K12: =K7/$E7 -> 0.8823553 | L12: =L7/$E7 -> 0.93679482 | ... T12: =T7/$E7 -> 0.83637311
C13: % vs 2005 | D13: =D8 -> Space heating (climate corrected) | E13: =E8/$E8 -> 1 | F13: =F8/$E8 -> 1.0188118 | G13: =G8/$E8 -> 0.95701117 | H13: =H8/$E8 -> 1.0097284 | I13: =I8/$E8 -> 0.98104669 | J13: =J8/$E8 -> 0.95161902 | K13: =K8/$E8 -> 0.94677571 | L13: =L8/$E8 -> 0.92942824 | ... S13: =S8/$E8 -> 0.92380579
C14: % vs 2005 | D14: =D9 -> Cooling (electricity) | E14: =E9/$E9 -> 1 | F14: =F9/$E9 -> 1.0774403 | G14: =G9/$E9 -> 1.1496746 | H14: =H9/$E9 -> 1.2867679 | I14: =I9/$E9 -> 1.3386117 | J14: =J9/$E9 -> 1.4796095 | K14: =K9/$E9 -> 1.537744 | L14: =L9/$E9 -> 1.5787419 | ... T14: =T9/$E9 -> 2.2158351
D16: % change heating vs 2005 | E16: =E7/$E7-1 -> 0 | F16: =F7/$E7-1 -> -0.017118561 | G16: =G7/$E7-1 -> -0.10332088 | H16: =H7/$E7-1 -> -0.039567746 | I16: =I7/$E7-1 -> -0.045610109 | J16: =J7/$E7-1 -> 0.028730626 | K16: =K7/$E7-1 -> -0.1176447 | L16: =L7/$E7-1 -> -0.063205178 | ... T16: =T7/$E7-1 -> -0.16362689
D17: % change heating climate corrected vs 2005 | E17: =E8/$E8-1 -> 0 | F17: =F8/$E8-1 -> 0.018811802 | G17: =G8/$E8-1 -> -0.042988828 | H17: =H8/$E8-1 -> 0.0097284446 | I17: =I8/$E8-1 -> -0.018953309 | J17: =J8/$E8-1 -> -0.04838098 | K17: =K8/$E8-1 -> -0.053224291 | L17: =L8/$E8-1 -> -0.070571756 | ... T17: =T8/$E8-1 -> #VALUE!
D18: % change cooling vs 2005 | E18: =E9/$E9-1 -> 0 | F18: =F9/$E9-1 -> 0.077440347 | G18: =G9/$E9-1 -> 0.14967462 | H18: =H9/$E9-1 -> 0.2867679 | I18: =I9/$E9-1 -> 0.33861171 | J18: =J9/$E9-1 -> 0.47960954 | K18: =K9/$E9-1 -> 0.53774403 | L18: =L9/$E9-1 -> 0.57874187 | ... T18: =T9/$E9-1 -> 1.2158351

Sheet Energy balances (for buildings)
A1: Historical data (Eurostat energy balances - in ktoe)
A2: Total
B3: 2005 | C3: 2006 | D3: 2007 | E3: 2008 | F3: 2009 | G3: 2010 | H3: 2011 | I3: 2012 | J3: 2013 | K3: 2014 | L3: 2015 | M3: 2016 | N3: 2017 | O3: 2018 | P3: 2019 | Q3: 2020 | R3: 2021
A4: Total | B4: 429954.06 | C4: 433151.92 | D4: 405203.87 | E4: 427667.38 | F4: 425367.18 | G4: 449365.86 | H4: 410547.35 | I4: 424272.36 | J4: 429187.03 | K4: 387911.75 | L4: 403008.24 | M4: 410734.67 | N4: 415601.84 | O4: 413774.01 | P4: 409552.34 | Q4: 402744.44 | R4: 424787.16 | U4: =(R4-B4)/1000 -> -5.166895
