Workbook

Sheet Colour palette
S1: 2020 | T1: 2021 | U1: 2022 | V1: 2023 | W1: 2024 | X1: 2025 | Y1: 2026 | Z1: 2027 | AA1: 2028 | AB1: 2029 | AC1: 2030 | AD1: 2031 | AE1: 2032 | AF1: 2033 | AG1: 2034 | AH1: 2035 | AI1: 2036 | AJ1: 2037 | AK1: 2038 | AL1: 2039 | AM1: 2040 | AN1: 2041 | AO1: 2042 | AP1: 2043 | AQ1: 2044 | AR1: 2045 | AS1: 2046 | AT1: 2047 | AU1: 2048 | AV1: 2049 | AW1: 2050
Q2: Demand-side Focus Pathway | R2: 1 | S2: 1 | T2: 0.98 | U2: 0.96 | V2: 0.94 | W2: 0.92 | X2: 0.9 | Y2: 0.88 | Z2: 0.86 | AA2: 0.85 | AB2: 0.83 | AC2: 0.81 | AD2: 0.79 | AE2: 0.77 | AF2: 0.75 | AG2: 0.73 | AH2: 0.71 | AI2: 0.69 | AJ2: 0.67 | AK2: 0.65 | AL2: 0.63 | AM2: 0.61 | AN2: 0.6 | AO2: 0.58 | AP2: 0.57 | AQ2: 0.56 | AR2: 0.54 | AS2: 0.53 | AT2: 0.52 | AU2: 0.51 | AV2: 0.5 | AW2: 0.49
Q3: High Renewable Energy Pathway | R3: 1 | S3: 1 | T3: 0.99 | U3: 0.99 | V3: 0.98 | W3: 0.97 | X3: 0.96 | Y3: 0.94 | Z3: 0.92 | AA3: 0.89 | AB3: 0.87 | AC3: 0.85 | AD3: 0.83 | AE3: 0.8 | AF3: 0.78 | AG3: 0.75 | AH3: 0.73 | AI3: 0.71 | AJ3: 0.69 | AK3: 0.67 | AL3: 0.64 | AM3: 0.62 | AN3: 0.61 | AO3: 0.6 | AP3: 0.59 | AQ3: 0.58 | AR3: 0.56 | AS3: 0.56 | AT3: 0.55 | AU3: 0.55 | AV3: 0.55 | AW3: 0.54
B4: Font and colours: | E4: Half page width: | Q4: Mixed Options Pathway | R4: 1 | S4: 1.01 | T4: 0.99 | U4: 0.98 | V4: 0.96 | W4: 0.95 | X4: 0.93 | Y4: 0.92 | Z4: 0.9 | AA4: 0.89 | AB4: 0.88 | AC4: 0.86 | AD4: 0.85 | AE4: 0.83 | AF4: 0.82 | AG4: 0.8 | AH4: 0.79 | AI4: 0.78 | AJ4: 0.77 | AK4: 0.77 | AL4: 0.76 | AM4: 0.76 | AN4: 0.76 | AO4: 0.76 | AP4: 0.76 | AQ4: 0.76 | AR4: 0.76 | AS4: 0.76 | AT4: 0.76 | AU4: 0.77 | AV4: 0.77 | AW4: 0.77
Q5: #REF! | R5: 1 | S5: 1 | T5: 0.99 | U5: 0.97 | V5: 0.95 | W5: 0.93 | X5: 0.91 | Y5: 0.9 | Z5: 0.88 | AA5: 0.86 | AB5: 0.84 | AC5: 0.83 | AD5: 0.81 | AE5: 0.79 | AF5: 0.77 | AG5: 0.76 | AH5: 0.74 | AI5: 0.73 | AJ5: 0.72 | AK5: 0.72 | AL5: 0.71 | AM5: 0.7 | AN5: 0.7 | AO5: 0.7 | AP5: 0.7 | AQ5: 0.7 | AR5: 0.7 | AS5: 0.7 | AT5: 0.71 | AU5: 0.71 | AV5: 0.71 | AW5: 0.71
A6: Font: | B6: Segoe UI, size 8 | Q6: #REF! | R6: 1 | S6: 1 | T6: 0.99 | U6: 0.97 | V6: 0.96 | W6: 0.95 | X6: 0.94 | Y6: 0.93 | Z6: 0.91 | AA6: 0.9 | AB6: 0.88 | AC6: 0.87 | AD6: 0.85 | AE6: 0.83 | AF6: 0.81 | AG6: 0.79 | AH6: 0.77 | AI6: 0.76 | AJ6: 0.74 | AK6: 0.72 | AL6: 0.71 | AM6: 0.69 | AN6: 0.69 | AO6: 0.68 | AP6: 0.68 | AQ6: 0.68 | AR6: 0.67 | AS6: 0.67 | AT6: 0.67 | AU6: 0.66 | AV6: 0.66 | AW6: 0.66
B7: Signature colour | Q7: #REF! | R7: 1 | S7: 1 | T7: 0.98 | U7: 0.96 | V7: 0.94 | W7: 0.92 | X7: 0.9 | Y7: 0.88 | Z7: 0.86 | AA7: 0.84 | AB7: 0.83 | AC7: 0.81 | AD7: 0.79 | AE7: 0.77 | AF7: 0.75 | AG7: 0.73 | AH7: 0.71 | AI7: 0.7 | AJ7: 0.7 | AK7: 0.69 | AL7: 0.68 | AM7: 0.68 | AN7: 0.68 | AO7: 0.69 | AP7: 0.69 | AQ7: 0.7 | AR7: 0.7 | AS7: 0.71 | AT7: 0.71 | AU7: 0.71 | AV7: 0.71 | AW7: 0.71
Q8: #REF! | R8: 1 | S8: 1 | T8: 0.99 | U8: 0.99 | V8: 0.98 | W8: 0.97 | X8: 0.96 | Y8: 0.94 | Z8: 0.92 | AA8: 0.89 | AB8: 0.87 | AC8: 0.85 | AD8: 0.83 | AE8: 0.8 | AF8: 0.78 | AG8: 0.76 | AH8: 0.73 | AI8: 0.71 | AJ8: 0.69 | AK8: 0.67 | AL8: 0.65 | AM8: 0.63 | AN8: 0.62 | AO8: 0.6 | AP8: 0.59 | AQ8: 0.58 | AR8: 0.57 | AS8: 0.56 | AT8: 0.56 | AU8: 0.55 | AV8: 0.55 | AW8: 0.54
A9: Gridlines: | B9: Signature colour | Q9: #REF! | R9: 1 | S9: 1 | T9: 0.99 | U9: 0.99 | V9: 0.98 | W9: 0.97 | X9: 0.96 | Y9: 0.94 | Z9: 0.92 | AA9: 0.89 | AB9: 0.87 | AC9: 0.85 | AD9: 0.83 | AE9: 0.8 | AF9: 0.78 | AG9: 0.76 | AH9: 0.73 | AI9: 0.71 | AJ9: 0.69 | AK9: 0.67 | AL9: 0.65 | AM9: 0.63 | AN9: 0.62 | AO9: 0.6 | AP9: 0.59 | AQ9: 0.58 | AR9: 0.57 | AS9: 0.56 | AT9: 0.56 | AU9: 0.55 | AV9: 0.55 | AW9: 0.54
B10: Transparency: 90% | Q10: #REF! | R10: 1 | S10: 1 | T10: 0.99 | U10: 0.99 | V10: 0.98 | W10: 0.97 | X10: 0.96 | Y10: 0.94 | Z10: 0.92 | AA10: 0.89 | AB10: 0.87 | AC10: 0.85 | AD10: 0.82 | AE10: 0.8 | AF10: 0.77 | AG10: 0.75 | AH10: 0.73 | AI10: 0.7 | AJ10: 0.68 | AK10: 0.66 | AL10: 0.64 | AM10: 0.61 | AN10: 0.6 | AO10: 0.59 | AP10: 0.58 | AQ10: 0.57 | AR10: 0.56 | AS10: 0.56 | AT10: 0.56 | AU10: 0.55 | AV10: 0.55 | AW10: 0.55
Q11: #REF! | R11: 1 | S11: 1 | T11: 0.99 | U11: 0.99 | V11: 0.98 | W11: 0.97 | X11: 0.96 | Y11: 0.94 | Z11: 0.92 | AA11: 0.89 | AB11: 0.87 | AC11: 0.85 | AD11: 0.82 | AE11: 0.8 | AF11: 0.77 | AG11: 0.75 | AH11: 0.73 | AI11: 0.7 | AJ11: 0.68 | AK11: 0.66 | AL11: 0.64 | AM11: 0.62 | AN11: 0.6 | AO11: 0.59 | AP11: 0.58 | AQ11: 0.57 | AR11: 0.56 | AS11: 0.56 | AT11: 0.56 | AU11: 0.55 | AV11: 0.55 | AW11: 0.55
A12: Lines: | B12: High width: 2.25 pt | Q12: #REF! | R12: #N/A | S12: #N/A | T12: #N/A | U12: #N/A | V12: #N/A | W12: #N/A | X12: #N/A | Y12: #N/A | Z12: #N/A | AA12: #N/A | AB12: #N/A | AC12: #N/A | AD12: #N/A | AE12: #N/A | AF12: #N/A | AG12: #N/A | AH12: #N/A | AI12: #N/A | AJ12: #N/A | AK12: #N/A | AL12: #N/A | AM12: #N/A | AN12: #N/A | AO12: #N/A | AP12: #N/A | AQ12: #N/A | AR12: #N/A | AS12: #N/A | AT12: #N/A | AU12: #N/A | AV12: #N/A | AW12: #N/A
B13: Low width: 0.25 pt | Q13: #REF! | R13: #N/A | S13: #N/A | T13: #N/A | U13: #N/A | V13: #N/A | W13: #N/A | X13: #N/A | Y13: #N/A | Z13: #N/A | AA13: #N/A | AB13: #N/A | AC13: #N/A | AD13: #N/A | AE13: #N/A | AF13: #N/A | AG13: #N/A | AH13: #N/A | AI13: #N/A | AJ13: #N/A | AK13: #N/A | AL13: #N/A | AM13: #N/A | AN13: #N/A | AO13: #N/A | AP13: #N/A | AQ13: #N/A | AR13: #N/A | AS13: #N/A | AT13: #N/A | AU13: #N/A | AV13: #N/A | AW13: #N/A
Q14: #REF! | R14: 1 | S14: 1 | T14: 0.99 | U14: 0.99 | V14: 0.98 | W14: 0.97 | X14: 0.96 | Y14: 0.94 | Z14: 0.92 | AA14: 0.89 | AB14: 0.87 | AC14: 0.85 | AD14: 0.82 | AE14: 0.8 | AF14: 0.78 | AG14: 0.75 | AH14: 0.73 | AI14: 0.71 | AJ14: 0.68 | AK14: 0.66 | AL14: 0.64 | AM14: 0.62 | AN14: 0.61 | AO14: 0.59 | AP14: 0.58 | AQ14: 0.57 | AR14: 0.56 | AS14: 0.56 | AT14: 0.55 | AU14: 0.55 | AV14: 0.55 | AW14: 0.54
A15: Colours: | B15: Primary colour palette | Q15: #REF! | R15: 1 | S15: 1 | T15: 0.99 | U15: 0.99 | V15: 0.98 | W15: 0.97 | X15: 0.96 | Y15: 0.94 | Z15: 0.92 | AA15: 0.89 | AB15: 0.87 | AC15: 0.85 | AD15: 0.82 | AE15: 0.79 | AF15: 0.77 | AG15: 0.74 | AH15: 0.71 | AI15: 0.69 | AJ15: 0.67 | AK15: 0.65 | AL15: 0.62 | AM15: 0.6 | AN15: 0.59 | AO15: 0.58 | AP15: 0.58 | AQ15: 0.57 | AR15: 0.56 | AS15: 0.56 | AT15: 0.55 | AU15: 0.55 | AV15: 0.55 | AW15: 0.55
Q16: #REF! | R16: 1 | S16: 1.01 | T16: 0.99 | U16: 0.98 | V16: 0.97 | W16: 0.95 | X16: 0.94 | Y16: 0.93 | Z16: 0.91 | AA16: 0.9 | AB16: 0.89 | AC16: 0.87 | AD16: 0.86 | AE16: 0.85 | AF16: 0.83 | AG16: 0.82 | AH16: 0.8 | AI16: 0.79 | AJ16: 0.78 | AK16: 0.77 | AL16: 0.76 | AM16: 0.75 | AN16: 0.75 | AO16: 0.75 | AP16: 0.75 | AQ16: 0.75 | AR16: 0.75 | AS16: 0.76 | AT16: 0.76 | AU16: 0.76 | AV16: 0.76 | AW16: 0.77
Q17: #REF! | R17: #N/A | S17: #N/A | T17: #N/A | U17: #N/A | V17: #N/A | W17: #N/A | X17: #N/A | Y17: #N/A | Z17: #N/A | AA17: #N/A | AB17: #N/A | AC17: #N/A | AD17: #N/A | AE17: #N/A | AF17: #N/A | AG17: #N/A | AH17: #N/A | AI17: #N/A | AJ17: #N/A | AK17: #N/A | AL17: #N/A | AM17: #N/A | AN17: #N/A | AO17: #N/A | AP17: #N/A | AQ17: #N/A | AR17: #N/A | AS17: #N/A | AT17: #N/A | AU17: #N/A | AV17: #N/A | AW17: #N/A
Q18: #REF! | R18: 1 | S18: 1 | T18: 0.99 | U18: 0.99 | V18: 0.98 | W18: 0.97 | X18: 0.96 | Y18: 0.94 | Z18: 0.92 | AA18: 0.89 | AB18: 0.87 | AC18: 0.85 | AD18: 0.82 | AE18: 0.8 | AF18: 0.77 | AG18: 0.75 | AH18: 0.72 | AI18: 0.7 | AJ18: 0.68 | AK18: 0.66 | AL18: 0.64 | AM18: 0.61 | AN18: 0.6 | AO18: 0.59 | AP18: 0.58 | AQ18: 0.57 | AR18: 0.56 | AS18: 0.56 | AT18: 0.55 | AU18: 0.55 | AV18: 0.55 | AW18: 0.54
B19: Primary colour palette | Q19: #REF! | R19: 1 | S19: 1 | T19: 0.99 | U19: 0.99 | V19: 0.98 | W19: 0.97 | X19: 0.96 | Y19: 0.94 | Z19: 0.92 | AA19: 0.89 | AB19: 0.87 | AC19: 0.85 | AD19: 0.82 | AE19: 0.8 | AF19: 0.77 | AG19: 0.75 | AH19: 0.72 | AI19: 0.7 | AJ19: 0.68 | AK19: 0.66 | AL19: 0.64 | AM19: 0.61 | AN19: 0.6 | AO19: 0.59 | AP19: 0.58 | AQ19: 0.57 | AR19: 0.56 | AS19: 0.56 | AT19: 0.56 | AU19: 0.55 | AV19: 0.55 | AW19: 0.54
Q20: #REF! | R20: #N/A | S20: #N/A | T20: #N/A | U20: #N/A | V20: #N/A | W20: #N/A | X20: #N/A | Y20: #N/A | Z20: #N/A | AA20: #N/A | AB20: #N/A | AC20: #N/A | AD20: #N/A | AE20: #N/A | AF20: #N/A | AG20: #N/A | AH20: #N/A | AI20: #N/A | AJ20: #N/A | AK20: #N/A | AL20: #N/A | AM20: #N/A | AN20: #N/A | AO20: #N/A | AP20: #N/A | AQ20: #N/A | AR20: #N/A | AS20: #N/A | AT20: #N/A | AU20: #N/A | AV20: #N/A | AW20: #N/A
B21: Primary colour palette | Q21: #REF! | R21: #N/A | S21: #N/A | T21: #N/A | U21: #N/A | V21: #N/A | W21: #N/A | X21: #N/A | Y21: #N/A | Z21: #N/A | AA21: #N/A | AB21: #N/A | AC21: #N/A | AD21: #N/A | AE21: #N/A | AF21: #N/A | AG21: #N/A | AH21: #N/A | AI21: #N/A | AJ21: #N/A | AK21: #N/A | AL21: #N/A | AM21: #N/A | AN21: #N/A | AO21: #N/A | AP21: #N/A | AQ21: #N/A | AR21: #N/A | AS21: #N/A | AT21: #N/A | AU21: #N/A | AV21: #N/A | AW21: #N/A
Q22: #REF! | R22: 1 | S22: 1 | T22: 0.99 | U22: 0.98 | V22: 0.98 | W22: 0.97 | X22: 0.96 | Y22: 0.94 | Z22: 0.92 | AA22: 0.89 | AB22: 0.87 | AC22: 0.85 | AD22: 0.82 | AE22: 0.8 | AF22: 0.77 | AG22: 0.75 | AH22: 0.73 | AI22: 0.7 | AJ22: 0.68 | AK22: 0.66 | AL22: 0.64 | AM22: 0.62 | AN22: 0.6 | AO22: 0.59 | AP22: 0.58 | AQ22: 0.57 | AR22: 0.56 | AS22: 0.56 | AT22: 0.55 | AU22: 0.55 | AV22: 0.54 | AW22: 0.54
Q23: #REF! | R23: 1 | S23: 1 | T23: 0.99 | U23: 0.99 | V23: 0.98 | W23: 0.97 | X23: 0.96 | Y23: 0.94 | Z23: 0.92 | AA23: 0.89 | AB23: 0.87 | AC23: 0.84 | AD23: 0.82 | AE23: 0.79 | AF23: 0.77 | AG23: 0.74 | AH23: 0.71 | AI23: 0.69 | AJ23: 0.67 | AK23: 0.65 | AL23: 0.63 | AM23: 0.6 | AN23: 0.6 | AO23: 0.59 | AP23: 0.58 | AQ23: 0.57 | AR23: 0.56 | AS23: 0.56 | AT23: 0.56 | AU23: 0.55 | AV23: 0.55 | AW23: 0.55
B24: Primary colour palette | Q24: #REF! | R24: #N/A | S24: #N/A | T24: #N/A | U24: #N/A | V24: #N/A | W24: #N/A | X24: #N/A | Y24: #N/A | Z24: #N/A | AA24: #N/A | AB24: #N/A | AC24: #N/A | AD24: #N/A | AE24: #N/A | AF24: #N/A | AG24: #N/A | AH24: #N/A | AI24: #N/A | AJ24: #N/A | AK24: #N/A | AL24: #N/A | AM24: #N/A | AN24: #N/A | AO24: #N/A | AP24: #N/A | AQ24: #N/A | AR24: #N/A | AS24: #N/A | AT24: #N/A | AU24: #N/A | AV24: #N/A | AW24: #N/A
Q25: #REF! | R25: 1 | S25: 1 | T25: 0.99 | U25: 0.99 | V25: 0.98 | W25: 0.97 | X25: 0.96 | Y25: 0.94 | Z25: 0.92 | AA25: 0.89 | AB25: 0.87 | AC25: 0.85 | AD25: 0.83 | AE25: 0.81 | AF25: 0.8 | AG25: 0.78 | AH25: 0.76 | AI25: 0.74 | AJ25: 0.72 | AK25: 0.7 | AL25: 0.68 | AM25: 0.66 | AN25: 0.65 | AO25: 0.64 | AP25: 0.63 | AQ25: 0.62 | AR25: 0.61 | AS25: 0.61 | AT25: 0.61 | AU25: 0.61 | AV25: 0.61 | AW25: 0.6
E26: Full page width: | Q26: #REF! | R26: 1 | S26: 1 | T26: 0.99 | U26: 0.99 | V26: 0.98 | W26: 0.97 | X26: 0.96 | Y26: 0.94 | Z26: 0.92 | AA26: 0.89 | AB26: 0.87 | AC26: 0.85 | AD26: 0.83 | AE26: 0.81 | AF26: 0.8 | AG26: 0.78 | AH26: 0.76 | AI26: 0.74 | AJ26: 0.72 | AK26: 0.7 | AL26: 0.68 | AM26: 0.66 | AN26: 0.65 | AO26: 0.64 | AP26: 0.63 | AQ26: 0.62 | AR26: 0.61 | AS26: 0.61 | AT26: 0.61 | AU26: 0.61 | AV26: 0.61 | AW26: 0.6
Q27: #REF! | R27: 1 | S27: 1.01 | T27: 0.99 | U27: 0.98 | V27: 0.96 | W27: 0.95 | X27: 0.94 | Y27: 0.92 | Z27: 0.91 | AA27: 0.89 | AB27: 0.88 | AC27: 0.87 | AD27: 0.85 | AE27: 0.84 | AF27: 0.82 | AG27: 0.81 | AH27: 0.79 | AI27: 0.78 | AJ27: 0.78 | AK27: 0.77 | AL27: 0.76 | AM27: 0.75 | AN27: 0.75 | AO27: 0.75 | AP27: 0.75 | AQ27: 0.75 | AR27: 0.75 | AS27: 0.75 | AT27: 0.75 | AU27: 0.76 | AV27: 0.76 | AW27: 0.76
Q28: #REF! | R28: #N/A | S28: #N/A | T28: #N/A | U28: #N/A | V28: #N/A | W28: #N/A | X28: #N/A | Y28: #N/A | Z28: #N/A | AA28: #N/A | AB28: #N/A | AC28: #N/A | AD28: #N/A | AE28: #N/A | AF28: #N/A | AG28: #N/A | AH28: #N/A | AI28: #N/A | AJ28: #N/A | AK28: #N/A | AL28: #N/A | AM28: #N/A | AN28: #N/A | AO28: #N/A | AP28: #N/A | AQ28: #N/A | AR28: #N/A | AS28: #N/A | AT28: #N/A | AU28: #N/A | AV28: #N/A | AW28: #N/A
Q29: #REF! | R29: #N/A | S29: #N/A | T29: #N/A | U29: #N/A | V29: #N/A | W29: #N/A | X29: #N/A | Y29: #N/A | Z29: #N/A | AA29: #N/A | AB29: #N/A | AC29: #N/A | AD29: #N/A | AE29: #N/A | AF29: #N/A | AG29: #N/A | AH29: #N/A | AI29: #N/A | AJ29: #N/A | AK29: #N/A | AL29: #N/A | AM29: #N/A | AN29: #N/A | AO29: #N/A | AP29: #N/A | AQ29: #N/A | AR29: #N/A | AS29: #N/A | AT29: #N/A | AU29: #N/A | AV29: #N/A | AW29: #N/A
Q30: #REF! | R30: 1 | S30: 1 | T30: 0.99 | U30: 0.99 | V30: 0.98 | W30: 0.97 | X30: 0.96 | Y30: 0.94 | Z30: 0.92 | AA30: 0.89 | AB30: 0.87 | AC30: 0.85 | AD30: 0.83 | AE30: 0.81 | AF30: 0.8 | AG30: 0.78 | AH30: 0.76 | AI30: 0.74 | AJ30: 0.72 | AK30: 0.7 | AL30: 0.68 | AM30: 0.65 | AN30: 0.65 | AO30: 0.64 | AP30: 0.63 | AQ30: 0.62 | AR30: 0.61 | AS30: 0.61 | AT30: 0.6 | AU30: 0.6 | AV30: 0.6 | AW30: 0.59
A31: Title and | B31: In Word document | Q31: #REF! | R31: 1 | S31: 1 | T31: 0.99 | U31: 0.99 | V31: 0.98 | W31: 0.97 | X31: 0.96 | Y31: 0.94 | Z31: 0.92 | AA31: 0.89 | AB31: 0.87 | AC31: 0.85 | AD31: 0.83 | AE31: 0.8 | AF31: 0.78 | AG31: 0.76 | AH31: 0.73 | AI31: 0.71 | AJ31: 0.69 | AK31: 0.66 | AL31: 0.64 | AM31: 0.62 | AN31: 0.61 | AO31: 0.6 | AP31: 0.6 | AQ31: 0.59 | AR31: 0.59 | AS31: 0.58 | AT31: 0.58 | AU31: 0.58 | AV31: 0.58 | AW31: 0.58
A32: source: | B32: (only unit on chart) | Q32: #REF! | R32: 1 | S32: 1 | T32: 0.99 | U32: 0.99 | V32: 0.98 | W32: 0.97 | X32: 0.96 | Y32: 0.94 | Z32: 0.92 | AA32: 0.89 | AB32: 0.87 | AC32: 0.85 | AD32: 0.82 | AE32: 0.79 | AF32: 0.76 | AG32: 0.73 | AH32: 0.7 | AI32: 0.68 | AJ32: 0.66 | AK32: 0.64 | AL32: 0.62 | AM32: 0.6 | AN32: 0.6 | AO32: 0.6 | AP32: 0.59 | AQ32: 0.59 | AR32: 0.59 | AS32: 0.59 | AT32: 0.59 | AU32: 0.6 | AV32: 0.6 | AW32: 0.6
Q33: #REF! | R33: 1 | S33: 1 | T33: 0.99 | U33: 0.99 | V33: 0.98 | W33: 0.97 | X33: 0.97 | Y33: 0.96 | Z33: 0.95 | AA33: 0.94 | AB33: 0.94 | AC33: 0.93 | AD33: 0.92 | AE33: 0.9 | AF33: 0.89 | AG33: 0.88 | AH33: 0.87 | AI33: 0.85 | AJ33: 0.83 | AK33: 0.81 | AL33: 0.8 | AM33: 0.78 | AN33: 0.77 | AO33: 0.76 | AP33: 0.76 | AQ33: 0.75 | AR33: 0.74 | AS33: 0.74 | AT33: 0.73 | AU33: 0.72 | AV33: 0.72 | AW33: 0.71
Q34: #REF! | R34: 1 | S34: 1 | T34: 0.99 | U34: 0.99 | V34: 0.98 | W34: 0.98 | X34: 0.97 | Y34: 0.96 | Z34: 0.95 | AA34: 0.95 | AB34: 0.94 | AC34: 0.93 | AD34: 0.92 | AE34: 0.91 | AF34: 0.9 | AG34: 0.89 | AH34: 0.87 | AI34: 0.86 | AJ34: 0.84 | AK34: 0.82 | AL34: 0.8 | AM34: 0.78 | AN34: 0.78 | AO34: 0.77 | AP34: 0.76 | AQ34: 0.76 | AR34: 0.75 | AS34: 0.74 | AT34: 0.74 | AU34: 0.73 | AV34: 0.72 | AW34: 0.71
Q35: #REF! | R35: 1 | S35: 1 | T35: 0.99 | U35: 0.99 | V35: 0.98 | W35: 0.98 | X35: 0.97 | Y35: 0.97 | Z35: 0.96 | AA35: 0.95 | AB35: 0.95 | AC35: 0.94 | AD35: 0.93 | AE35: 0.92 | AF35: 0.9 | AG35: 0.89 | AH35: 0.88 | AI35: 0.86 | AJ35: 0.85 | AK35: 0.83 | AL35: 0.81 | AM35: 0.79 | AN35: 0.78 | AO35: 0.78 | AP35: 0.77 | AQ35: 0.76 | AR35: 0.75 | AS35: 0.75 | AT35: 0.74 | AU35: 0.73 | AV35: 0.72 | AW35: 0.71
Q36: #REF! | R36: 1 | S36: 1 | T36: 0.99 | U36: 0.99 | V36: 0.98 | W36: 0.97 | X36: 0.97 | Y36: 0.96 | Z36: 0.95 | AA36: 0.94 | AB36: 0.93 | AC36: 0.92 | AD36: 0.91 | AE36: 0.9 | AF36: 0.89 | AG36: 0.88 | AH36: 0.86 | AI36: 0.85 | AJ36: 0.83 | AK36: 0.81 | AL36: 0.79 | AM36: 0.77 | AN36: 0.77 | AO36: 0.76 | AP36: 0.75 | AQ36: 0.75 | AR36: 0.74 | AS36: 0.73 | AT36: 0.73 | AU36: 0.72 | AV36: 0.71 | AW36: 0.71
Q37: #REF! | R37: 1 | S37: 1 | T37: 0.98 | U37: 0.96 | V37: 0.95 | W37: 0.93 | X37: 0.91 | Y37: 0.9 | Z37: 0.89 | AA37: 0.88 | AB37: 0.87 | AC37: 0.86 | AD37: 0.84 | AE37: 0.83 | AF37: 0.82 | AG37: 0.8 | AH37: 0.79 | AI37: 0.77 | AJ37: 0.75 | AK37: 0.72 | AL37: 0.7 | AM37: 0.68 | AN37: 0.67 | AO37: 0.66 | AP37: 0.65 | AQ37: 0.64 | AR37: 0.63 | AS37: 0.63 | AT37: 0.62 | AU37: 0.61 | AV37: 0.61 | AW37: 0.6
Q38: #REF! | R38: 1 | S38: 1 | T38: 0.99 | U38: 0.98 | V38: 0.96 | W38: 0.95 | X38: 0.94 | Y38: 0.92 | Z38: 0.91 | AA38: 0.89 | AB38: 0.88 | AC38: 0.86 | AD38: 0.85 | AE38: 0.83 | AF38: 0.81 | AG38: 0.8 | AH38: 0.78 | AI38: 0.78 | AJ38: 0.77 | AK38: 0.76 | AL38: 0.76 | AM38: 0.75 | AN38: 0.75 | AO38: 0.75 | AP38: 0.75 | AQ38: 0.75 | AR38: 0.75 | AS38: 0.75 | AT38: 0.75 | AU38: 0.75 | AV38: 0.75 | AW38: 0.76
Q39: #REF! | R39: 1 | S39: 0.99 | T39: 0.97 | U39: 0.95 | V39: 0.93 | W39: 0.91 | X39: 0.89 | Y39: 0.88 | Z39: 0.87 | AA39: 0.85 | AB39: 0.84 | AC39: 0.83 | AD39: 0.81 | AE39: 0.79 | AF39: 0.77 | AG39: 0.76 | AH39: 0.74 | AI39: 0.72 | AJ39: 0.71 | AK39: 0.69 | AL39: 0.68 | AM39: 0.66 | AN39: 0.65 | AO39: 0.64 | AP39: 0.64 | AQ39: 0.63 | AR39: 0.62 | AS39: 0.62 | AT39: 0.61 | AU39: 0.61 | AV39: 0.6 | AW39: 0.6
Q40: #REF! | R40: 1 | S40: 1 | T40: 0.99 | U40: 0.97 | V40: 0.96 | W40: 0.95 | X40: 0.94 | Y40: 0.93 | Z40: 0.91 | AA40: 0.9 | AB40: 0.88 | AC40: 0.87 | AD40: 0.85 | AE40: 0.83 | AF40: 0.81 | AG40: 0.79 | AH40: 0.77 | AI40: 0.76 | AJ40: 0.74 | AK40: 0.73 | AL40: 0.71 | AM40: 0.69 | AN40: 0.69 | AO40: 0.68 | AP40: 0.68 | AQ40: 0.68 | AR40: 0.67 | AS40: 0.67 | AT40: 0.67 | AU40: 0.66 | AV40: 0.66 | AW40: 0.66
...

Sheet 1. GHG emissions
A1: Total agriculture emissions
B2: Source | C2: Unit | D2: 2005 | I2: 2010 | N2: 2015 | S2: 2020 | X2: 2025 | AC2: 2030 | AH2: 2035 | AM2: 2040 | AR2: 2045 | AW2: 2050
A3: Total | B3: EEA GHG data viewer | C3: Mt CO2e | D3: 380.05617 | E3: 377.2945 | F3: 380.21219 | G3: 377.76149 | H3: 372.74538 | I3: 367.48312 | J3: 366.72673 | K3: 366.27471 | L3: 367.90328 | M3: 372.86435 | N3: 374.48107 | O3: 375.9252 | P3: 378.15636 | Q3: 374.98913 | R3: 370.86908 | S3: 371.90062 | T3: 368.6119 | U3: 360.87143
A4: Enteric fermentation | B4: EEA GHG data viewer | C4: Mt CO2e | D4: 189.01043 | E4: 187.98271 | F4: 188.92079 | G4: 188.12321 | H4: 186.40298 | I4: 184.31825 | J4: 182.10599 | K4: 182.09599 | L4: 182.87488 | M4: 184.16849 | N4: 185.88128 | O4: 186.47719 | P4: 186.64579 | Q4: 185.63822 | R4: 183.81564 | S4: 183.74841 | T4: 182.5455
A5: Manure management | B5: EEA GHG data viewer | C5: Mt CO2e | D5: 69.088235 | E5: 68.598819 | F5: 68.898852 | G5: 67.314392 | H5: 66.943395 | I5: 64.598334 | J5: 64.685387 | K5: 63.783446 | L5: 63.011645 | M5: 63.612132 | N5: 64.258188 | O5: 64.247368 | P5: 64.513166 | Q5: 64.267157 | R5: 63.777674 | S5: 64.090869 | T5: 62.90261
A6: Fertilizer use | B6: EEA GHG data viewer | C6: Mt CO2e | D6: 117.67972 | E6: 116.36457 | F6: 117.15945 | G6: 117.87195 | H6: 114.33474 | I6: 113.44434 | J6: 114.55727 | K6: 114.62184 | L6: 116.62336 | M6: 119.73777 | N6: 118.73614 | O6: 119.61502 | P6: 121.73857 | Q6: 119.99454 | R6: 118.13703 | S6: 118.62947 | T6: 117.99413
A7: Other | B7: EEA GHG data viewer | C7: Mt CO2e | D7: =D3-D4-D5-D6 -> 4.2777841 | E7: =E3-E4-E5-E6 -> 4.3484008 | F7: =F3-F4-F5-F6 -> 5.2331005 | G7: =G3-G4-G5-G6 -> 4.4519321 | H7: =H3-H4-H5-H6 -> 5.0642661 | I7: =I3-I4-I5-I6 -> 5.1221914 | J7: =J3-J4-J5-J6 -> 5.378086 | K7: =K3-K4-K5-K6 -> 5.7734343 | ... T7: =T3-T4-T5-T6 -> 5.1696654 | AY7: =AC8/D3-1 -> -0.12328049
A8: linear trajectory 1 | B8: linear trajectory | C8: Mt CO2e | U8: 360.87143 | V8: 357.41283 | W8: 353.95424 | X8: 350.49564 | Y8: 347.03705 | Z8: 343.57845 | AA8: 340.11985 | AB8: 336.66126 | AC8: 333.20266 | AD8: =($AW8-$AC8)/(2050-2030)+AC8 -> 328.872 | AE8: =($AW8-$AC8)/(2050-2030)+AD8 -> 324.54134 | AF8: =($AW8-$AC8)/(2050-2030)+AE8 -> 320.21068 | AG8: =($AW8-$AC8)/(2050-2030)+AF8 -> 315.88002 | AH8: =($AW8-$AC8)/(2050-2030)+AG8 -> 311.54936 | AI8: =($AW8-$AC8)/(2050-2030)+AH8 -> 307.2187 | AJ8: =($AW8-$AC8)/(2050-2030)+AI8 -> 302.88804 | AK8: =($AW8-$AC8)/(2050-2030)+AJ8 -> 298.55738 | ... AV8: =($AW8-$AC8)/(2050-2030)+AU8 -> 250.92011 | AW8: =AW11 -> 246.58945 | AY8: =AW8/D3-1 -> -0.35117631
A10: 2030 benchmark | B10: FF55 MIX (2005-2030 % change) | C10: Mt CO2e | AC10: =(AC33/$D33*$D3) -> 333.20266
A11: 2050 benchmark | B11: CTP MIX (IA figure 19) | AW11: =(267/$D33*$D3) -> 246.58945
A12: 2050 benchmark (min) | B12: 1.5TECH | C12: Mt CO2e | AW12: =276.9*O28 -> 248.81995
A13: 2050 benchmark (max) | B13: 1.5LIFE | C13: Mt CO2e | AW13: =230.4*O28 -> 207.03545
A14: scenarios 2040 advice | B14: ESABCC - see below | C14: Mt CO2e | AC14: =AC37 -> 315.89633 | AM14: =AM37 -> 282.75463 | AW14: =AW37 -> 268.44377
A17: Average 2005-2022 | B17: calculated | C17: Mt CO2e | D17: =(U3-D3)/17 -> -1.1285142
A18: Average 2017-2021 | B18: calculated | C18: Mt CO2e | D18: =AVERAGE(T3-S3,S3-R3,R3-Q3,Q3-P3) -> -2.3861142
A19: Average 2018-2022 | B19: calculated | C19: Mt CO2e | D19: =(U3-Q3)/4 -> -3.5294258
A20: Average 2022-2030 | B20: calculated | C20: Mt CO2e | D20: =(AC8-T3)/9 -> -3.9343599
A21: Average 2023-2030 | B21: calculated | C21: Mt CO2e | D21: =(AC8-U3)/8 -> -3.458596
A22: Average 2031-2050 min | B22: calculated | C22: Mt CO2e | D22: =AD8-AC8 -> -4.3306607
A23: Average 2031-2050 min | B23: calculated | C23: Mt CO2e | D23: =AD9-AC9 -> 0
A25: Benchmark data
A26: EU27/UK ratio | AH26: 0
B27: Source | C27: Unit | D27: 2005 | I27: 2010 | N27: 2015 | S27: 2020 | X27: 2025 | AC27: 2030 | AH27: 2035 | AM27: 2040 | AR27: 2045 | AW27: 2050
A28: EU27 | B28: EEA GHG data viewer | N28: =N3 -> 374.48107 | O28: =N28/(N28+N29) -> 0.89859138
A29: UK | B29: UNFCCC CRF table | N29: 42.261267
A31: 2030 benchmark | AH31: 0
B32: Source | C32: Unit | D32: 2005 | I32: 2010 | N32: 2015 | S32: 2020 | X32: 2025 | AC32: 2030 | AH32: 2035 | AM32: 2040 | AR32: 2045 | AW32: 2050
A33: Agriculture emissions | B33: FF55 MIX | C33: Mt CO2e | D33: 411.51395 | I33: 394.50204 | N33: 400.61529 | S33: 391.78659 | X33: 378.76049 | AC33: 360.78231
A36: 2040 advice | AH36: 0
A37: Average of 90-95% env-friendly paths | B37: ESABCC Database: CH4 + N2O from agriculture | C37: Mt CO2e | AC37: =[1]Agriculture!AP45 -> 315.89633 | AM37: =[1]Agriculture!AZ45 -> 282.75463 | AW37: =[1]Agriculture!BJ45 -> 268.44377
A38: Single scenario chosen because range of outcomes is narrow - so floating bars are very difficult to see | C38: Mt CO2e
U41: =U3/D3-1 -> -0.050478701 | AM41: =AM14/D3-1 -> -0.25601883 | AN41: % change vs 2005
A45: 2005 emissions (inventory) | B45: =D3 -> 380.05617
A46: 2050 MIX % below 2005 | B46: =AW11/B45-1 -> -0.35117631
A47: 2050 1.5 TECH % below 2005 | B47: =AW12/B45-1 -> -0.34530743
A48: 2050 1.5 LIFE % below 2005 | B48: =AW13/B45-1 -> -0.45525038
A49: 2040 avg % below 2005 | B49: =AM14/B45-1 -> -0.25601883 | T49: =T4/T$3 -> 0.4952241
A50: 2040 advice % below 2005 by 2030 | B50: =AC14/B45-1 -> -0.16881673 | T50: =T5/T$3 -> 0.17064726
A51: 2040 advice % below 2005 by 2050 | B51: =AW37/D3-1 -> -0.29367342 | T51: =T6/T$3 -> 0.32010396
A52: 2040 advice Demand-focus Pathway: 2050 vs 2005 | B52: =140.79/B45-1 -> -0.62955476
...

Sheet 2. animal production and consum
A1: Dairy cattle
B2: Source | C2: Unit | D2: 2005 | I2: 2010 | N2: 2015 | S2: 2020 | U2: 2010-2020 | V2: 2010-2020 | AW2: 2050
A3: Consumption | B3: FAOSTAT | C3: Mt | I3: 80.573 | J3: 82.019 | K3: 80.759 | L3: 82.016 | M3: 79.044 | N3: 80.785 | O3: 81.824 | P3: 82.568 | Q3: 85.249 | R3: 86.294 | S3: 86.631 | U3: =S3/I3-1 -> 0.075186477 | V3: =S3-I3 -> 6.058
A4: Production | B4: FAOSTAT | C4: Mt | I4: 141.069 | J4: 143.444 | K4: 143.756 | L4: 145.262 | M4: 150.148 | N4: 153.161 | O4: 154.834 | P4: 155.97 | Q4: 158.302 | R4: 161.245 | S4: 163.065 | U4: =S4/I4-1 -> 0.1559237 | V4: =S4-I4 -> 21.996
A5: Herd size | B5: EU CRF tables | C5: million heads | D5: 23.169958 | E5: 22.724647 | F5: 22.471954 | G5: 22.454053 | H5: 22.090777 | I5: 21.546766 | J5: 21.357889 | K5: 21.446461 | L5: 21.59493 | M5: 21.64177 | N5: 21.637552 | O5: 21.582381 | P5: 21.389742 | Q5: 21.081265 | R5: 20.81697 | S5: 20.632262 | T5: 20.327267 | U5: =S5/I5-1 -> -0.042442727 | V5: =S5-I5 -> -0.91450349
D7: 2016-2020 | E7: 2017-2021
A8: Average consumption
A9: Average production
A10: Average herd size | E10: =(T5-P5)/4*1000 -> -265.61852
A12: Non-dairy cattle
B13: Source | C13: Unit | I13: 2010 | N13: 2015 | S13: 2020 | AW13: 2050
A14: Consumption (in Mt) | B14: FAOSTAT | C14: Mt | I14: 6.953 | J14: 6.741 | K14: 6.643 | L14: 6.422 | M14: 6.112 | N14: 6.051 | O14: 6.116 | P14: 6.022 | Q14: 6.237 | R14: 6.246 | S14: 6.115 | U14: =S14/I14-1 -> -0.12052352 | V14: =S14-I14 -> -0.838
A15: Production (in Mt) | B15: FAOSTAT | C15: Mt | I15: 7.257 | J15: 7.126 | K15: 6.857 | L15: 6.567 | M15: 6.597 | N15: 6.827 | O15: 6.999 | P15: 6.993 | Q15: 7.112 | R15: 6.999 | S15: 6.936 | U15: =S15/I15-1 -> -0.044233154 | V15: =S15-I15 -> -0.321
A16: Herd size (million head, right axis) | B16: EU CRF tables | C16: million heads | D16: 60.724761 | E16: 60.839169 | F16: 61.637469 | G16: 61.571172 | H16: 61.218665 | I16: 60.587279 | J16: 59.664191 | K16: 59.6065 | L16: 60.168643 | M16: 60.893261 | N16: 61.356187 | O16: 62.007257 | P16: 61.873208 | Q16: 61.283198 | R16: 60.588898 | S16: 60.163155 | T16: 59.906106 | U16: =S16/I16-1 -> -0.0070002127 | V16: =S16-I16 -> -0.42412384
D18: 2016-2020 | E18: 2017-2021 | I18: =AVERAGE(S14-R14,R14-Q14,Q14-P14,P14-O14) -> -0.00025
A19: Average consumption
A20: Average production
A21: Average herd size | E21: =(T16-P16)/4*1000 -> -491.77541
A23: Pigs and swines
B24: Source | C24: Unit | I24: 2010 | N24: 2015 | S24: 2020 | AW24: 2050
A25: Consumption (in Mt) | B25: FAOSTAT | C25: Mt | I25: 19.178 | J25: 18.883 | K25: 18.523 | L25: 18.243 | M25: 17.812 | N25: 18.361 | O25: 17.991 | P25: 18.218 | Q25: 18.671 | R25: 18.189 | S25: 17.457 | U25: =S25/I25-1 -> -0.089738242 | V25: =S25-I25 -> -1.721
A26: Production (in Mt) | B26: FAOSTAT | C26: Mt | I26: 22.224 | J26: 22.457 | K26: 22.002 | L26: 21.686 | M26: 21.746 | N26: 22.569 | O26: 22.946 | P26: 22.824 | Q26: 23.223 | R26: 22.996 | S26: 23.219 | U26: =S26/I26-1 -> 0.044771418 | V26: =S26-I26 -> 0.995
A27: Herd size (million head, right axis) | B27: EU CRF tables | C27: million heads | D27: 151.65402 | E27: 152.80496 | F27: 153.54327 | G27: 146.36727 | H27: 143.99196 | I27: 144.06175 | J27: 142.26143 | K27: 138.26839 | L27: 136.46509 | M27: 138.4114 | N27: 139.35306 | O27: 137.69743 | P27: 138.80286 | Q27: 139.68198 | R27: 137.3796 | S27: 139.98062 | T27: 137.82915 | U27: =S27/I27-1 -> -0.028329006 | V27: =S27-I27 -> -4.0811261
D29: 2016-2020 | E29: 2017-2021 | I29: =AVERAGE(S25-R25,R25-Q25,Q25-P25,P25-O25) -> -0.1335
A30: Average consumption
A31: Average production
A32: Average herd size | E32: =(T27-P27)/4*1000 -> -243.42769

Sheet 3. crop area and production
A1: Area and production
B2: Source | C2: Unit | D2: 2005 | I2: 2010 | N2: 2015 | S2: 2020 | V2: 2005-2020 | AR2: 2050
A3: Cropland area | B3: EU CRF tables | C3: kha | D3: 126.86262 | E3: 126.48799 | F3: 126.04921 | G3: 125.70024 | H3: 125.23159 | I3: 124.57823 | J3: 124.2133 | K3: 123.91357 | L3: 123.71573 | M3: 123.27482 | N3: 123.05077 | O3: 122.74795 | P3: 120.93348 | Q3: 121.71412 | R3: 121.34089 | S3: 121.29976 | T3: 120.93348 | V3: =S3/I3-1 -> -0.026316536
A4: Cereal crop production | B4: FAOSTAT | C4: Mt | I4: 263.463 | J4: 273.974 | K4: 268.655 | L4: 290.066 | M4: 309.576 | N4: 294.141 | O4: 280.962 | P4: 289.274 | Q4: 274.46 | R4: 300.237 | S4: 287.384 | V4: =S4/I4-1 -> 0.090794533
A5: Sugar crop production | B5: FAOSTAT | C5: Mt | I5: 98.592 | J5: 116.647 | K5: 108.266 | L5: 100.858 | M5: 123.761 | N5: 97.785 | O5: 110.932 | P5: 137.062 | Q5: 113.958 | R5: 113.128 | S5: 100.145 | V5: =S5/I5-1 -> 0.015751785
A6: Oilseed crop production | B6: FAOSTAT | C6: Mt | I6: 40.441 | J6: 41.215 | K6: 35.641 | L6: 45.572 | M6: 44.065 | N6: 43.408 | O6: 43.174 | P6: 47.069 | Q6: 47.374 | R6: 42.266 | S6: 43.913 | V6: =S6/I6-1 -> 0.085853466
A8: Yields
A9: Item | B9: Source | C9: Unit | D9: 2005 | E9: 2006 | F9: 2007 | G9: 2008 | H9: 2009 | I9: 2010 | J9: 2011 | K9: 2012 | L9: 2013 | M9: 2014 | N9: 2015 | O9: 2016 | P9: 2017 | Q9: 2018 | R9: 2019 | S9: 2020 | T9: 2021 | V9: 2005-2021
A10: Cereals, primary | B10: FAOSTAT | C10: t/ha | D10: 4.7115 | E10: 4.562 | F10: 4.4911 | G10: 5.106 | H10: 4.969 | I10: 4.916 | J10: 5.061 | K10: 4.8213 | L10: 5.2534 | M10: 5.6122 | N10: 5.3778 | O10: 5.1938 | P10: 5.4995 | Q10: 5.2344 | R10: 5.5771 | S10: 5.4627 | T10: 5.6663 | V10: =T10/D10-1 -> 0.20265308
A11: Oilcrops, Cake Equivalent | B11: FAOSTAT | C11: t/ha | D11: 1.3958 | E11: 1.3202 | F11: 1.2914 | G11: 1.4316 | H11: 1.5011 | I11: 1.3851 | J11: 1.3321 | K11: 1.3482 | L11: 1.4623 | M11: 1.6801 | N11: 1.5219 | O11: 1.5107 | P11: 1.599 | Q11: 1.5336 | R11: 1.5235 | S11: 1.4901 | T11: 1.5689 | V11: =T11/D11-1 -> 0.1240149
A12: Sugar Crops Primary | B12: FAOSTAT | C12: t/ha | D12: 60.1884 | E12: 59.2092 | F12: 63.6249 | G12: 66.4542 | H12: 71.2961 | I12: 66.1853 | J12: 75.9979 | K12: 69.6783 | L12: 68.9369 | M12: 79.8484 | N12: 72.032 | O12: 75.0564 | P12: 81.6333 | Q12: 69.0316 | R12: 73.8051 | S12: 67.8159 | T12: 76.1826 | V12: =T12/D12-1 -> 0.26573559
A14: Average 2017-2021 | D14: =AVERAGE(T3-S3,S3-R3,R3-Q3,Q3-P3) -> 0

Sheet 4. GHG intensity
A1: Dairy cattle
B2: Source | C2: Unit | D2: 2005 | I2: 2010 | N2: 2015 | S2: 2020 | V2: 2010-2020 | W2: 2010-2020 | AX2: 2050
A3: GHG emissions (Mt CO2e) | B3: EU CRF tables | C3: Mt | D3: 99.998262 | E3: 98.653368 | F3: 98.105363 | G3: 98.305981 | H3: 96.860706 | I3: 95.722197 | J3: 95.978298 | K3: 96.460344 | L3: 96.995255 | M3: 98.379592 | N3: 99.228927 | O3: 99.404098 | P3: 99.368209 | Q3: 98.627444 | R3: 98.201803 | S3: 98.634543 | T3: 97.789543 | V3: =S3/I3-1 -> 0.030424981 | W3: =S3-I3 -> 2.9123461
A4: Production (Mt) | B4: FAOSTAT | C4: Mt | I4: 141.069 | J4: 143.444 | K4: 143.756 | L4: 145.262 | M4: 150.148 | N4: 153.161 | O4: 154.834 | P4: 155.97 | Q4: 158.302 | R4: 161.245 | S4: 163.065 | V4: =S4/I4-1 -> 0.1559237 | W4: =S4-I4 -> 21.996
A5: GHG intensity (t CO2e/t) | I5: =I3/I4 -> 0.67854877 | J5: =J3/J4 -> 0.66909943 | K5: =K3/K4 -> 0.67100047 | L5: =L3/L4 -> 0.66772628 | M5: =M3/M4 -> 0.65521747 | N5: =N3/N4 -> 0.64787333 | O5: =O3/O4 -> 0.64200433 | P5: =P3/P4 -> 0.63709822 | ... S5: =S3/S4 -> 0.60487869 | V5: =S5/I5-1 -> -0.10857007
A7: Average 2016-2020 | I7: =AVERAGE(S5-R5,R5-Q5,Q5-P5,P5-O5)*1000 -> -9.2814095
A9: Non-dairy cattle
B10: Source | C10: Unit | I10: 2010 | N10: 2015 | S10: 2020 | AX10: 2050
A11: GHG emissions (Mt CO2e) | B11: EU CRF tables | C11: Mt | I11: 102.54706 | J11: 100.8661 | K11: 101.08755 | L11: 101.558 | M11: 102.10483 | N11: 103.13451 | O11: 103.76937 | P11: 103.8493 | Q11: 103.26175 | R11: 101.69849 | S11: 100.80836 | T11: 100.33957 | V11: =S11/I11-1 -> -0.016955139 | W11: =S11-I11 -> -1.7386997
A12: Production (Mt) | B12: FAOSTAT | C12: Mt | I12: 7.257 | J12: 7.126 | K12: 6.857 | L12: 6.567 | M12: 6.597 | N12: 6.827 | O12: 6.999 | P12: 6.993 | Q12: 7.112 | R12: 6.999 | S12: 6.936 | V12: =S12/I12-1 -> -0.044233154 | W12: =S12-I12 -> -0.321
A13: GHG intensity (t CO2e/t) | I13: =I11/I12 -> 14.130779 | J13: =J11/J12 -> 14.154659 | K13: =K11/K12 -> 14.742241 | L13: =L11/L12 -> 15.4649 | M13: =M11/M12 -> 15.477463 | N13: =N11/N12 -> 15.106857 | O13: =O11/O12 -> 14.826314 | P13: =P11/P12 -> 14.850464 | ... S13: =S11/S12 -> 14.534078 | V13: =S13/I13-1 -> 0.02854045
A15: Average 2016-2020 | I15: =AVERAGE(S13-R13,R13-Q13,Q13-P13,P13-O13)*1000 -> -73.05914
A17: Pigs and swines
B18: Source | C18: Unit | I18: 2010 | N18: 2015 | S18: 2020 | AX18: 2050
A19: GHG emissions (Mt CO2e) | B19: EU CRF tables | C19: Mt | I19: 30.015658 | J19: 30.069212 | K19: 29.046903 | L19: 28.235123 | M19: 28.725672 | N19: 29.003392 | O19: 28.761486 | P19: 29.033236 | Q19: 28.991729 | R19: 28.777768 | S19: 29.343136 | T19: 28.575035 | V19: =S19/I19-1 -> -0.022405728 | W19: =S19-I19 -> -0.67252268
A20: Production (in Mt) | B20: FAOSTAT | C20: Mt | I20: 22.224 | J20: 22.457 | K20: 22.002 | L20: 21.686 | M20: 21.746 | N20: 22.569 | O20: 22.946 | P20: 22.824 | Q20: 23.223 | R20: 22.996 | S20: 23.219 | V20: =S20/I20-1 -> 0.044771418 | W20: =S20-I20 -> 0.995
A21: GHG intensity (t CO2e/t) | I21: =I19/I20 -> 1.3505966 | J21: =J19/J20 -> 1.3389683 | K21: =K19/K20 -> 1.3201938 | L21: =L19/L20 -> 1.3019977 | M21: =M19/M20 -> 1.3209635 | N21: =N19/N20 -> 1.2850987 | O21: =O19/O20 -> 1.2534423 | P21: =P19/P20 -> 1.2720485 | ... S21: =S19/S20 -> 1.2637554 | V21: =S21/I21-1 -> -0.064298415
A23: Average 2016-2020 | I23: =AVERAGE(S21-R21,R21-Q21,Q21-P21,P21-O21)*1000 -> 2.5782724
A43: Dairy | I43: =(S5-O5)/4*1000 -> -9.2814095
A44: non dairy | I44: =(S13-O13)/4*1000 -> -73.05914
A45: pig | I45: =(S21-O21)/4*1000 -> 2.5782724

Sheet 5. Fertilizer use
A1: Area and production
B2: Source | C2: Unit | D2: 2005 | I2: 2010 | N2: 2015 | S2: 2020 | X2: 2025 | AC2: 2030 | AE2: 2009-2017 | AF2: 2017-2021 | AR2: 2050
A3: Total | B3: EU CRF tables | C3: Mt N | D3: =D4+D5 -> 14.900541 | E3: =E4+E5 -> 14.807648 | F3: =F4+F5 -> 15.009521 | G3: =G4+G5 -> 14.783451 | H3: =H4+H5 -> 14.304166 | I3: =I4+I5 -> 14.367613 | J3: =J4+J5 -> 14.598439 | K3: =K4+K5 -> 14.720365 | ... T3: =T4+T5 -> 15.00954 | AE3: =P3/H3-1 -> 0.099302644 | AF3: =T3/P3-1 -> -0.04547443
A4: Inorganic | B4: EU CRF tables | C4: Mt N | D4: 9.9723143 | E4: 9.8864534 | F4: 10.015004 | G4: 9.8337052 | H4: 9.3564789 | I4: 9.4495828 | J4: 9.6150922 | K4: 9.7296806 | L4: 9.8513727 | M4: 10.067803 | N4: 10.243902 | O4: 10.344739 | P4: 10.500076 | Q4: 10.354158 | R4: 9.8697321 | S4: 9.9890406 | T4: 9.8448346 | AE4: =P4/H4-1 -> 0.12222517 | AF4: =T4/P4-1 -> -0.062403495
A5: Organic | B5: EU CRF tables | C5: Mt N | D5: 4.9282263 | E5: 4.921195 | F5: 4.9945168 | G5: 4.9497455 | H5: 4.9476869 | I5: 4.9180303 | J5: 4.9833468 | K5: 4.9906844 | L5: 5.0485838 | M5: 5.1286708 | N5: 5.167839 | O5: 5.1688688 | P5: 5.2245312 | Q5: 5.214978 | R5: 5.1836709 | S5: 5.2495705 | T5: 5.1647051 | AE5: =P5/H5-1 -> 0.055954288 | AF5: =T5/P5-1 -> -0.011451001
A6: Use per ha | B6: calculated | C6: kg N/ha | D6: =D3/'3. crop area and production'!D3*1000 -> 117.45414 | E6: =E3/'3. crop area and production'!E3*1000 -> 117.06763 | F6: =F3/'3. crop area and production'!F3*1000 -> 119.07668 | G6: =G3/'3. crop area and production'!G3*1000 -> 117.60877 | H6: =H3/'3. crop area and production'!H3*1000 -> 114.22171 | I6: =I3/'3. crop area and production'!I3*1000 -> 115.33005 | J6: =J3/'3. crop area and production'!J3*1000 -> 117.52718 | K6: =K3/'3. crop area and production'!K3*1000 -> 118.79542 | ... T6: =T3/'3. crop area and production'!T3*1000 -> 124.11401 | AE6: =P6/H6-1 -> 0.13837305 | AF6: =T6/P6-1 -> -0.04547443
A7: 2030 benchmark | B7: Farm to Fork strategy | C7: Mt N | AC7: =0.8*S3 -> 12.190889
A8: linear trajectory | B8: calculated | T8: 15.00954 | U8: 14.696356 | V8: 14.383173 | W8: 14.069989 | X8: 13.756806 | Y8: 13.443623 | Z8: 13.130439 | AA8: 12.817256 | AB8: 12.504072 | AC8: 12.190889
A11: Share inorganic | D11: =D4/D3 -> 0.66925856 | E11: =E4/E3 -> 0.66765857 | F11: =F4/F3 -> 0.66724343 | G11: =G4/G3 -> 0.66518335 | H11: =H4/H3 -> 0.65410867 | I11: =I4/I3 -> 0.65770025 | J11: =J4/J3 -> 0.65863838 | K11: =K4/K3 -> 0.66096735 | ... T11: =T4/T3 -> 0.65590516
A12: Share organic | D12: =D5/D3 -> 0.33074144 | E12: =E5/E3 -> 0.33234143 | F12: =F5/F3 -> 0.33275657 | G12: =G5/G3 -> 0.33481665 | H12: =H5/H3 -> 0.34589133 | I12: =I5/I3 -> 0.34229975 | J12: =J5/J3 -> 0.34136162 | K12: =K5/K3 -> 0.33903265 | ... T12: =T5/T3 -> 0.34409484
A14: Change 2017-2021 | D14: =AVERAGE(T3-S3,S3-R3,R3-Q3,Q3-P3)*1000 -> -178.76689
A15: Change 2022-2030 | D15: =(U8-T8)*1000 -> -313.18342
D16: =D15/D14 -> 1.7519096

Sheet 6. animal product consumption
A1: Animal product consumption (in kcal/cap/year)
A2: Bovine meat
B3: Source | C3: Unit | D3: `10 | N3: `20 | X3: ´30 | AH3: ´40 | AR3: ´50
A4: Historic | B4: FAOSTAT | C4: kcal/cap/day | D4: 61.35 | E4: 58.61 | F4: 57.58 | G4: 55.36 | H4: 52.58 | I4: 51.75 | J4: 52.15 | K4: 51.15 | L4: 52.93 | M4: 53.35 | N4: 52.12
A5: 2050 benchmark | B5: ACP4A Diet 5 | C5: kcal/cap/day | AR5: 48
A6: linear trajectory | C6: kcal/cap/day | N6: 52.12 | O6: 51.982667 | P6: 51.845333 | Q6: 51.708 | R6: 51.570667 | S6: 51.433333 | T6: 51.296 | U6: 51.158667 | V6: 51.021333 | W6: 50.884 | X6: 50.746667 | Y6: 50.609333 | Z6: 50.472 | AA6: 50.334667 | AB6: 50.197333 | AC6: 50.06 | AD6: 49.922667 | AE6: 49.785333 | AF6: 49.648 | AG6: 49.510667 | AH6: 49.373333 | AI6: 49.236 | AJ6: 49.098667 | AK6: 48.961333 | AL6: 48.824 | AM6: 48.686667 | AN6: 48.549333 | AO6: 48.412 | AP6: 48.274667 | AQ6: 48.137333 | AR6: 48
A8: Average 2016-2020 | D8: =AVERAGE(N4-M4,M4-L4,L4-K4,K4-J4)*365 -> -2.7375
A9: Average 2021-2050 | D9: =(P6-O6)*365 -> -50.126667
A10: RoC | D10: =D9/D8 -> 18.311111
A12: Dairy
B13: Source | C13: Unit | D13: `10 | N13: `20 | X13: ´30 | AH13: ´40 | AR13: ´50
A14: Historic | B14: FAOSTAT | C14: kcal/cap/day | D14: 445.86 | E14: 449.11 | F14: 445.83 | G14: 446.01 | H14: 448.15 | I14: 454.4 | J14: 459.88 | K14: 464.48 | L14: 475.64 | M14: 535.85 | N14: 545.11 | O14: 550.38
A15: 2050 benchmark | B15: ACP4A Diet 5 | C15: kcal/cap/day | AR15: 301
A16: linear trajectory | C16: kcal/cap/day | N16: 472.94 | O16: 467.20867 | P16: 461.47733 | Q16: 455.746 | R16: 450.01467 | S16: 444.28333 | T16: 438.552 | U16: 432.82067 | V16: 427.08933 | W16: 421.358 | X16: 415.62667 | Y16: 409.89533 | Z16: 404.164 | AA16: 398.43267 | AB16: 392.70133 | AC16: 386.97 | AD16: 381.23867 | AE16: 375.50733 | AF16: 369.776 | AG16: 364.04467 | AH16: 358.31333 | AI16: 352.582 | AJ16: 346.85067 | AK16: 341.11933 | AL16: 335.388 | AM16: 329.65667 | AN16: 323.92533 | AO16: 318.194 | AP16: 312.46267 | AQ16: 306.73133 | AR16: 301
A18: Average 2016-2020 | D18: =AVERAGE(N14-M14,M14-L14,L14-K14,K14-J14)*365 -> 7777.2375
A19: Average 2021-2050 | D19: =(P16-O16)*365 -> -2091.9367
A20: RoC | D20: =D19/D18 -> -0.26898197
A22: Pig meat
B23: Source | C23: Unit | D23: `10 | N23: `20 | X23: ´30 | AH23: ´40 | AR23: ´50
A24: Historic | B24: FAOSTAT | C24: kcal/cap/day | D24: 222.45 | E24: 219.28 | F24: 214.18 | G24: 209.97 | H24: 207.18 | I24: 212.86 | J24: 208.92 | K24: 211.2 | L24: 215.94 | M24: 211.64 | N24: 203.79
A25: 2050 benchmark | B25: ACP4A Diet 5 | C25: kcal/cap/day | AR25: 187
A26: linear trajectory | C26: kcal/cap/day | N26: 203.79 | O26: 203.23033 | P26: 202.67067 | Q26: 202.111 | R26: 201.55133 | S26: 200.99167 | T26: 200.432 | U26: 199.87233 | V26: 199.31267 | W26: 198.753 | X26: 198.19333 | Y26: 197.63367 | Z26: 197.074 | AA26: 196.51433 | AB26: 195.95467 | AC26: 195.395 | AD26: 194.83533 | AE26: 194.27567 | AF26: 193.716 | AG26: 193.15633 | AH26: 192.59667 | AI26: 192.037 | AJ26: 191.47733 | AK26: 190.91767 | AL26: 190.358 | AM26: 189.79833 | AN26: 189.23867 | AO26: 188.679 | AP26: 188.11933 | AQ26: 187.55967 | AR26: 187
A28: Average 2016-2020 | D28: =(N24-J24)/4*365 -> -468.1125
A29: Average 2021-2050 | D29: =(R26-Q26)*365 -> -204.27833
A30: RoC | D30: =D29/D28 -> 0.43638726
A52: Animal product consumption (in kg/cap/year)
A53: Red meat (bovine, mutton, pork)
B54: Source | C54: Unit | D54: 2010 | I54: 2015 | N54: 2020 | S54: 2025 | X54: 2030 | AC54: 2035 | AH54: 2040 | AM54: 2045 | AR54: 2050
A55: Historic | B55: FAOSTAT | C55: kg/cap/year | D55: 63.3 | E55: 61.99 | F55: 60.86 | G55: 59.65 | H55: 57.52 | I55: 58.2 | J55: 57.45 | K55: 57.38 | L55: 58.72 | M55: 57.42 | N55: 55.34
A56: Historic | B56: calculated | C56: kg/cap/week | D56: =D55/52 -> 1.2173077 | E56: =E55/52 -> 1.1921154 | F56: =F55/52 -> 1.1703846 | G56: =G55/52 -> 1.1471154 | H56: =H55/52 -> 1.1061538 | I56: =I55/52 -> 1.1192308 | J56: =J55/52 -> 1.1048077 | K56: =K55/52 -> 1.1034615 | ... N56: =N55/52 -> 1.0642308
A57: Benchmark min | B57: WRCF | C57: kg/cap/week | D57: 0.525 | E57: 0.525 | F57: 0.525 | G57: 0.525 | H57: 0.525 | I57: 0.525 | J57: 0.525 | K57: 0.525 | L57: 0.525 | M57: 0.525 | N57: 0.525
A58: Benchmark max | B58: WRCF | C58: kg/cap/week | D58: 0.75 | E58: 0.75 | F58: 0.75 | G58: 0.75 | H58: 0.75 | I58: 0.75 | J58: 0.75 | K58: 0.75 | L58: 0.75 | M58: 0.75 | N58: 0.75

Sheet 7. food waste
A1: EU level
B2: Source | C2: Unit | D2: 2020 | I2: 2025 | N2: 2030
A3: Households | B3: Eurostat ENV_WASFW$DEFAULTVIEW | C3: kg/cap/year | D3: 70
A4: Restaurant sector | B4: Eurostat ENV_WASFW$DEFAULTVIEW | C4: kg/cap/year | D4: 12
A5: Retail and distribution | B5: Eurostat ENV_WASFW$DEFAULTVIEW | C5: kg/cap/year | D5: 9
A6: Food processing | B6: Eurostat ENV_WASFW$DEFAULTVIEW | C6: kg/cap/year | D6: 26
A7: Primary production (agriculture and fishery) | B7: Eurostat ENV_WASFW$DEFAULTVIEW | C7: kg/cap/year | D7: 14
A8: Total food waste | D8: =SUM(D3:D7) -> 131
A9: 2030 benchmark | N9: =0.5*D8 -> 65.5
A10: linear trajectory | D10: 131 | E10: 124.45 | F10: 117.9 | G10: 111.35 | H10: 104.8 | I10: 98.25 | J10: 91.7 | K10: 85.15 | L10: 78.6 | M10: 72.05 | N10: 65.5
A23: Per member state
A24: NACE_R2 (Labels) | B24: Total (aggregate changing according to the context) | C24: Primary production of food - agriculture, fishing and aquaculture | D24: Manufacture of food products and beverages | E24: Retail and other distribution of food | F24: Restaurants and food services | G24: Total activities by households
A25: Cyprus | B25: 397 | C25: 49 | D25: 190 | E25: 56 | F25: 30 | G25: 71
A26: Belgium | B26: 250 | C26: 3 | D26: 161 | E26: 6 | F26: 8 | G26: 71
A27: Denmark | B27: 221 | C27: 11 | D27: 102 | E27: 17 | F27: 11 | G27: 79
A28: Greece | B28: 191 | C28: 35 | D28: 35 | E28: 14 | F28: 21 | G28: 87
A29: Portugal | B29: 184 | C29: 10 | D29: 6 | E29: 21 | F29: 23 | G29: 124
A30: Netherlands | B30: 161 | C30: 27 | D30: 59 | E30: 12 | F30: 5 | G30: 59
A31: Ireland | B31: 155 | C31: 14 | D31: 44 | E31: 12 | F31: 36 | G31: 48
A32: Malta | B32: 154 | C32: 1 | D32: 9 | E32: 8 | F32: 45 | G32: 92
A33: Luxembourg | B33: 147 | C33: 12 | D33: 17 | E33: 14 | F33: 14 | G33: 91
A34: Italy | B34: 146 | C34: 21 | D34: 9 | E34: 6 | F34: 3 | G34: 107
A35: Latvia | B35: 145 | C35: 17 | D35: 19 | E35: 8 | F35: 19 | G35: 82
A36: Lithuania | B36: 137 | C36: 29 | D36: 10 | E36: 10 | F36: 2 | G36: 86
... A51: Slovenia | B51: 68 | C51: 0 | D51: 5 | E51: 7 | F51: 20 | G51: 36

Sheet 8. Bioenergy crops
A1: Energy crops
A2: Cereal crops
B3: Source | C3: Unit | D3: 2005 | I3: 2010 | N3: 2015 | S3: 2020 | X3: 2025 | AC3: 2030 | AH3: 2035 | AM3: 2040 | AR3: 2045 | AW3: 2050
A4: Total cereal supply | B4: calculated | C4: Mt dry mass | D4: =SUM(D5:D7) -> 279.5 | E4: =SUM(E5:E7) -> 267.4 | F4: =SUM(F5:F7) -> 276.3 | G4: =SUM(G5:G7) -> 299.5 | H4: =SUM(H5:H7) -> 283 | I4: =SUM(I5:I7) -> 270 | J4: =SUM(J5:J7) -> 287.8 | K4: =SUM(K5:K7) -> 270.5 | ... T4: =SUM(T5:T7) -> 297.2
A5: Cereal production | B5: JRC | C5: Mt dry mass | D5: 291.7 | E5: 275.7 | F5: 267.9 | G5: 318.3 | H5: 300.6 | I5: 286.4 | J5: 297 | K5: 287.7 | L5: 311.6 | M5: 329.8 | N5: 314.4 | O5: 303.4 | P5: 310 | Q5: 298 | R5: 322.4 | S5: 307.6 | T5: 320.1
A6: Cereal imports | B6: JRC | C6: Mt dry mass | D6: 12.6 | E6: 14.4 | F6: 29.6 | G6: 16 | H6: 11.4 | I6: 16.5 | J6: 17.6 | K6: 18.2 | L6: 20.7 | M6: 18.7 | N6: 25.2 | O6: 22.5 | P6: 27.2 | Q6: 32.5 | R6: 28.3 | S6: 23.1 | T6: 25.4
A7: Cereal exports | B7: JRC | C7: Mt dry mass | D7: -24.8 | E7: -22.7 | F7: -21.2 | G7: -34.8 | H7: -29 | I7: -32.9 | J7: -26.8 | K7: -35.4 | L7: -46.4 | M7: -53 | N7: -51.8 | O7: -39.9 | P7: -36.2 | Q7: -36.3 | R7: -55.6 | S7: -43.4 | T7: -48.3
A8: Cereal crops for bioenergy | B8: JRC | C8: Mt dry mass | D8: 4.2 | E8: 5 | F8: 5.8 | G8: 6.9 | H8: 8.2 | I8: 8.9 | J8: 10.4 | K8: 9.8 | L8: 10.4 | M8: 11 | N8: 9.9 | O8: 10.5 | P8: 11.2 | Q8: 11.3 | R8: 11.5 | S8: 12.1 | T8: 13.4
A9: % of supply for bioenergy | B9: calculated | C9: % | D9: =D8/D4 -> 0.015026834 | E9: =E8/E4 -> 0.018698579 | F9: =F8/F4 -> 0.020991676 | G9: =G8/G4 -> 0.023038397 | H9: =H8/H4 -> 0.028975265 | I9: =I8/I4 -> 0.032962963 | J9: =J8/J4 -> 0.036136206 | K9: =K8/K4 -> 0.036229205 | ... T9: =T8/T4 -> 0.045087483
A11: oilseed crops and products
B12: Source | C12: Unit | D12: 2005 | I12: 2010 | N12: 2015 | S12: 2020 | X12: 2025 | AC12: 2030 | AH12: 2035 | AM12: 2040 | AR12: 2045 | AW12: 2050
A13: Total vegetable oil supply | B13: JRC | C13: Mt dry mass | D13: 18.406878 | E13: 20.057495 | F13: 20.543321 | G13: 22.641502 | H13: 23.165086 | I13: 22.751517 | J13: 22.997128 | K13: 23.299925 | L13: 25.611764 | M13: 26.3381 | N13: 26.60869 | O13: 26.22001 | P13: 27.721953 | Q13: 27.870534 | R13: 28.247351 | S13: 27.389566 | T13: 26.344101
A14: Vegetable oils for bioenergy | B14: JRC | C14: Mt dry mass | D14: 2.8210611 | E14: 4.0116693 | F14: 5.6960849 | G14: 7.0942504 | H14: 8.6843033 | I14: 9.8552235 | J14: 9.467157 | K14: 9.7826174 | L14: 9.9984164 | M14: 11.089818 | N14: 10.622129 | O14: 9.8576406 | P14: 11.080819 | Q14: 10.987829 | R14: 10.640526 | S14: 10.85356 | T14: 10.491016
A15: % of supply for bioenergy | B15: calculated | C15: % | D15: =D14/D13 -> 0.15326125 | E15: =E14/E13 -> 0.2000085 | F15: =F14/F13 -> 0.27727186 | G15: =G14/G13 -> 0.31332949 | H15: =H14/H13 -> 0.37488758 | I15: =I14/I13 -> 0.43316776 | J15: =J14/J13 -> 0.41166692 | K15: =K14/K13 -> 0.41985618 | ... T15: =T14/T13 -> 0.39823019
A17: CTP data
B18: Source | C18: Unit | D18: 2005 | I18: 2010 | N18: 2015 | S18: 2020 | X18: 2025 | AC18: 2030 | AH18: 2035 | AM18: 2040 | AR18: 2045 | AW18: 2050
A19: Total foodcrop use for biofuels | B19: CTP IA figure 79 | C19: Mtoe | N19: 14 | AC19: 22 | AW19: 6
A21: Graph feed
B22: Source | C22: Unit | D22: 2005 | I22: 2010 | N22: 2015 | S22: 2020 | X22: 2025 | AC22: 2030 | AH22: 2035 | AM22: 2040 | AR22: 2045 | AW22: 2050
A23: Historic total | B23: see above | C23: Mt fresh material | D23: =D24+D25 -> 7.0210611 | E23: =E24+E25 -> 9.0116693 | F23: =F24+F25 -> 11.496085 | G23: =G24+G25 -> 13.99425 | H23: =H24+H25 -> 16.884303 | I23: =I24+I25 -> 18.755224 | J23: =J24+J25 -> 19.867157 | K23: =K24+K25 -> 19.582617 | ... T23: =T24+T25 -> 23.891016
A24: Cereal crops | B24: see above | C24: Mt fresh material | D24: =D8 -> 4.2 | E24: =E8 -> 5 | F24: =F8 -> 5.8 | G24: =G8 -> 6.9 | H24: =H8 -> 8.2 | I24: =I8 -> 8.9 | J24: =J8 -> 10.4 | K24: =K8 -> 9.8 | ... T24: =T8 -> 13.4
A25: Oilseed crops and products | B25: see above | C25: Mt fresh material | D25: =D14 -> 2.8210611 | E25: =E14 -> 4.0116693 | F25: =F14 -> 5.6960849 | G25: =G14 -> 7.0942504 | H25: =H14 -> 8.6843033 | I25: =I14 -> 9.8552235 | J25: =J14 -> 9.467157 | K25: =K14 -> 9.7826174 | ... T25: =T14 -> 10.491016
A26: 2030 benchmark | B26: see above | C26: Mt fresh material | AC26: =AC19/N19*N23 -> 32.24906
A27: 2050 benchmark | B27: see above | C27: Mt fresh material | AW27: =AW19/N19*N23 -> 8.7951982
A28: linear trajectory | T28: 23.891016 | U28: 24.819688 | V28: 25.748359 | W28: 26.677031 | X28: 27.605702 | Y28: 28.534374 | Z28: 29.463045 | AA28: 30.391717 | AB28: 31.320389 | AC28: 32.24906 | AD28: 31.076367 | AE28: 29.903674 | AF28: 28.730981 | AG28: 27.558288 | AH28: 26.385595 | AI28: 25.212902 | AJ28: 24.040209 | AK28: 22.867515 | AL28: 21.694822 | AM28: 20.522129 | AN28: 19.349436 | AO28: 18.176743 | AP28: 17.00405 | AQ28: 15.831357 | AR28: 14.658664 | AS28: 13.485971 | AT28: 12.313278 | AU28: 11.140584 | AV28: 9.9678913 | AW28: 8.7951982
A30: Average 2017-2021 | D30: =AVERAGE(T23-S23,S23-R23,R23-Q23,Q23-P23)*1000 -> 402.54938
A31: Average 2021-2030 | D31: =(U28-T28)*1000 -> 928.67156
A32: Average 2030-2050 | D32: =AN28-AM28 -> -1.1726931
A34: 2015 level | B34: CTP IA part 2 figure 79 | C34: Mtoe | D34: 14
A35: 2030 benchmark | B35: CTP IA part 2 figure 79 | C35: Mtoe | D35: 22
A36: 2050 benchmark | B36: CTP IA part 2 figure 79 | C36: Mtoe | D36: 6
A37: ratio
