Workbook
Name EJ2TWh: 'L8. bioenergy'!$B$118

Sheet 0. LULUCF ranges 2030 and 2050
B1: 2050
A2: 2040 advice MIN | B2: -273
A3: 1,5TECH | B3: -317
A4: 2040 advice MAX | B4: -400
A5: LULUCF Regulation IA | B5: -400
A6: CTP-MIX | B6: -425
A7: 1,5LIFE | B7: -464

Sheet L1. GHG emissions and removals
A1: Total LULUCF emissions and removals
B2: Source | C2: Unit | D2: 2005 | I2: 2010 | N2: 2015 | S2: 2020 | X2: 2025 | AC2: 2030 | AH2: 2035 | AM2: 2040 | AR2: 2045 | AW2: 2050
A3: Total | B3: EEA GHG data viewer | C3: Mt CO2e | D3: =D33/1000 -> -342.10948 | E3: =E33/1000 -> -351.29638 | F3: =F33/1000 -> -300.61729 | G3: =G33/1000 -> -344.26277 | H3: =H33/1000 -> -347.02233 | I3: =I33/1000 -> -352.59019 | J3: =J33/1000 -> -347.2738 | K3: =K33/1000 -> -342.6336 | ... T3: =T33/1000 -> -229.98467 | U3: -243.76729
A4: Forest land | B4: EEA GHG data viewer | C4: Mt CO2e | D4: =D34/1000 -> -414.79156 | E4: =E34/1000 -> -410.56395 | F4: =F34/1000 -> -366.51829 | G4: =G34/1000 -> -431.2254 | H4: =H34/1000 -> -449.76762 | I4: =I34/1000 -> -433.19132 | J4: =J34/1000 -> -426.44365 | K4: =K34/1000 -> -424.19423 | ... T4: =T34/1000 -> -280.82938
A5: Cropland | B5: EEA GHG data viewer | C5: Mt CO2e | D5: =D38/1000 -> 41.885534 | E5: =E38/1000 -> 42.292718 | F5: =F38/1000 -> 46.325952 | G5: =G38/1000 -> 47.762401 | H5: =H38/1000 -> 46.3501 | I5: =I38/1000 -> 36.721832 | J5: =J38/1000 -> 36.216021 | K5: =K38/1000 -> 36.317395 | ... T5: =T38/1000 -> 22.646398
A6: Grassland | B6: EEA GHG data viewer | C6: Mt CO2e | D6: =D42/1000 -> 32.510711 | E6: =E42/1000 -> 27.337326 | F6: =F42/1000 -> 33.798483 | G6: =G42/1000 -> 31.158826 | H6: =H42/1000 -> 32.804095 | I6: =I42/1000 -> 31.258861 | J6: =J42/1000 -> 32.79328 | K6: =K42/1000 -> 33.714568 | ... T6: =T42/1000 -> 24.955054
A7: Wetlands | B7: EEA GHG data viewer | C7: Mt CO2e | D7: =D46/1000 -> 20.342633 | E7: =E46/1000 -> 19.996684 | F7: =F46/1000 -> 18.814036 | G7: =G46/1000 -> 19.020276 | H7: =H46/1000 -> 18.775734 | I7: =I46/1000 -> 20.203806 | J7: =J46/1000 -> 19.884201 | K7: =K46/1000 -> 18.656852 | ... T7: =T46/1000 -> 21.269812
A8: Settlements and other land | B8: EEA GHG data viewer | C8: Mt CO2e | D8: =(D50+D54+D59)/1000 -> 33.109972 | E8: =(E50+E54+E59)/1000 -> 32.212374 | F8: =(F50+F54+F59)/1000 -> 32.992411 | G8: =(G50+G54+G59)/1000 -> 32.784342 | H8: =(H50+H54+H59)/1000 -> 33.007915 | I8: =(I50+I54+I59)/1000 -> 29.589637 | J8: =(J50+J54+J59)/1000 -> 26.990699 | K8: =(K50+K54+K59)/1000 -> 25.943854 | ... T8: =(T50+T54+T59)/1000 -> 28.569496
A9: Harvested Wood Products | B9: EEA GHG data viewer | C9: Mt CO2e | D9: =D58/1000 -> -56.082216 | E9: =E58/1000 -> -63.46251 | F9: =F58/1000 -> -66.939589 | G9: =G58/1000 -> -44.678084 | H9: =H58/1000 -> -29.131363 | I9: =I58/1000 -> -38.111945 | J9: =J58/1000 -> -37.63463 | K9: =K58/1000 -> -33.982435 | ... T9: =T58/1000 -> -47.39009
A10: 2030 benchmark | B10: LULUCF target | C10: Mt CO2e | AC10: -310
A11: 2050 benchmark | B11: 1,5TECH | C11: Mt CO2e | AW11: -400
A12: linear trajectory | T12: -229.98467 | U12: -238.87526 | V12: -247.76585 | W12: -256.65644 | X12: -265.54704 | Y12: -274.43763 | Z12: -283.32822 | AA12: -292.21881 | AB12: -301.10941 | AC12: -310 | AD12: -314.5 | AE12: -319 | AF12: -323.5 | AG12: -328 | AH12: -332.5 | AI12: -337 | AJ12: -341.5 | AK12: -346 | AL12: -350.5 | AM12: -355 | AN12: -359.5 | AO12: -364 | AP12: -368.5 | AQ12: -373 | AR12: -377.5 | AS12: -382 | AT12: -386.5 | AU12: -391 | AV12: -395.5 | AW12: -400
A13: 2040 advice scenarios | AC13: =[1]LULUCF!AO$2 -> -293.8927 | AM13: =[1]LULUCF!AY$2 -> -322.874 | AW13: =[1]LULUCF!BI$2 -> -312.0757
D14: Total LULUCF | E14: forests
A15: Average 2005-2022 | D15: =(U3-D3)/17 -> 5.7848345 | E15: =(T4-D4)/15 -> 8.9308116
A16: Average 2017-2021 | B16: calculated | C16: Mt CO2e | D16: =(T3-P3)/4 -> 4.9528062 | E16: =(T4-P4)/4 -> 7.9457223
A17: Average 2018-2022 | D17: =(U3-Q3)/4 -> 3.5054378
A18: Average 2022-2030 | B18: calculated | C18: Mt CO2e | D18: =(AC10-T3)/9 -> -8.8905926
A19: Average 2023-2030 | D19: =(AC10-U3)/8 -> -8.2790888
A20: Average 2031-2050 | B20: calculated | C20: Mt CO2e | D20: =AE12-AD12 -> -4.5
A31: Raw historic data
B32: Source | C32: Unit | D32: 2005 | I32: 2010 | N32: 2015 | S32: 2020 | X32: 2025 | AC32: 2030 | AH32: 2035 | AM32: 2040 | AR32: 2045 | AW32: 2050
A33: 4 - Land Use, Land-Use Change and Forestry | B33: EEA GHG data viewer | C33: kt CO2e | D33: -342109.48 | E33: -351296.38 | F33: -300617.29 | G33: -344262.77 | H33: -347022.33 | I33: -352590.19 | J33: -347273.8 | K33: -342633.6 | L33: -342604.91 | M33: -327802.72 | N33: -322423.84 | O33: -318486.52 | P33: -249795.89 | Q33: -257789.04 | R33: -247317.62 | S33: -241038.06 | T33: -229984.67
A34: 4.A - Forest Land | B34: EEA GHG data viewer | C34: kt CO2e | D34: -414791.56 | E34: -410563.95 | F34: -366518.29 | G34: -431225.4 | H34: -449767.62 | I34: -433191.32 | J34: -426443.65 | K34: -424194.23 | L34: -440719.83 | M34: -401752.84 | N34: -390728.12 | O34: -382319.48 | P34: -312612.27 | Q34: -306983.57 | R34: -293839.66 | S34: -291708.25 | T34: -280829.38 | AH34: 0
A35: 4.A Emissions/Removal 4(II) Emissions and removals from drainage and rewetting and other management of organic and mineral soils | B35: EEA GHG data viewer | C35: kt CO2e | D35: 6164.5346 | E35: 6134.6956 | F35: 6093.7787 | G35: 5995.6613 | H35: 5923.1604 | I35: 5876.0253 | J35: 5774.7116 | K35: 5697.0937 | L35: 5674.6291 | M35: 5682.7152 | N35: 5711.3328 | O35: 5731.582 | P35: 5822.2115 | Q35: 5942.1408 | R35: 5986.9323 | S35: 5974.1736 | T35: 5998.4522
A36: 4.A.1 - Forest Land remaining forest land | B36: EEA GHG data viewer | C36: kt CO2e | D36: -367661.57 | E36: -361722.76 | F36: -320959.79 | G36: -380485.51 | H36: -398817.46 | I36: -382951.34 | J36: -378357.98 | K36: -379233.64 | L36: -395006.85 | M36: -357531.23 | N36: -346994.36 | O36: -340275.66 | P36: -275499.83 | Q36: -268577.79 | R36: -257172.34 | S36: -254999.58 | T36: -245522.86
A37: 4.A.2 - Land converted to forest land | B37: EEA GHG data viewer | C37: kt CO2e | D37: -53294.525 | E37: -54975.885 | F37: -51652.277 | G37: -56735.561 | H37: -56873.315 | I37: -56116.005 | J37: -53860.385 | K37: -50657.691 | L37: -51387.608 | M37: -49904.325 | N37: -49445.086 | O37: -47775.398 | P37: -42934.649 | Q37: -44347.914 | R37: -42654.25 | S37: -42682.845 | T37: -41304.978
A38: 4.B - Cropland | B38: EEA GHG data viewer | C38: kt CO2e | D38: 41885.534 | E38: 42292.718 | F38: 46325.952 | G38: 47762.401 | H38: 46350.1 | I38: 36721.832 | J38: 36216.021 | K38: 36317.395 | L38: 38971.129 | M38: 36049.323 | N38: 30257.074 | O38: 25855.204 | P38: 27354.586 | Q38: 25495.22 | R38: 21646.503 | S38: 22368.512 | T38: 22646.398
A39: 4.B Emissions/Removal 4(II) Emissions and removals from drainage and rewetting and other management of organic and mineral soils | B39: EEA GHG data viewer | C39: kt CO2e | D39: 1651.8694 | E39: 1694.8861 | F39: 1744.0836 | G39: 1789.2601 | H39: 1818.8711 | I39: 1765.6166 | J39: 1813.6047 | K39: 1763.0616 | L39: 1750.7773 | M39: 1769.0881 | N39: 1751.156 | O39: 1752.7805 | P39: 1768.536 | Q39: 1763.6206 | R39: 1758.0616 | S39: 1754.9709 | T39: 1773.9593
A40: 4.B.1 - Cropland remaining cropland | B40: EEA GHG data viewer | C40: kt CO2e | D40: 12655.327 | E40: 13196.996 | F40: 17513.827 | G40: 18553.757 | H40: 18278.44 | I40: 10101.065 | J40: 10615.392 | K40: 11426.706 | L40: 13475.572 | M40: 13976.749 | N40: 7172.1112 | O40: 4741.9902 | P40: 6168.3838 | Q40: 5440.6095 | R40: 3091.2412 | S40: 5303.8136 | T40: 5160.8284
A41: 4.B.2 - Land converted to cropland | B41: EEA GHG data viewer | C41: kt CO2e | D41: 27578.338 | E41: 27400.837 | F41: 27068.042 | G41: 27419.384 | H41: 26252.788 | I41: 24855.15 | J41: 23787.025 | K41: 23127.628 | L41: 23744.78 | M41: 20303.486 | N41: 21333.807 | O41: 19360.433 | P41: 19417.666 | Q41: 18290.99 | R41: 16797.2 | S41: 15309.727 | T41: 15711.61
A42: 4.C - Grassland | B42: EEA GHG data viewer | C42: kt CO2e | D42: 32510.711 | E42: 27337.326 | F42: 33798.483 | G42: 31158.826 | H42: 32804.095 | I42: 31258.861 | J42: 32793.28 | K42: 33714.568 | L42: 40699.16 | M42: 23694.883 | N42: 21547.003 | O42: 21169.805 | P42: 25072.843 | Q42: 16449.56 | R42: 18244.112 | S42: 18543.53 | T42: 24955.054
A43: 4.C Emissions/Removal 4(II) Emissions and removals from drainage and rewetting and other management of organic and mineral soils | B43: EEA GHG data viewer | C43: kt CO2e | D43: 2451.1526 | E43: 2459.2736 | F43: 2471.8795 | G43: 2483.3087 | H43: 2488.7693 | I43: 2560.1237 | J43: 2513.1334 | K43: 2514.4881 | L43: 2516.0064 | M43: 2514.5551 | N43: 2534.1426 | O43: 2539.9283 | P43: 2556.3404 | Q43: 2582.0536 | R43: 2571.9702 | S43: 2604.8196 | T43: 2558.8339
A44: 4.C.1 - Grassland remaining grassland | B44: EEA GHG data viewer | C44: kt CO2e | D44: 36858.535 | E44: 32135.397 | F44: 38101.62 | G44: 38126.853 | H44: 38781.632 | I44: 36320.437 | J44: 37049.807 | K44: 39519.465 | L44: 35689.767 | M44: 29354.73 | N44: 28964.728 | O44: 29609.633 | P44: 33929.288 | Q44: 26908.439 | R44: 27076.728 | S44: 30502.277 | T44: 35626.801
A45: 4.C.2 - Land converted to grassland | B45: EEA GHG data viewer | C45: kt CO2e | D45: -6798.9768 | E45: -7257.3441 | F45: -6775.0168 | G45: -9451.3358 | H45: -8466.3069 | I45: -7621.7 | J45: -6769.6595 | K45: -8319.3843 | L45: 2493.386 | M45: -8174.4029 | N45: -9951.8678 | O45: -10979.756 | P45: -11412.785 | Q45: -13040.933 | R45: -11404.586 | S45: -14563.567 | T45: -13230.581
A46: 4.D - Wetlands | B46: EEA GHG data viewer | C46: kt CO2e | D46: 20342.633 | E46: 19996.684 | F46: 18814.036 | G46: 19020.276 | H46: 18775.734 | I46: 20203.806 | J46: 19884.201 | K46: 18656.852 | L46: 21154.751 | M46: 20163.324 | N46: 22092.727 | O46: 20224.48 | P46: 21688.377 | Q46: 21436.103 | R46: 20796.377 | S46: 21449.869 | T46: 21269.812
... A59: 4.H - Other LULUCF | B59: EEA GHG data viewer | C59: kt CO2e | D59: 741.44867 | E59: 673.57027 | F59: 618.72911 | G59: 574.04627 | H59: 537.26648 | I59: 506.79385 | J59: 483.69279 | K59: 464.68615 | L59: 448.97239 | M59: 435.92706 | N59: 425.13817 | O59: 415.61239 | P59: 407.64986 | Q59: 400.97974 | R59: 395.44853 | S59: 390.88163 | T59: 387.93264
A63: 2050 benchmark data
B64: Source | C64: Unit | D64: 2005 | I64: 2010 | N64: 2015 | S64: 2020 | X64: 2025 | AC64: 2030 | AH64: 2035 | AM64: 2040 | AR64: 2045 | AW64: 2050
A65: 1,5TECH (EU28) | B65: ACP4A in depth analysis figure 91 | C65: Mt CO2e | AW65: -316.9
...

Sheet L2. Areas per land-use category
B2: Source | C2: Unit | D2: 2005 | I2: 2010 | N2: 2015 | S2: 2020 | X2: 2025 | AC2: 2030 | AH2: 2035 | AM2: 2040 | AR2: 2045 | AW2: 2050
A3: Other | B3: EU CRF | C3: Mha | D3: =(D45+D46)/1000 -> 9.7953991 | E3: =(E45+E46)/1000 -> 9.7959074 | F3: =(F45+F46)/1000 -> 9.7572115 | G3: =(G45+G46)/1000 -> 9.7458752 | H3: =(H45+H46)/1000 -> 9.7467353 | I3: =(I45+I46)/1000 -> 9.743464 | J3: =(J45+J46)/1000 -> 9.737071 | K3: =(K45+K46)/1000 -> 9.7332284 | ... T3: =(T45+T46)/1000 -> 9.6581874
A4: Wetland | B4: EU CRF | C4: Mha | D4: =(D42+D43)/1000 -> 23.617011 | E4: =(E42+E43)/1000 -> 23.643923 | F4: =(F42+F43)/1000 -> 23.650087 | G4: =(G42+G43)/1000 -> 23.659178 | H4: =(H42+H43)/1000 -> 23.748532 | I4: =(I42+I43)/1000 -> 23.788149 | J4: =(J42+J43)/1000 -> 23.812529 | K4: =(K42+K43)/1000 -> 23.830707 | ... T4: =(T42+T43)/1000 -> 23.865851
A5: Settlements | B5: EU CRF | C5: Mha | D5: =D44/1000 -> 24.878754 | E5: =E44/1000 -> 25.279947 | F5: =F44/1000 -> 25.511878 | G5: =G44/1000 -> 25.737735 | H5: =H44/1000 -> 25.974293 | I5: =I44/1000 -> 26.206306 | J5: =J44/1000 -> 26.434756 | K5: =K44/1000 -> 26.666697 | ... T5: =T44/1000 -> 28.147401
A6: Grassland | B6: EU CRF | C6: Mha | D6: =(D40+D41)/1000 -> 73.526082 | E6: =(E40+E41)/1000 -> 73.406397 | F6: =(F40+F41)/1000 -> 73.377404 | G6: =(G40+G41)/1000 -> 73.286862 | H6: =(H40+H41)/1000 -> 73.222142 | I6: =(I40+I41)/1000 -> 73.43947 | J6: =(J40+J41)/1000 -> 73.382588 | K6: =(K40+K41)/1000 -> 73.26315 | ... T6: =(T40+T41)/1000 -> 73.200879
A7: Cropland | B7: EU CRF | C7: Mha | D7: =D39/1000 -> 127.46156 | E7: =E39/1000 -> 126.48799 | F7: =F39/1000 -> 126.04921 | G7: =G39/1000 -> 125.70024 | H7: =H39/1000 -> 125.23159 | I7: =I39/1000 -> 124.57823 | J7: =J39/1000 -> 124.2133 | K7: =K39/1000 -> 123.91357 | ... T7: =T39/1000 -> 120.93348
A8: Forest land | B8: EU CRF | C8: Mha | D8: =(D37+D38)/1000 -> 164.26181 | E8: =(E37+E38)/1000 -> 164.92577 | F8: =(F37+F38)/1000 -> 165.19464 | G8: =(G37+G38)/1000 -> 165.40985 | H8: =(H37+H38)/1000 -> 165.61601 | I8: =(I37+I38)/1000 -> 165.78413 | J8: =(J37+J38)/1000 -> 165.95999 | K8: =(K37+K38)/1000 -> 166.13248 | ... T8: =(T37+T38)/1000 -> 167.73412
D10: 2005-2021 change | E10: 2005-2021 change
A11: Cropland | D11: -5.9291396 | E11: -0.051216051
A12: Grassland | D12: -0.3580194 | E12: -0.0044229587
A13: Other | D13: -0.12029962 | E13: -0.014007768
A14: Wetland | D14: 0.23065256 | E14: 0.010536496
A15: Settlements | D15: 3.0618893 | E15: 0.13138304
A16: Forest land | D16: 3.1142124 | E16: 0.021138821
A18: Average 2017-2021
A19: Forests | D19: =AVERAGE(T8-S8,S8-R8,R8-Q8,Q8-P8)*1000 -> 194.42641
A20: Grasslands | D20: =AVERAGE(T6-S6,S6-R6,R6-Q6,Q6-P6)*1000 -> 43.914757
A21: Wetlands | D21: =AVERAGE(T4-S4,S4-R4,R4-Q4,Q4-P4)*400 -> -0.37606847
A35: CRF data
B36: Source | C36: Unit | D36: 2005 | I36: 2010 | N36: 2015 | S36: 2020 | X36: 2025 | AC36: 2030 | AH36: 2035 | AM36: 2040 | AR36: 2045 | AW36: 2050
A37: Forest land (managed) | B37: EU CRF | C37: kha | D37: =[2]Table4.1!$L7 -> 162122.34 | E37: =[3]Table4.1!$B$17 -> 162781.6 | F37: =[4]Table4.1!$B$17 -> 163046.6 | G37: =[5]Table4.1!$B$17 -> 163258.17 | H37: =[6]Table4.1!$B$17 -> 163460.66 | I37: =[7]Table4.1!$B$17 -> 163624.9 | J37: =[8]Table4.1!$B$17 -> 163797.41 | K37: =[9]Table4.1!$B$17 -> 163966.02 | L37: =[10]Table4.1!$B$17 -> 164114.87 | M37: =[11]Table4.1!$B$17 -> 164252.55 | N37: =[12]Table4.1!$B$17 -> 164399.67 | O37: =[13]Table4.1!$B$17 -> 164550.41 | P37: =[14]Table4.1!$B$17 -> 164770.56 | Q37: =[15]Table4.1!$B$17 -> 164951.34 | R37: =[16]Table4.1!$B$17 -> 165143.47 | S37: =[17]Table4.1!$B$17 -> 165324.48 | T37: =[18]Table4.1!$B$17 -> 165531.79
A38: Forest land (unmanaged) | B38: EU CRF | C38: kha | D38: =[2]Table4.1!$L8 -> 2139.479 | E38: =[3]Table4.1!$C$17 -> 2144.1629 | F38: =[4]Table4.1!$C$17 -> 2148.0414 | G38: =[5]Table4.1!$C$17 -> 2151.6759 | H38: =[6]Table4.1!$C$17 -> 2155.3559 | I38: =[7]Table4.1!$C$17 -> 2159.2345 | J38: =[8]Table4.1!$C$17 -> 2162.5818 | K38: =[9]Table4.1!$C$17 -> 2166.4603 | L38: =[10]Table4.1!$C$17 -> 2170.3389 | M38: =[11]Table4.1!$C$17 -> 2174.2174 | N38: =[12]Table4.1!$C$17 -> 2178.096 | O38: =[13]Table4.1!$C$17 -> 2181.9745 | P38: =[14]Table4.1!$C$17 -> 2185.8531 | Q38: =[15]Table4.1!$C$17 -> 2189.6682 | R38: =[16]Table4.1!$C$17 -> 2193.6347 | S38: =[17]Table4.1!$C$17 -> 2197.4135 | T38: =[18]Table4.1!$C$17 -> 2202.3296
A39: Cropland | B39: EU CRF | C39: kha | D39: =[2]Table4.1!$L9 -> 127461.56 | E39: =[3]Table4.1!$D$17 -> 126487.99 | F39: =[4]Table4.1!$D$17 -> 126049.21 | G39: =[5]Table4.1!$D$17 -> 125700.24 | H39: =[6]Table4.1!$D$17 -> 125231.59 | I39: =[7]Table4.1!$D$17 -> 124578.23 | J39: =[8]Table4.1!$D$17 -> 124213.3 | K39: =[9]Table4.1!$D$17 -> 123913.57 | L39: =[10]Table4.1!$D$17 -> 123715.73 | M39: =[11]Table4.1!$D$17 -> 123274.82 | N39: =[12]Table4.1!$D$17 -> 123050.77 | O39: =[13]Table4.1!$D$17 -> 122747.95 | P39: =[14]Table4.1!$D$17 -> 122455.46 | Q39: =[15]Table4.1!$D$17 -> 121714.12 | R39: =[16]Table4.1!$D$17 -> 121340.89 | S39: =[17]Table4.1!$D$17 -> 121299.76 | T39: =[18]Table4.1!$D$17 -> 120933.48
A40: Grassland (managed) | B40: EU CRF | C40: kha | D40: =[2]Table4.1!$L10 -> 73233.905 | E40: =[3]Table4.1!$E$17 -> 73064.111 | F40: =[4]Table4.1!$E$17 -> 73014.187 | G40: =[5]Table4.1!$E$17 -> 72892.204 | H40: =[6]Table4.1!$E$17 -> 72804.312 | I40: =[7]Table4.1!$E$17 -> 72994.615 | J40: =[8]Table4.1!$E$17 -> 72936.468 | K40: =[9]Table4.1!$E$17 -> 72818.314 | L40: =[10]Table4.1!$E$17 -> 72738.133 | M40: =[11]Table4.1!$E$17 -> 72765.106 | N40: =[12]Table4.1!$E$17 -> 72719.233 | O40: =[13]Table4.1!$E$17 -> 72720.537 | P40: =[14]Table4.1!$E$17 -> 72665.824 | Q40: =[15]Table4.1!$E$17 -> 73063.539 | R40: =[16]Table4.1!$E$17 -> 73113.613 | S40: =[17]Table4.1!$E$17 -> 72824.951 | T40: =[18]Table4.1!$E$17 -> 72868.978
A41: Grassland (unmanaged) | B41: EU CRF | C41: kha | D41: =[2]Table4.1!$L11 -> 292.17687 | E41: =[3]Table4.1!$F$17 -> 342.28611 | F41: =[4]Table4.1!$F$17 -> 363.21691 | G41: =[5]Table4.1!$F$17 -> 394.65834 | H41: =[6]Table4.1!$F$17 -> 417.82967 | I41: =[7]Table4.1!$F$17 -> 444.85468 | J41: =[8]Table4.1!$F$17 -> 446.12019 | K41: =[9]Table4.1!$F$17 -> 444.83659 | L41: =[10]Table4.1!$F$17 -> 425.56246 | M41: =[11]Table4.1!$F$17 -> 407.09792 | N41: =[12]Table4.1!$F$17 -> 403.94628 | O41: =[13]Table4.1!$F$17 -> 382.16146 | P41: =[14]Table4.1!$F$17 -> 359.39567 | Q41: =[15]Table4.1!$F$17 -> 357.14834 | R41: =[16]Table4.1!$F$17 -> 348.91009 | S41: =[17]Table4.1!$F$17 -> 341.76243 | T41: =[18]Table4.1!$F$17 -> 331.90077
A42: Wetlands (managed) | B42: EU CRF | C42: kha | D42: =[2]Table4.1!$L12 -> 6610.8309 | E42: =[3]Table4.1!$G$17 -> 6623.7312 | F42: =[4]Table4.1!$G$17 -> 6642.9447 | G42: =[5]Table4.1!$G$17 -> 6658.7118 | H42: =[6]Table4.1!$G$17 -> 6676.6662 | I42: =[7]Table4.1!$G$17 -> 6698.8206 | J42: =[8]Table4.1!$G$17 -> 6718.8639 | K42: =[9]Table4.1!$G$17 -> 6738.2182 | L42: =[10]Table4.1!$G$17 -> 6773.2805 | M42: =[11]Table4.1!$G$17 -> 6780.2205 | N42: =[12]Table4.1!$G$17 -> 6810.1129 | O42: =[13]Table4.1!$G$17 -> 6823.1441 | P42: =[14]Table4.1!$G$17 -> 6826.0969 | Q42: =[15]Table4.1!$G$17 -> 6823.151 | R42: =[16]Table4.1!$G$17 -> 6827.2175 | S42: =[17]Table4.1!$G$17 -> 6831.6723 | T42: =[18]Table4.1!$G$17 -> 6828.0887
A43: Wetlands (unmanaged) | B43: EU CRF | C43: kha | D43: =[2]Table4.1!$L13 -> 17006.18 | E43: =[3]Table4.1!$H$17 -> 17020.191 | F43: =[4]Table4.1!$H$17 -> 17007.143 | G43: =[5]Table4.1!$H$17 -> 17000.466 | H43: =[6]Table4.1!$H$17 -> 17071.866 | I43: =[7]Table4.1!$H$17 -> 17089.329 | J43: =[8]Table4.1!$H$17 -> 17093.665 | K43: =[9]Table4.1!$H$17 -> 17092.488 | L43: =[10]Table4.1!$H$17 -> 17044.261 | M43: =[11]Table4.1!$H$17 -> 17057.626 | N43: =[12]Table4.1!$H$17 -> 17037.653 | O43: =[13]Table4.1!$H$17 -> 17032.965 | P43: =[14]Table4.1!$H$17 -> 17043.515 | Q43: =[15]Table4.1!$H$17 -> 17050.576 | R43: =[16]Table4.1!$H$17 -> 17047.545 | S43: =[17]Table4.1!$H$17 -> 17051.069 | T43: =[18]Table4.1!$H$17 -> 17037.763
A44: Settlements | B44: EU CRF | C44: kha | D44: =[2]Table4.1!$L14 -> 24878.754 | E44: =[3]Table4.1!$I$17 -> 25279.947 | F44: =[4]Table4.1!$I$17 -> 25511.878 | G44: =[5]Table4.1!$I$17 -> 25737.735 | H44: =[6]Table4.1!$I$17 -> 25974.293 | I44: =[7]Table4.1!$I$17 -> 26206.306 | J44: =[8]Table4.1!$I$17 -> 26434.756 | K44: =[9]Table4.1!$I$17 -> 26666.697 | L44: =[10]Table4.1!$I$17 -> 26822.588 | M44: =[11]Table4.1!$I$17 -> 27087.879 | N44: =[12]Table4.1!$I$17 -> 27213.455 | O44: =[13]Table4.1!$I$17 -> 27392.642 | P44: =[14]Table4.1!$I$17 -> 27534.107 | Q44: =[15]Table4.1!$I$17 -> 27698.438 | R44: =[16]Table4.1!$I$17 -> 27847.688 | S44: =[17]Table4.1!$I$17 -> 28005.231 | T44: =[18]Table4.1!$I$17 -> 28147.401
A45: Other land | B45: EU CRF | C45: kha | D45: =[2]Table4.1!$L15 -> 9473.0509 | E45: =[3]Table4.1!$J$17 -> 9473.5592 | F45: =[4]Table4.1!$J$17 -> 9434.8633 | G45: =[5]Table4.1!$J$17 -> 9423.527 | H45: =[6]Table4.1!$J$17 -> 9424.3871 | I45: =[7]Table4.1!$J$17 -> 9421.1158 | J45: =[8]Table4.1!$J$17 -> 9414.7228 | K45: =[9]Table4.1!$J$17 -> 9410.8803 | L45: =[10]Table4.1!$J$17 -> 9412.8076 | M45: =[11]Table4.1!$J$17 -> 9418.1316 | N45: =[12]Table4.1!$J$17 -> 9404.912 | O45: =[13]Table4.1!$J$17 -> 9386.1299 | P45: =[14]Table4.1!$J$17 -> 9377.0807 | Q45: =[15]Table4.1!$J$17 -> 9369.9707 | R45: =[16]Table4.1!$J$17 -> 9354.9055 | S45: =[17]Table4.1!$J$17 -> 9341.6244 | T45: =[18]Table4.1!$J$17 -> 9335.8392
A46: Total unmanaged land | B46: EU CRF | C46: kha | D46: =[2]Table4.1!$L16 -> 322.3482 | E46: =[3]Table4.1!$K$17 -> 322.3482 | F46: =[4]Table4.1!$K$17 -> 322.3482 | G46: =[5]Table4.1!$K$17 -> 322.3482 | H46: =[6]Table4.1!$K$17 -> 322.3482 | I46: =[7]Table4.1!$K$17 -> 322.3482 | J46: =[8]Table4.1!$K$17 -> 322.3482 | K46: =[9]Table4.1!$K$17 -> 322.3482 | L46: =[10]Table4.1!$K$17 -> 322.3482 | M46: =[11]Table4.1!$K$17 -> 322.3482 | N46: =[12]Table4.1!$K$17 -> 322.3482 | O46: =[13]Table4.1!$K$17 -> 322.3482 | P46: =[14]Table4.1!$K$17 -> 322.3482 | Q46: =[15]Table4.1!$K$17 -> 322.3482 | R46: =[16]Table4.1!$K$17 -> 322.3482 | S46: =[17]Table4.1!$K$17 -> 322.3482 | T46: =[18]Table4.1!$K$17 -> 322.3482

Sheet L3 & L4. A-deforestation
A1: De- and aforestation
B2: Source | C2: Unit | D2: 2005 | I2: 2010 | N2: 2015 | S2: 2020 | X2: 2025 | AC2: 2030 | AH2: 2035 | AM2: 2040 | AR2: 2045 | AW2: 2050
A3: Deforestation | B3: CRF table | C3: kha | D3: =-SUM(D29:D33) -> -125.94032 | E3: =-SUM(E29:E33) -> -129.78837 | F3: =-SUM(F29:F33) -> -138.54181 | G3: =-SUM(G29:G33) -> -122.74189 | H3: =-SUM(H29:H33) -> -127.4806 | I3: =-SUM(I29:I33) -> -132.69654 | J3: =-SUM(J29:J33) -> -112.73472 | K3: =-SUM(K29:K33) -> -110.29006 | ... T3: =-SUM(T29:T33) -> -114.52995
A4: Afforestation | B4: CRF table | C4: kha | D4: =SUM(D45:D49) -> 487.99763 | E4: =SUM(E45:E49) -> 435.65374 | F4: =SUM(F45:F49) -> 407.43344 | G4: =SUM(G45:G49) -> 337.95296 | H4: =SUM(H45:H49) -> 334.02645 | I4: =SUM(I45:I49) -> 300.95644 | J4: =SUM(J45:J49) -> 288.30719 | K4: =SUM(K45:K49) -> 282.84221 | ... T4: =SUM(T45:T49) -> 326.75899
A5: Net afforestation | B5: CRF table | C5: kha | D5: =D4+D3 -> 362.05732 | E5: =E4+E3 -> 305.86537 | F5: =F4+F3 -> 268.89164 | G5: =G4+G3 -> 215.21107 | H5: =H4+H3 -> 206.54586 | I5: =I4+I3 -> 168.25989 | J5: =J4+J3 -> 175.57247 | K5: =K4+K3 -> 172.55215 | ... T5: =T4+T3 -> 212.22904
A8: Average 2017-2021
A9: deforestation | D9: =AVERAGE(T3-S3,S3-R3,R3-Q3,Q3-P3)*-1 -> -1.1489287
A10: afforestation | D10: =AVERAGE(T4-S4,S4-R4,R4-Q4,Q4-P4) -> -4.1191059
A26: Raw GHG inventory data
A27: Deforestation
B28: Source | C28: Unit | D28: 2005 | I28: 2010 | N28: 2015 | S28: 2020 | X28: 2025 | AC28: 2030 | AH28: 2035 | AM28: 2040 | AR28: 2045 | AW28: 2050
A29: forest to cropland | B29: CRF table | C29: kha | D29: =[2]Table4.1!$D$7 -> 33.318239 | E29: =[3]Table4.1!$D$7 -> 31.681326 | F29: =[4]Table4.1!$D$7 -> 23.241787 | G29: =[5]Table4.1!$D$7 -> 22.341294 | H29: =[6]Table4.1!$D$7 -> 23.88165 | I29: =[7]Table4.1!$D$7+[7]Table4.1!$D$8 -> 21.481525 | J29: =[8]Table4.1!$D$7 -> 23.159099 | K29: =[9]Table4.1!$D$7 -> 20.781829 | L29: =[10]Table4.1!$D$7 -> 28.133102 | M29: =[11]Table4.1!$D$7 -> 24.841272 | N29: =[12]Table4.1!$D$7 -> 27.792474 | O29: =[13]Table4.1!$D$7 -> 27.518626 | P29: =[14]Table4.1!$D$7+[14]Table4.1!$D$8 -> 26.334292 | Q29: =[15]Table4.1!$D$7+[15]Table4.1!$D$8 -> 26.457955 | R29: =[16]Table4.1!$D$7+[16]Table4.1!$D$8 -> 26.449009 | S29: =[17]Table4.1!$D$7+[17]Table4.1!$D$8 -> 26.555964 | T29: =[18]Table4.1!$D$7+[18]Table4.1!$D$8 -> 26.378856
A30: forest to grassland | B30: CRF table | C30: kha | D30: =[2]Table4.1!$E$7 -> 40.914585 | E30: =[3]Table4.1!$E$7+[3]Table4.1!$E$8 -> 41.684668 | F30: =[4]Table4.1!$E$7+[4]Table4.1!$E$8 -> 49.068145 | G30: =[5]Table4.1!$E$7+[5]Table4.1!$E$8 -> 39.056935 | H30: =[6]Table4.1!$E$7+[6]Table4.1!$E$8 -> 37.755441 | I30: =[7]Table4.1!$E$7+[7]Table4.1!$E$8 -> 43.566804 | J30: =[8]Table4.1!$E$7 -> 36.565503 | K30: =[9]Table4.1!$E$7+[9]Table4.1!$E$8 -> 33.480942 | L30: =[10]Table4.1!$E$7 -> 60.175513 | M30: =[11]Table4.1!$E$7 -> 42.64301 | N30: =[12]Table4.1!$E$7 -> 39.76132 | O30: =[13]Table4.1!$E$7+[13]Table4.1!$E$8 -> 41.401094 | P30: =[14]Table4.1!$E$7+[14]Table4.1!$E$8 -> 35.725452 | Q30: =[15]Table4.1!$E$7+[15]Table4.1!$E$8 -> 35.405807 | R30: =[16]Table4.1!$E$7+[16]Table4.1!$E$8 -> 34.638349 | S30: =[17]Table4.1!$E$7+[17]Table4.1!$E$8 -> 34.536476 | T30: =[18]Table4.1!$E$7+[18]Table4.1!$E$8 -> 35.368072
A31: forest to wetland | B31: CRF table | C31: kha | D31: =[2]Table4.1!$G$7 -> 5.8321122 | E31: =[3]Table4.1!$G$7+[3]Table4.1!$H$7+[3]Table4.1!$G$8 -> 6.8385389 | F31: =[4]Table4.1!$G$7+[4]Table4.1!$H$7+[4]Table4.1!$G$8 -> 10.098348 | G31: =[5]Table4.1!$G$7+[5]Table4.1!$H$7 -> 11.671909 | H31: =[6]Table4.1!$G$7+[6]Table4.1!$H$7 -> 10.409403 | I31: =[7]Table4.1!$G$7+[7]Table4.1!$H$7 -> 15.13695 | J31: =[8]Table4.1!$G$7+[8]Table4.1!$H$7 -> 7.4796061 | K31: =[9]Table4.1!$G$7+[9]Table4.1!$H$7+[9]Table4.1!$G$8 -> 9.6357332 | L31: =[10]Table4.1!$G$7+[10]Table4.1!$H$7 -> 7.4343511 | M31: =[11]Table4.1!$G$7+[11]Table4.1!$H$7 -> 8.5637366 | N31: =[12]Table4.1!$G$7+[12]Table4.1!$H$7 -> 7.8538326 | O31: =[13]Table4.1!$G$7+[13]Table4.1!$H$7 -> 14.194243 | P31: =[14]Table4.1!$G$7+[14]Table4.1!$H$7 -> 12.062808 | Q31: =[15]Table4.1!$G$7+[15]Table4.1!$H$7+[15]Table4.1!$G$8 -> 2.9885184 | R31: =[16]Table4.1!$G$7+[16]Table4.1!$H$7+[16]Table4.1!$G$8 -> 4.1072255 | S31: =[17]Table4.1!$G$7+[17]Table4.1!$H$7 -> 4.5025449 | T31: =[18]Table4.1!$G$7+[18]Table4.1!$H$7+[18]Table4.1!$G$8 -> 4.3155621
A32: forest to settlement | B32: CRF table | C32: kha | D32: =[2]Table4.1!$I$7+[2]Table4.1!$I$8 -> 43.865365 | E32: =[3]Table4.1!$I$7+[3]Table4.1!$I$8 -> 45.752063 | F32: =[4]Table4.1!$I$7+[4]Table4.1!$I$8 -> 52.582624 | G32: =[5]Table4.1!$I$7+[5]Table4.1!$I$8 -> 47.235624 | H32: =[6]Table4.1!$I$7+[6]Table4.1!$I$8 -> 50.782658 | I32: =[7]Table4.1!$I$7+[7]Table4.1!$I$8 -> 46.928714 | J32: =[8]Table4.1!$I$7+[8]Table4.1!$I$8 -> 43.186369 | K32: =[9]Table4.1!$I$7+[9]Table4.1!$I$8 -> 44.09906 | L32: =[10]Table4.1!$I$7+[10]Table4.1!$I$8 -> 43.754948 | M32: =[11]Table4.1!$I$7+[11]Table4.1!$I$8 -> 46.77923 | N32: =[12]Table4.1!$I$7+[12]Table4.1!$I$8 -> 44.405465 | O32: =[13]Table4.1!$I$7+[13]Table4.1!$I$8 -> 57.933724 | P32: =[14]Table4.1!$I$7+[14]Table4.1!$I$8 -> 41.870437 | Q32: =[15]Table4.1!$I$7+[15]Table4.1!$I$8 -> 44.663782 | R32: =[16]Table4.1!$I$7+[16]Table4.1!$I$8 -> 44.485226 | S32: =[17]Table4.1!$I$7+[17]Table4.1!$I$8 -> 42.870649 | T32: =[18]Table4.1!$I$7+[18]Table4.1!$I$8 -> 44.159012
A33: forest to other land | B33: CRF table | C33: kha | D33: =[2]Table4.1!$J$7+[2]Table4.1!$J$8 -> 2.0100157 | E33: =[3]Table4.1!$J$7+[3]Table4.1!$J$8 -> 3.8317784 | F33: =[4]Table4.1!$J$7+[4]Table4.1!$J$8 -> 3.5509022 | G33: =[5]Table4.1!$J$7+[5]Table4.1!$J$8 -> 2.4361246 | H33: =[6]Table4.1!$J$7+[6]Table4.1!$J$8 -> 4.6514444 | I33: =[7]Table4.1!$J$7+[7]Table4.1!$J$8 -> 5.582552 | J33: =[8]Table4.1!$J$7+[8]Table4.1!$J$8 -> 2.3441441 | K33: =[9]Table4.1!$J$7+[9]Table4.1!$J$8 -> 2.2924981 | L33: =[10]Table4.1!$J$7+[10]Table4.1!$J$8 -> 2.209566 | M33: =[11]Table4.1!$J$7+[11]Table4.1!$J$8 -> 2.3124362 | N33: =[12]Table4.1!$J$7+[12]Table4.1!$J$8 -> 1.9512364 | O33: =[13]Table4.1!$J$7+[13]Table4.1!$J$8 -> 2.3955825 | P33: =[14]Table4.1!$J$7+[14]Table4.1!$J$8 -> 3.1326747 | Q33: =[15]Table4.1!$J$7+[15]Table4.1!$J$8 -> 5.6739981 | R33: =[16]Table4.1!$J$7+[16]Table4.1!$J$8 -> 4.3038935 | S33: =[17]Table4.1!$J$7+[17]Table4.1!$J$8 -> 4.4524894 | T33: =[18]Table4.1!$J$7+[18]Table4.1!$J$8 -> 4.3084458
A35: forest to cropland | B35: CRF table | C35: kt CO2e | D35: =[2]Table4.B!$R$13 -> 9347.7353 | E35: =[19]Table4.B!$R$13 -> 9144.2417 | F35: =[20]Table4.B!$R$13 -> 8370.0781 | G35: =[21]Table4.B!$R$13 -> 8217.8589 | H35: =[22]Table4.B!$R$13 -> 8614.6591 | I35: =[23]Table4.B!$R$13 -> 8534.2282 | J35: =[24]Table4.B!$R$13 -> 8864.5076 | K35: =[25]Table4.B!$R$13 -> 8368.9978 | L35: =[26]Table4.B!$R$13 -> 10325.668 | M35: =[27]Table4.B!$R$13 -> 9250.1171 | N35: =[28]Table4.B!$R$13 -> 9770.222 | O35: =[29]Table4.B!$R$13 -> 9168.769 | P35: =[30]Table4.B!$R$13 -> 8692.2913 | Q35: =[31]Table4.B!$R$13 -> 8144.3454 | R35: =[32]Table4.B!$R$13 -> 8106.2915 | S35: =[33]Table4.B!$R$13 -> 7864.6216 | T35: =[18]Table4.B!$R$13 -> 8110.8854
A36: forest to grassland | B36: CRF table | C36: kt CO2e | D36: =[2]Table4.C!$R$13 -> 10290.664 | E36: =[19]Table4.C!$R$13 -> 10260.783 | F36: =[20]Table4.C!$R$13 -> 12347.639 | G36: =[21]Table4.C!$R$13 -> 10267.156 | H36: =[22]Table4.C!$R$13 -> 10599.111 | I36: =[23]Table4.C!$R$13 -> 11272.992 | J36: =[24]Table4.C!$R$13 -> 10370.429 | K36: =[25]Table4.C!$R$13 -> 9141.9368 | L36: =[26]Table4.C!$R$13 -> 15914.115 | M36: =[27]Table4.C!$R$13 -> 10417.006 | N36: =[28]Table4.C!$R$13 -> 10144.877 | O36: =[29]Table4.C!$R$13 -> 9964.1096 | P36: =[30]Table4.C!$R$13 -> 9040.1052 | Q36: =[31]Table4.C!$R$13 -> 7857.9096 | R36: =[32]Table4.C!$R$13 -> 7985.2195 | S36: =[33]Table4.C!$R$13 -> 6821.0216 | T36: =[18]Table4.C!$R$13 -> 7181.5954
A37: forest to wetland | B37: CRF table | C37: kt CO2e
A38: forest to settlement | B38: CRF table | C38: kt CO2e | D38: =[2]Table4.E!$R$13 -> 12769.716 | E38: =[19]Table4.E!$R$13 -> 12227.449 | F38: =[20]Table4.E!$R$13 -> 14143.326 | G38: =[21]Table4.E!$R$13 -> 13998.933 | H38: =[22]Table4.E!$R$13 -> 14209.884 | I38: =[23]Table4.E!$R$13 -> 13648.032 | J38: =[24]Table4.E!$R$13 -> 12793.84 | K38: =[25]Table4.E!$R$13 -> 12949.644 | L38: =[26]Table4.E!$R$13 -> 13394.987 | M38: =[27]Table4.E!$R$13 -> 13547.059 | N38: =[28]Table4.E!$R$13 -> 14124.55 | O38: =[29]Table4.E!$R$13 -> 17481.475 | P38: =[30]Table4.E!$R$13 -> 13087.102 | Q38: =[31]Table4.E!$R$13 -> 13222.874 | R38: =[32]Table4.E!$R$13 -> 12667.466 | S38: =[33]Table4.E!$R$13 -> 12684.518 | T38: =[18]Table4.E!$R$13 -> 12370.236
A39: forest to other land | B39: CRF table | C39: kt CO2e | D39: =[2]Table4.F!$R$13 -> 771.83927 | E39: =[19]Table4.F!$R$13 -> 2156.2496 | F39: =[20]Table4.F!$R$13 -> 780.51647 | G39: =[21]Table4.F!$R$13 -> 755.08623 | H39: =[22]Table4.F!$R$13 -> 979.58899 | I39: =[23]Table4.F!$R$13 -> 877.80968 | J39: =[24]Table4.F!$R$13 -> 796.29746 | K39: =[25]Table4.F!$R$13 -> 849.60632 | L39: =[26]Table4.F!$R$13 -> 795.59329 | M39: =[27]Table4.F!$R$13 -> 818.02726 | N39: =[28]Table4.F!$R$13 -> 821.14191 | O39: =[29]Table4.F!$R$13 -> 852.31457 | P39: =[30]Table4.F!$R$13 -> 861.31308 | Q39: =[31]Table4.F!$R$13 -> 1388.6384 | R39: =[32]Table4.F!$R$13 -> 851.17281 | S39: =[33]Table4.F!$R$13 -> 882.30682 | T39: =[18]Table4.F!$R$13 -> 833.3021
A40: Total emissions | B40: calculated | C40: Mt CO2e | D40: =SUM(D35:D39)/1000 -> 33.179954 | E40: =SUM(E35:E39)/1000 -> 33.788723 | F40: =SUM(F35:F39)/1000 -> 35.641559 | G40: =SUM(G35:G39)/1000 -> 33.239034 | H40: =SUM(H35:H39)/1000 -> 34.403243 | I40: =SUM(I35:I39)/1000 -> 34.333061 | J40: =SUM(J35:J39)/1000 -> 32.825073 | K40: =SUM(K35:K39)/1000 -> 31.310185 | ... T40: =SUM(T35:T39)/1000 -> 28.496018
A43: Aforestation
B44: Source | C44: Unit | D44: 2005 | I44: 2010 | N44: 2015 | S44: 2020 | X44: 2025 | AC44: 2030 | AH44: 2035 | AM44: 2040 | AR44: 2045 | AW44: 2050
A45: cropland to forest land | B45: CRF table | C45: kha | D45: =[2]Table4.1!$B$9 -> 124.84574 | E45: =[3]Table4.1!$B$9 -> 104.22353 | F45: =[4]Table4.1!$B$9 -> 175.51473 | G45: =[5]Table4.1!$B$9 -> 134.7488 | H45: =[6]Table4.1!$B$9 -> 127.75938 | I45: =[7]Table4.1!$B$9 -> 100.36458 | J45: =[8]Table4.1!$B$9 -> 92.349774 | K45: =[9]Table4.1!$B$9 -> 87.280747 | L45: =[10]Table4.1!$B$9 -> 80.820681 | M45: =[11]Table4.1!$B$9 -> 67.863174 | N45: =[12]Table4.1!$B$9 -> 66.051101 | O45: =[13]Table4.1!$B$9 -> 75.006317 | P45: =[14]Table4.1!$B$9 -> 112.26121 | Q45: =[15]Table4.1!$B$9 -> 83.034498 | R45: =[16]Table4.1!$B$9 -> 81.842832 | S45: =[17]Table4.1!$B$9 -> 81.226276 | T45: =[18]Table4.1!$B$9 -> 93.600396
A46: grassland to forest land | B46: CRF table | C46: kha | D46: =[2]Table4.1!$B$10+[2]Table4.1!$C$10 -> 335.03116 | E46: =[3]Table4.1!$B$10+[3]Table4.1!$C$10 -> 299.23582 | F46: =[4]Table4.1!$B$10+[4]Table4.1!$C$10+[4]Table4.1!$B$11 -> 198.29155 | G46: =[5]Table4.1!$B$10+[5]Table4.1!$C$10+[5]Table4.1!$B$11 -> 175.29188 | H46: =[6]Table4.1!$B$10+[6]Table4.1!$C$10+[6]Table4.1!$B$11 -> 178.42468 | I46: =[7]Table4.1!$B$10+[7]Table4.1!$C$10+[7]Table4.1!$B$11 -> 169.56038 | J46: =[8]Table4.1!$B$10+[8]Table4.1!$C$10+[8]Table4.1!$B$11 -> 162.85017 | K46: =[9]Table4.1!$B$10+[9]Table4.1!$C$10+[9]Table4.1!$B$11 -> 166.99228 | L46: =[10]Table4.1!$B$10+[10]Table4.1!$C$10+[10]Table4.1!$B$11 -> 178.98562 | M46: =[11]Table4.1!$B$10+[11]Table4.1!$C$10+[11]Table4.1!$B$11 -> 171.35176 | N46: =[12]Table4.1!$B$10+[12]Table4.1!$C$10+[12]Table4.1!$B$11 -> 170.72446 | O46: =[13]Table4.1!$B$10+[13]Table4.1!$C$10+[13]Table4.1!$B$11 -> 188.7492 | P46: =[14]Table4.1!$B$10+[14]Table4.1!$C$10+[14]Table4.1!$B$11 -> 199.30704 | Q46: =[15]Table4.1!$B$10+[15]Table4.1!$C$10+[15]Table4.1!$B$11 -> 176.44139 | R46: =[16]Table4.1!$B$10+[16]Table4.1!$C$10+[16]Table4.1!$B$11 -> 184.71789 | S46: =[17]Table4.1!$B$10+[17]Table4.1!$C$10+[17]Table4.1!$B$11 -> 184.06452 | T46: =[18]Table4.1!$B$10+[18]Table4.1!$C$10+[18]Table4.1!$B$11 -> 190.97774
A47: wetland to forest land | B47: CRF table | C47: kha | D47: =[2]Table4.1!$B$12+[2]Table4.1!$B$13 -> 10.40709 | E47: =[3]Table4.1!$B$12+[3]Table4.1!$B$13 -> 14.497609 | F47: =[4]Table4.1!$B$12+[4]Table4.1!$B$13 -> 12.986807 | G47: =[5]Table4.1!$B$12+[5]Table4.1!$B$13 -> 9.2454512 | H47: =[6]Table4.1!$B$12+[6]Table4.1!$B$13 -> 8.5872938 | I47: =[7]Table4.1!$B$12+[7]Table4.1!$B$13 -> 10.220269 | J47: =[8]Table4.1!$B$12+[8]Table4.1!$B$13 -> 10.759436 | K47: =[9]Table4.1!$B$12+[9]Table4.1!$B$13 -> 8.4406651 | L47: =[10]Table4.1!$B$12+[10]Table4.1!$B$13 -> 9.3328171 | M47: =[11]Table4.1!$B$12+[11]Table4.1!$B$13 -> 12.722048 | N47: =[12]Table4.1!$B$12+[12]Table4.1!$B$13 -> 15.965877 | O47: =[13]Table4.1!$B$12+[13]Table4.1!$B$13 -> 16.700427 | P47: =[14]Table4.1!$B$12+[14]Table4.1!$B$13 -> 15.479353 | Q47: =[15]Table4.1!$B$12+[15]Table4.1!$B$13 -> 21.099632 | R47: =[16]Table4.1!$B$12+[16]Table4.1!$B$13 -> 22.796586 | S47: =[17]Table4.1!$B$12+[17]Table4.1!$B$13 -> 15.862268 | T47: =[18]Table4.1!$B$12+[18]Table4.1!$B$13 -> 20.987889
A48: settlement to forest land | B48: CRF table | C48: kha | D48: =[2]Table4.1!$B$14 -> 12.515059 | E48: =[3]Table4.1!$B$14 -> 12.42378 | F48: =[4]Table4.1!$B$14 -> 16.26594 | G48: =[5]Table4.1!$B$14 -> 14.172173 | H48: =[6]Table4.1!$B$14 -> 11.442457 | I48: =[7]Table4.1!$B$14 -> 15.250092 | J48: =[8]Table4.1!$B$14 -> 14.837649 | K48: =[9]Table4.1!$B$14 -> 14.857304 | L48: =[10]Table4.1!$B$14 -> 20.42961 | M48: =[11]Table4.1!$B$14 -> 11.414547 | N48: =[12]Table4.1!$B$14 -> 13.658465 | O48: =[13]Table4.1!$B$14 -> 12.970495 | P48: =[14]Table4.1!$B$14 -> 7.9332018 | Q48: =[15]Table4.1!$B$14 -> 12.177692 | R48: =[16]Table4.1!$B$14 -> 14.312671 | S48: =[17]Table4.1!$B$14 -> 10.905251 | T48: =[18]Table4.1!$B$14 -> 14.466898
A49: other land to forest land | B49: CRF table | C49: kha | D49: =[2]Table4.1!$B$15 -> 5.1985895 | E49: =[3]Table4.1!$B$15 -> 5.2730055 | F49: =[4]Table4.1!$B$15 -> 4.3744143 | G49: =[5]Table4.1!$B$15 -> 4.4946564 | H49: =[6]Table4.1!$B$15 -> 7.8126477 | I49: =[7]Table4.1!$B$15 -> 5.5611166 | J49: =[8]Table4.1!$B$15 -> 7.5101553 | K49: =[9]Table4.1!$B$15 -> 5.2712145 | L49: =[10]Table4.1!$B$15 -> 4.9151427 | M49: =[11]Table4.1!$B$15 -> 3.3918464 | N49: =[12]Table4.1!$B$15 -> 6.447464 | O49: =[13]Table4.1!$B$15 -> 4.7151847 | P49: =[14]Table4.1!$B$15 -> 8.2546061 | Q49: =[15]Table4.1!$B$15 -> 7.0683499 | R49: =[16]Table4.1!$B$15 -> 6.5046606 | S49: =[17]Table4.1!$B$15 -> 5.6569088 | T49: =[18]Table4.1!$B$15 -> 6.7260658

Sheet L5. Net land take
A1: Net land take
B2: Source | C2: Unit | D2: 2005 | I2: 2010 | N2: 2015 | S2: 2020 | X2: 2025 | AC2: 2030 | AH2: 2035 | AM2: 2040 | AR2: 2045 | AW2: 2050
A3: annual increase in settlement area | B3: EU CRF | C3: kha | E3: ='L2. Areas per land-use category'!E44-'L2. Areas per land-use category'!D44 -> 401.19321 | F3: ='L2. Areas per land-use category'!F44-'L2. Areas per land-use category'!E44 -> 231.93072 | G3: ='L2. Areas per land-use category'!G44-'L2. Areas per land-use category'!F44 -> 225.85634 | H3: ='L2. Areas per land-use category'!H44-'L2. Areas per land-use category'!G44 -> 236.55834 | I3: ='L2. Areas per land-use category'!I44-'L2. Areas per land-use category'!H44 -> 232.01301 | J3: ='L2. Areas per land-use category'!J44-'L2. Areas per land-use category'!I44 -> 228.45056 | K3: ='L2. Areas per land-use category'!K44-'L2. Areas per land-use category'!J44 -> 231.94095 | L3: ='L2. Areas per land-use category'!L44-'L2. Areas per land-use category'!K44 -> 155.8901 | ... T3: ='L2. Areas per land-use category'!T44-'L2. Areas per land-use category'!S44 -> 142.1697
A4: 2050 benchmark | B4: 7th EAP | AW4: 0
A5: linear trajectory to benchmark | T5: 142.1697 | U5: 137.26729 | V5: 132.36489 | W5: 127.46249 | X5: 122.56008 | Y5: 117.65768 | Z5: 112.75528 | AA5: 107.85287 | AB5: 102.95047 | AC5: 98.048068 | AD5: 93.145664 | AE5: 88.243261 | AF5: 83.340858 | AG5: 78.438454 | AH5: 73.536051 | AI5: 68.633647 | AJ5: 63.731244 | AK5: 58.828841 | AL5: 53.926437 | AM5: 49.024034 | AN5: 44.121631 | AO5: 39.219227 | AP5: 34.316824 | AQ5: 29.41442 | AR5: 24.512017 | AS5: 19.609614 | AT5: 14.70721 | AU5: 9.8048068 | AV5: 4.9024034 | AW5: -2.8421709e-14
A7: Average 2017-2021 | D7: =(T3-P3)/5 -> 0.14096135
A8: Average until 2050 | D8: =U5-T5 -> -4.9024034

Sheet L6. forest living biomass
A1: Total
B2: Source | C2: Unit | D2: 2005 | I2: 2010 | N2: 2015 | S2: 2020 | X2: 2025 | AC2: 2030 | AH2: 2035 | AM2: 2040 | AR2: 2045 | AW2: 2050
A3: Net annual increment (NAI) | B3: calculated | C3: Mt CO2e | D3: =D5+D4 -> 797.38002 | E3: =E5+E4 -> 770.36259 | F3: =F5+F4 -> 762.03286 | G3: =G5+G4 -> 805.35226 | H3: =H5+H4 -> 778.47125 | I3: =I5+I4 -> 817.26999 | J3: =J5+J4 -> 808.82173 | K3: =K5+K4 -> 811.41271 | ... T3: =T5+T4 -> 718.48072
A4: Wood harvesting | B4: FAOSTAT | C4: Mt CO2e | D4: =D46 -> 435.62471 | E4: =E46 -> 413.85044 | F4: =F46 -> 442.28 | G4: =G46 -> 413.26197 | H4: =H46 -> 381.02848 | I4: =I46 -> 428.20067 | J4: =J46 -> 428.36404 | K4: =K46 -> 428.69638 | ... T4: =T46 -> 486.72093
A5: Living biomass sink | B5: EU GHG inventory | C5: Mt CO2e | D5: 361.75532 | E5: 356.51215 | F5: 319.75286 | G5: 392.09029 | H5: 397.44277 | I5: 389.06932 | J5: 380.45769 | K5: 382.71633 | L5: 391.0715 | M5: 361.98172 | N5: 342.92376 | O5: 337.35383 | P5: 287.58912 | Q5: 267.15615 | R5: 245.09632 | S5: 246.71294 | T5: 231.75979
A6: Deadwood, litter and soil sink | B6: EU GHG inventory | C6: Mt CO2e | D6: =D35/1000-D5 -> 53.036684 | E6: =E35/1000-E5 -> 54.05185 | F6: =F35/1000-F5 -> 46.765143 | G6: =G35/1000-G5 -> 39.134711 | H6: =H35/1000-H5 -> 52.325229 | I6: =I35/1000-I5 -> 44.12168 | J6: =J35/1000-J5 -> 45.986309 | K6: =K35/1000-K5 -> 41.477673 | ... T6: =T35/1000-T5 -> 49.069206
A7: 2030 benchmark | B7: CTP IA fig 10 | C7: Mt CO2e | AC7: 380
A8: 2050 benchmark | B8: CTP IA fig 10 | AW8: 450
A9: linear trajectory | T9: 280.829 | U9: 291.848 | V9: 302.867 | W9: 313.886 | X9: 324.905 | Y9: 335.924 | Z9: 346.943 | AA9: 357.962 | AB9: 368.981 | AC9: 380 | AD9: 383.5 | AE9: 387 | AF9: 390.5 | AG9: 394 | AH9: 397.5 | AI9: 401 | AJ9: 404.5 | AK9: 408 | AL9: 411.5 | AM9: 415 | AN9: 418.5 | AO9: 422 | AP9: 425.5 | AQ9: 429 | AR9: 432.5 | AS9: 436 | AT9: 439.5 | AU9: 443 | AV9: 446.5 | AW9: 450
A13: total decrease | D13: =T6-D6 -> -3.9674782
A14: contribution harvesting | D14: =D4-T4 -> -51.096224 | E14: =D14/D13 -> 12.878766
A15: contribution net annual increment | D15: =T3-D3 -> -78.899298 | E15: =D15/D13 -> 19.886511
A17: Average 2017-2021 | D17: =(T5+T6-P5-P6)/4 -> -7.94575
A18: Average 2022-2030 | D18: =X9-W9 -> 11.019
A19: Average 2031-2050 | D19: =(AH9-AG9) -> 3.5
A27: Raw data
A28: Carbon stock changes
B29: Source | C29: Unit | D29: 2005 | I29: 2010 | N29: 2015 | S29: 2020 | X29: 2025 | AC29: 2030 | AH29: 2035 | AM29: 2040 | AR29: 2045 | AW29: 2050
A30: Carbon stock gain in livin biomass | B30: EU GHG inventory CRF | C30: kt C | D30: =[34]Table4.A!$M$10 -> 207379.81 | E30: =[3]Table4.A!$M$10 -> 206916.63 | F30: =[4]Table4.A!$M$10 -> 206146.03 | G30: =[5]Table4.A!$M$10 -> 218343.43 | H30: =[6]Table4.A!$M$10 -> 220287.8 | I30: =[7]Table4.A!$M$10 -> 219703.98 | J30: =[8]Table4.A!$M$10 -> 219467.88 | K30: =[9]Table4.A!$M$10 -> 219573.06 | L30: =[10]Table4.A!$M$10 -> 219562.61 | M30: =[11]Table4.A!$M$10 -> 216997.79 | N30: =[12]Table4.A!$M$10 -> 213886.85 | O30: =[13]Table4.A!$M$10 -> 216230.89 | P30: =[14]Table4.A!$M$10 -> 212622.79 | Q30: =[15]Table4.A!$M$10 -> 210749.79 | R30: =[16]Table4.A!$M$10 -> 205781.43 | S30: =[17]Table4.A!$M$10 -> 205587.37 | T30: =[35]Table4.A!$M$10 -> 204988.07
A31: Carbon stock loss in livin biomass | B31: EU GHG inventory CRF | C31: kt C | D31: =[34]Table4.A!$N$10 -> -108647.47 | E31: =[3]Table4.A!$N$10 -> -109615.28 | F31: =[4]Table4.A!$N$10 -> -118877.23 | G31: =[5]Table4.A!$N$10 -> -111331.89 | H31: =[6]Table4.A!$N$10 -> -111815.43 | I31: =[7]Table4.A!$N$10 -> -113516.94 | J31: =[8]Table4.A!$N$10 -> -115631.18 | K31: =[9]Table4.A!$N$10 -> -115119.91 | L31: =[10]Table4.A!$N$10 -> -112829.13 | M31: =[11]Table4.A!$N$10 -> -118203.65 | N31: =[12]Table4.A!$N$10 -> -120294.12 | O31: =[13]Table4.A!$N$10 -> -124158.34 | P31: =[14]Table4.A!$N$10 -> -134132.31 | Q31: =[15]Table4.A!$N$10 -> -137835.99 | R31: =[16]Table4.A!$N$10 -> -138888.33 | S31: =[17]Table4.A!$N$10 -> -138253.05 | T31: =[35]Table4.A!$N$10 -> -141734.85
A32: Carbon stock change in livin biomass | B32: EU GHG inventory CRF | C32: kt C | D32: =[34]Table4.A!$O$10 -> 98732.346 | E32: =[3]Table4.A!$O$10 -> 97301.351 | F32: =[4]Table4.A!$O$10 -> 87268.793 | G32: =[5]Table4.A!$O$10 -> 107011.54 | H32: =[6]Table4.A!$O$10 -> 108472.37 | I32: =[7]Table4.A!$O$10 -> 106187.04 | J32: =[8]Table4.A!$O$10 -> 103836.71 | K32: =[9]Table4.A!$O$10 -> 104453.15 | L32: =[10]Table4.A!$O$10 -> 106733.49 | M32: =[11]Table4.A!$O$10 -> 98794.137 | N32: =[12]Table4.A!$O$10 -> 93592.729 | O32: =[13]Table4.A!$O$10 -> 92072.552 | P32: =[14]Table4.A!$O$10 -> 78490.48 | Q32: =[15]Table4.A!$O$10 -> 72913.796 | R32: =[16]Table4.A!$O$10 -> 66893.1 | S32: =[17]Table4.A!$O$10 -> 67334.318 | T32: =[35]Table4.A!$O$10 -> 63253.219
A33: Living biomass sink | B33: calculated | C33: kt CO2e | D33: =D32*3.664 -> 361755.32 | E33: =E32*3.664 -> 356512.15 | F33: =F32*3.664 -> 319752.86 | G33: =G32*3.664 -> 392090.29 | H33: =H32*3.664 -> 397442.77 | I33: =I32*3.664 -> 389069.32 | J33: =J32*3.664 -> 380457.69 | K33: =K32*3.664 -> 382716.33 | ... T33: =T32*3.664 -> 231759.79
A34: Other sink | B34: calculated | C34: kt CO2e | D34: =D35-D33 -> 53036.684 | E34: =E35-E33 -> 54051.85 | F34: =F35-F33 -> 46765.143 | G34: =G35-G33 -> 39134.711 | H34: =H35-H33 -> 52325.229 | I34: =I35-I33 -> 44121.68 | J34: =J35-J33 -> 45986.309 | K34: =K35-K33 -> 41477.673 | ... T34: =T35-T33 -> 49069.206
A35: Total forest sink | B35: EU GHG inventory CRF | C35: kt CO2e | D35: 414792 | E35: 410564 | F35: 366518 | G35: 431225 | H35: 449768 | I35: 433191 | J35: 426444 | K35: 424194 | L35: 440720 | M35: 401753 | N35: 390728 | O35: 382319 | P35: 312612 | Q35: 306984 | R35: 293840 | S35: 291708 | T35: 280829
A37: Forestry production (under bark, see https://www.fao.org/forestry/34572-0902b3c041384fd87f2451da2bb9237.pdf)
B38: Source | C38: Unit | D38: 2005 | I38: 2010 | N38: 2015 | S38: 2020 | X38: 2025 | AC38: 2030 | AH38: 2035 | AM38: 2040 | AR38: 2045 | AW38: 2050
A39: Total roundwood | B39: FAOSTAT (forestry production) | C39: m3 | D39: 460574145 | E39: 433530614 | F39: 468797364 | G39: 432739074 | H39: 398124538 | I39: 446468578 | J39: 446615838 | K39: 443430262 | L39: 450606123 | M39: 453214196 | N39: 461695344 | O39: 468061982 | P39: 474392337 | Q39: 501933432 | R39: 506039930 | S39: 491417002 | T39: 511594835
A40: Industrial roundwood, coniferous | B40: FAOSTAT (forestry production) | C40: m3 | D40: 294097435 | E40: 262622588 | F40: 301493661 | G40: 260166548 | H40: 234305455 | I40: 260519141 | J40: 261493683 | K40: 247737638 | L40: 252296108 | M40: 263378906 | N40: 266015239 | O40: 271688584 | P40: 276969329 | Q40: 298192704 | R40: 302398403 | S40: 296463359 | T40: 309452345
A41: Industrial roundwood, non-coniferous | B41: FAOSTAT (forestry production) | C41: m3 | D41: 74886069 | E41: 74800741 | F41: 75257447 | G41: 72992611 | H41: 63207478 | I41: 70501691 | J41: 74968028 | K41: 77498724 | L41: 75663291 | M41: 76637396 | N41: 76702244 | O41: 78047433 | P41: 78880573 | Q41: 83096962 | R41: 81937463 | S41: 75102628 | T41: 77854019
A42: Wood fuel, coniferous | B42: FAOSTAT (forestry production) | C42: m3 | D42: 27152686 | E42: 28952978 | F42: 28682165 | G42: 30401637 | H42: 30681192 | I42: 34075222 | J42: 33134947 | K42: 35161654 | L42: 36134528 | M42: 33468238 | N42: 36889858 | O42: 34260759 | P42: 34358391 | Q42: 37796911 | R42: 38791643 | S42: 38973580 | T42: 39315356
A43: Wood fuel, non-coniferous | B43: FAOSTAT (forestry production) | C43: m3 | D43: 64437955 | E43: 67154307 | F43: 63364091 | G43: 69178278 | H43: 69930413 | I43: 81372524 | J43: 77019180 | K43: 83032246 | L43: 86512196 | M43: 79729656 | N43: 82088003 | O43: 84065206 | P43: 84184044 | Q43: 82846855 | R43: 82912421 | S43: 80877435 | T43: 84973115
B45: Source | C45: Unit | D45: 2005 | I45: 2010 | N45: 2015 | S45: 2020 | X45: 2025 | AC45: 2030 | AH45: 2035 | AM45: 2040 | AR45: 2045 | AW45: 2050
A46: Total roundwood | B46: calculated | C46: Mt CO2e | D46: =SUM(D47:D50) -> 435.62471 | E46: =SUM(E47:E50) -> 413.85044 | F46: =SUM(F47:F50) -> 442.28 | G46: =SUM(G47:G50) -> 413.26197 | H46: =SUM(H47:H50) -> 381.02848 | I46: =SUM(I47:I50) -> 428.20067 | J46: =SUM(J47:J50) -> 428.36404 | K46: =SUM(K47:K50) -> 428.69638 | ... T46: =SUM(T47:T50) -> 486.72093
A47: Industrial roundwood, coniferous | B47: calculated | C47: Mt CO2e | D47: =D40*$D$54*$D$55*$D$57*$D$59/1000000 -> 246.86218 | E47: =E40*$D$54*$D$55*$D$57*$D$59/1000000 -> 220.44254 | F47: =F40*$D$54*$D$55*$D$57*$D$59/1000000 -> 253.07049 | G47: =G40*$D$54*$D$55*$D$57*$D$59/1000000 -> 218.38096 | H47: =H40*$D$54*$D$55*$D$57*$D$59/1000000 -> 196.67344 | I47: =I40*$D$54*$D$55*$D$57*$D$59/1000000 -> 218.67692 | J47: =J40*$D$54*$D$55*$D$57*$D$59/1000000 -> 219.49494 | K47: =K40*$D$54*$D$55*$D$57*$D$59/1000000 -> 207.94827 | ... T47: =T40*$D$54*$D$55*$D$57*$D$59/1000000 -> 259.75092
A48: Industrial roundwood, non-coniferous | B48: calculated | C48: Mt CO2e | D48: =D41*$D$54*$D$56*$D$58*$D$59/1000000 -> 89.208629 | E48: =E41*$D$54*$D$56*$D$58*$D$59/1000000 -> 89.106981 | F48: =F41*$D$54*$D$56*$D$58*$D$59/1000000 -> 89.651036 | G48: =G41*$D$54*$D$56*$D$58*$D$59/1000000 -> 86.953032 | H48: =H41*$D$54*$D$56*$D$58*$D$59/1000000 -> 75.296414 | I48: =I41*$D$54*$D$56*$D$58*$D$59/1000000 -> 83.985703 | J48: =J41*$D$54*$D$56*$D$58*$D$59/1000000 -> 89.306263 | K48: =K41*$D$54*$D$56*$D$58*$D$59/1000000 -> 92.320975 | ... T48: =T41*$D$54*$D$56*$D$58*$D$59/1000000 -> 92.744223
A49: Wood fuel, coniferous | B49: calculated | C49: Mt CO2e | D49: =D42*$D$54*$D$55*$D$57*$D$59/1000000 -> 22.791668 | E49: =E42*$D$54*$D$55*$D$57*$D$59/1000000 -> 24.302814 | F49: =F42*$D$54*$D$55*$D$57*$D$59/1000000 -> 24.075496 | G49: =G42*$D$54*$D$55*$D$57*$D$59/1000000 -> 25.518802 | H49: =H42*$D$54*$D$55*$D$57*$D$59/1000000 -> 25.753458 | I49: =I42*$D$54*$D$55*$D$57*$D$59/1000000 -> 28.60237 | J49: =J42*$D$54*$D$55*$D$57*$D$59/1000000 -> 27.813113 | K49: =K42*$D$54*$D$55*$D$57*$D$59/1000000 -> 29.514309 | ... T49: =T42*$D$54*$D$55*$D$57*$D$59/1000000 -> 33.000881
A50: Wood fuel, non-coniferous | B50: calculated | C50: Mt CO2e | D50: =D43*$D$54*$D$56*$D$58*$D$59/1000000 -> 76.762229 | E50: =E43*$D$54*$D$56*$D$58*$D$59/1000000 -> 79.998105 | F50: =F43*$D$54*$D$56*$D$58*$D$59/1000000 -> 75.48298 | G50: =G43*$D$54*$D$56*$D$58*$D$59/1000000 -> 82.409177 | H50: =H43*$D$54*$D$56*$D$58*$D$59/1000000 -> 83.305164 | I50: =I43*$D$54*$D$56*$D$58*$D$59/1000000 -> 96.93567 | J50: =J43*$D$54*$D$56*$D$58*$D$59/1000000 -> 91.749714 | K50: =K43*$D$54*$D$56*$D$58*$D$59/1000000 -> 98.912827 | ... T50: =T43*$D$54*$D$56*$D$58*$D$59/1000000 -> 101.2249
A52: Conversion factor
B53: Source | C53: Unit | D53: Value
A54: under bark to over bark | C54: % | D54: 1.1363636
...

Sheet L7. Emission reductions others
A1: Total LULUCF emissions and removals
B2: Source | C2: Unit | D2: 2005 | I2: 2010 | N2: 2015 | S2: 2020 | X2: 2025 | AC2: 2030 | AH2: 2035 | AM2: 2040 | AR2: 2045 | AW2: 2050
A3: Total | B3: calculated | C3: Mt CO2e | D3: =D4+D5+D6+D7 -> 127.84885 | E3: =E4+E5+E6+E7 -> 121.8391 | F3: =F4+F5+F6+F7 -> 131.93088 | G3: =G4+G5+G6+G7 -> 130.72584 | H3: =H4+H5+H6+H7 -> 130.93784 | I3: =I4+I5+I6+I7 -> 117.77413 | J3: =J4+J5+J6+J7 -> 115.8842 | K3: =K4+K5+K6+K7 -> 114.63267 | ... T3: =T4+T5+T6+T7 -> 97.44076
A4: Cropland | B4: EEA GHG data viewer | C4: Mt CO2e | D4: ='L1. GHG emissions and removals'!D5 -> 41.885534 | E4: ='L1. GHG emissions and removals'!E5 -> 42.292718 | F4: ='L1. GHG emissions and removals'!F5 -> 46.325952 | G4: ='L1. GHG emissions and removals'!G5 -> 47.762401 | H4: ='L1. GHG emissions and removals'!H5 -> 46.3501 | I4: ='L1. GHG emissions and removals'!I5 -> 36.721832 | J4: ='L1. GHG emissions and removals'!J5 -> 36.216021 | K4: ='L1. GHG emissions and removals'!K5 -> 36.317395 | ... T4: ='L1. GHG emissions and removals'!T5 -> 22.646398
A5: Grassland | B5: EEA GHG data viewer | C5: Mt CO2e | D5: ='L1. GHG emissions and removals'!D6 -> 32.510711 | E5: ='L1. GHG emissions and removals'!E6 -> 27.337326 | F5: ='L1. GHG emissions and removals'!F6 -> 33.798483 | G5: ='L1. GHG emissions and removals'!G6 -> 31.158826 | H5: ='L1. GHG emissions and removals'!H6 -> 32.804095 | I5: ='L1. GHG emissions and removals'!I6 -> 31.258861 | J5: ='L1. GHG emissions and removals'!J6 -> 32.79328 | K5: ='L1. GHG emissions and removals'!K6 -> 33.714568 | ... T5: ='L1. GHG emissions and removals'!T6 -> 24.955054
A6: Wetlands | B6: EEA GHG data viewer | C6: Mt CO2e | D6: ='L1. GHG emissions and removals'!D7 -> 20.342633 | E6: ='L1. GHG emissions and removals'!E7 -> 19.996684 | F6: ='L1. GHG emissions and removals'!F7 -> 18.814036 | G6: ='L1. GHG emissions and removals'!G7 -> 19.020276 | H6: ='L1. GHG emissions and removals'!H7 -> 18.775734 | I6: ='L1. GHG emissions and removals'!I7 -> 20.203806 | J6: ='L1. GHG emissions and removals'!J7 -> 19.884201 | K6: ='L1. GHG emissions and removals'!K7 -> 18.656852 | ... T6: ='L1. GHG emissions and removals'!T7 -> 21.269812
A7: Settlements and other land | B7: EEA GHG data viewer | C7: Mt CO2e | D7: ='L1. GHG emissions and removals'!D8 -> 33.109972 | E7: ='L1. GHG emissions and removals'!E8 -> 32.212374 | F7: ='L1. GHG emissions and removals'!F8 -> 32.992411 | G7: ='L1. GHG emissions and removals'!G8 -> 32.784342 | H7: ='L1. GHG emissions and removals'!H8 -> 33.007915 | I7: ='L1. GHG emissions and removals'!I8 -> 29.589637 | J7: ='L1. GHG emissions and removals'!J8 -> 26.990699 | K7: ='L1. GHG emissions and removals'!K8 -> 25.943854 | ... T7: ='L1. GHG emissions and removals'!T8 -> 28.569496
A8: 2030 benchmark | B8: CTP IA figure 10 | C8: Mt CO2e | AC8: 86
A9: 2050 benchmark | B9: CTP IA figure 10 | C9: Mt CO2e | AW9: 25
A10: linear trajectory | C10: Mt CO2e | T10: 97.44076 | U10: 96.169564 | V10: 94.898369 | W10: 93.627173 | X10: 92.355978 | Y10: 91.084782 | Z10: 89.813587 | AA10: 88.542391 | AB10: 87.271196 | AC10: 86 | AD10: 82.95 | AE10: 79.9 | AF10: 76.85 | AG10: 73.8 | AH10: 70.75 | AI10: 67.7 | AJ10: 64.65 | AK10: 61.6 | AL10: 58.55 | AM10: 55.5 | AN10: 52.45 | AO10: 49.4 | AP10: 46.35 | AQ10: 43.3 | AR10: 40.25 | AS10: 37.2 | AT10: 34.15 | AU10: 31.1 | AV10: 28.05 | AW10: 25
A12: Average 2005-2021 | D12: =(T3-D3)/16 -> -1.9005057 | E12: =T3/D3-1 -> -0.23784407
A13: Average 2017-2021 | D13: =(T3-P3)/4 -> -1.4630925
A14: Average 2022-2030 | D14: =U10-T10 -> -1.2711955
A15: Average 2031-2050 | D15: =AF10-AE10 -> -3.05
D19: 2005-2021 | E19: 2005-2021
A20: total | D20: =T3-D3 -> -30.408091 | E20: =T3/D3-1 -> -0.23784407
A21: Cropland | D21: =T4-D4 -> -19.239136 | E21: =T4/D4-1 -> -0.45932651
A22: Grassland | D22: =T5-D5 -> -7.5556576 | E22: =T5/D5-1 -> -0.23240518
A23: Wetlands | D23: =T6-D6 -> 0.92717831 | E23: =T6/D6-1 -> 0.045578087
A24: Settlements and other land | D24: =T7-D7 -> -4.5404757 | E24: =T7/D7-1 -> -0.13713318

Sheet L8. bioenergy
A1: Graph feed
C2: Source | D2: Unit | E2: 2005 | J2: 2010 | O2: 2015 | T2: 2020 | Y2: 2025 | AD2: 2030 | AI2: 2035 | AN2: 2040 | AS2: 2045 | AX2: 2050
A3: Total | D3: TWh | E3: =SUM(E4:E7) -> 896.38544 | F3: =SUM(F4:F7) -> 972.06546 | G3: =SUM(G4:G7) -> 1075.9482 | H3: =SUM(H4:H7) -> 1192.6217 | I3: =SUM(I4:I7) -> 1270.256 | J3: =SUM(J4:J7) -> 1406.1824 | K3: =SUM(K4:K7) -> 1373.9625 | L3: =SUM(L4:L7) -> 1504.2289 | ... U3: =SUM(U4:U7) -> 1795.6962
A4: Power and heat | D4: TWh | E4: =SUM(E42:E51)/1000 -> 216.8346 | F4: =SUM(F42:F51)/1000 -> 243.42546 | G4: =SUM(G42:G51)/1000 -> 281.75917 | H4: =SUM(H42:H51)/1000 -> 343.72267 | I4: =SUM(I42:I51)/1000 -> 397.94206 | J4: =SUM(J42:J51)/1000 -> 463.51748 | K4: =SUM(K42:K51)/1000 -> 481.50767 | L4: =SUM(L42:L51)/1000 -> 544.1782 | ... U4: =SUM(U42:U51)/1000 -> 729.17529
A5: Industry | D5: TWh | E5: =SUM(E52:E61)/1000 -> 201.32205 | F5: =SUM(F52:F61)/1000 -> 209.75636 | G5: =SUM(G52:G61)/1000 -> 218.36648 | H5: =SUM(H52:H61)/1000 -> 210.71205 | I5: =SUM(I52:I61)/1000 -> 207.77662 | J5: =SUM(J52:J61)/1000 -> 224.9394 | K5: =SUM(K52:K61)/1000 -> 224.67066 | L5: =SUM(L52:L61)/1000 -> 216.96218 | ... U5: =SUM(U52:U61)/1000 -> 256.79753
A6: Transport | D6: TWh | E6: =SUM(E62:E71)/1000 -> 36.520967 | F6: =SUM(F62:F71)/1000 -> 60.421134 | G6: =SUM(G62:G71)/1000 -> 84.486593 | H6: =SUM(H62:H71)/1000 -> 104.15973 | I6: =SUM(I62:I71)/1000 -> 123.11383 | J6: =SUM(J62:J71)/1000 -> 139.67661 | K6: =SUM(K62:K71)/1000 -> 147.56041 | L6: =SUM(L62:L71)/1000 -> 157.28238 | ... U6: =SUM(U62:U71)/1000 -> 194.75992
A7: Other sectors | D7: TWh | E7: =SUM(E72:E81)/1000 -> 441.70782 | F7: =SUM(F72:F81)/1000 -> 458.46251 | G7: =SUM(G72:G81)/1000 -> 491.33596 | H7: =SUM(H72:H81)/1000 -> 534.02721 | I7: =SUM(I72:I81)/1000 -> 541.42353 | J7: =SUM(J72:J81)/1000 -> 578.0489 | K7: =SUM(K72:K81)/1000 -> 520.22379 | L7: =SUM(L72:L81)/1000 -> 585.80613 | ... U7: =SUM(U72:U81)/1000 -> 614.9635
A8: 2030 benchmark | D8: TWh | AD8: =SUM(B15:E15) -> 1783.0389
A9: 2050 benchmark | D9: TWh | AX9: =SUM(B16:E16) -> 2815.0902
A10: 2040 advice scenarios | D10: TWh | AN10: =AVERAGE(AN121:AN126)*EJ2TWh -> 1963.0972 | AX10: =AVERAGE(AX121:AX126)*EJ2TWh -> 2077.338
B13: Power and heat | C13: Transport | D13: Industry | E13: Other sectors
A14: 2021 | B14: =U4 -> 729.17529 | C14: =U6 -> 194.75992 | D14: =U5 -> 256.79753 | E14: =U7 -> 614.9635
A15: 2030 | B15: =F108*$B$117 -> 613.44428 | C15: =(F110+F111+F114)*$B$117 -> 236.52449 | D15: =F109*$B$117 -> 308.13944 | E15: =(F112+F113+F115)*$B$117 -> 624.93066
A16: 2050 | B16: =K108*$B$117 -> 1229.9912 | C16: =(K110+K111+K114)*$B$117 -> 519.91367 | D16: =K109*$B$117 -> 339.72021 | E16: =(K112+K113+K115)*$B$117 -> 725.46518
U18: =U4/$U$3 -> 0.40606828
U19: =U5/$U$3 -> 0.14300722
U20: =U6/$U$3 -> 0.10845928
U21: =U7/$U$3 -> 0.34246522
H30: Average 2017-2021 | I30: =(U3-Q3)/4 -> 56.24768
H31: Average 2022-2030 | I31: =(AD8-U3)/9 -> -1.4063728
H32: Average 2031-2050 | I32: =(AX9-AD8)/20 -> 51.602567
A39: Raw data
A40: Historic data
C41: Source | D41: Unit | E41: 2005 | J41: 2010 | O41: 2015 | T41: 2020 | Y41: 2025 | AD41: 2030 | AI41: 2035 | AN41: 2040 | AS41: 2045 | AX41: 2050
A42: Transformation input - energy use | B42: Primary solid biofuels | C42: energy balance | D42: GWh | E42: 164104.33 | F42: 174969.61 | G42: 183274.44 | H42: 202074.78 | I42: 217786.84 | J42: 257534.27 | K42: 255453.04 | L42: 287713.13 | M42: 291684.3 | N42: 293392.07 | O42: 298222.06 | P42: 304271.56 | Q42: 312410.14 | R42: 317735.01 | S42: 332665.14 | T42: 341979.28 | U42: 384161.48
A43: Transformation input - energy use | B43: Charcoal | C43: energy balance | D43: GWh | E43: 0 | F43: 0 | G43: 0 | H43: 0 | I43: 0 | J43: 0 | K43: 0 | L43: 0 | M43: 0 | N43: 0 | O43: 0 | P43: 0 | Q43: 0 | R43: 0.167 | S43: 6.833 | T43: 0 | U43: 0
A44: Transformation input - energy use | B44: Pure biogasoline | C44: energy balance | D44: GWh | E44: 6454.615 | F44: 9707.165 | G44: 12366.48 | H44: 19619.537 | I44: 24059.307 | J44: 28028.452 | K44: 28089.302 | L44: 28373.948 | M44: 26724.414 | N44: 26432.067 | O44: 27441.63 | P44: 27263.683 | Q44: 29042.607 | R44: 31362.43 | S44: 32815.067 | T44: 32710.338 | U44: 36531.809
A45: Transformation input - energy use | B45: Blended biogasoline | C45: energy balance | D45: GWh | E45: 0 | F45: 0 | G45: 0 | H45: 0 | I45: 0 | J45: 0 | K45: 0 | L45: 0 | M45: 0 | N45: 0 | O45: 0 | P45: 0 | Q45: 0 | R45: 0 | S45: 0 | T45: 0 | U45: 0
A46: Transformation input - energy use | B46: Pure biodiesels | C46: energy balance | D46: GWh | E46: 17620.64 | F46: 24534.078 | G46: 43572.87 | H46: 70563.715 | I46: 93601.753 | J46: 104794.64 | K46: 112777.53 | L46: 125982.66 | M46: 111173.9 | N46: 120701.75 | O46: 119256.33 | P46: 117261.49 | Q46: 128558.1 | R46: 145347.2 | S46: 149101.34 | T46: 155275.69 | U46: 158092.28
A47: Transformation input - energy use | B47: Blended biodiesels | C47: energy balance | D47: GWh | E47: 0 | F47: 0 | G47: 0 | H47: 0 | I47: 0 | J47: 0 | K47: 0 | L47: 0 | M47: 10.278 | N47: 10.278 | O47: 20.556 | P47: 10.278 | Q47: 13.587 | R47: 11.906 | S47: 11.478 | T47: 11.929 | U47: 54.976
A48: Transformation input - energy use | B48: Pure bio jet kerosene | C48: energy balance | D48: GWh | E48: 0 | F48: 0 | G48: 0 | H48: 0 | I48: 0 | J48: 0 | K48: 0 | L48: 0 | M48: 0 | N48: 0 | O48: 0 | P48: 0 | Q48: 0 | R48: 0 | S48: 0 | T48: 0 | U48: 0
A49: Transformation input - energy use | B49: Blended bio jet kerosene | C49: energy balance | D49: GWh | E49: 0 | F49: 0 | G49: 0 | H49: 0 | I49: 0 | J49: 0 | K49: 0 | L49: 0 | M49: 0 | N49: 0 | O49: 0 | P49: 0 | Q49: 0 | R49: 0 | S49: 0 | T49: 0 | U49: 0
A50: Transformation input - energy use | B50: Other liquid biofuels | C50: energy balance | D50: GWh | E50: 5673.882 | F50: 8271.97 | G50: 4926.736 | H50: 5506.914 | I50: 10314.912 | J50: 12830.382 | K50: 8366.45 | L50: 9238.421 | M50: 10973.93 | N50: 11663.528 | O50: 12864.803 | P50: 12402.728 | Q50: 11680.658 | R50: 11944.37 | S50: 12882.295 | T50: 12275.861 | U50: 11634.687
A51: Transformation input - energy use | B51: Biogases | C51: energy balance | D51: GWh | E51: 22981.133 | F51: 25942.633 | G51: 37618.637 | H51: 45957.729 | I51: 52179.243 | J51: 60329.74 | K51: 76821.349 | L51: 92870.045 | M51: 107159 | N51: 114866.09 | O51: 119559.14 | P51: 121834.21 | Q51: 124093.25 | R51: 124776.73 | S51: 127449.81 | T51: 132721.14 | U51: 138700.06
A52: Final consumption - industry sector - energy use | B52: Primary solid biofuels | C52: energy balance | D52: GWh | E52: 199345.48 | F52: 207534.16 | G52: 215460.95 | H52: 207137.57 | I52: 204216.19 | J52: 219870.82 | K52: 219628.87 | L52: 213283.07 | M52: 216596.68 | N52: 219163.45 | O52: 227848.52 | P52: 236864.39 | Q52: 238161.75 | R52: 240546.69 | S52: 245080.04 | T52: 244203.96 | U52: 245631.23
A53: Final consumption - industry sector - energy use | B53: Charcoal | C53: energy balance | D53: GWh | E53: 171.111 | F53: 179.667 | G53: 171.111 | H53: 436.333 | I53: 222.444 | J53: 85.556 | K53: 85.556 | L53: 85.556 | M53: 96.807 | N53: 96.65 | O53: 96.492 | P53: 96.383 | Q53: 99.202 | R53: 89.541 | S53: 86.269 | T53: 86.261 | U53: 86.261
... A101: Final consumption - other sectors - households - energy use | B101: Biogases | C101: energy balance | D101: GWh | E101: 140.833 | F101: 313.611 | G101: 836.111 | H101: 1519.083 | I101: 2038.091 | J101: 2376.868 | K101: 2084.14 | L101: 2671.832 | M101: 3066.392 | N101: 3544.289 | O101: 3822.069 | P101: 4126.612 | Q101: 4103.064 | R101: 3624.741 | S101: 3678.333 | T101: 3414.703 | U101: 2763.611
A103: Benchmark data
A104: Source CTP IA Figure 77: Use of bioenergy by sector and by scenario
A105: Unit: Mtoe
...

Sheet Fig. 74 woody biomass S&D
A1: Total supply and demand
B2: Source | C2: Unit | D2: 2009 | E2: 2010 | F2: 2011 | G2: 2012 | H2: 2013 | I2: 2014 | J2: 2015 | K2: 2016 | L2: 2017 | N2: 2009-2017 | O2: 2009-2017
A3: Supply - unknown | B3: calculated | C3: 10^6 m3 | D3: =D44/1000 -> 61.277 | E3: =E44/1000 -> 44.722 | F3: =F44/1000 -> 44.898 | G3: =G44/1000 -> 56.254 | H3: =H44/1000 -> 75.547 | I3: =I44/1000 -> 77.18 | J3: =J44/1000 -> 85.398 | K3: =K44/1000 -> 97.199 | L3: =L44/1000 -> 103.699 | N3: =L3-D3 -> 42.422 | O3: =L3/D3-1 -> 0.6922989
