Workbook

Sheet Read me
A1: Trade flows — the input–output model of EU-27 manufacturing · IO-model masterfile v1
A2: Workbook | B2: Trade flows — IO-model masterfile v1 (EU-27 manufacturing input–output model, dashboard, underlying data and sources)
A3: Compiled | B3: 2026-08-11
A4: Status | B4: AI-compiled — pending Secretariat verification. Every statistical value is fetched from the public Eurostat API by the scripts named below; every curated figure carries its source on its own sheet and in the Sources sheet.
A5: What this is | B5: The COMPLETE input–output modelling behind /beta/overview-industry/trade-flows, rebuilt inside one workbook: the FIGARO use matrices (total / domestic / imported), the technical and import coefficient matrices, the Leontief inverse, the import-requirements matrix, multipliers, the import and value-added content of final demand and of extra-EU exports — plus the dashboard, the Eurostat trade backbone, the published FIGARO layers and every curated dependency register. It is a superset of the in-page "handover workbook" download, which only carries the result tables.
A6: Live formulas | B6: Everything derived is an Excel formula: the coefficient sheets divide the Z sheets by output, the Leontief inverse is one MINVERSE array formula over (I − A), the import-requirements sheet is one MMULT array formula, and the Multipliers and Dashboard sheets are built from SUM / SUMPRODUCT / INDEX / MATCH / COUNTIF over the data sheets. Change any underlying cell (a Z-matrix value, a backbone flow, a curated register row) and every dependent figure — up to and including the Dashboard — recalculates. Full recalculation on open is switched on.
A7: How to make changes | B7: 1) Edit the underlying cell (Z sheets, Trade backbone, or a curated register). 2) Let Excel recalculate (F9 / on open). 3) Record the edit in the Change log sheet (date, cell, old → new, reason, source). 4) For changes that should persist, carry them back to the repository — the canonical data lives in trade-data.ts / the generated extracts, and this file is regenerated from them; a hand-edited copy of this workbook is a working copy, not the source of truth.
A8: Model scope | B8: Reference year 2023; EU-27 treated as one economy ("imported" = from outside the EU). 64 A*64 industries (the whole economy, not only manufacturing — a manufacturing-only model would misstate the chains through energy, mining and services). € million, current basic prices. Matrices condensed from Eurostat FIGARO naio_10_fcp_ii4 (~11 M cells) by scripts/fetch-figaro-io-dataset.mjs; aggregation choices are documented in that script's header.
A9: Three data layers | B9: Layer 1 — trade backbone: ext_tec01, all 24 Section C divisions, 2023 + 2024, enterprise attribution. Layer 2 — input–output: the FIGARO matrices modelled here, plus the published application datasets (use-table input mixes, import origins, export destinations, foreign value added). Layer 3 — curated dependency registers: EC/JRC critical raw materials, SWD(2021) 352 strategic families, manufactured-product dependencies, energy dependency — "as reported by <source>", NOT derivable from official statistics and never arithmetically combined with the statistical layers.
A10: Raw data included | B10: The ENTIRE condensed FIGARO account is embedded: "FIGARO raw 2023" and "FIGARO raw 2022" hold every origin block (24 origins × 70 product/VA rows × 69 use columns per year, € million, zero cells blank), and "FIGARO exports raw" holds extra-EU exports by industry × destination (intermediate + final, both years). NOTHING between the raw sheets and the Dashboard is pre-computed outside Excel: the Z sheets are SUMs/references over the raw 2023 sheet (fixed 24-row stride per product row, EU27 origin first), the IO model reads the Z and exports-raw sheets, and everything above reads the IO model — edit one raw cell and the whole chain recalculates. 2022 is included for reference; to model it, repoint the Z-sheet formulas (same layout).
A11: Sheet map | B11: Dashboard → Figures (NATIVE Excel charts generated from the sheet data: trade balance, dependency map, import content — they recalculate with the sheets) → Methodology → Method figure (the model as one diagram) → Concepts (plain-language glossary: what an IO table is, what the Leontief inverse does, …) → FIGARO raw 2023 / FIGARO raw 2022 / FIGARO exports raw (the full embedded dataset) → IO model → Z total / Z domestic / Z imported (derived from the raw sheets by formula) → A domestic / A import → I minus A → Leontief inverse → Import requirements → Multipliers → Trade backbone → FIGARO partners → Foreign value added → Imported inputs → Critical materials → Product dependencies → Strategic dependencies → Energy dependency → Risk map → Critical inputs → Sources → Change log. The Methodology sheet states, for every derived sheet, the formula it implements and the exact cell references. Only the method diagram is an image; the data figures are real charts over live ranges.
A12: Reproducible | B12: node scripts/build-trade-flows-io-model-workbook.mjs rebuilds this file. Upstream: node scripts/fetch-figaro-io-dataset.mjs (FIGARO matrices), node scripts/fetch-trade-flows-io-data.mjs (backbone + published IO layers). Curated registers: beta/modules/overview-industry/trade-flows/trade-data.ts.
A13: Live module | B13: /beta/overview-industry/trade-flows on the MethodHub — same data, with the FIGARO table viewer and analysis dashboard at /trade-flows/figaro.

Sheet Dashboard
A1: Dashboard — every figure below is an Excel formula over the data sheets and recalculates when they are edited
A3: Headline — Section C manufacturing, reference year 2023 (Trade backbone, published IO layers, model)
A4: Extra-EU exports € bn (aggregate row) | B4: =INDEX('Trade backbone'!E:E,MATCH("C",'Trade backbone'!A:A,0)) -> 1649.9 | F4: ext_tec01 Section C aggregate; enterprise attribution.
A5: Extra-EU imports € bn (aggregate row) | B5: =INDEX('Trade backbone'!D:D,MATCH("C",'Trade backbone'!A:A,0)) -> 975.7 | F5: Includes trade not allocable to a division.
A6: Extra-EU trade balance € bn | B6: =INDEX('Trade backbone'!E:E,MATCH("C",'Trade backbone'!A:A,0))-INDEX('Trade backbone'!D:D,MATCH("C",'Trade backbone'!A:A,0)) -> 674.2 | F6: A large surplus that masks acute input dependencies.
A7: Foreign value added in exports % (published) | B7: =INDEX('Foreign value added'!E:E,MATCH("C",'Foreign value added'!A:A,0)) -> 22.4 | F7: FIGARO naio_10_fgfoee, EU-27 as one economy.
A8: Imported share of intermediate inputs % (use table) | B8: =INDEX('Imported inputs'!E:E,MATCH("C",'Imported inputs'!A:A,0)) -> 19.2 | F8: EU-27 use table at basic prices.
A9: Model: import content of manufacturing exports % (export-weighted) | B9: =SUMPRODUCT(('Multipliers'!$C$3:$C$66="C")*'Multipliers'!$E$3:$E$66,'Multipliers'!$H$3:$H$66)/SUMPRODUCT(('Multipliers'!$C$3:$C$66="C")*1,'Multipliers'!$H$3:$H$66) -> 23.91503 | F9: This workbook's own Leontief derivation (Multipliers sheet), weighted by extra-EU exports across the C industries.
A10: Model health: worst accounting-identity error (pp) | B10: =MAX(ABS('Multipliers'!G3:G66)) -> 8.8817842e-14 | F10: Import content + VA content − 100, worst industry. Near zero when the model is consistent; grows if an edit breaks the balance. Array-entered (Ctrl+Shift+Enter) in older Excel.
A12: Curated dependency registers — counts (COUNTIF over the register sheets)
A13: Critical raw materials tracked | B13: =COUNTA('Critical materials'!A2:A15) -> 14 | F13: CRMA Annex I/II designations with EC/JRC reliance figures.
A14: — of which Strategic (CRMA Annex I) | B14: =COUNTIF('Critical materials'!B2:B15,"Strategic*") -> 12
A15: Manufactured-product dependencies tracked | B15: =COUNTA('Product dependencies'!A2:A12) -> 11 | F15: The "not just raw materials" register.
A16: Strategic product families (SWD(2021) 352) | B16: =COUNTA('Strategic dependencies'!A2:A7) -> 6
A17: Dependencies with China as largest supplier (materials + products) | B17: =COUNTIF('Critical materials'!D2:D15,"*China*")+COUNTIF('Product dependencies'!E2:E12,"*China*") -> 18 | F17: Largest single supplier, as reported by each source.
A18: Materials with 100 % import reliance | B18: =COUNTIF('Critical materials'!C2:C15,100) -> 11
A19: Overall EU energy import dependency % | B19: ='Energy dependency'!C2 -> 57.3 | F19: Live nrg_ind_id headline row.
A21: Dependencies by supplier country (COUNTIF across the three curated registers)
A22: Supplier (as recorded) | B22: Materials | C22: Products | D22: Strategic families | E22: Total
A23: Brazil | B23: =COUNTIF('Critical materials'!D2:D15,"Brazil") -> 1 | C23: =COUNTIF('Product dependencies'!E2:E12,"Brazil") -> 0 | D23: =COUNTIF('Strategic dependencies'!E2:E7,"Brazil") -> 0 | E23: =SUM(B23:D23) -> 1
A24: Chile | B24: =COUNTIF('Critical materials'!D2:D15,"Chile") -> 1 | C24: =COUNTIF('Product dependencies'!E2:E12,"Chile") -> 0 | D24: =COUNTIF('Strategic dependencies'!E2:E7,"Chile") -> 0 | E24: =SUM(B24:D24) -> 1
A25: China | B25: =COUNTIF('Critical materials'!D2:D15,"China") -> 9 | C25: =COUNTIF('Product dependencies'!E2:E12,"China") -> 8 | D25: =COUNTIF('Strategic dependencies'!E2:E7,"China") -> 2 | E25: =SUM(B25:D25) -> 19
A26: China / India | B26: =COUNTIF('Critical materials'!D2:D15,"China / India") -> 0 | C26: =COUNTIF('Product dependencies'!E2:E12,"China / India") -> 1 | D26: =COUNTIF('Strategic dependencies'!E2:E7,"China / India") -> 1 | E26: =SUM(B26:D26) -> 2
A27: DR Congo (mining) | B27: =COUNTIF('Critical materials'!D2:D15,"DR Congo (mining)") -> 1 | C27: =COUNTIF('Product dependencies'!E2:E12,"DR Congo (mining)") -> 0 | D27: =COUNTIF('Strategic dependencies'!E2:E7,"DR Congo (mining)") -> 0 | E27: =SUM(B27:D27) -> 1
A28: South Africa | B28: =COUNTIF('Critical materials'!D2:D15,"South Africa") -> 1 | C28: =COUNTIF('Product dependencies'!E2:E12,"South Africa") -> 0 | D28: =COUNTIF('Strategic dependencies'!E2:E7,"South Africa") -> 1 | E28: =SUM(B28:D28) -> 2
A29: South-East Asia | B29: =COUNTIF('Critical materials'!D2:D15,"South-East Asia") -> 0 | C29: =COUNTIF('Product dependencies'!E2:E12,"South-East Asia") -> 1 | D29: =COUNTIF('Strategic dependencies'!E2:E7,"South-East Asia") -> 0 | E29: =SUM(B29:D29) -> 1
A30: Taiwan / East Asia | B30: =COUNTIF('Critical materials'!D2:D15,"Taiwan / East Asia") -> 0 | C30: =COUNTIF('Product dependencies'!E2:E12,"Taiwan / East Asia") -> 1 | D30: =COUNTIF('Strategic dependencies'!E2:E7,"Taiwan / East Asia") -> 1 | E30: =SUM(B30:D30) -> 2
A31: Türkiye | B31: =COUNTIF('Critical materials'!D2:D15,"Türkiye") -> 1 | C31: =COUNTIF('Product dependencies'!E2:E12,"Türkiye") -> 0 | D31: =COUNTIF('Strategic dependencies'!E2:E7,"Türkiye") -> 1 | E31: =SUM(B31:D31) -> 2
A33: By NACE division — balance, input mix, dependency count (INDEX/MATCH + COUNTIF)
A34: Division | B34: Extra-EU balance 2023 €bn | C34: Imported-input share % | D34: Curated dependency mentions | F34: Label / note
A35: C10 | B35: =INDEX('Trade backbone'!F:F,MATCH("C10",'Trade backbone'!A:A,0)) -> 53 | C35: =INDEX('Imported inputs'!E:E,MATCH("C10-12",'Imported inputs'!A:A,0)) -> 10.4 | D35: =COUNTIF('Critical materials'!F2:F15,"*C10*")+COUNTIF('Product dependencies'!C2:C12,"*C10*")+COUNTIF('Strategic dependencies'!B2:B7,"*C10*")+COUNTIF('Critical inputs'!A:A,"C10") -> 2 | F35: Food products — input mix is the C10-12 group figure
A36: C11 | B36: =INDEX('Trade backbone'!F:F,MATCH("C11",'Trade backbone'!A:A,0)) -> 18.6 | C36: =INDEX('Imported inputs'!E:E,MATCH("C10-12",'Imported inputs'!A:A,0)) -> 10.4 | D36: =COUNTIF('Critical materials'!F2:F15,"*C11*")+COUNTIF('Product dependencies'!C2:C12,"*C11*")+COUNTIF('Strategic dependencies'!B2:B7,"*C11*")+COUNTIF('Critical inputs'!A:A,"C11") -> 0 | F36: Beverages — input mix is the C10-12 group figure
A37: C12 | B37: =INDEX('Trade backbone'!F:F,MATCH("C12",'Trade backbone'!A:A,0)) -> 0.6 | C37: =INDEX('Imported inputs'!E:E,MATCH("C10-12",'Imported inputs'!A:A,0)) -> 10.4 | D37: =COUNTIF('Critical materials'!F2:F15,"*C12*")+COUNTIF('Product dependencies'!C2:C12,"*C12*")+COUNTIF('Strategic dependencies'!B2:B7,"*C12*")+COUNTIF('Critical inputs'!A:A,"C12") -> 0 | F37: Tobacco products — input mix is the C10-12 group figure
A38: C13 | B38: =INDEX('Trade backbone'!F:F,MATCH("C13",'Trade backbone'!A:A,0)) -> 4.1 | C38: =INDEX('Imported inputs'!E:E,MATCH("C13-15",'Imported inputs'!A:A,0)) -> 17.8 | D38: =COUNTIF('Critical materials'!F2:F15,"*C13*")+COUNTIF('Product dependencies'!C2:C12,"*C13*")+COUNTIF('Strategic dependencies'!B2:B7,"*C13*")+COUNTIF('Critical inputs'!A:A,"C13") -> 0 | F38: Textiles — input mix is the C13-15 group figure
A39: C14 | B39: =INDEX('Trade backbone'!F:F,MATCH("C14",'Trade backbone'!A:A,0)) -> -0.6 | C39: =INDEX('Imported inputs'!E:E,MATCH("C13-15",'Imported inputs'!A:A,0)) -> 17.8 | D39: =COUNTIF('Critical materials'!F2:F15,"*C14*")+COUNTIF('Product dependencies'!C2:C12,"*C14*")+COUNTIF('Strategic dependencies'!B2:B7,"*C14*")+COUNTIF('Critical inputs'!A:A,"C14") -> 1 | F39: Wearing apparel — input mix is the C13-15 group figure
A40: C15 | B40: =INDEX('Trade backbone'!F:F,MATCH("C15",'Trade backbone'!A:A,0)) -> 4.3 | C40: =INDEX('Imported inputs'!E:E,MATCH("C13-15",'Imported inputs'!A:A,0)) -> 17.8 | D40: =COUNTIF('Critical materials'!F2:F15,"*C15*")+COUNTIF('Product dependencies'!C2:C12,"*C15*")+COUNTIF('Strategic dependencies'!B2:B7,"*C15*")+COUNTIF('Critical inputs'!A:A,"C15") -> 0 | F40: Leather & footwear — input mix is the C13-15 group figure
A41: C16 | B41: =INDEX('Trade backbone'!F:F,MATCH("C16",'Trade backbone'!A:A,0)) -> 9.7 | C41: =INDEX('Imported inputs'!E:E,MATCH("C16",'Imported inputs'!A:A,0)) -> 9.6 | D41: =COUNTIF('Critical materials'!F2:F15,"*C16*")+COUNTIF('Product dependencies'!C2:C12,"*C16*")+COUNTIF('Strategic dependencies'!B2:B7,"*C16*")+COUNTIF('Critical inputs'!A:A,"C16") -> 0 | F41: Wood & cork products
A42: C17 | B42: =INDEX('Trade backbone'!F:F,MATCH("C17",'Trade backbone'!A:A,0)) -> 9.1 | C42: =INDEX('Imported inputs'!E:E,MATCH("C17",'Imported inputs'!A:A,0)) -> 11.7 | D42: =COUNTIF('Critical materials'!F2:F15,"*C17*")+COUNTIF('Product dependencies'!C2:C12,"*C17*")+COUNTIF('Strategic dependencies'!B2:B7,"*C17*")+COUNTIF('Critical inputs'!A:A,"C17") -> 2 | F42: Paper & paper products
A43: C18 | B43: =INDEX('Trade backbone'!F:F,MATCH("C18",'Trade backbone'!A:A,0)) -> 1.4 | C43: =INDEX('Imported inputs'!E:E,MATCH("C18",'Imported inputs'!A:A,0)) -> 12.4 | D43: =COUNTIF('Critical materials'!F2:F15,"*C18*")+COUNTIF('Product dependencies'!C2:C12,"*C18*")+COUNTIF('Strategic dependencies'!B2:B7,"*C18*")+COUNTIF('Critical inputs'!A:A,"C18") -> 0 | F43: Printing & recorded media
A44: C19 | B44: =INDEX('Trade backbone'!F:F,MATCH("C19",'Trade backbone'!A:A,0)) -> -161.8 | C44: =INDEX('Imported inputs'!E:E,MATCH("C19",'Imported inputs'!A:A,0)) -> 63.4 | D44: =COUNTIF('Critical materials'!F2:F15,"*C19*")+COUNTIF('Product dependencies'!C2:C12,"*C19*")+COUNTIF('Strategic dependencies'!B2:B7,"*C19*")+COUNTIF('Critical inputs'!A:A,"C19") -> 1 | F44: Coke & refined petroleum
...

Sheet Figures
A1: Figures — NATIVE Excel charts, generated from the sheet data: each chart reads a live range (named in its caption), so editing the underlying sheets moves the charts. The chart-data blocks in columns N–V are formulas over the data sheets — do not delete them. Only the row ORDER of figures 1 and 3 is fixed at build time (Excel cannot re-sort a chart range); values, bar lengths, positions and the surplus/deficit colour routing are all live. Chart colours are colour-vision-deficiency checked (teal = surplus, red = deficit; blue = raw material, orange = product).
N2: Chart data — live formulas over the data sheets. The charts read these ranges; do not delete.
A3: Figure 1 · Extra-EU trade balance by division, 2023 — native chart over Figures!P5:Q28 (live formulas over the Trade backbone sheet)
N4: Division | O4: Extra-EU balance 2023 €bn | P4: Surplus | Q4: Deficit | T4: Code | U4: Industry | V4: Import content %
N5: C28 · Machinery & equipment n.e.c. | O5: =INDEX('Trade backbone'!$F:$F,MATCH("C28",'Trade backbone'!$A:$A,0)) -> 165 | P5: =IF(O5>=0,O5,NA()) -> 165 | Q5: =IF(O5<0,O5,NA()) -> #N/A | T5: C19 | U5: =$T5&" · "&INDEX('Multipliers'!$B:$B,MATCH($T5,'Multipliers'!$A:$A,0)) -> C19 · Manufacture of coke and refined petroleum products | V5: =INDEX('Multipliers'!$E:$E,MATCH($T5,'Multipliers'!$A:$A,0)) -> 63.7
N6: C29 · Motor vehicles & parts | O6: =INDEX('Trade backbone'!$F:$F,MATCH("C29",'Trade backbone'!$A:$A,0)) -> 160.1 | P6: =IF(O6>=0,O6,NA()) -> 160.1 | Q6: =IF(O6<0,O6,NA()) -> #N/A | T6: C24 | U6: =$T6&" · "&INDEX('Multipliers'!$B:$B,MATCH($T6,'Multipliers'!$A:$A,0)) -> C24 · Manufacture of basic metals | V6: =INDEX('Multipliers'!$E:$E,MATCH($T6,'Multipliers'!$A:$A,0)) -> 31.7
N7: C21 · Pharmaceuticals | O7: =INDEX('Trade backbone'!$F:$F,MATCH("C21",'Trade backbone'!$A:$A,0)) -> 110.8 | P7: =IF(O7>=0,O7,NA()) -> 110.8 | Q7: =IF(O7<0,O7,NA()) -> #N/A | T7: H50 | U7: =$T7&" · "&INDEX('Multipliers'!$B:$B,MATCH($T7,'Multipliers'!$A:$A,0)) -> H50 · Water transport | V7: =INDEX('Multipliers'!$E:$E,MATCH($T7,'Multipliers'!$A:$A,0)) -> 30.4
N8: C20 · Chemicals & chemical products | O8: =INDEX('Trade backbone'!$F:$F,MATCH("C20",'Trade backbone'!$A:$A,0)) -> 73.9 | P8: =IF(O8>=0,O8,NA()) -> 73.9 | Q8: =IF(O8<0,O8,NA()) -> #N/A | T8: C20 | U8: =$T8&" · "&INDEX('Multipliers'!$B:$B,MATCH($T8,'Multipliers'!$A:$A,0)) -> C20 · Manufacture of chemicals and chemical products | V8: =INDEX('Multipliers'!$E:$E,MATCH($T8,'Multipliers'!$A:$A,0)) -> 28.9
N9: C30 · Other transport equipment (aero, … | O9: =INDEX('Trade backbone'!$F:$F,MATCH("C30",'Trade backbone'!$A:$A,0)) -> 63.1 | P9: =IF(O9>=0,O9,NA()) -> 63.1 | Q9: =IF(O9<0,O9,NA()) -> #N/A | T9: H51 | U9: =$T9&" · "&INDEX('Multipliers'!$B:$B,MATCH($T9,'Multipliers'!$A:$A,0)) -> H51 · Air transport | V9: =INDEX('Multipliers'!$E:$E,MATCH($T9,'Multipliers'!$A:$A,0)) -> 28.4
N10: C10 · Food products | O10: =INDEX('Trade backbone'!$F:$F,MATCH("C10",'Trade backbone'!$A:$A,0)) -> 53 | P10: =IF(O10>=0,O10,NA()) -> 53 | Q10: =IF(O10<0,O10,NA()) -> #N/A | T10: C30 | U10: =$T10&" · "&INDEX('Multipliers'!$B:$B,MATCH($T10,'Multipliers'!$A:$A,0)) -> C30 · Manufacture of other transport equipment | V10: =INDEX('Multipliers'!$E:$E,MATCH($T10,'Multipliers'!$A:$A,0)) -> 27.2
N11: C25 · Fabricated metal products | O11: =INDEX('Trade backbone'!$F:$F,MATCH("C25",'Trade backbone'!$A:$A,0)) -> 28.7 | P11: =IF(O11>=0,O11,NA()) -> 28.7 | Q11: =IF(O11<0,O11,NA()) -> #N/A | T11: C27 | U11: =$T11&" · "&INDEX('Multipliers'!$B:$B,MATCH($T11,'Multipliers'!$A:$A,0)) -> C27 · Manufacture of electrical equipment | V11: =INDEX('Multipliers'!$E:$E,MATCH($T11,'Multipliers'!$A:$A,0)) -> 22.9
N12: C32 · Other manufacturing (medical, ins… | O12: =INDEX('Trade backbone'!$F:$F,MATCH("C32",'Trade backbone'!$A:$A,0)) -> 25.2 | P12: =IF(O12>=0,O12,NA()) -> 25.2 | Q12: =IF(O12<0,O12,NA()) -> #N/A | T12: C22 | U12: =$T12&" · "&INDEX('Multipliers'!$B:$B,MATCH($T12,'Multipliers'!$A:$A,0)) -> C22 · Manufacture of rubber and plastic products | V12: =INDEX('Multipliers'!$E:$E,MATCH($T12,'Multipliers'!$A:$A,0)) -> 22.4
N13: C27 · Electrical equipment | O13: =INDEX('Trade backbone'!$F:$F,MATCH("C27",'Trade backbone'!$A:$A,0)) -> 23.6 | P13: =IF(O13>=0,O13,NA()) -> 23.6 | Q13: =IF(O13<0,O13,NA()) -> #N/A | T13: C29 | U13: =$T13&" · "&INDEX('Multipliers'!$B:$B,MATCH($T13,'Multipliers'!$A:$A,0)) -> C29 · Manufacture of motor vehicles, trailers and semi-trailers | V13: =INDEX('Multipliers'!$E:$E,MATCH($T13,'Multipliers'!$A:$A,0)) -> 21.6
N14: C26 · Computer, electronic & optical | O14: =INDEX('Trade backbone'!$F:$F,MATCH("C26",'Trade backbone'!$A:$A,0)) -> 22.2 | P14: =IF(O14>=0,O14,NA()) -> 22.2 | Q14: =IF(O14<0,O14,NA()) -> #N/A | T14: C26 | U14: =$T14&" · "&INDEX('Multipliers'!$B:$B,MATCH($T14,'Multipliers'!$A:$A,0)) -> C26 · Manufacture of computer, electronic and optical products | V14: =INDEX('Multipliers'!$E:$E,MATCH($T14,'Multipliers'!$A:$A,0)) -> 21.1
N15: C22 · Rubber & plastics | O15: =INDEX('Trade backbone'!$F:$F,MATCH("C22",'Trade backbone'!$A:$A,0)) -> 19.6 | P15: =IF(O15>=0,O15,NA()) -> 19.6 | Q15: =IF(O15<0,O15,NA()) -> #N/A | T15: C21 | U15: =$T15&" · "&INDEX('Multipliers'!$B:$B,MATCH($T15,'Multipliers'!$A:$A,0)) -> C21 · Manufacture of basic pharmaceutical products and pharmaceutical prepa… | V15: =INDEX('Multipliers'!$E:$E,MATCH($T15,'Multipliers'!$A:$A,0)) -> 21
N16: C11 · Beverages | O16: =INDEX('Trade backbone'!$F:$F,MATCH("C11",'Trade backbone'!$A:$A,0)) -> 18.6 | P16: =IF(O16>=0,O16,NA()) -> 18.6 | Q16: =IF(O16<0,O16,NA()) -> #N/A | T16: C13-15 | U16: =$T16&" · "&INDEX('Multipliers'!$B:$B,MATCH($T16,'Multipliers'!$A:$A,0)) -> C13-15 · Manufacture of textiles, wearing apparel, leather and related products | V16: =INDEX('Multipliers'!$E:$E,MATCH($T16,'Multipliers'!$A:$A,0)) -> 20.6
N17: C23 · Non-metallic minerals (cement, gl… | O17: =INDEX('Trade backbone'!$F:$F,MATCH("C23",'Trade backbone'!$A:$A,0)) -> 15.1 | P17: =IF(O17>=0,O17,NA()) -> 15.1 | Q17: =IF(O17<0,O17,NA()) -> #N/A
N18: C16 · Wood & cork products | O18: =INDEX('Trade backbone'!$F:$F,MATCH("C16",'Trade backbone'!$A:$A,0)) -> 9.7 | P18: =IF(O18>=0,O18,NA()) -> 9.7 | Q18: =IF(O18<0,O18,NA()) -> #N/A
N19: C31 · Furniture | O19: =INDEX('Trade backbone'!$F:$F,MATCH("C31",'Trade backbone'!$A:$A,0)) -> 9.5 | P19: =IF(O19>=0,O19,NA()) -> 9.5 | Q19: =IF(O19<0,O19,NA()) -> #N/A
N20: C17 · Paper & paper products | O20: =INDEX('Trade backbone'!$F:$F,MATCH("C17",'Trade backbone'!$A:$A,0)) -> 9.1 | P20: =IF(O20>=0,O20,NA()) -> 9.1 | Q20: =IF(O20<0,O20,NA()) -> #N/A
N21: C15 · Leather & footwear | O21: =INDEX('Trade backbone'!$F:$F,MATCH("C15",'Trade backbone'!$A:$A,0)) -> 4.3 | P21: =IF(O21>=0,O21,NA()) -> 4.3 | Q21: =IF(O21<0,O21,NA()) -> #N/A
N22: C13 · Textiles | O22: =INDEX('Trade backbone'!$F:$F,MATCH("C13",'Trade backbone'!$A:$A,0)) -> 4.1 | P22: =IF(O22>=0,O22,NA()) -> 4.1 | Q22: =IF(O22<0,O22,NA()) -> #N/A
N23: C24 · Basic metals | O23: =INDEX('Trade backbone'!$F:$F,MATCH("C24",'Trade backbone'!$A:$A,0)) -> 4.1 | P23: =IF(O23>=0,O23,NA()) -> 4.1 | Q23: =IF(O23<0,O23,NA()) -> #N/A
N24: C18 · Printing & recorded media | O24: =INDEX('Trade backbone'!$F:$F,MATCH("C18",'Trade backbone'!$A:$A,0)) -> 1.4 | P24: =IF(O24>=0,O24,NA()) -> 1.4 | Q24: =IF(O24<0,O24,NA()) -> #N/A
N25: C12 · Tobacco products | O25: =INDEX('Trade backbone'!$F:$F,MATCH("C12",'Trade backbone'!$A:$A,0)) -> 0.6 | P25: =IF(O25>=0,O25,NA()) -> 0.6 | Q25: =IF(O25<0,O25,NA()) -> #N/A
N26: C14 · Wearing apparel | O26: =INDEX('Trade backbone'!$F:$F,MATCH("C14",'Trade backbone'!$A:$A,0)) -> -0.6 | P26: =IF(O26>=0,O26,NA()) -> #N/A | Q26: =IF(O26<0,O26,NA()) -> -0.6
N27: C33 · Repair & installation of machinery | O27: =INDEX('Trade backbone'!$F:$F,MATCH("C33",'Trade backbone'!$A:$A,0)) -> -6.1 | P27: =IF(O27>=0,O27,NA()) -> #N/A | Q27: =IF(O27<0,O27,NA()) -> -6.1
N28: C19 · Coke & refined petroleum | O28: =INDEX('Trade backbone'!$F:$F,MATCH("C19",'Trade backbone'!$A:$A,0)) -> -161.8 | P28: =IF(O28>=0,O28,NA()) -> #N/A | Q28: =IF(O28<0,O28,NA()) -> -161.8
A49: Figure 2 · The import-dependency map — native scatter over the Risk map sheet columns D:E; per-point details are in that sheet's table
A84: Figure 3 · Import content of final demand, top 12 industries — native chart over Figures!U5:V16 (live formulas over the Multipliers sheet)

Sheet Methodology
A1: Methodology & derivations — how every number in this workbook is computed
A2: 1 · The accounting identity | B2: An input–output table reads each industry twice: each ROW is an industry as a seller, each COLUMN the same industry as a buyer. Reading a column down gives the industry's input recipe. Every euro of output is bought either as another industry's intermediate input or as final demand: x = A·x + f (output = intermediate demand + final demand). In this workbook the identity is checked per industry on the IO model sheet: column-based output (everything industry j buys, incl. value added — Z total column sums) against row-based output (everything EU industry i sells: its DOMESTIC deliveries to EU intermediate use and final demand — Z domestic rows, because the Z total rows additionally contain imported supply of the same products — plus extra-EU exports). The residual column should stay near zero (rounding and the FIGARO balancing item only) — if an edit breaks it, the edit broke the balance.
A3: 2 · Technical coefficients (A domestic) | B3: a_ij = Z_domestic(i,j) / x_j — the euros of DOMESTIC (intra-EU) product i needed per euro of output of industry j. Sheet "A domestic", each cell an explicit division of the Z domestic sheet by output on the IO model sheet (e.g. cell C3 = 'Z domestic'!C3 / 'IO model'!$D$4). The import coefficients m_ij = Z_imported(i,j) / x_j are the same construction on sheet "A import" — the extra-EU input recipe.
A4: 3 · Leontief inverse | B4: Solving x = A·x + f for output gives x = (I − A)⁻¹ · f. The matrix L = (I − A_domestic)⁻¹ (sheet "Leontief inverse", one MINVERSE array formula over the "I minus A" sheet) converts a bill of final demand into the TOTAL output every industry must produce — direct plus indirect: one euro of car demand pulls in steel, the steel pulls in iron ore and electricity, and so on; L sums the whole regress (I + A + A² + …). Column sums of L are the output multipliers on the Multipliers sheet.
A5: 4 · Import requirements | B5: M = A_import · L (sheet "Import requirements", one MMULT array formula): cell (i,j) is the euros of extra-EU imports of product i required — directly and through all domestic supply chains — per euro of final demand for industry j's output. Column sums are the IMPORT CONTENT of final demand (Multipliers sheet): what one euro spent on industry j's output pulls in from outside the EU.
A6: 5 · Value-added content and the model check | B6: v_j = (all six value-added and adjustment rows) / x_j on the IO model sheet. The value-added content of final demand is v′·L (SUMPRODUCT of the v vector with each L column). Accounting identity: import content + value-added content = 1 exactly (every euro of final demand is ultimately either extra-EU imports or EU value added, taxes included). The Multipliers sheet carries the check column; the Dashboard surfaces its worst deviation.
A7: 6 · Imports embodied in exports | B7: Applying the same requirements to extra-EU exports e (IO model sheet, from the FIGARO inter-country accounts): imports embodied in industry j's exports = import content_j × e_j; the output needed economy-wide to produce the EU's exports is L·e (an MMULT column on the Multipliers sheet). This is the workbook's own derivation of what Eurostat publishes as "foreign value added in exports".
A8: 7 · Cross-check vs the published FVA | B8: The Multipliers sheet compares the model's import content of exports with the PUBLISHED FIGARO foreign-value-added shares (naio_10_fgfoee, on the Foreign value added sheet). The two are close but conceptually distinct and are NOT expected to be identical: import content counts gross imported inputs (which contain the partner's own imported inputs, and re-imported EU value), while FVA counts only foreign value added, computed by Eurostat from the full 46-country inter-country model rather than this condensed EU-vs-rest account. Differences of a few percentage points are the method, not an error. OECD TiVA offers an independent series for level checks.
A9: 8 · Enterprise vs product attribution | B9: "Imports of division X" is not one number. The Trade backbone (ext_tec01) books trade to the NACE code of the trading ENTERPRISE; the IO layer follows the PRODUCT. C19 is the worked example: refiners import ~€218 bn of crude (enterprise view, backbone sheet), but crude is a MINING product, so the product view (FIGARO partners sheet) shows only ~€62 bn of refined-product imports — and the crude reappears on the model sheets as imported intermediate input INTO refining (row B of the Z imported column for C19). All three lenses are kept, each labelled; each answers a different question: who imports (enterprise), what crosses the border (product), what does an industry depend on (input–output).
A10: 9 · Grouped industries | B10: FIGARO and the use table publish some divisions only as groups: C10-12 (food, beverages & tobacco), C13-15 (textiles, apparel & leather), C31_32 (furniture & other manufacturing). Those divisions inherit group-level figures. Known within-group skews: C14: Within C13–C15, finished-apparel imports are far more concentrated in China, Bangladesh, Türkiye and India than the group average. | C31: Within C31–C32, furniture imports are strongly China-weighted; C32 (medical devices, instruments) leans US/CH.
A11: 10 · Curated-layer definitions | B11: Import reliance (critical materials, risk map x-axis): IR = (imports − exports) / (domestic production + imports − exports) — the EC criticality methodology; it nets out re-exports, so it differs from customs shares. Supplier concentration (y-axis): the largest single supplier's share of EU supply — a first-moment proxy for the HHI; it understates concentration when suppliers two and three are also non-diversified and says nothing about substitutability, stocks or recyclability. Product-dependency shares are customs-based ("largest supplier's share of extra-EU imports") unless the Share basis column says otherwise. All curated figures are quoted "as reported by <source>" and must not be arithmetically combined with the statistical layers.
A12: 11 · Known limits | B12: Modelled statistics: FIGARO balances supply and use across countries and can differ from raw customs data (CIF/FOB, re-exports, balancing). Proportionality: every euro of an industry's output is assumed to use the same input recipe (no scale effects, no substitution). Current prices: year-on-year changes mix price and volume. Named partners: FIGARO names 23 partner areas — Taiwan is inside "Rest of the world", so the semiconductor dependency is invisible in the named-partner shares and appears only in the curated layer. The Section C aggregate of ext_tec01 does not equal the sum of its 24 divisions (non-allocable trade; both are shown on the Trade backbone sheet).
A13: 12 · Where every derivation lives | B13: Z total C3 = SUM of the 24 origin rows of 'FIGARO raw 2023' for that product row × use column; Z domestic C3 = the EU27 origin row; Z imported C3 = SUM of the 23 partner rows (fixed 24-row stride per product row). IO model: x_j = SUM of Z total column j (rows 3–72); exports = SUM of the industry's row in both 2023 blocks of 'FIGARO exports raw'; residual check per industry. A domestic C3 = 'Z domestic'!C3/'IO model'!$D$4 (and so on cell by cell). A import C3 = 'Z imported'!C3/'IO model'!$D$4. I minus A C3 = 1−'A domestic'!C3 on the diagonal, else −'A domestic'!C3. Leontief inverse: {=MINVERSE('I minus A'!C3:BN66)}. Import requirements: {=MMULT('A import'!C3:BN66,'Leontief inverse'!C3:BN66)}. Multipliers: output multiplier = SUM(L column); import content = SUM(Import requirements column); VA content = SUMPRODUCT(v vector, L column); check = import + VA content − 1; embodied imports = import content × exports; output for exports = {=MMULT(L, exports)}. Dashboard: INDEX/MATCH on the backbone and published sheets; COUNTIF/SUMPRODUCT over the curated registers; LARGE/INDEX/MATCH for the top-10 tables.

Sheet Method figure
A1: The method, as one picture — read with the Methodology and Concepts sheets. Every box names the workbook sheet that holds that step as live formulas.
A3: Method figure · From the FIGARO table to every derived number

Sheet Concepts
A1: Term | B1: Plain-language explanation | C1: Where it lives in this workbook
A2: Input–output (IO) table | B2: A grid of the whole economy. Each ROW is an industry as a seller (who buys its product); each COLUMN is the same industry as a buyer (what it must purchase to produce). Reading a column down gives that industry's complete shopping list — its "recipe". Invented by Wassily Leontief in the 1930s (Nobel Prize 1973); today every EU national accounts system publishes one. | C2: Z total / Z domestic / Z imported
A3: Use table (at basic prices) | B3: The half of the IO framework used here: what each industry USES as inputs, valued at the prices producers actually receive (basic prices — before trade margins, transport margins and product taxes are stacked on top). Its counterpart, the supply table, records who makes what; Eurostat balances the two before publication. | C3: Z sheets; the published mixes on "Imported inputs"
A4: Intermediate consumption / intermediate demand | B4: Goods and services bought by one industry and USED UP making something else — crude oil into a refinery, steel into a car, electricity into a smelter. This is what the Z matrix contains. It is the opposite of final demand: intermediate purchases stay inside the production system. | C4: Z sheets; "IO model" columns E and K
A5: Final demand (f) | B5: Where output leaves the production system for good: household consumption, government consumption, non-profit consumption, investment (gross fixed capital formation) and inventory changes. In this EU-27 account, extra-EU exports are a sixth destination, held in their own column on the IO model sheet. | C5: Z sheets, last 5 columns; exports on "IO model" col M
A6: Gross output (x) | B6: Everything an industry produces in a year, in euros. Two ways to count it must agree: everything the industry PAYS FOR (all inputs + all value added — the column sum) and everything it SELLS (intermediate deliveries + final demand + exports — the row sum). The IO model sheet computes both and shows the residual; if an edit makes them disagree, the edit broke the accounting. | C6: "IO model" cols D and N, residual col O
A7: Value added (v) | B7: What is left of an industry's revenue after paying for inputs: wages (compensation of employees, D1), profits (gross operating surplus, B2A3G) and production taxes net of subsidies. Value added is what GDP sums. In the FIGARO account it occupies six extra rows under the 64 industry rows. | C7: "Z domestic" rows 67–72; "IO model" cols F–I
A8: Technical coefficient (a_ij) | B8: The recipe per euro: how many cents of product i industry j needs to produce one euro of its own output. Computed by dividing every cell of the domestic Z matrix by the buying industry's output. The full 64×64 grid of these is the A matrix — the economy's complete recipe book. | C8: "A domestic" (every cell a live division)
A9: Import coefficient (m_ij) | B9: The same recipe, but counting only inputs bought from OUTSIDE the EU: cents of imported product i per euro of industry j's output. Together, domestic coefficients + import coefficients + value added per euro sum to exactly 1 for every industry — every euro of output is fully accounted for. | C9: "A import"
A10: Leontief inverse (L = (I − A)⁻¹) | B10: THE central object of IO modelling. A alone only gives the DIRECT inputs. But the steel in a car needed iron ore; the ore needed mining machinery; the machinery needed steel again — an infinite ripple (I + A + A² + A³ + …). The Leontief inverse sums that entire infinite chain in one matrix operation: cell (i,j) says how much TOTAL output of industry i is needed, directly and indirectly, per euro of final demand for industry j. In this workbook it is one live MINVERSE formula, so it re-solves itself whenever A changes. ("Leontief reserve" is a common mishearing — the term is Leontief INVERSE, after Wassily Leontief.) | C10: "Leontief inverse" (one MINVERSE array formula)
A11: Output multiplier | B11: The column sum of the Leontief inverse: total euros of economy-wide output triggered by one euro of final demand for an industry's product. A multiplier of 1.6 means one euro of car demand generates €1.60 of production across the whole EU economy — the car itself plus €0.60 of upstream deliveries. | C11: "Multipliers" col D; top-10 on the Dashboard
A12: Import content of final demand | B12: The column sum of the import-requirements matrix M = A_import · L: cents of every euro of final demand that end up as extra-EU imports, counting both direct imports and imports hidden deep in the domestic supply chain. Refined petroleum is the extreme case — most of a euro spent on it leaks abroad as crude. | C12: "Import requirements", "Multipliers" col E
... A24: CBAM / CRMA | B24: The policy front lines this module feeds: the Carbon Border Adjustment Mechanism (imports of cement, steel, aluminium, fertilisers, electricity, hydrogen pay a carbon price at the border) and the Critical Raw Materials Act, Reg. (EU) 2024/1252 (34 critical materials, 17 of them strategic, with 2030 extraction/processing/recycling benchmarks). The dependency registers use the CRMA's legal Annex I/II designations, not editorial ratings. | C24: "Critical materials", "Strategic dependencies"

Sheet FIGARO raw 2023
A1: FIGARO raw dataset — 2023, € million (naio_10_fcp_ii4, condensed to EU-27 as one economy; extract of 2026-07-07). One row per product row × origin, the 24 origins contiguous per product row: origin EU27 is intra-EU supply (and carries the six value-added rows); every other origin is that partner's exports into EU-27 use. Zero cells are left blank. The Z sheets derive from THIS sheet by formula (fixed 24-row stride) — edit a cell here and the whole model recalculates.
A2: Row code | B2: Row label | C2: Origin | D2: A01 | E2: A02 | F2: A03 | G2: B | H2: C10-12 | I2: C13-15 | J2: C16 | K2: C17 | L2: C18 | M2: C19 | N2: C20 | O2: C21 | P2: C22 | Q2: C23 | R2: C24 | S2: C25 | T2: C26 | U2: C27 | V2: C28 | W2: C29 | X2: C30 | Y2: C31_32 | Z2: C33 | AA2: D35 | AB2: E36 | AC2: E37-39 | AD2: F | AE2: G45 | AF2: G46 | AG2: G47 | AH2: H49 | AI2: H50 | AJ2: H51 | AK2: H52 | AL2: H53 | AM2: I | AN2: J58 | AO2: J59_60 | AP2: J61 | AQ2: J62_63 | AR2: K64 | AS2: K65 | AT2: K66 | AU2: L | AV2: M69_70 | AW2: M71 | AX2: M72 | AY2: M73 | AZ2: M74_75 | BA2: N77 | BB2: N78 | BC2: N79 | BD2: N80-82 | BE2: O84 | BF2: P85 | BG2: Q86 | BH2: Q87_88 | BI2: R90-92 | BJ2: R93 | BK2: S94 | BL2: S95 | BM2: S96 | BN2: T | BO2: U | BP2: P3_S13 | BQ2: P3_S14 | BR2: P3_S15 | BS2: P51G | BT2: P5M
D3: Crop and animal production, hunting and related service activities | E3: Forestry and logging | F3: Fishing and aquaculture | G3: Mining and quarrying | H3: Manufacture of food products | I3: Manufacture of textiles, wearing apparel, leather and related products | J3: Manufacture of wood and of products of wood and cork, except furniture | K3: Manufacture of paper and paper products | L3: Printing and reproduction of recorded media | M3: Manufacture of coke and refined petroleum products | N3: Manufacture of chemicals and chemical products | O3: Manufacture of basic pharmaceutical products and pharmaceutical prepa… | P3: Manufacture of rubber and plastic products | Q3: Manufacture of other non-metallic mineral products | R3: Manufacture of basic metals | S3: Manufacture of fabricated metal products, except machinery and equipm… | T3: Manufacture of computer, electronic and optical products | U3: Manufacture of electrical equipment | V3: Manufacture of machinery and equipment n.e.c. | W3: Manufacture of motor vehicles, trailers and semi-trailers | X3: Manufacture of other transport equipment | Y3: Manufacture of furniture | Z3: Repair and installation of machinery and equipment | AA3: Electricity, gas, steam and air conditioning supply | AB3: Water collection, treatment and supply | AC3: Sewerage, waste management, remediation activities | AD3: Construction | AE3: Wholesale and retail trade and repair of motor vehicles and motorcycl… | AF3: Wholesale trade, except of motor vehicles and motorcycles | AG3: Retail trade, except of motor vehicles and motorcycles | AH3: Land transport and transport via pipelines | AI3: Water transport | AJ3: Air transport | AK3: Warehousing and support activities for transportation | AL3: Postal and courier activities | AM3: Accommodation and food service activities | AN3: Publishing activities | AO3: Motion picture, video, television programme production | AP3: Telecommunications | AQ3: Computer programming, consultancy, and information service activities | AR3: Financial service activities, except insurance and pension funding | AS3: Insurance, reinsurance and pension funding, except compulsory social … | AT3: Activities auxiliary to financial services and insurance activities | AU3: Real estate activities | AV3: Legal and accounting activities | AW3: Architectural and engineering activities | AX3: Scientific research and development | AY3: Advertising and market research | AZ3: Other professional, scientific and technical activities | BA3: Rental and leasing activities | BB3: Employment activities | BC3: Travel agency, tour operator reservation service and related activiti… | BD3: Security and investigation, service and landscape, office administrat… | BE3: Public administration and defence | BF3: Education | BG3: Human health activities | BH3: Residential care activities and social work activities without accomm… | BI3: Creative, arts and entertainment activities | BJ3: Sports activities and amusement and recreation activities | BK3: Activities of membership organisations | BL3: Repair of computers and personal and household goods | BM3: Other personal service activities | BN3: Activities of households as employers | BO3: Activities of extraterritorial organisations and bodies | BP3: Government consumption | BQ3: Household consumption | BR3: NPISH consumption | BS3: Gross fixed capital formation | BT3: Changes in inventories & valuables
A4: A01 | B4: Crop and animal production, hunting and related service activities | C4: EU27 | D4: 67150.7 | E4: 614.2 | F4: 95.6 | G4: 86 | H4: 253682.6 | I4: 2698.5 | J4: 390.8 | K4: 262.2 | L4: 24.9 | M4: 120.2 | N4: 2182.4 | O4: 503.7 | P4: 1483 | Q4: 149.3 | R4: 212.6 | S4: 199.2 | T4: 184.8 | U4: 118.3 | V4: 250.5 | W4: 306.8 | X4: 97.9 | Y4: 250 | Z4: 77.4 | AA4: 1620.4 | AB4: 48.2 | AC4: 152 | AD4: 1405.8 | AE4: 130.6 | AF4: 7522.9 | AG4: 3588.9 | AH4: 354.6 | AI4: 115.1 | AJ4: 112.1 | AK4: 374.9 | AL4: 28.2 | AM4: 15037.7 | AN4: 46.8 | AO4: 89.2 | AP4: 96.6 | AQ4: 237.5 | AR4: 62.2 | AS4: 58.3 | AT4: 42.8 | AU4: 428.7 | AV4: 325.7 | AW4: 220.3 | AX4: 260.1 | AY4: 55 | AZ4: 151.3 | BA4: 115.6 | BB4: 54.1 | BC4: 102.1 | BD4: 3732.3 | BE4: 1535.3 | BF4: 749.5 | BG4: 1154 | BH4: 863.1 | BI4: 272.1 | BJ4: 343.6 | BK4: 149.3 | BL4: 11.9 | BM4: 188.8 | BP4: 1987.4 | BQ4: 143744.9 | BR4: 54.7 | BS4: 9052.5 | BT4: 5093.2
A5: A01 | B5: Crop and animal production, hunting and related service activities | C5: NO | D5: 1.7 | E5: 6.6 | H5: 9.3 | J5: 19.3 | K5: 5.7 | N5: 0.3 | O5: 0.4 | P5: 0.2 | S5: 0.1 | Y5: 0.8 | AA5: 0.2 | AD5: 0.5 | AF5: 0.1 | AM5: 0.7 | BD5: 0.2 | BE5: 0.1 | BG5: 0.2 | BH5: 0.1 | BM5: 0.1 | BP5: 0.2 | BQ5: 14.1 | BS5: 0.1 | BT5: 0.5
A6: A01 | B6: Crop and animal production, hunting and related service activities | C6: CH | D6: 16.2 | E6: 0.3 | F6: 0.1 | G6: 0.1 | H6: 97.4 | I6: 1.6 | J6: 0.2 | K6: 0.2 | L6: 0.1 | M6: 0.3 | N6: 1.8 | O6: 0.8 | P6: 3.4 | Q6: 0.3 | R6: 0.3 | S6: 0.3 | T6: 0.3 | U6: 0.3 | V6: 0.4 | W6: 0.4 | X6: 0.2 | Y6: 0.4 | Z6: 0.2 | AA6: 0.7 | AB6: 0.1 | AC6: 0.2 | AD6: 0.5 | AE6: 0.2 | AF6: 1.8 | AG6: 0.7 | AH6: 0.2 | AI6: 0.3 | AJ6: 0.2 | AK6: 0.2 | AL6: 0.1 | AM6: 5.8 | AN6: 0.2 | AO6: 0.3 | AP6: 0.2 | AQ6: 0.4 | AR6: 0.1 | AS6: 0.1 | AT6: 0.1 | AU6: 0.1 | AV6: 0.2 | AW6: 0.2 | AX6: 0.2 | AY6: 0.2 | AZ6: 0.2 | BA6: 0.2 | BB6: 0.1 | BC6: 0.2 | BD6: 1.1 | BE6: 0.6 | BF6: 0.4 | BG6: 0.7 | BH6: 0.6 | BI6: 0.3 | BJ6: 0.2 | BK6: 0.1 | BL6: 0.1 | BM6: 0.2 | BP6: 0.7 | BQ6: 79.2 | BS6: 2.3 | BT6: 5.4
A7: A01 | B7: Crop and animal production, hunting and related service activities | C7: UK | D7: 166.7 | E7: 0.7 | G7: 0.1 | H7: 982.3 | I7: 4.9 | J7: 0.2 | K7: 0.6 | L7: 0.1 | M7: 0.8 | N7: 14.2 | O7: 14.9 | P7: 7 | Q7: 0.4 | R7: 0.7 | S7: 0.7 | T7: 1.2 | U7: 0.6 | V7: 1.2 | W7: 1.5 | X7: 0.4 | Y7: 1 | Z7: 0.3 | AA7: 2 | AB7: 0.1 | AC7: 0.6 | AD7: 4.1 | AE7: 0.5 | AF7: 28.7 | AG7: 2.2 | AH7: 1 | AI7: 0.5 | AJ7: 0.6 | AK7: 1.1 | AL7: 0.2 | AM7: 24.3 | AN7: 1.1 | AO7: 0.7 | AP7: 0.7 | AQ7: 7 | AR7: 0.7 | AS7: 0.5 | AT7: 0.8 | AU7: 0.7 | AV7: 4.7 | AW7: 1.5 | AX7: 0.6 | AY7: 0.5 | AZ7: 0.5 | BA7: 1.1 | BB7: 0.2 | BC7: 0.7 | BD7: 6.2 | BE7: 2.7 | BF7: 1.4 | BG7: 7.8 | BH7: 4.1 | BI7: 0.7 | BJ7: 0.5 | BK7: 0.3 | BM7: 0.4 | BP7: 54 | BQ7: 562.4 | BS7: 28.6 | BT7: 34
A8: A01 | B8: Crop and animal production, hunting and related service activities | C8: ME | D8: 1 | H8: 6.2 | I8: 0.1 | J8: 0.3 | N8: 0.2 | P8: 0.1 | AF8: 0.3 | AM8: 0.6 | BD8: 0.1 | BE8: 0.1 | BG8: 0.1 | BH8: 0.1 | BP8: 0.1 | BQ8: 10.3 | BS8: 0.1 | BT8: 0.4
A9: A01 | B9: Crop and animal production, hunting and related service activities | C9: MK | D9: 28.7 | E9: 0.1 | H9: 65.6 | I9: 0.7 | N9: 1.5 | O9: 0.2 | P9: 1.5 | Q9: 0.1 | AA9: 0.8 | AD9: 0.5 | AF9: 2.3 | AG9: 0.3 | AH9: 0.1 | AI9: 0.1 | AM9: 4.2 | BA9: 0.1 | BD9: 0.6 | BE9: 0.4 | BF9: 0.2 | BG9: 0.6 | BH9: 0.3 | BI9: 0.1 | BP9: 0.5 | BQ9: 94.8 | BS9: 1.3 | BT9: 2.2
A10: A01 | B10: Crop and animal production, hunting and related service activities | C10: AL | D10: 8.2 | E10: 0.1 | F10: 0.1 | H10: 44.1 | I10: 1.1 | K10: 0.1 | M10: 0.1 | N10: 1.6 | O10: 0.5 | P10: 0.5 | Y10: 0.1 | AA10: 0.3 | AD10: 0.1 | AF10: 1.3 | AG10: 0.2 | AH10: 0.1 | AI10: 0.1 | AM10: 3.5 | BC10: 0.1 | BD10: 0.2 | BE10: 0.2 | BF10: 0.1 | BG10: 0.3 | BH10: 0.2 | BJ10: 0.1 | BP10: 0.4 | BQ10: 57.4 | BS10: 0.9 | BT10: 0.9
A11: A01 | B11: Crop and animal production, hunting and related service activities | C11: RS | D11: 60.9 | E11: 0.3 | H11: 379.1 | I11: 10.5 | J11: 0.2 | K11: 0.3 | M11: 0.1 | N11: 5.2 | O11: 1.2 | P11: 8.2 | Q11: 0.1 | R11: 0.1 | S11: 0.2 | T11: 0.2 | U11: 0.2 | V11: 0.3 | W11: 0.2 | Y11: 0.7 | AA11: 0.7 | AC11: 0.2 | AD11: 0.3 | AE11: 0.1 | AF11: 6.5 | AG11: 0.8 | AH11: 0.1 | AI11: 0.1 | AK11: 0.1 | AM11: 6.4 | AN11: 0.1 | AP11: 0.1 | AQ11: 0.8 | AU11: 0.1 | AV11: 0.3 | AX11: 0.1 | AY11: 0.1 | AZ11: 0.1 | BD11: 1.8 | BE11: 1 | BF11: 0.4 | BG11: 0.8 | BH11: 0.7 | BI11: 0.2 | BK11: 0.1 | BM11: 0.1 | BP11: 2.2 | BQ11: 254.4 | BS11: 6.7 | BT11: 12.9
A12: A01 | B12: Crop and animal production, hunting and related service activities | C12: TR | D12: 106 | E12: 0.6 | F12: 0.2 | H12: 409.8 | I12: 8.4 | J12: 0.1 | K12: 0.3 | M12: 0.2 | N12: 8.2 | O12: 1.6 | P12: 6.8 | Q12: 0.1 | U12: 0.1 | V12: 0.1 | Y12: 0.5 | AA12: 3.3 | AC12: 0.2 | AD12: 0.5 | AF12: 8.4 | AG12: 1.6 | AH12: 0.4 | AI12: 0.4 | AK12: 0.1 | AM12: 21.6 | AO12: 0.1 | AQ12: 0.1 | AU12: 0.2 | AV12: 0.2 | AX12: 0.2 | AY12: 0.1 | AZ12: 0.1 | BA12: 0.1 | BD12: 2.4 | BE12: 2.3 | BF12: 1.1 | BG12: 3.5 | BH12: 2 | BI12: 0.2 | BJ12: 0.3 | BK12: 0.2 | BM12: 0.2 | BP12: 0.8 | BQ12: 518.4 | BS12: 8.8 | BT12: 15.3
A13: A01 | B13: Crop and animal production, hunting and related service activities | C13: RU | D13: 35.4 | E13: 0.2 | H13: 207 | I13: 3.9 | J13: 0.1 | K13: 0.2 | M13: 1.3 | N13: 5.9 | O13: 0.7 | P13: 3.3 | Q13: 0.1 | R13: 0.5 | S13: 0.2 | T13: 0.1 | U13: 0.1 | V13: 0.2 | W13: 0.2 | Y13: 0.4 | AA13: 2.2 | AC13: 0.2 | AD13: 0.4 | AE13: 0.1 | AF13: 2.4 | AG13: 0.6 | AH13: 0.4 | AI13: 0.3 | AJ13: 0.1 | AK13: 0.5 | AM13: 5.8 | AN13: 0.1 | AP13: 0.1 | AQ13: 0.3 | AR13: 0.1 | AU13: 0.1 | AV13: 0.2 | AX13: 0.1 | AY13: 0.1 | BA13: 0.1 | BD13: 0.7 | BE13: 0.6 | BF13: 0.4 | BG13: 0.8 | BH13: 0.4 | BI13: 0.1 | BJ13: 0.1 | BK13: 0.1 | BM13: 0.1 | BP13: 0.1 | BQ13: 184.9 | BS13: 4.8 | BT13: 2.8
A14: A01 | B14: Crop and animal production, hunting and related service activities | C14: ZA | D14: 53.1 | E14: 0.9 | H14: 435.2 | I14: 5.9 | J14: 0.2 | K14: 0.3 | M14: 0.1 | N14: 11.8 | O14: 1.5 | P14: 6.6 | Q14: 0.2 | S14: 0.1 | T14: 0.1 | U14: 0.1 | V14: 0.2 | W14: 0.4 | Y14: 0.5 | AA14: 1.3 | AC14: 0.2 | AD14: 0.4 | AE14: 0.1 | AF14: 2.7 | AG14: 0.7 | AH14: 0.2 | AI14: 0.4 | AJ14: 0.1 | AK14: 0.1 | AM14: 20.5 | AO14: 0.2 | AP14: 0.1 | AQ14: 0.4 | AU14: 0.1 | AV14: 0.2 | AW14: 0.1 | AX14: 0.1 | AY14: 0.1 | AZ14: 0.1 | BA14: 0.2 | BC14: 0.6 | BD14: 3.7 | BE14: 3.2 | BF14: 0.8 | BG14: 2.6 | BH14: 2.3 | BI14: 0.4 | BJ14: 0.4 | BK14: 0.2 | BM14: 0.3 | BP14: 1.4 | BQ14: 325.9 | BS14: 7.6 | BT14: 8.8
A15: A01 | B15: Crop and animal production, hunting and related service activities | C15: CA | D15: 75.6 | E15: 0.4 | F15: 0.1 | H15: 575 | I15: 14.9 | J15: 0.3 | K15: 0.7 | L15: 0.1 | M15: 2.2 | N15: 14.1 | O15: 4 | P15: 10.5 | Q15: 0.3 | R15: 1 | S15: 0.3 | T15: 0.2 | U15: 0.2 | V15: 0.3 | W15: 0.5 | X15: 0.3 | Y15: 1 | Z15: 0.1 | AA15: 1.1 | AC15: 0.3 | AD15: 0.9 | AE15: 0.1 | AF15: 7.4 | AG15: 0.6 | AH15: 0.7 | AI15: 0.1 | AK15: 0.5 | AM15: 12.2 | AN15: 0.1 | AO15: 0.1 | AQ15: 0.2 | AU15: 0.1 | AV15: 0.3 | AW15: 0.1 | AX15: 0.2 | AY15: 0.1 | AZ15: 0.1 | BA15: 0.1 | BD15: 1.5 | BE15: 1.1 | BF15: 0.7 | BG15: 2.3 | BH15: 1.3 | BI15: 0.1 | BJ15: 0.1 | BK15: 0.1 | BM15: 0.2 | BP15: 8.7 | BQ15: 316.7 | BS15: 12.3 | BT15: 19.6
A16: A01 | B16: Crop and animal production, hunting and related service activities | C16: US | D16: 231 | E16: 3.7 | F16: 3.1 | H16: 2541.1 | I16: 28.3 | J16: 3.8 | K16: 1.7 | N16: 32.9 | O16: 5.4 | P16: 28.5 | Q16: 0.1 | S16: 0.1 | W16: 0.2 | Y16: 1.8 | AA16: 2.1 | AC16: 0.6 | AD16: 1 | AF16: 11.2 | AG16: 1.5 | AH16: 0.2 | AI16: 2 | AJ16: 0.1 | AK16: 0.2 | AM16: 73.8 | AO16: 0.4 | AR16: 0.1 | AU16: 0.2 | AV16: 0.5 | AX16: 0.4 | AY16: 0.1 | AZ16: 0.3 | BC16: 0.3 | BD16: 17.2 | BE16: 15.5 | BF16: 3.3 | BG16: 11.2 | BH16: 9.6 | BI16: 1.8 | BJ16: 0.3 | BK16: 0.7 | BM16: 1.1 | BP16: 8.9 | BQ16: 1735 | BS16: 53.2 | BT16: 88.9
A17: A01 | B17: Crop and animal production, hunting and related service activities | C17: MX | D17: 17.5 | E17: 0.2 | H17: 148.9 | I17: 1 | K17: 0.1 | M17: 0.1 | N17: 1.2 | O17: 0.2 | P17: 1.1 | Y17: 0.1 | AA17: 0.3 | AD17: 0.2 | AF17: 0.5 | AG17: 0.2 | AI17: 0.1 | AM17: 3.9 | BD17: 1 | BE17: 0.7 | BF17: 0.3 | BG17: 0.7 | BH17: 0.5 | BI17: 0.1 | BJ17: 0.1 | BM17: 0.1 | BP17: 0.2 | BQ17: 124.1 | BS17: 4.6 | BT17: 6.8
A18: A01 | B18: Crop and animal production, hunting and related service activities | C18: AR | D18: 19.4 | E18: 0.1 | H18: 136.3 | I18: 2.3 | K18: 0.1 | N18: 2.3 | O18: 0.4 | P18: 2.2 | Y18: 0.1 | AA18: 0.6 | AD18: 0.1 | AF18: 0.8 | AG18: 0.2 | AM18: 3.2 | BD18: 0.6 | BE18: 0.5 | BF18: 0.2 | BG18: 0.4 | BH18: 0.3 | BP18: 0.4 | BQ18: 104.6 | BS18: 4 | BT18: 5.7
A19: A01 | B19: Crop and animal production, hunting and related service activities | C19: BR | D19: 194.2 | E19: 1.9 | H19: 1687.8 | I19: 29.3 | J19: 13.6 | K19: 17.6 | M19: 4.2 | N19: 30.6 | O19: 3.5 | P19: 21.5 | Q19: 0.2 | R19: 0.5 | S19: 0.1 | V19: 0.1 | W19: 0.3 | Y19: 2 | Z19: 0.1 | AA19: 2.8 | AC19: 0.6 | AD19: 2.4 | AF19: 7.5 | AG19: 1.5 | AH19: 0.3 | AI19: 0.7 | AJ19: 0.1 | AK19: 0.2 | AM19: 43.4 | AO19: 0.1 | AQ19: 0.1 | AU19: 0.3 | AV19: 0.5 | AW19: 0.1 | AX19: 0.3 | AY19: 0.2 | AZ19: 0.2 | BC19: 0.1 | BD19: 8.1 | BE19: 6.2 | BF19: 2.6 | BG19: 6.2 | BH19: 5 | BI19: 0.6 | BJ19: 0.5 | BK19: 0.3 | BM19: 0.6 | BP19: 2.3 | BQ19: 1118 | BS19: 41.1 | BT19: 61.4
A20: A01 | B20: Crop and animal production, hunting and related service activities | C20: CN | D20: 70.5 | E20: 0.6 | H20: 575.6 | I20: 10.7 | J20: 0.1 | K20: 0.3 | N20: 5 | O20: 1.7 | P20: 8.3 | Q20: 0.1 | Y20: 0.7 | AA20: 1.7 | AC20: 0.2 | AD20: 0.2 | AF20: 3.6 | AG20: 0.6 | AH20: 0.1 | AI20: 0.2 | AK20: 0.1 | AM20: 12 | AU20: 0.1 | AV20: 0.2 | AX20: 0.1 | AZ20: 0.1 | BD20: 3.2 | BE20: 2.1 | BF20: 0.7 | BG20: 1.9 | BH20: 1.5 | BI20: 0.2 | BJ20: 0.1 | BK20: 0.1 | BM20: 0.2 | BP20: 1.7 | BQ20: 380.9 | BS20: 12.7 | BT20: 22
A21: A01 | B21: Crop and animal production, hunting and related service activities | C21: JP | D21: 1.2 | H21: 10.3 | I21: 0.1 | N21: 0.1 | P21: 0.1 | AF21: 0.1 | AM21: 0.5 | BD21: 0.1 | BG21: 0.1 | BH21: 0.1 | BP21: 0.1 | BQ21: 6.9 | BS21: 0.1 | BT21: 0.2
A22: A01 | B22: Crop and animal production, hunting and related service activities | C22: KR | D22: 0.8 | H22: 5.9 | N22: 0.1 | P22: 0.1 | AM22: 0.3 | BD22: 0.1 | BQ22: 4.7 | BS22: 0.1 | BT22: 0.2
A23: A01 | B23: Crop and animal production, hunting and related service activities | C23: IN | D23: 25.2 | E23: 0.3 | H23: 183.8 | I23: 3.2 | K23: 0.1 | N23: 1.9 | O23: 0.5 | P23: 3 | Y23: 0.2 | AA23: 0.6 | AD23: 0.1 | AF23: 1.2 | AG23: 0.3 | AI23: 0.1 | AM23: 5 | AX23: 0.1 | AY23: 0.1 | BD23: 1.3 | BE23: 1 | BF23: 0.3 | BG23: 0.7 | BH23: 0.6 | BI23: 0.1 | BJ23: 0.1 | BK23: 0.1 | BM23: 0.1 | BP23: 0.6 | BQ23: 138.1 | BS23: 3.2 | BT23: 7
A24: A01 | B24: Crop and animal production, hunting and related service activities | C24: ID | D24: 43.5 | E24: 0.3 | H24: 229.8 | I24: 3 | J24: 0.1 | K24: 0.1 | N24: 5.2 | O24: 0.5 | P24: 10.7 | Q24: 0.1 | Y24: 0.2 | AA24: 1.8 | AC24: 0.1 | AD24: 0.1 | AF24: 2.3 | AG24: 0.6 | AH24: 0.1 | AI24: 0.1 | AM24: 7.1 | AO24: 0.5 | AU24: 0.1 | AX24: 0.1 | BD24: 1.7 | BE24: 0.9 | BF24: 0.4 | BG24: 0.8 | BH24: 0.6 | BI24: 0.2 | BJ24: 0.1 | BK24: 0.1 | BM24: 0.1 | BP24: 0.1 | BQ24: 183.2 | BS24: 7.5 | BT24: 7.1
A25: A01 | B25: Crop and animal production, hunting and related service activities | C25: SA | D25: 0.2 | H25: 2.2 | AM25: 0.1 | BQ25: 1.8 | BT25: -0.3
A26: A01 | B26: Crop and animal production, hunting and related service activities | C26: AU | D26: 30.2 | E26: 0.4 | H26: 211.7 | I26: 2.1 | M26: 0.3 | N26: 1.8 | O26: 0.3 | P26: 1.6 | R26: 0.1 | Y26: 0.1 | AA26: 0.2 | AD26: 0.1 | AF26: 0.9 | AG26: 0.1 | AH26: 0.1 | AI26: 0.7 | AJ26: 0.1 | AK26: 0.2 | AM26: 6.2 | BD26: 1.8 | BE26: 1.8 | BF26: 0.2 | BG26: 0.9 | BH26: 0.8 | BI26: 0.2 | BK26: 0.1 | BM26: 0.1 | BP26: 0.1 | BQ26: 227.6 | BS26: 4.4 | BT26: 18.2
A27: A01 | B27: Crop and animal production, hunting and related service activities | C27: WRL_REST | D27: 2233.2 | E27: 18.1 | F27: 0.6 | G27: 0.6 | H27: 15073.7 | I27: 176.5 | J27: 3.5 | K27: 9.2 | L27: 0.3 | M27: 6.1 | N27: 195.8 | O27: 29.4 | P27: 203.1 | Q27: 2.5 | R27: 1.3 | S27: 1.6 | T27: 0.6 | U27: 1.5 | V27: 1.9 | W27: 3.1 | X27: 0.4 | Y27: 12.9 | Z27: 0.5 | AA27: 48.6 | AB27: 0.3 | AC27: 4.7 | AD27: 11.1 | AE27: 0.6 | AF27: 101.8 | AG27: 21.6 | AH27: 4 | AI27: 6.7 | AJ27: 0.8 | AK27: 2.7 | AL27: 0.1 | AM27: 415.9 | AN27: 0.3 | AO27: 1.6 | AP27: 0.2 | AQ27: 1 | AR27: 0.3 | AS27: 0.2 | AT27: 0.2 | AU27: 3.2 | AV27: 3.8 | AW27: 0.5 | AX27: 4.1 | AY27: 2.3 | AZ27: 2.2 | BA27: 0.8 | BB27: 0.4 | BC27: 1.8 | BD27: 101.3 | BE27: 61.1 | BF27: 22.4 | BG27: 58.4 | BH27: 47.1 | BI27: 7 | BJ27: 3.5 | BK27: 3.5 | BM27: 6.1 | BP27: 24.2 | BQ27: 12127.6 | BS27: 403.5 | BT27: 631.6
A28: A02 | B28: Forestry and logging | C28: EU27 | D28: 638.8 | E28: 15576.3 | F28: 38.5 | G28: 69.7 | H28: 526.2 | I28: 16.1 | J28: 16502.8 | K28: 6988.6 | L28: 9.9 | M28: 9.5 | N28: 269 | O28: 14.1 | P28: 75.2 | Q28: 34.2 | R28: 31.6 | S28: 32.8 | T28: 9.8 | U28: 17.5 | V28: 21.7 | W28: 47 | X28: 8.1 | Y28: 978.5 | Z28: 5.6 | AA28: 1218.5 | AB28: 5 | AC28: 20 | AD28: 731.7 | AE28: 13.2 | AF28: 273.8 | AG28: 49.2 | AH28: 57.1 | AI28: 2.1 | AJ28: 4.2 | AK28: 26.9 | AL28: 1.9 | AM28: 87.8 | AN28: 2.6 | AO28: 4.9 | AP28: 3.9 | AQ28: 14.4 | AR28: 5.2 | AS28: 1.2 | AT28: 2.1 | AU28: 41.2 | AV28: 14.1 | AW28: 46.6 | AX28: 11.1 | AY28: 4.7 | AZ28: 5.9 | BA28: 4 | BB28: 2.8 | BC28: 2.6 | BD28: 155.7 | BE28: 262.6 | BF28: 31.4 | BG28: 45 | BH28: 16 | BI28: 28.1 | BJ28: 21.4 | BK28: 16 | BL28: 7.4 | BM28: 21.6 | BP28: 1547.1 | BQ28: 11516.8 | BR28: 8.1 | BS28: 487.5 | BT28: 1141.6
A29: A02 | B29: Forestry and logging | C29: NO | D29: 0.4 | E29: 36.8 | H29: 1 | I29: 0.1 | J29: 107.5 | K29: 31.6 | N29: 1 | O29: 0.6 | P29: 0.2 | Q29: 0.1 | S29: 0.3 | Y29: 4.4 | AA29: 1 | AD29: 2.7 | AF29: 0.1 | AH29: 0.1 | AM29: 0.6 | AW29: 0.1 | BD29: 0.6 | BE29: 0.4 | BG29: 0.2 | BH29: 0.2 | BI29: 0.1 | BK29: 0.2 | BM29: 0.3 | BQ29: 27.2 | BT29: 0.7
A30: A02 | B30: Forestry and logging | C30: CH | D30: 0.4 | E30: 1.9 | H30: 2 | I30: 0.1 | J30: 32.1 | K30: 5.7 | N30: 1.8 | O30: 0.1 | P30: 0.2 | Q30: 0.1 | R30: 0.1 | S30: 0.1 | W30: 0.1 | Y30: 0.9 | AA30: 1.4 | AD30: 0.8 | AF30: 0.4 | AG30: 0.1 | AJ30: 0.1 | AM30: 0.3 | AQ30: 0.1 | AW30: 0.1 | BD30: 0.4 | BE30: 0.4 | BG30: 0.1 | BH30: 0.1 | BI30: 0.1 | BK30: 0.1 | BM30: 0.1 | BQ30: 19.2 | BT30: 1.7
A31: A02 | B31: Forestry and logging | C31: UK | D31: 0.9 | E31: 1.7 | H31: 0.5 | J31: 11.8 | K31: 2 | N31: 0.3 | O31: 0.2 | P31: 0.1 | S31: 0.1 | T31: 0.1 | V31: 0.1 | W31: 0.1 | Y31: 0.5 | AA31: 0.4 | AD31: 1.7 | AF31: 0.5 | AG31: 0.1 | AH31: 0.1 | AJ31: 0.3 | AM31: 0.1 | AN31: 0.1 | AQ31: 0.5 | AV31: 0.1 | BA31: 0.1 | BC31: 0.1 | BD31: 0.1 | BE31: 0.5 | BG31: 0.1 | BI31: 0.2 | BQ31: 6.7 | BS31: 0.2 | BT31: 0.7
A32: A02 | B32: Forestry and logging | C32: ME | H32: 0.1 | J32: 0.6 | Y32: 0.2 | AD32: 0.5 | BQ32: 0.2 | BS32: 0.1 | BT32: 0.1
A33: A02 | B33: Forestry and logging | C33: MK | E33: 0.1 | J33: 0.9 | K33: 0.1 | BE33: 0.1 | BI33: 0.1 | BQ33: 0.2 | BS33: 0.1
A34: A02 | B34: Forestry and logging | C34: AL | J34: 0.1
A35: A02 | B35: Forestry and logging | C35: RS | D35: 0.1 | E35: 0.5 | H35: 0.2 | J35: 3.5 | K35: 0.7 | N35: 0.1 | Y35: 0.2 | AA35: 0.2 | AD35: 0.1 | AF35: 0.1 | BE35: 0.1 | BQ35: 1.6 | BT35: 0.4
A36: A02 | B36: Forestry and logging | C36: TR | D36: 0.1 | E36: 0.2 | H36: 0.1 | J36: 1.7 | K36: 0.3 | Y36: 0.1 | AA36: 0.1 | AD36: 0.1 | BE36: 0.1 | BQ36: 1.2
A37: A02 | B37: Forestry and logging | C37: RU | D37: 0.2 | E37: 0.6 | H37: 0.8 | J37: 3.7 | K37: 0.8 | M37: 1 | N37: 0.2 | P37: 0.1 | R37: 0.2 | V37: 0.1 | W37: 0.1 | Y37: 0.2 | AA37: 0.7 | AD37: 0.4 | AF37: 0.2 | AG37: 0.1 | AJ37: 0.1 | AK37: 0.1 | AM37: 0.1 | AQ37: 0.1 | BE37: 0.2 | BI37: 0.1 | BQ37: 3.2 | BS37: 0.1 | BT37: 0.4
A38: A02 | B38: Forestry and logging | C38: ZA | E38: 0.2 | J38: 2 | K38: 0.2 | P38: 0.1 | AA38: 0.1 | BE38: 0.2 | BI38: 0.1 | BQ38: 0.5
A39: A02 | B39: Forestry and logging | C39: CA | D39: 8.4 | E39: 0.5 | H39: 63.4 | I39: 1.7 | J39: 5.4 | K39: 0.6 | N39: 1.1 | O39: 0.5 | P39: 1.2 | S39: 0.1 | T39: 0.1 | V39: 0.1 | W39: 0.1 | Y39: 0.3 | AA39: 0.1 | AD39: 0.7 | AF39: 1 | AG39: 0.1 | AJ39: 0.1 | AK39: 0.1 | AM39: 1.1 | AN39: 0.1 | AQ39: 0.4 | AV39: 0.2 | AX39: 0.1 | BA39: 0.1 | BD39: 0.4 | BE39: 0.8 | BF39: 0.1 | BG39: 0.2 | BH39: 0.2 | BI39: 0.4 | BP39: 1 | BQ39: 34.3 | BS39: 1.7 | BT39: 2.2
A40: A02 | B40: Forestry and logging | C40: US | D40: 3.4 | E40: 4.6 | H40: 1.9 | J40: 50.6 | K40: 10.9 | N40: 1.9 | O40: 0.4 | P40: 0.5 | Q40: 0.1 | S40: 0.2 | Y40: 2 | AA40: 1.4 | AD40: 6.2 | AF40: 0.3 | AG40: 0.1 | AH40: 0.1 | AJ40: 0.2 | AM40: 0.3 | AW40: 0.1 | BD40: 0.4 | BE40: 1.6 | BG40: 0.1 | BH40: 0.1 | BI40: 0.8 | BK40: 0.1 | BM40: 0.1 | BQ40: 22.7 | BT40: 4.8
...

Sheet FIGARO raw 2022
A1: FIGARO raw dataset — 2022, € million (naio_10_fcp_ii4, condensed to EU-27 as one economy; extract of 2026-07-07). One row per product row × origin, the 24 origins contiguous per product row: origin EU27 is intra-EU supply (and carries the six value-added rows); every other origin is that partner's exports into EU-27 use. Zero cells are left blank. Reference year only — the model reads 2023. To model 2022 instead, repoint the Z-sheet formulas (same layout, same stride).
A2: Row code | B2: Row label | C2: Origin | D2: A01 | E2: A02 | F2: A03 | G2: B | H2: C10-12 | I2: C13-15 | J2: C16 | K2: C17 | L2: C18 | M2: C19 | N2: C20 | O2: C21 | P2: C22 | Q2: C23 | R2: C24 | S2: C25 | T2: C26 | U2: C27 | V2: C28 | W2: C29 | X2: C30 | Y2: C31_32 | Z2: C33 | AA2: D35 | AB2: E36 | AC2: E37-39 | AD2: F | AE2: G45 | AF2: G46 | AG2: G47 | AH2: H49 | AI2: H50 | AJ2: H51 | AK2: H52 | AL2: H53 | AM2: I | AN2: J58 | AO2: J59_60 | AP2: J61 | AQ2: J62_63 | AR2: K64 | AS2: K65 | AT2: K66 | AU2: L | AV2: M69_70 | AW2: M71 | AX2: M72 | AY2: M73 | AZ2: M74_75 | BA2: N77 | BB2: N78 | BC2: N79 | BD2: N80-82 | BE2: O84 | BF2: P85 | BG2: Q86 | BH2: Q87_88 | BI2: R90-92 | BJ2: R93 | BK2: S94 | BL2: S95 | BM2: S96 | BN2: T | BO2: U | BP2: P3_S13 | BQ2: P3_S14 | BR2: P3_S15 | BS2: P51G | BT2: P5M
